Workbook

Sheet detalle CIE10
A1: CIE_10 | B1: Descriptor
A2: J00-J06
A3: J00X | B3: RINOFARINGITIS AGUDA (RESFRIADO COMUN)
A4: J010 | B4: SINUSITIS MAXILAR AGUDA
A5: J011 | B5: SINUSITIS FRONTAL AGUDA
A6: J012 | B6: SINUSITIS ETMOIDAL AGUDA
A7: J013 | B7: SINUSITIS ESFENOIDAL AGUDA
A8: J014 | B8: PANSINUSITIS AGUDA
A9: J018 | B9: OTRAS SINUSITIS AGUDAS
A10: J019 | B10: SINUSITIS AGUDA, NO ESPECIFICADA
A11: J020 | B11: FARINGITIS ESTREPTOCOCICA
A12: J028 | B12: FARINGITIS AGUDA DEBIDA A OTROS MICROORGANISMOS ESPECIFICADOS
A13: J029 | B13: FARINGITIS AGUDA, NO ESPECIFICADA
A14: J030 | B14: AMIGDALITIS ESTREPTOCOCICA
... A24: J069 | B24: INFECCION AGUDA DE LAS VÍAS RESPIRATORIAS SUPERIORES, NO ESPECIFICADA
A26: J09-J11
A27: J09X | B27: INFLUENZA DEBIDA A CIERTOS VIRUS DE LA INFLUENZA IDENTIFICADOS
A28: J100 | B28: INFLUENZA CON NEUMONIA, DEBIDA A VIRUS DE LA INFLUENZA IDENTIFICADO
A29: J101 | B29: INFLUENZA CON OTRAS MANIFESTACIONES RESPIRATORIAS, DEBIDA A VIRUS DE LA INFLUENZA IDENTIFICADO
A30: J108 | B30: INFLUENZA, CON OTRAS MANIFESTACIONES, DEBIDA A VIRUS DE LA INFLUENZA IDENTIFICADO
A31: J110 | B31: INFLUENZA CON NEUMONIA, VIRUS NO IDENTIFICADO
A32: J111 | B32: INFLUENZA CON OTRAS MANIFESTACIONES RESPIRATORIAS, VIRUS NO IDENTIFICADO
A33: J118 | B33: INFLUENZA CON OTRAS MANIFESTACIONES, VIRUS NO IDENTIFICADO
A36: J12-J18
A37: J120 | B37: NEUMONIA DEBIDA A ADENOVIRUS
A38: J121 | B38: NEUMONIA DEBIDA A VIRUS SINCICIAL RESPIRATORIO
A39: J122 | B39: NEUMONIA DEBIDA A VIRUS PARAINFLUENZA
A40: J123 | B40: NEUMONÍA DEBIDA A METANEUMOVIRUS HUMANO
A41: J128 | B41: NEUMONIA DEBIDA A OTROS VIRUS
A42: J129 | B42: NEUMONIA VIRAL, NO ESPECIFICADA (VIRUS)
A43: J13X | B43: NEUMONIA DEBIDA A STREPTOCOCCUS PNEUMONIAE
A44: J14X | B44: NEUMONIA DEBIDA A HAEMOPHILUS INFLUENZAE
A45: J150 | B45: NEUMONIA DEBIDA A KLEBSIELLA PNEUMONIAE
A46: J151 | B46: NEUMONIA DEBIDA A PSEUDOMONAS
A47: J152 | B47: NEUMONIA DEBIDA A ESTAFILOCOCOS
A48: J153 | B48: NEUMONIA DEBIDA A ESTREPTOCOCOS DEL GRUPO B
... A61: J189 | B61: NEUMONIA, NO ESPECIFICADA
A64: J20-J21
A65: J200 | B65: BRONQUITIS AGUDA DEBIDA A MYCOPLASMA PNEUMONIAE
A66: J201 | B66: BRONQUITIS AGUDA DEBIDA A HAEMOPHILUS INFLUENZAE
...

Sheet FORMATO
A2: X X X X X | B2: 1 | C2: =+B2+1 -> 2 | D2: =+C2+1 -> 3 | E2: =+D2+1 -> 4 | F2: =+E2+1 -> 5 | G2: =+F2+1 -> 6 | H2: =+G2+1 -> 7 | I2: =+H2+1 -> 8 | J2: =+I2+1 -> 9 | ... AA2: =+Z2+1 -> 26 | AB2: 27 | AC2: =+AB2+1 -> 28 | AD2: 29 | AE2: 30 | AF2: 31 | AG2: TOTAL
A3: Total de Inscritos | B3: =SUM(B4:B27) -> 0 | C3: =SUM(C4:C27) -> 0 | D3: =SUM(D4:D27) -> 0 | E3: =SUM(E4:E27) -> 0 | F3: =SUM(F4:F27) -> 0 | G3: =SUM(G4:G27) -> 0 | H3: =SUM(H4:H27) -> 0 | I3: =SUM(I4:I27) -> 0 | ... AF3: =SUM(AF4:AF27) -> 0 | AG3: =SUM(B3:AF3) -> 0
A4: 08:00 | AG4: =SUM(B4:AF4) -> 0
A5: 09:00 | AG5: =SUM(B5:AF5) -> 0
A6: 10:00 | AG6: =SUM(B6:AF6) -> 0
A7: 11:00 | AG7: =SUM(B7:AF7) -> 0
A8: 12:00 | AG8: =SUM(B8:AF8) -> 0
A9: 13:00 | AG9: =SUM(B9:AF9) -> 0
A10: 14:00 | AG10: =SUM(B10:AF10) -> 0
A11: 15:00 | AG11: =SUM(B11:AF11) -> 0
A12: 16:00 | AG12: =SUM(B12:AF12) -> 0
A13: 17:00 | AG13: =SUM(B13:AF13) -> 0
A14: 18:00 | AG14: =SUM(B14:AF14) -> 0
A15: 19:00 | AG15: =SUM(B15:AF15) -> 0
... A27: 07:00 | AG27: =SUM(B27:AF27) -> 0
A28: Total de atendidos | B28: =SUM(B29:B52) -> 0 | C28: =SUM(C29:C52) -> 0 | D28: =SUM(D29:D52) -> 0 | E28: =SUM(E29:E52) -> 0 | F28: =SUM(F29:F52) -> 0 | G28: =SUM(G29:G52) -> 0 | H28: =SUM(H29:H52) -> 0 | I28: =SUM(I29:I52) -> 0 | ... AF28: =SUM(AF29:AF52) -> 0 | AG28: =SUM(B28:AF28) -> 0
A29: 08:00 | AG29: =SUM(B29:AF29) -> 0
A30: 09:00 | AG30: =SUM(B30:AF30) -> 0
A31: 10:00 | AG31: =SUM(B31:AF31) -> 0
A32: 11:00 | AG32: =SUM(B32:AF32) -> 0
A33: 12:00 | AG33: =SUM(B33:AF33) -> 0
A34: 13:00 | AG34: =SUM(B34:AF34) -> 0
A35: 14:00 | AG35: =SUM(B35:AF35) -> 0
A36: 15:00 | AG36: =SUM(B36:AF36) -> 0
A37: 16:00 | AG37: =SUM(B37:AF37) -> 0
A38: 17:00 | AG38: =SUM(B38:AF38) -> 0
A39: 18:00 | AG39: =SUM(B39:AF39) -> 0
A40: 19:00 | AG40: =SUM(B40:AF40) -> 0
... A52: 07:00 | AG52: =SUM(B52:AF52) -> 0
A53: Total de NSP | B53: =SUM(B54:B77) -> 0 | C53: =SUM(C54:C77) -> 0 | D53: =SUM(D54:D77) -> 0 | E53: =SUM(E54:E77) -> 0 | F53: =SUM(F54:F77) -> 0 | G53: =SUM(G54:G77) -> 0 | H53: =SUM(H54:H77) -> 0 | I53: =SUM(I54:I77) -> 0 | ... AF53: =SUM(AF54:AF77) -> 0 | AG53: =SUM(B53:AF53) -> 0
A54: 08:00 | AG54: =SUM(B54:AF54) -> 0
A55: 09:00 | AG55: =SUM(B55:AF55) -> 0
A56: 10:00 | AG56: =SUM(B56:AF56) -> 0
A57: 11:00 | AG57: =SUM(B57:AF57) -> 0
A58: 12:00 | AG58: =SUM(B58:AF58) -> 0
A59: 13:00 | AG59: =SUM(B59:AF59) -> 0
A60: 14:00 | AG60: =SUM(B60:AF60) -> 0
A61: 15:00 | AG61: =SUM(B61:AF61) -> 0
A62: 16:00 | AG62: =SUM(B62:AF62) -> 0
A63: 17:00 | AG63: =SUM(B63:AF63) -> 0
...

Sheet CONSOLIDADO
A2: 2019 | B2: ENERO | C2: FEBRERO | D2: MARZO | E2: ABRIL | F2: MAYO | G2: JUNIO | H2: JULIO | I2: AGOSTO | J2: SEPTIEMBRE | K2: OCTUBRE | L2: NOVIEMBRE | M2: DICIEMBRE | N2: TOTAL
A3: Total de Inscritos | B3: =+ENERO!AG3 -> 6497 | C3: =+FEBRERO!AG3 -> 5688 | D3: =+MARZO!AG3 -> 6448 | E3: =+ABRIL!AG3 -> 5662 | F3: =+MAYO!AG3 -> 6212 | G3: =+JUNIO!AG3 -> 6358 | H3: =+JULIO!AG3 -> 5478 | I3: =+AGOSTO!AG3 -> 6354 | J3: =+SEPTIEMBRE!AG3 -> 6735 | K3: =+OCTUBRE!AG3 -> 5836 | L3: =+NOVIEMBRE!AG3 -> 5266 | M3: =+DICIEMBRE!AG3 -> 5179 | N3: =SUM(B3:M3) -> 71713
A4: 08:00 | B4: =+ENERO!AG4 -> 52 | C4: =+FEBRERO!AG4 -> 50 | D4: =+MARZO!AG4 -> 54 | E4: =+ABRIL!AG4 -> 50 | F4: =+MAYO!AG4 -> 62 | G4: =+JUNIO!AG4 -> 64 | H4: =+JULIO!AG4 -> 35 | I4: =+AGOSTO!AG4 -> 69 | J4: =+SEPTIEMBRE!AG4 -> 59 | K4: =+OCTUBRE!AG4 -> 44 | L4: =+NOVIEMBRE!AG4 -> 58 | M4: =+DICIEMBRE!AG4 -> 50 | N4: =SUM(B4:M4) -> 647
A5: 09:00 | B5: =+ENERO!AG5 -> 81 | C5: =+FEBRERO!AG5 -> 75 | D5: =+MARZO!AG5 -> 81 | E5: =+ABRIL!AG5 -> 85 | F5: =+MAYO!AG5 -> 120 | G5: =+JUNIO!AG5 -> 125 | H5: =+JULIO!AG5 -> 114 | I5: =+AGOSTO!AG5 -> 121 | J5: =+SEPTIEMBRE!AG5 -> 148 | K5: =+OCTUBRE!AG5 -> 89 | L5: =+NOVIEMBRE!AG5 -> 111 | M5: =+DICIEMBRE!AG5 -> 103 | N5: =SUM(B5:M5) -> 1253
A6: 10:00 | B6: =+ENERO!AG6 -> 108 | C6: =+FEBRERO!AG6 -> 113 | D6: =+MARZO!AG6 -> 108 | E6: =+ABRIL!AG6 -> 148 | F6: =+MAYO!AG6 -> 167 | G6: =+JUNIO!AG6 -> 182 | H6: =+JULIO!AG6 -> 111 | I6: =+AGOSTO!AG6 -> 171 | J6: =+SEPTIEMBRE!AG6 -> 188 | K6: =+OCTUBRE!AG6 -> 136 | L6: =+NOVIEMBRE!AG6 -> 96 | M6: =+DICIEMBRE!AG6 -> 106 | N6: =SUM(B6:M6) -> 1634
A7: 11:00 | B7: =+ENERO!AG7 -> 416 | C7: =+FEBRERO!AG7 -> 309 | D7: =+MARZO!AG7 -> 418 | E7: =+ABRIL!AG7 -> 219 | F7: =+MAYO!AG7 -> 189 | G7: =+JUNIO!AG7 -> 209 | H7: =+JULIO!AG7 -> 149 | I7: =+AGOSTO!AG7 -> 183 | J7: =+SEPTIEMBRE!AG7 -> 250 | K7: =+OCTUBRE!AG7 -> 138 | L7: =+NOVIEMBRE!AG7 -> 169 | M7: =+DICIEMBRE!AG7 -> 138 | N7: =SUM(B7:M7) -> 2787
A8: 12:00 | B8: =+ENERO!AG8 -> 211 | C8: =+FEBRERO!AG8 -> 207 | D8: =+MARZO!AG8 -> 267 | E8: =+ABRIL!AG8 -> 166 | F8: =+MAYO!AG8 -> 190 | G8: =+JUNIO!AG8 -> 210 | H8: =+JULIO!AG8 -> 146 | I8: =+AGOSTO!AG8 -> 196 | J8: =+SEPTIEMBRE!AG8 -> 232 | K8: =+OCTUBRE!AG8 -> 158 | L8: =+NOVIEMBRE!AG8 -> 124 | M8: =+DICIEMBRE!AG8 -> 131 | N8: =SUM(B8:M8) -> 2238
A9: 13:00 | B9: =+ENERO!AG9 -> 206 | C9: =+FEBRERO!AG9 -> 128 | D9: =+MARZO!AG9 -> 191 | E9: =+ABRIL!AG9 -> 159 | F9: =+MAYO!AG9 -> 142 | G9: =+JUNIO!AG9 -> 210 | H9: =+JULIO!AG9 -> 125 | I9: =+AGOSTO!AG9 -> 149 | J9: =+SEPTIEMBRE!AG9 -> 191 | K9: =+OCTUBRE!AG9 -> 125 | L9: =+NOVIEMBRE!AG9 -> 92 | M9: =+DICIEMBRE!AG9 -> 124 | N9: =SUM(B9:M9) -> 1842
A10: 14:00 | B10: =+ENERO!AG10 -> 204 | C10: =+FEBRERO!AG10 -> 174 | D10: =+MARZO!AG10 -> 233 | E10: =+ABRIL!AG10 -> 137 | F10: =+MAYO!AG10 -> 177 | G10: =+JUNIO!AG10 -> 164 | H10: =+JULIO!AG10 -> 123 | I10: =+AGOSTO!AG10 -> 164 | J10: =+SEPTIEMBRE!AG10 -> 187 | K10: =+OCTUBRE!AG10 -> 128 | L10: =+NOVIEMBRE!AG10 -> 110 | M10: =+DICIEMBRE!AG10 -> 101 | N10: =SUM(B10:M10) -> 1902
A11: 15:00 | B11: =+ENERO!AG11 -> 215 | C11: =+FEBRERO!AG11 -> 182 | D11: =+MARZO!AG11 -> 248 | E11: =+ABRIL!AG11 -> 190 | F11: =+MAYO!AG11 -> 179 | G11: =+JUNIO!AG11 -> 204 | H11: =+JULIO!AG11 -> 159 | I11: =+AGOSTO!AG11 -> 222 | J11: =+SEPTIEMBRE!AG11 -> 199 | K11: =+OCTUBRE!AG11 -> 130 | L11: =+NOVIEMBRE!AG11 -> 143 | M11: =+DICIEMBRE!AG11 -> 100 | N11: =SUM(B11:M11) -> 2171
A12: 16:00 | B12: =+ENERO!AG12 -> 205 | C12: =+FEBRERO!AG12 -> 221 | D12: =+MARZO!AG12 -> 261 | E12: =+ABRIL!AG12 -> 179 | F12: =+MAYO!AG12 -> 207 | G12: =+JUNIO!AG12 -> 212 | H12: =+JULIO!AG12 -> 174 | I12: =+AGOSTO!AG12 -> 201 | J12: =+SEPTIEMBRE!AG12 -> 259 | K12: =+OCTUBRE!AG12 -> 164 | L12: =+NOVIEMBRE!AG12 -> 162 | M12: =+DICIEMBRE!AG12 -> 191 | N12: =SUM(B12:M12) -> 2436
A13: 17:00 | B13: =+ENERO!AG13 -> 1136 | C13: =+FEBRERO!AG13 -> 999 | D13: =+MARZO!AG13 -> 1279 | E13: =+ABRIL!AG13 -> 1375 | F13: =+MAYO!AG13 -> 1671 | G13: =+JUNIO!AG13 -> 1704 | H13: =+JULIO!AG13 -> 1517 | I13: =+AGOSTO!AG13 -> 1661 | J13: =+SEPTIEMBRE!AG13 -> 1480 | K13: =+OCTUBRE!AG13 -> 1562 | L13: =+NOVIEMBRE!AG13 -> 1216 | M13: =+DICIEMBRE!AG13 -> 1133 | N13: =SUM(B13:M13) -> 16733
A14: 18:00 | B14: =+ENERO!AG14 -> 581 | C14: =+FEBRERO!AG14 -> 544 | D14: =+MARZO!AG14 -> 585 | E14: =+ABRIL!AG14 -> 640 | F14: =+MAYO!AG14 -> 640 | G14: =+JUNIO!AG14 -> 639 | H14: =+JULIO!AG14 -> 567 | I14: =+AGOSTO!AG14 -> 703 | J14: =+SEPTIEMBRE!AG14 -> 662 | K14: =+OCTUBRE!AG14 -> 547 | L14: =+NOVIEMBRE!AG14 -> 516 | M14: =+DICIEMBRE!AG14 -> 493 | N14: =SUM(B14:M14) -> 7117
... A27: 07:00 | B27: =+ENERO!AG27 -> 49 | C27: =+FEBRERO!AG27 -> 38 | D27: =+MARZO!AG27 -> 39 | E27: =+ABRIL!AG27 -> 22 | F27: =+MAYO!AG27 -> 41 | G27: =+JUNIO!AG27 -> 31 | H27: =+JULIO!AG27 -> 23 | I27: =+AGOSTO!AG27 -> 46 | J27: =+SEPTIEMBRE!AG27 -> 21 | K27: =+OCTUBRE!AG27 -> 25 | L27: =+NOVIEMBRE!AG27 -> 20 | M27: =+DICIEMBRE!AG27 -> 14 | N27: =SUM(B27:M27) -> 369
A28: Total de atendidos | B28: =+ENERO!AG28 -> 5938 | C28: =+FEBRERO!AG28 -> 5319 | D28: =+MARZO!AG28 -> 5734 | E28: =+ABRIL!AG28 -> 5114 | F28: =+MAYO!AG28 -> 5518 | G28: =+JUNIO!AG28 -> 5586 | H28: =+JULIO!AG28 -> 5211 | I28: =+AGOSTO!AG28 -> 5859 | J28: =+SEPTIEMBRE!AG28 -> 6140 | K28: =+OCTUBRE!AG28 -> 5334 | L28: =+NOVIEMBRE!AG28 -> 4817 | M28: =+DICIEMBRE!AG28 -> 4768 | N28: =SUM(B28:M28) -> 65338 | O28: =+N28-65340 -> -2
A29: 08:00 | B29: =+ENERO!AG29 -> 37 | C29: =+FEBRERO!AG29 -> 40 | D29: =+MARZO!AG29 -> 20 | E29: =+ABRIL!AG29 -> 37 | F29: =+MAYO!AG29 -> 42 | G29: =+JUNIO!AG29 -> 31 | H29: =+JULIO!AG29 -> 12 | I29: =+AGOSTO!AG29 -> 37 | J29: =+SEPTIEMBRE!AG29 -> 32 | K29: =+OCTUBRE!AG29 -> 30 | L29: =+NOVIEMBRE!AG29 -> 34 | M29: =+DICIEMBRE!AG29 -> 24 | N29: =SUM(B29:M29) -> 376
A30: 09:00 | B30: =+ENERO!AG30 -> 62 | C30: =+FEBRERO!AG30 -> 66 | D30: =+MARZO!AG30 -> 62 | E30: =+ABRIL!AG30 -> 38 | F30: =+MAYO!AG30 -> 62 | G30: =+JUNIO!AG30 -> 62 | H30: =+JULIO!AG30 -> 61 | I30: =+AGOSTO!AG30 -> 78 | J30: =+SEPTIEMBRE!AG30 -> 73 | K30: =+OCTUBRE!AG30 -> 57 | L30: =+NOVIEMBRE!AG30 -> 68 | M30: =+DICIEMBRE!AG30 -> 56 | N30: =SUM(B30:M30) -> 745
A31: 10:00 | B31: =+ENERO!AG31 -> 85 | C31: =+FEBRERO!AG31 -> 98 | D31: =+MARZO!AG31 -> 93 | E31: =+ABRIL!AG31 -> 97 | F31: =+MAYO!AG31 -> 126 | G31: =+JUNIO!AG31 -> 114 | H31: =+JULIO!AG31 -> 116 | I31: =+AGOSTO!AG31 -> 117 | J31: =+SEPTIEMBRE!AG31 -> 148 | K31: =+OCTUBRE!AG31 -> 99 | L31: =+NOVIEMBRE!AG31 -> 88 | M31: =+DICIEMBRE!AG31 -> 93 | N31: =SUM(B31:M31) -> 1274
A32: 11:00 | B32: =+ENERO!AG32 -> 210 | C32: =+FEBRERO!AG32 -> 215 | D32: =+MARZO!AG32 -> 211 | E32: =+ABRIL!AG32 -> 167 | F32: =+MAYO!AG32 -> 147 | G32: =+JUNIO!AG32 -> 155 | H32: =+JULIO!AG32 -> 114 | I32: =+AGOSTO!AG32 -> 164 | J32: =+SEPTIEMBRE!AG32 -> 207 | K32: =+OCTUBRE!AG32 -> 117 | L32: =+NOVIEMBRE!AG32 -> 109 | M32: =+DICIEMBRE!AG32 -> 105 | N32: =SUM(B32:M32) -> 1921
A33: 12:00 | B33: =+ENERO!AG33 -> 231 | C33: =+FEBRERO!AG33 -> 213 | D33: =+MARZO!AG33 -> 266 | E33: =+ABRIL!AG33 -> 136 | F33: =+MAYO!AG33 -> 155 | G33: =+JUNIO!AG33 -> 119 | H33: =+JULIO!AG33 -> 117 | I33: =+AGOSTO!AG33 -> 142 | J33: =+SEPTIEMBRE!AG33 -> 181 | K33: =+OCTUBRE!AG33 -> 116 | L33: =+NOVIEMBRE!AG33 -> 88 | M33: =+DICIEMBRE!AG33 -> 103 | N33: =SUM(B33:M33) -> 1867
A34: 13:00 | B34: =+ENERO!AG34 -> 185 | C34: =+FEBRERO!AG34 -> 143 | D34: =+MARZO!AG34 -> 144 | E34: =+ABRIL!AG34 -> 110 | F34: =+MAYO!AG34 -> 114 | G34: =+JUNIO!AG34 -> 112 | H34: =+JULIO!AG34 -> 106 | I34: =+AGOSTO!AG34 -> 137 | J34: =+SEPTIEMBRE!AG34 -> 151 | K34: =+OCTUBRE!AG34 -> 116 | L34: =+NOVIEMBRE!AG34 -> 94 | M34: =+DICIEMBRE!AG34 -> 104 | N34: =SUM(B34:M34) -> 1516
A35: 14:00 | B35: =+ENERO!AG35 -> 205 | C35: =+FEBRERO!AG35 -> 164 | D35: =+MARZO!AG35 -> 216 | E35: =+ABRIL!AG35 -> 144 | F35: =+MAYO!AG35 -> 147 | G35: =+JUNIO!AG35 -> 119 | H35: =+JULIO!AG35 -> 111 | I35: =+AGOSTO!AG35 -> 138 | J35: =+SEPTIEMBRE!AG35 -> 167 | K35: =+OCTUBRE!AG35 -> 107 | L35: =+NOVIEMBRE!AG35 -> 119 | M35: =+DICIEMBRE!AG35 -> 124 | N35: =SUM(B35:M35) -> 1761
A36: 15:00 | B36: =+ENERO!AG36 -> 229 | C36: =+FEBRERO!AG36 -> 178 | D36: =+MARZO!AG36 -> 257 | E36: =+ABRIL!AG36 -> 165 | F36: =+MAYO!AG36 -> 164 | G36: =+JUNIO!AG36 -> 147 | H36: =+JULIO!AG36 -> 148 | I36: =+AGOSTO!AG36 -> 142 | J36: =+SEPTIEMBRE!AG36 -> 189 | K36: =+OCTUBRE!AG36 -> 121 | L36: =+NOVIEMBRE!AG36 -> 126 | M36: =+DICIEMBRE!AG36 -> 129 | N36: =SUM(B36:M36) -> 1995
A37: 16:00 | B37: =+ENERO!AG37 -> 233 | C37: =+FEBRERO!AG37 -> 215 | D37: =+MARZO!AG37 -> 211 | E37: =+ABRIL!AG37 -> 150 | F37: =+MAYO!AG37 -> 179 | G37: =+JUNIO!AG37 -> 157 | H37: =+JULIO!AG37 -> 161 | I37: =+AGOSTO!AG37 -> 176 | J37: =+SEPTIEMBRE!AG37 -> 196 | K37: =+OCTUBRE!AG37 -> 127 | L37: =+NOVIEMBRE!AG37 -> 137 | M37: =+DICIEMBRE!AG37 -> 140 | N37: =SUM(B37:M37) -> 2082
A38: 17:00 | B38: =+ENERO!AG38 -> 454 | C38: =+FEBRERO!AG38 -> 445 | D38: =+MARZO!AG38 -> 374 | E38: =+ABRIL!AG38 -> 330 | F38: =+MAYO!AG38 -> 357 | G38: =+JUNIO!AG38 -> 329 | H38: =+JULIO!AG38 -> 365 | I38: =+AGOSTO!AG38 -> 396 | J38: =+SEPTIEMBRE!AG38 -> 360 | K38: =+OCTUBRE!AG38 -> 286 | L38: =+NOVIEMBRE!AG38 -> 288 | M38: =+DICIEMBRE!AG38 -> 300 | N38: =SUM(B38:M38) -> 4284
A39: 18:00 | B39: =+ENERO!AG39 -> 577 | C39: =+FEBRERO!AG39 -> 507 | D39: =+MARZO!AG39 -> 556 | E39: =+ABRIL!AG39 -> 569 | F39: =+MAYO!AG39 -> 646 | G39: =+JUNIO!AG39 -> 650 | H39: =+JULIO!AG39 -> 700 | I39: =+AGOSTO!AG39 -> 705 | J39: =+SEPTIEMBRE!AG39 -> 644 | K39: =+OCTUBRE!AG39 -> 625 | L39: =+NOVIEMBRE!AG39 -> 541 | M39: =+DICIEMBRE!AG39 -> 485 | N39: =SUM(B39:M39) -> 7205
A40: 19:00 | B40: =+ENERO!AG40 -> 572 | C40: =+FEBRERO!AG40 -> 522 | D40: =+MARZO!AG40 -> 592 | E40: =+ABRIL!AG40 -> 648 | F40: =+MAYO!AG40 -> 652 | G40: =+JUNIO!AG40 -> 699 | H40: =+JULIO!AG40 -> 783 | I40: =+AGOSTO!AG40 -> 809 | J40: =+SEPTIEMBRE!AG40 -> 701 | K40: =+OCTUBRE!AG40 -> 737 | L40: =+NOVIEMBRE!AG40 -> 599 | M40: =+DICIEMBRE!AG40 -> 527 | N40: =SUM(B40:M40) -> 7841
... A80: PAR | B80: =+ENERO!AG80 -> 1130 | C80: =+FEBRERO!AG80 -> 619 | D80: =+MARZO!AG80 -> 809 | E80: =+ABRIL!AG80 -> 1168 | F80: =+MAYO!AG80 -> 858 | G80: =+JUNIO!AG80 -> 3 | H80: =+JULIO!AG80 -> 1028 | I80: =+AGOSTO!AG80 -> 726 | J80: =+SEPTIEMBRE!AG80 -> 1033 | K80: =+OCTUBRE!AG80 -> 1105 | L80: =+NOVIEMBRE!AG80 -> 247 | M80: =+DICIEMBRE!AG80 -> 484 | N80: =SUM(B80:M80) -> 9210
A81: TOTAL NSP | B81: =+ENERO!AG81 -> 559 | C81: =+FEBRERO!AG81 -> 369 | D81: =+MARZO!AG81 -> 714 | E81: =+ABRIL!AG81 -> 548 | F81: =+MAYO!AG81 -> 694 | G81: =+JUNIO!AG81 -> 772 | H81: =+JULIO!AG81 -> 267 | I81: =+AGOSTO!AG81 -> 495 | J81: =+SEPTIEMBRE!AG81 -> 596 | K81: =+OCTUBRE!AG81 -> 502 | L81: =+NOVIEMBRE!AG81 -> 450 | M81: =+DICIEMBRE!AG81 -> 411 | N81: =SUM(B81:M81) -> 6377 | O81: =IF(N81<>N53,"*","")
A82: PAR | B82: =+ENERO!AG82 -> 35 | C82: =+FEBRERO!AG82 -> 4 | D82: =+MARZO!AG82 -> 24 | E82: =+ABRIL!AG82 -> 4 | F82: =+MAYO!AG82 -> 0 | G82: =+JUNIO!AG82 -> 0 | H82: =+JULIO!AG82 -> 0 | I82: =+AGOSTO!AG82 -> 0 | J82: =+SEPTIEMBRE!AG82 -> 0 | K82: =+OCTUBRE!AG82 -> 4 | L82: =+NOVIEMBRE!AG82 -> 0 | M82: =+DICIEMBRE!AG82 -> 0 | N82: =SUM(B82:M82) -> 71
A83: SAR | B83: =+ENERO!AG83 -> 524 | C83: =+FEBRERO!AG83 -> 365 | D83: =+MARZO!AG83 -> 690 | E83: =+ABRIL!AG83 -> 544 | F83: =+MAYO!AG83 -> 694 | G83: =+JUNIO!AG83 -> 772 | H83: =+JULIO!AG83 -> 267 | I83: =+AGOSTO!AG83 -> 495 | J83: =+SEPTIEMBRE!AG83 -> 596 | K83: =+OCTUBRE!AG83 -> 498 | L83: =+NOVIEMBRE!AG83 -> 450 | M83: =+DICIEMBRE!AG83 -> 411 | N83: =SUM(B83:M83) -> 6306
A84: NSP PEDIATR. / ADULTOS | B84: =+ENERO!AG84 -> 559 | C84: =+FEBRERO!AG84 -> 369 | D84: =+MARZO!AG84 -> 714 | E84: =+ABRIL!AG84 -> 548 | F84: =+MAYO!AG84 -> 694 | G84: =+JUNIO!AG84 -> 772 | H84: =+JULIO!AG84 -> 267 | I84: =+AGOSTO!AG84 -> 495 | J84: =+SEPTIEMBRE!AG84 -> 596 | K84: =+OCTUBRE!AG84 -> 502 | L84: =+NOVIEMBRE!AG84 -> 450 | M84: =+DICIEMBRE!AG84 -> 411 | N84: =SUM(B84:M84) -> 6377 | O84: =IF(N84<>N82+N83,"*","") | P84: NSP
A85: NSP PEDIATRICOS (<15 AÑOS) | B85: =+ENERO!AG85 -> 108 | C85: =+FEBRERO!AG85 -> 55 | D85: =+MARZO!AG85 -> 162 | E85: =+ABRIL!AG85 -> 120 | F85: =+MAYO!AG85 -> 145 | G85: =+JUNIO!AG85 -> 178 | H85: =+JULIO!AG85 -> 37 | I85: =+AGOSTO!AG85 -> 122 | J85: =+SEPTIEMBRE!AG85 -> 108 | K85: =+OCTUBRE!AG85 -> 116 | L85: =+NOVIEMBRE!AG85 -> 89 | M85: =+DICIEMBRE!AG85 -> 81 | N85: =SUM(B85:M85) -> 1321
A86: NSP ADULTOS | B86: =+ENERO!AG86 -> 451 | C86: =+FEBRERO!AG86 -> 314 | D86: =+MARZO!AG86 -> 552 | E86: =+ABRIL!AG86 -> 428 | F86: =+MAYO!AG86 -> 549 | G86: =+JUNIO!AG86 -> 594 | H86: =+JULIO!AG86 -> 230 | I86: =+AGOSTO!AG86 -> 373 | J86: =+SEPTIEMBRE!AG86 -> 488 | K86: =+OCTUBRE!AG86 -> 386 | L86: =+NOVIEMBRE!AG86 -> 361 | M86: =+DICIEMBRE!AG86 -> 330 | N86: =SUM(B86:M86) -> 5056
A87: NSP CATEGORIZACION | B87: =+ENERO!AG87 -> 559 | C87: =+FEBRERO!AG87 -> 369 | D87: =+MARZO!AG87 -> 714 | E87: =+ABRIL!AG87 -> 548 | F87: =+MAYO!AG87 -> 694 | G87: =+JUNIO!AG87 -> 772 | H87: =+JULIO!AG87 -> 267 | I87: =+AGOSTO!AG87 -> 495 | J87: =+SEPTIEMBRE!AG87 -> 596 | K87: =+OCTUBRE!AG87 -> 502 | L87: =+NOVIEMBRE!AG87 -> 450 | M87: =+DICIEMBRE!AG87 -> 411 | N87: =SUM(B87:M87) -> 6377 | O87: =IF(N87<>N84,"*","")
A88: SIN CATEGORIZACIÓN nsp | B88: =+ENERO!AG88 -> 142 | C88: =+FEBRERO!AG88 -> 84 | D88: =+MARZO!AG88 -> 152 | E88: =+ABRIL!AG88 -> 173 | F88: =+MAYO!AG88 -> 280 | G88: =+JUNIO!AG88 -> 245 | H88: =+JULIO!AG88 -> 122 | I88: =+AGOSTO!AG88 -> 182 | J88: =+SEPTIEMBRE!AG88 -> 194 | K88: =+OCTUBRE!AG88 -> 183 | L88: =+NOVIEMBRE!AG88 -> 121 | M88: =+DICIEMBRE!AG88 -> 122 | N88: =SUM(B88:M88) -> 2000
A89: C2 | B89: =+ENERO!AG89 -> 0 | C89: =+FEBRERO!AG89 -> 0 | D89: =+MARZO!AG89 -> 0 | E89: =+ABRIL!AG89 -> 0 | F89: =+MAYO!AG89 -> 0 | G89: =+JUNIO!AG89 -> 0 | H89: =+JULIO!AG89 -> 0 | I89: =+AGOSTO!AG89 -> 0 | J89: =+SEPTIEMBRE!AG89 -> 0 | K89: =+OCTUBRE!AG89 -> 0 | L89: =+NOVIEMBRE!AG89 -> 0 | M89: =+DICIEMBRE!AG89 -> 0 | N89: =SUM(B89:M89) -> 0
A90: C3 | B90: =+ENERO!AG90 -> 1 | C90: =+FEBRERO!AG90 -> 2 | D90: =+MARZO!AG90 -> 3 | E90: =+ABRIL!AG90 -> 0 | F90: =+MAYO!AG90 -> 4 | G90: =+JUNIO!AG90 -> 3 | H90: =+JULIO!AG90 -> 1 | I90: =+AGOSTO!AG90 -> 2 | J90: =+SEPTIEMBRE!AG90 -> 2 | K90: =+OCTUBRE!AG90 -> 2 | L90: =+NOVIEMBRE!AG90 -> 6 | M90: =+DICIEMBRE!AG90 -> 3 | N90: =SUM(B90:M90) -> 29
A91: C4 | B91: =+ENERO!AG91 -> 204 | C91: =+FEBRERO!AG91 -> 102 | D91: =+MARZO!AG91 -> 257 | E91: =+ABRIL!AG91 -> 156 | F91: =+MAYO!AG91 -> 120 | G91: =+JUNIO!AG91 -> 159 | H91: =+JULIO!AG91 -> 39 | I91: =+AGOSTO!AG91 -> 125 | J91: =+SEPTIEMBRE!AG91 -> 153 | K91: =+OCTUBRE!AG91 -> 141 | L91: =+NOVIEMBRE!AG91 -> 177 | M91: =+DICIEMBRE!AG91 -> 144 | N91: =SUM(B91:M91) -> 1777
A92: C5 | B92: =+ENERO!AG92 -> 212 | C92: =+FEBRERO!AG92 -> 181 | D92: =+MARZO!AG92 -> 302 | E92: =+ABRIL!AG92 -> 219 | F92: =+MAYO!AG92 -> 290 | G92: =+JUNIO!AG92 -> 365 | H92: =+JULIO!AG92 -> 105 | I92: =+AGOSTO!AG92 -> 186 | J92: =+SEPTIEMBRE!AG92 -> 247 | K92: =+OCTUBRE!AG92 -> 176 | L92: =+NOVIEMBRE!AG92 -> 146 | M92: =+DICIEMBRE!AG92 -> 142 | N92: =SUM(B92:M92) -> 2571
...

Sheet ENERO
A2: ENERO | B2: 1 | C2: =+B2+1 -> 2 | D2: =+C2+1 -> 3 | E2: =+D2+1 -> 4 | F2: =+E2+1 -> 5 | G2: =+F2+1 -> 6 | H2: =+G2+1 -> 7 | I2: =+H2+1 -> 8 | J2: =+I2+1 -> 9 | ... AA2: =+Z2+1 -> 26 | AB2: 27 | AC2: =+AB2+1 -> 28 | AD2: =+AC2+1 -> 29 | AE2: =+AD2+1 -> 30 | AF2: =+AE2+1 -> 31 | AG2: TOTAL
A3: Total de Inscritos | B3: =SUM(B4:B27) -> 215 | C3: =SUM(C4:C27) -> 245 | D3: =SUM(D4:D27) -> 233 | E3: =SUM(E4:E27) -> 212 | F3: =SUM(F4:F27) -> 264 | G3: =SUM(G4:G27) -> 243 | H3: =SUM(H4:H27) -> 236 | I3: =SUM(I4:I27) -> 167 | ... AF3: =SUM(AF4:AF27) -> 168 | AG3: =SUM(B3:AF3) -> 6497
A4: 08:00 | B4: 8 | F4: 12 | G4: 2 | M4: 3 | N4: 5 | T4: 4 | U4: 4 | AA4: 6 | AB4: 8 | AG4: =SUM(B4:AF4) -> 52
A5: 09:00 | B5: 3 | F5: 10 | G5: 11 | M5: 11 | N5: 9 | T5: 12 | U5: 8 | AA5: 12 | AB5: 5 | AG5: =SUM(B5:AF5) -> 81
A6: 10:00 | B6: 13 | F6: 16 | G6: 18 | M6: 4 | N6: 13 | T6: 14 | U6: 12 | AA6: 11 | AB6: 7 | AG6: =SUM(B6:AF6) -> 108
A7: 11:00 | B7: 9 | C7: 17 | D7: 12 | E7: 18 | F7: 18 | G7: 18 | H7: 8 | I7: 12 | J7: 13 | K7: 20 | L7: 12 | M7: 23 | N7: 20 | O7: 23 | P7: 5 | Q7: 9 | R7: 9 | S7: 11 | T7: 13 | U7: 13 | V7: 9 | W7: 5 | X7: 13 | Y7: 9 | Z7: 9 | AA7: 20 | AB7: 12 | AC7: 11 | AD7: 8 | AE7: 30 | AF7: 7 | AG7: =SUM(B7:AF7) -> 416
A8: 12:00 | B8: 9 | C8: 5 | D8: 7 | E8: 2 | F8: 22 | G8: 19 | H8: 6 | I8: 2 | J8: 7 | K8: 2 | L8: 5 | M8: 11 | N8: 18 | O8: 6 | P8: 6 | Q8: 9 | R8: 5 | S8: 3 | T8: 10 | U8: 8 | V8: 4 | W8: 3 | X8: 5 | Y8: 1 | Z8: 5 | AA8: 11 | AB8: 9 | AC8: 4 | AD8: 3 | AE8: 2 | AF8: 2 | AG8: =SUM(B8:AF8) -> 211
A9: 13:00 | B9: 14 | C9: 9 | D9: 5 | E9: 5 | F9: 7 | G9: 10 | H9: 10 | I9: 10 | J9: 7 | K9: 2 | L9: 4 | M9: 14 | N9: 10 | O9: 6 | P9: 5 | Q9: 6 | R9: 1 | S9: 2 | T9: 11 | U9: 13 | V9: 3 | W9: 1 | X9: 5 | Y9: 2 | Z9: 1 | AA9: 11 | AB9: 16 | AC9: 9 | AD9: 3 | AE9: 3 | AF9: 1 | AG9: =SUM(B9:AF9) -> 206
A10: 14:00 | B10: 8 | C10: 5 | D10: 2 | E10: 3 | F10: 11 | G10: 15 | H10: 7 | I10: 7 | J10: 3 | K10: 6 | L10: 4 | M10: 17 | N10: 13 | O10: 2 | P10: 1 | Q10: 5 | R10: 4 | S10: 2 | T10: 11 | U10: 23 | V10: 7 | W10: 5 | X10: 6 | Y10: 4 | Z10: 4 | AA10: 9 | AB10: 7 | AC10: 3 | AD10: 2 | AE10: 5 | AF10: 3 | AG10: =SUM(B10:AF10) -> 204
A11: 15:00 | B11: 11 | C11: 7 | D11: 4 | E11: 4 | F11: 23 | G11: 10 | H11: 4 | I11: 11 | J11: 9 | K11: 8 | L11: 2 | M11: 25 | N11: 14 | Q11: 4 | R11: 5 | S11: 2 | T11: 11 | U11: 11 | V11: 3 | W11: 1 | Y11: 5 | Z11: 3 | AA11: 8 | AB11: 15 | AC11: 5 | AD11: 3 | AE11: 6 | AF11: 1 | AG11: =SUM(B11:AF11) -> 215
A12: 16:00 | B12: 9 | C12: 7 | D12: 1 | E12: 7 | F12: 11 | G12: 15 | I12: 3 | J12: 3 | K12: 10 | M12: 17 | N12: 14 | O12: 4 | P12: 4 | Q12: 2 | R12: 5 | S12: 8 | T12: 13 | U12: 8 | V12: 5 | W12: 3 | X12: 1 | Y12: 8 | Z12: 2 | AA12: 18 | AB12: 14 | AC12: 3 | AD12: 1 | AE12: 8 | AF12: 1 | AG12: =SUM(B12:AF12) -> 205
A13: 17:00 | B13: 19 | C13: 67 | D13: 63 | E13: 48 | F13: 24 | G13: 11 | H13: 56 | I13: 27 | J13: 40 | K13: 36 | L13: 49 | M13: 17 | N13: 22 | O13: 49 | P13: 34 | Q13: 33 | R13: 34 | S13: 31 | T13: 14 | U13: 13 | V13: 55 | W13: 38 | X13: 43 | Y13: 55 | Z13: 44 | AA13: 19 | AB13: 15 | AC13: 58 | AD13: 35 | AE13: 50 | AF13: 37 | AG13: =SUM(B13:AF13) -> 1136
A14: 18:00 | B14: 17 | C14: 25 | D14: 26 | E14: 14 | F14: 15 | G14: 17 | H14: 21 | I14: 17 | J14: 15 | K14: 19 | L14: 10 | M14: 20 | N14: 12 | O14: 21 | P14: 15 | Q14: 28 | R14: 24 | S14: 18 | T14: 10 | U14: 10 | V14: 20 | W14: 28 | X14: 29 | Y14: 17 | Z14: 19 | AA14: 16 | AB14: 16 | AC14: 26 | AD14: 19 | AE14: 22 | AF14: 15 | AG14: =SUM(B14:AF14) -> 581
A15: 19:00 | B15: 8 | C15: 24 | D15: 21 | E15: 10 | F15: 15 | G15: 19 | H15: 32 | I15: 16 | J15: 16 | K15: 14 | L15: 11 | M15: 14 | N15: 9 | O15: 13 | P15: 21 | Q15: 16 | R15: 23 | S15: 2 | T15: 16 | U15: 10 | V15: 27 | W15: 25 | X15: 20 | Y15: 16 | Z15: 18 | AA15: 21 | AB15: 16 | AC15: 19 | AD15: 22 | AE15: 10 | AF15: 8 | AG15: =SUM(B15:AF15) -> 512
A16: 20:00 | B16: 23 | C16: 23 | D16: 17 | E16: 17 | F16: 17 | G16: 17 | H16: 28 | I16: 19 | J16: 18 | K16: 19 | L16: 23 | M16: 7 | N16: 17 | O16: 17 | P16: 20 | Q16: 16 | R16: 14 | T16: 20 | U16: 11 | V16: 23 | W16: 26 | X16: 14 | Y16: 7 | Z16: 16 | AA16: 11 | AB16: 7 | AC16: 22 | AD16: 17 | AE16: 18 | AF16: 11 | AG16: =SUM(B16:AF16) -> 515
A17: 21:00 | B17: 16 | C17: 17 | D17: 15 | E17: 22 | F17: 11 | G17: 16 | H17: 20 | I17: 10 | J17: 11 | K17: 16 | L17: 20 | M17: 15 | N17: 9 | O17: 23 | P17: 18 | Q17: 14 | R17: 18 | T17: 10 | U17: 19 | V17: 21 | W17: 20 | X17: 17 | Y17: 18 | Z17: 15 | AA17: 18 | AB17: 15 | AC17: 22 | AD17: 11 | AE17: 22 | AF17: 22 | AG17: =SUM(B17:AF17) -> 501
A18: 22:00 | B18: 11 | C18: 11 | D18: 22 | E18: 19 | F18: 16 | G18: 12 | H18: 12 | I18: 10 | J18: 17 | K18: 14 | L18: 16 | M18: 11 | N18: 16 | O18: 20 | P18: 13 | Q18: 15 | R18: 18 | S18: 4 | T18: 13 | U18: 15 | V18: 18 | W18: 20 | X18: 23 | Y18: 21 | Z18: 20 | AA18: 22 | AB18: 17 | AC18: 20 | AD18: 19 | AE18: 16 | AF18: 8 | AG18: =SUM(B18:AF18) -> 489
A19: 23:00 | B19: 14 | C19: 8 | D19: 11 | E19: 14 | F19: 11 | G19: 13 | H19: 12 | I19: 7 | J19: 8 | K19: 15 | L19: 9 | M19: 10 | N19: 18 | O19: 14 | P19: 20 | Q19: 12 | R19: 9 | S19: 17 | T19: 9 | U19: 9 | V19: 13 | W19: 10 | X19: 9 | Y19: 13 | Z19: 19 | AA19: 17 | AB19: 10 | AC19: 16 | AD19: 11 | AE19: 14 | AF19: 17 | AG19: =SUM(B19:AF19) -> 389
A20: 00:00 | B20: 8 | C20: 1 | D20: 13 | E20: 5 | F20: 3 | G20: 2 | H20: 7 | I20: 4 | J20: 2 | K20: 5 | L20: 8 | M20: 8 | N20: 9 | O20: 6 | P20: 5 | Q20: 9 | R20: 6 | S20: 16 | T20: 12 | U20: 7 | V20: 6 | W20: 6 | X20: 7 | Y20: 11 | Z20: 8 | AA20: 6 | AB20: 6 | AC20: 7 | AD20: 7 | AE20: 6 | AF20: 18 | AG20: =SUM(B20:AF20) -> 224
A21: 01:00 | B21: 3 | C21: 5 | D21: 4 | E21: 9 | F21: 8 | G21: 6 | H21: 2 | I21: 3 | J21: 3 | K21: 4 | L21: 7 | M21: 4 | N21: 2 | O21: 5 | P21: 7 | Q21: 3 | R21: 5 | S21: 11 | T21: 4 | U21: 1 | V21: 9 | X21: 3 | Y21: 4 | Z21: 6 | AA21: 7 | AB21: 4 | AC21: 2 | AD21: 2 | AE21: 5 | AF21: 9 | AG21: =SUM(B21:AF21) -> 147
A22: 02:00 | B22: 4 | C22: 10 | D22: 2 | E22: 3 | F22: 2 | H22: 4 | I22: 2 | J22: 1 | K22: 3 | L22: 2 | M22: 3 | N22: 3 | O22: 2 | Q22: 1 | R22: 5 | S22: 2 | T22: 6 | U22: 1 | V22: 1 | W22: 3 | X22: 2 | Y22: 2 | AA22: 2 | AB22: 1 | AC22: 3 | AD22: 5 | AE22: 3 | AF22: 1 | AG22: =SUM(B22:AF22) -> 79
A23: 03:00 | C23: 2 | D23: 2 | E23: 1 | F23: 3 | G23: 3 | H23: 3 | I23: 1 | J23: 6 | K23: 2 | L23: 2 | M23: 2 | N23: 5 | O23: 2 | P23: 1 | Q23: 2 | R23: 2 | S23: 1 | V23: 1 | W23: 3 | X23: 1 | Y23: 1 | Z23: 2 | AB23: 1 | AC23: 1 | AF23: 3 | AG23: =SUM(B23:AF23) -> 53
A24: 04:00 | B24: 3 | C24: 1 | D24: 1 | E24: 2 | F24: 2 | H24: 3 | I24: 2 | J24: 1 | K24: 1 | N24: 2 | Q24: 1 | R24: 2 | S24: 2 | T24: 5 | U24: 5 | W24: 1 | Z24: 2 | AA24: 2 | AB24: 3 | AC24: 1 | AF24: 3 | AG24: =SUM(B24:AF24) -> 45
A25: 05:00 | D25: 1 | E25: 3 | F25: 2 | G25: 1 | I25: 1 | J25: 3 | K25: 1 | L25: 1 | M25: 2 | N25: 3 | O25: 2 | P25: 2 | R25: 4 | U25: 3 | V25: 1 | W25: 2 | X25: 1 | Z25: 1 | AA25: 3 | AB25: 1 | AC25: 1 | AE25: 1 | AG25: =SUM(B25:AF25) -> 40
A26: 06:00 | B26: 3 | C26: 1 | D26: 2 | E26: 2 | F26: 1 | G26: 2 | H26: 1 | I26: 1 | J26: 1 | M26: 2 | N26: 1 | O26: 1 | Q26: 3 | R26: 1 | U26: 1 | V26: 1 | W26: 1 | X26: 1 | Y26: 3 | Z26: 1 | AA26: 3 | AB26: 2 | AC26: 1 | AE26: 2 | AF26: 1 | AG26: =SUM(B26:AF26) -> 39
A27: 07:00 | B27: 2 | D27: 2 | E27: 4 | F27: 4 | G27: 6 | I27: 2 | K27: 2 | L27: 4 | M27: 6 | P27: 1 | S27: 3 | T27: 5 | U27: 2 | Z27: 3 | AA27: 1 | AC27: 1 | AE27: 1 | AG27: =SUM(B27:AF27) -> 49
A28: Total de atendidos | B28: =SUM(B29:B52) -> 207 | C28: =SUM(C29:C52) -> 196 | D28: =SUM(D29:D52) -> 201 | E28: =SUM(E29:E52) -> 200 | F28: =SUM(F29:F52) -> 252 | G28: =SUM(G29:G52) -> 227 | H28: =SUM(H29:H52) -> 206 | I28: =SUM(I29:I52) -> 159 | ... AF28: =SUM(AF29:AF52) -> 163 | AG28: =SUM(B28:AF28) -> 5938
A29: 08:00 | B29: 2 | E29: 2 | F29: 5 | G29: 1 | L29: 2 | M29: 4 | S29: 2 | T29: 6 | U29: 2 | Z29: 3 | AA29: 3 | AB29: 5 | AG29: =SUM(B29:AF29) -> 37
A30: 09:00 | B30: 8 | E30: 1 | F30: 16 | G30: 5 | M30: 5 | N30: 5 | T30: 6 | U30: 3 | AA30: 8 | AB30: 5 | AG30: =SUM(B30:AF30) -> 62
A31: 10:00 | B31: 7 | F31: 13 | G31: 11 | M31: 11 | N31: 5 | T31: 10 | U31: 13 | AA31: 8 | AB31: 7 | AG31: =SUM(B31:AF31) -> 85
A32: 11:00 | B32: 7 | C32: 16 | D32: 12 | E32: 4 | F32: 15 | G32: 10 | H32: 3 | I32: 3 | J32: 3 | K32: 2 | L32: 7 | M32: 8 | N32: 10 | O32: 3 | P32: 2 | Q32: 6 | R32: 3 | S32: 3 | T32: 13 | U32: 10 | V32: 3 | X32: 9 | Y32: 7 | Z32: 6 | AA32: 10 | AB32: 9 | AC32: 9 | AD32: 7 | AE32: 6 | AF32: 4 | AG32: =SUM(B32:AF32) -> 210
A33: 12:00 | B33: 7 | C33: 5 | D33: 7 | E33: 4 | F33: 14 | G33: 10 | H33: 5 | I33: 7 | J33: 7 | K33: 7 | L33: 6 | M33: 15 | N33: 10 | O33: 4 | P33: 4 | Q33: 5 | R33: 5 | S33: 3 | T33: 13 | U33: 11 | V33: 7 | W33: 8 | X33: 8 | Y33: 3 | Z33: 8 | AA33: 14 | AB33: 9 | AC33: 5 | AD33: 4 | AE33: 11 | AF33: 5 | AG33: =SUM(B33:AF33) -> 231
A34: 13:00 | B34: 10 | C34: 6 | D34: 4 | E34: 1 | F34: 18 | G34: 16 | H34: 5 | J34: 3 | K34: 4 | L34: 7 | M34: 13 | N34: 9 | O34: 3 | P34: 4 | Q34: 3 | R34: 6 | S34: 6 | T34: 9 | U34: 13 | V34: 3 | X34: 5 | Z34: 1 | AA34: 17 | AB34: 8 | AC34: 3 | AD34: 1 | AE34: 6 | AF34: 1 | AG34: =SUM(B34:AF34) -> 185
A35: 14:00 | B35: 17 | C35: 4 | D35: 1 | E35: 2 | F35: 14 | G35: 15 | H35: 3 | I35: 4 | J35: 8 | K35: 5 | L35: 3 | M35: 12 | N35: 10 | O35: 6 | P35: 7 | Q35: 6 | R35: 2 | T35: 9 | U35: 11 | V35: 4 | W35: 3 | X35: 7 | Y35: 5 | Z35: 3 | AA35: 7 | AB35: 10 | AC35: 9 | AD35: 3 | AE35: 12 | AF35: 3 | AG35: =SUM(B35:AF35) -> 205
A36: 15:00 | B36: 12 | C36: 3 | D36: 4 | E36: 5 | F36: 12 | G36: 13 | H36: 8 | I36: 6 | J36: 8 | K36: 5 | L36: 8 | M36: 22 | N36: 20 | O36: 7 | Q36: 3 | R36: 3 | S36: 5 | T36: 14 | U36: 15 | V36: 5 | W36: 4 | Y36: 4 | Z36: 2 | AA36: 14 | AB36: 11 | AC36: 5 | AD36: 3 | AE36: 7 | AF36: 1 | AG36: =SUM(B36:AF36) -> 229
A37: 16:00 | B37: 9 | C37: 7 | D37: 1 | E37: 4 | F37: 20 | G37: 11 | H37: 6 | I37: 5 | J37: 8 | K37: 8 | M37: 30 | N37: 12 | O37: 6 | P37: 4 | Q37: 7 | R37: 7 | S37: 3 | T37: 15 | U37: 15 | V37: 6 | W37: 3 | X37: 1 | Y37: 5 | Z37: 3 | AA37: 14 | AB37: 15 | AC37: 3 | AD37: 2 | AE37: 2 | AF37: 1 | AG37: =SUM(B37:AF37) -> 233
A38: 17:00 | B38: 11 | C38: 59 | D38: 55 | E38: 12 | F38: 8 | G38: 17 | H38: 8 | I38: 9 | J38: 12 | K38: 13 | L38: 5 | M38: 17 | N38: 17 | O38: 8 | P38: 13 | Q38: 11 | R38: 12 | S38: 10 | T38: 11 | U38: 11 | V38: 13 | W38: 13 | X38: 8 | Y38: 16 | Z38: 16 | AA38: 17 | AB38: 16 | AC38: 10 | AD38: 9 | AE38: 12 | AF38: 5 | AG38: =SUM(B38:AF38) -> 454
A39: 18:00 | B39: 17 | C39: 15 | D39: 17 | E39: 19 | F39: 18 | G39: 21 | H39: 18 | I39: 23 | J39: 19 | K39: 21 | L39: 14 | M39: 15 | N39: 22 | O39: 16 | P39: 28 | Q39: 18 | R39: 16 | S39: 17 | T39: 11 | U39: 7 | V39: 27 | W39: 30 | X39: 18 | Y39: 18 | Z39: 23 | AA39: 11 | AB39: 14 | AC39: 20 | AD39: 22 | AE39: 24 | AF39: 18 | AG39: =SUM(B39:AF39) -> 577
A40: 19:00 | B40: 14 | C40: 17 | D40: 16 | E40: 27 | F40: 17 | G40: 11 | H40: 19 | I40: 27 | J40: 20 | K40: 19 | L40: 22 | M40: 13 | N40: 12 | O40: 22 | P40: 20 | Q40: 26 | R40: 20 | S40: 4 | T40: 12 | U40: 16 | V40: 31 | W40: 25 | X40: 18 | Y40: 17 | Z40: 26 | AA40: 13 | AB40: 14 | AC40: 19 | AD40: 18 | AE40: 15 | AF40: 22 | AG40: =SUM(B40:AF40) -> 572
A41: 20:00 | B41: 16 | C41: 15 | D41: 15 | E41: 27 | F41: 13 | G41: 13 | H41: 37 | I41: 21 | J41: 18 | K41: 28 | L41: 25 | M41: 11 | N41: 15 | O41: 32 | P41: 21 | Q41: 24 | R41: 17 | T41: 14 | U41: 7 | V41: 33 | W41: 26 | X41: 15 | Y41: 17 | Z41: 9 | AA41: 15 | AB41: 9 | AC41: 32 | AD41: 22 | AE41: 17 | AF41: 15 | AG41: =SUM(B41:AF41) -> 579
...

Sheet FEBRERO
A2: FEBRERO | B2: 1 | C2: =+B2+1 -> 2 | D2: =+C2+1 -> 3 | E2: =+D2+1 -> 4 | F2: =+E2+1 -> 5 | G2: =+F2+1 -> 6 | H2: =+G2+1 -> 7 | I2: =+H2+1 -> 8 | J2: =+I2+1 -> 9 | ... AA2: =+Z2+1 -> 26 | AB2: 27 | AC2: =+AB2+1 -> 28 | AG2: TOTAL
A3: Total de Inscritos | B3: =SUM(B4:B27) -> 170 | C3: =SUM(C4:C27) -> 226 | D3: =SUM(D4:D27) -> 217 | E3: =SUM(E4:E27) -> 225 | F3: =SUM(F4:F27) -> 206 | G3: =SUM(G4:G27) -> 196 | H3: =SUM(H4:H27) -> 182 | I3: =SUM(I4:I27) -> 167 | ... AF3: =SUM(AF4:AF27) -> 0 | AG3: =SUM(B3:AF3) -> 5688
A4: 08:00 | C4: 7 | D4: 7 | J4: 7 | K4: 6 | Q4: 5 | R4: 4 | X4: 9 | Y4: 5 | AG4: =SUM(B4:AF4) -> 50
A5: 09:00 | C5: 12 | D5: 4 | J5: 11 | K5: 12 | Q5: 10 | R5: 9 | X5: 8 | Y5: 9 | AG5: =SUM(B5:AF5) -> 75
A6: 10:00 | C6: 13 | D6: 11 | J6: 17 | K6: 12 | M6: 1 | Q6: 15 | R6: 19 | X6: 16 | Y6: 9 | AG6: =SUM(B6:AF6) -> 113
A7: 11:00 | B7: 2 | C7: 19 | D7: 23 | E7: 7 | F7: 12 | G7: 8 | H7: 9 | I7: 6 | J7: 11 | K7: 7 | L7: 7 | M7: 11 | N7: 22 | O7: 4 | P7: 4 | Q7: 16 | R7: 18 | S7: 6 | T7: 11 | U7: 9 | V7: 16 | W7: 11 | X7: 10 | Y7: 19 | Z7: 15 | AA7: 15 | AB7: 2 | AC7: 9 | AG7: =SUM(B7:AF7) -> 309
A8: 12:00 | B8: 2 | C8: 10 | D8: 15 | E8: 6 | F8: 1 | G8: 3 | H8: 4 | I8: 2 | J8: 13 | K8: 17 | L8: 9 | N8: 5 | O8: 3 | P8: 6 | Q8: 15 | R8: 21 | S8: 4 | T8: 8 | U8: 6 | V8: 8 | X8: 13 | Y8: 12 | Z8: 8 | AA8: 5 | AB8: 9 | AC8: 2 | AG8: =SUM(B8:AF8) -> 207
A9: 13:00 | B9: 2 | C9: 9 | D9: 6 | E9: 1 | F9: 4 | G9: 5 | H9: 1 | J9: 9 | K9: 9 | L9: 4 | M9: 5 | N9: 4 | O9: 2 | P9: 2 | Q9: 6 | R9: 10 | S9: 5 | T9: 4 | V9: 3 | W9: 5 | X9: 8 | Y9: 11 | Z9: 4 | AA9: 3 | AB9: 3 | AC9: 3 | AG9: =SUM(B9:AF9) -> 128
A10: 14:00 | B10: 6 | C10: 9 | D10: 6 | E10: 5 | F10: 6 | G10: 2 | H10: 3 | I10: 3 | J10: 13 | K10: 12 | L10: 6 | M10: 2 | N10: 9 | O10: 2 | P10: 5 | Q10: 13 | R10: 8 | S10: 7 | T10: 3 | U10: 4 | V10: 3 | W10: 2 | X10: 12 | Y10: 15 | Z10: 6 | AA10: 6 | AB10: 3 | AC10: 3 | AG10: =SUM(B10:AF10) -> 174
A11: 15:00 | B11: 4 | C11: 9 | D11: 15 | E11: 4 | F11: 4 | G11: 4 | H11: 9 | I11: 1 | J11: 12 | K11: 14 | L11: 3 | M11: 2 | N11: 5 | O11: 4 | P11: 3 | Q11: 16 | R11: 8 | S11: 5 | T11: 8 | U11: 3 | V11: 4 | W11: 4 | X11: 12 | Y11: 11 | Z11: 7 | AA11: 2 | AB11: 8 | AC11: 1 | AG11: =SUM(B11:AF11) -> 182
A12: 16:00 | B12: 10 | C12: 14 | D12: 16 | E12: 8 | F12: 1 | G12: 6 | H12: 7 | I12: 10 | J12: 16 | K12: 12 | L12: 3 | M12: 3 | N12: 3 | O12: 2 | P12: 3 | Q12: 15 | R12: 18 | S12: 10 | T12: 4 | U12: 4 | V12: 3 | W12: 13 | X12: 11 | Y12: 16 | Z12: 6 | AA12: 1 | AB12: 5 | AC12: 1 | AG12: =SUM(B12:AF12) -> 221
A13: 17:00 | B13: 34 | C13: 20 | D13: 13 | E13: 43 | F13: 36 | G13: 41 | H13: 43 | I13: 33 | J13: 19 | K13: 16 | L13: 62 | M13: 49 | N13: 28 | O13: 52 | P13: 36 | Q13: 15 | R13: 12 | S13: 51 | T13: 47 | U13: 41 | V13: 48 | W13: 31 | X13: 15 | Y13: 13 | Z13: 50 | AA13: 48 | AB13: 47 | AC13: 56 | AG13: =SUM(B13:AF13) -> 999
A14: 18:00 | B14: 14 | C14: 21 | D14: 11 | E14: 32 | F14: 17 | G14: 21 | H14: 24 | I14: 13 | J14: 22 | K14: 19 | L14: 31 | M14: 16 | N14: 14 | O14: 17 | P14: 19 | Q14: 16 | R14: 15 | S14: 25 | T14: 23 | U14: 26 | V14: 14 | W14: 19 | X14: 15 | Y14: 9 | Z14: 29 | AA14: 18 | AB14: 17 | AC14: 27 | AG14: =SUM(B14:AF14) -> 544
A15: 19:00 | B15: 11 | C15: 10 | D15: 13 | E15: 20 | F15: 23 | G15: 12 | H15: 11 | I15: 19 | J15: 15 | K15: 12 | L15: 22 | M15: 14 | N15: 17 | O15: 24 | P15: 8 | Q15: 10 | R15: 15 | S15: 21 | T15: 14 | U15: 20 | V15: 22 | W15: 16 | X15: 22 | Y15: 12 | Z15: 15 | AA15: 21 | AB15: 17 | AC15: 12 | AG15: =SUM(B15:AF15) -> 448
A16: 20:00 | B16: 11 | C16: 10 | D16: 13 | E16: 22 | F16: 28 | G16: 19 | H16: 15 | I16: 14 | J16: 12 | K16: 14 | L16: 12 | M16: 12 | N16: 22 | O16: 13 | P16: 18 | Q16: 17 | R16: 14 | S16: 20 | T16: 17 | U16: 20 | V16: 15 | W16: 16 | X16: 9 | Y16: 13 | Z16: 20 | AA16: 21 | AB16: 19 | AC16: 20 | AG16: =SUM(B16:AF16) -> 456
A17: 21:00 | B17: 11 | C17: 11 | D17: 16 | E17: 21 | F17: 25 | G17: 22 | H17: 11 | I17: 20 | J17: 16 | K17: 14 | L17: 25 | M17: 15 | N17: 19 | O17: 13 | P17: 17 | Q17: 11 | R17: 20 | S17: 12 | T17: 9 | U17: 21 | V17: 21 | W17: 11 | X17: 15 | Y17: 9 | Z17: 20 | AA17: 18 | AB17: 12 | AC17: 13 | AG17: =SUM(B17:AF17) -> 448
A18: 22:00 | B18: 11 | C18: 13 | D18: 24 | E18: 17 | F18: 16 | G18: 17 | H18: 11 | I18: 17 | J18: 16 | K18: 11 | L18: 11 | M18: 11 | N18: 21 | O18: 15 | P18: 15 | Q18: 13 | R18: 7 | S18: 16 | T18: 11 | U18: 27 | V18: 13 | W18: 9 | X18: 19 | Y18: 16 | Z18: 16 | AA18: 11 | AB18: 13 | AC18: 11 | AG18: =SUM(B18:AF18) -> 408
A19: 23:00 | B19: 17 | C19: 12 | D19: 10 | E19: 16 | F19: 12 | G19: 11 | H19: 12 | I19: 14 | J19: 11 | K19: 11 | L19: 15 | M19: 10 | N19: 4 | O19: 10 | P19: 7 | Q19: 11 | R19: 9 | S19: 10 | T19: 14 | U19: 8 | V19: 7 | W19: 15 | X19: 10 | Y19: 8 | Z19: 8 | AA19: 8 | AB19: 8 | AC19: 11 | AG19: =SUM(B19:AF19) -> 299
A20: 00:00 | B20: 12 | C20: 6 | D20: 5 | E20: 6 | F20: 10 | G20: 5 | H20: 6 | I20: 5 | J20: 12 | K20: 6 | L20: 5 | M20: 4 | N20: 4 | O20: 6 | P20: 8 | Q20: 7 | R20: 8 | S20: 11 | T20: 9 | U20: 5 | V20: 6 | W20: 7 | X20: 6 | Y20: 5 | Z20: 5 | AA20: 8 | AB20: 3 | AC20: 2 | AG20: =SUM(B20:AF20) -> 182
A21: 01:00 | B21: 6 | C21: 8 | D21: 3 | E21: 7 | F21: 4 | G21: 6 | H21: 2 | I21: 3 | J21: 7 | K21: 2 | L21: 4 | M21: 2 | N21: 4 | O21: 7 | P21: 5 | Q21: 5 | R21: 7 | S21: 2 | T21: 6 | U21: 5 | V21: 4 | W21: 1 | X21: 4 | Y21: 8 | Z21: 4 | AA21: 7 | AB21: 4 | AC21: 1 | AG21: =SUM(B21:AF21) -> 128
A22: 02:00 | B22: 4 | C22: 7 | D22: 2 | E22: 4 | F22: 2 | G22: 2 | H22: 5 | I22: 2 | J22: 7 | K22: 5 | L22: 5 | M22: 4 | N22: 1 | O22: 4 | P22: 5 | Q22: 2 | R22: 4 | S22: 2 | T22: 5 | U22: 1 | V22: 2 | X22: 1 | Y22: 1 | Z22: 2 | AA22: 3 | AB22: 3 | AC22: 2 | AG22: =SUM(B22:AF22) -> 87
A23: 03:00 | C23: 5 | D23: 2 | F23: 2 | G23: 6 | H23: 2 | J23: 3 | K23: 6 | M23: 1 | N23: 5 | O23: 3 | Q23: 5 | R23: 2 | S23: 1 | U23: 1 | V23: 3 | W23: 1 | X23: 2 | Y23: 3 | Z23: 2 | AA23: 5 | AB23: 1 | AG23: =SUM(B23:AF23) -> 61
A24: 04:00 | B24: 5 | E24: 2 | F24: 2 | G24: 3 | H24: 2 | J24: 3 | L24: 2 | M24: 1 | O24: 3 | P24: 2 | Q24: 6 | R24: 2 | S24: 4 | T24: 1 | U24: 1 | V24: 1 | W24: 3 | Y24: 2 | AA24: 1 | AB24: 5 | AC24: 2 | AG24: =SUM(B24:AF24) -> 53
A25: 05:00 | B25: 2 | E25: 2 | F25: 1 | G25: 3 | H25: 3 | K25: 3 | L25: 2 | O25: 2 | P25: 2 | Q25: 1 | R25: 2 | S25: 2 | T25: 1 | U25: 2 | W25: 1 | X25: 4 | Z25: 3 | AA25: 2 | AB25: 3 | AC25: 2 | AG25: =SUM(B25:AF25) -> 43
A26: 06:00 | B26: 2 | D26: 1 | E26: 1 | H26: 1 | I26: 1 | J26: 1 | K26: 2 | O26: 2 | Q26: 4 | R26: 5 | S26: 1 | T26: 2 | U26: 1 | W26: 1 | X26: 1 | Y26: 1 | Z26: 3 | AA26: 2 | AC26: 3 | AG26: =SUM(B26:AF26) -> 35
A27: 07:00 | B27: 4 | C27: 1 | D27: 1 | E27: 1 | H27: 1 | I27: 4 | J27: 2 | K27: 2 | P27: 2 | Q27: 5 | R27: 1 | T27: 2 | W27: 6 | X27: 6 | AG27: =SUM(B27:AF27) -> 38
A28: Total de atendidos | B28: =SUM(B29:B52) -> 167 | C28: =SUM(C29:C52) -> 218 | D28: =SUM(D29:D52) -> 210 | E28: =SUM(E29:E52) -> 206 | F28: =SUM(F29:F52) -> 170 | G28: =SUM(G29:G52) -> 185 | H28: =SUM(H29:H52) -> 173 | I28: =SUM(I29:I52) -> 151 | ... AF28: =SUM(AF29:AF52) -> 0 | AG28: =SUM(B28:AF28) -> 5319
A29: 08:00 | C29: 7 | D29: 4 | J29: 7 | K29: 3 | P29: 2 | Q29: 4 | R29: 2 | W29: 4 | X29: 7 | AG29: =SUM(B29:AF29) -> 40
A30: 09:00 | C30: 12 | D30: 5 | J30: 11 | K30: 9 | Q30: 3 | R30: 8 | X30: 11 | Y30: 7 | AG30: =SUM(B30:AF30) -> 66
A31: 10:00 | C31: 13 | D31: 8 | J31: 16 | K31: 13 | Q31: 14 | R31: 11 | X31: 13 | Y31: 10 | AG31: =SUM(B31:AF31) -> 98
A32: 11:00 | B32: 2 | C32: 19 | D32: 14 | E32: 7 | F32: 12 | G32: 8 | H32: 9 | I32: 6 | J32: 10 | K32: 9 | L32: 2 | M32: 7 | N32: 5 | O32: 4 | P32: 2 | Q32: 13 | R32: 16 | S32: 4 | T32: 6 | U32: 4 | V32: 7 | W32: 6 | X32: 11 | Y32: 12 | Z32: 7 | AA32: 7 | AB32: 1 | AC32: 5 | AG32: =SUM(B32:AF32) -> 215
A33: 12:00 | B33: 2 | C33: 9 | D33: 15 | E33: 6 | F33: 1 | G33: 3 | H33: 4 | I33: 2 | J33: 13 | K33: 8 | L33: 10 | M33: 5 | N33: 10 | O33: 3 | P33: 8 | Q33: 11 | R33: 9 | S33: 5 | T33: 10 | U33: 9 | V33: 8 | W33: 5 | X33: 12 | Y33: 10 | Z33: 11 | AA33: 9 | AB33: 10 | AC33: 5 | AG33: =SUM(B33:AF33) -> 213
A34: 13:00 | B34: 2 | C34: 9 | D34: 16 | E34: 1 | F34: 4 | G34: 5 | H34: 1 | J34: 9 | K34: 8 | L34: 5 | M34: 2 | N34: 12 | O34: 1 | Q34: 14 | R34: 11 | S34: 2 | T34: 3 | U34: 2 | V34: 8 | W34: 2 | X34: 10 | Y34: 8 | Z34: 1 | AA34: 1 | AB34: 2 | AC34: 4 | AG34: =SUM(B34:AF34) -> 143
A35: 14:00 | B35: 6 | C35: 9 | D35: 2 | E35: 5 | F35: 6 | G35: 2 | H35: 3 | I35: 3 | J35: 13 | K35: 11 | L35: 8 | M35: 5 | N35: 6 | O35: 3 | P35: 6 | Q35: 6 | R35: 6 | S35: 11 | T35: 4 | U35: 3 | V35: 7 | W35: 3 | X35: 7 | Y35: 10 | Z35: 6 | AA35: 6 | AB35: 4 | AC35: 3 | AG35: =SUM(B35:AF35) -> 164
A36: 15:00 | B36: 4 | C36: 9 | D36: 12 | E36: 4 | F36: 4 | G36: 4 | H36: 9 | I36: 1 | J36: 12 | K36: 10 | L36: 1 | M36: 1 | N36: 11 | O36: 4 | P36: 4 | Q36: 9 | R36: 8 | S36: 5 | T36: 9 | U36: 4 | V36: 2 | W36: 6 | X36: 16 | Y36: 11 | Z36: 7 | AA36: 5 | AB36: 5 | AC36: 1 | AG36: =SUM(B36:AF36) -> 178
A37: 16:00 | B37: 10 | C37: 14 | D37: 18 | E37: 8 | F37: 1 | G37: 6 | H37: 7 | I37: 10 | J37: 16 | K37: 17 | L37: 6 | M37: 4 | N37: 3 | O37: 2 | P37: 2 | Q37: 18 | R37: 14 | S37: 5 | T37: 3 | U37: 3 | V37: 5 | W37: 2 | X37: 12 | Y37: 14 | Z37: 5 | AA37: 3 | AB37: 7 | AG37: =SUM(B37:AF37) -> 215
A38: 17:00 | B38: 33 | C38: 17 | D38: 17 | E38: 37 | F38: 31 | G38: 37 | H38: 41 | I38: 29 | J38: 18 | K38: 14 | L38: 6 | M38: 10 | N38: 5 | O38: 7 | P38: 6 | Q38: 21 | R38: 11 | S38: 9 | T38: 5 | U38: 10 | V38: 12 | W38: 10 | X38: 9 | Y38: 15 | Z38: 6 | AA38: 12 | AB38: 5 | AC38: 12 | AG38: =SUM(B38:AF38) -> 445
A39: 18:00 | B39: 14 | C39: 20 | D39: 8 | E39: 27 | F39: 15 | G39: 18 | H39: 22 | I39: 10 | J39: 19 | K39: 17 | L39: 19 | M39: 16 | N39: 26 | O39: 18 | P39: 20 | Q39: 11 | R39: 14 | S39: 14 | T39: 16 | U39: 25 | V39: 19 | W39: 20 | X39: 11 | Y39: 16 | Z39: 29 | AA39: 21 | AB39: 23 | AC39: 19 | AG39: =SUM(B39:AF39) -> 507
A40: 19:00 | B40: 11 | C40: 7 | D40: 12 | E40: 17 | F40: 20 | G40: 12 | H40: 11 | I40: 19 | J40: 15 | K40: 15 | L40: 21 | M40: 27 | N40: 19 | O40: 17 | P40: 19 | Q40: 14 | R40: 14 | S40: 22 | T40: 22 | U40: 35 | V40: 24 | W40: 21 | X40: 10 | Y40: 15 | Z40: 29 | AA40: 24 | AB40: 22 | AC40: 28 | AG40: =SUM(B40:AF40) -> 522
A41: 20:00 | B41: 11 | C41: 10 | D41: 11 | E41: 19 | F41: 24 | G41: 18 | H41: 14 | I41: 13 | J41: 10 | K41: 11 | L41: 39 | M41: 17 | N41: 21 | O41: 19 | P41: 18 | Q41: 16 | R41: 16 | S41: 31 | T41: 18 | U41: 27 | V41: 28 | W41: 12 | X41: 11 | Y41: 13 | Z41: 38 | AA41: 25 | AB41: 8 | AC41: 25 | AG41: =SUM(B41:AF41) -> 523
...

Sheet MARZO
A2: MARZO | B2: 1 | C2: =+B2+1 -> 2 | D2: =+C2+1 -> 3 | E2: =+D2+1 -> 4 | F2: =+E2+1 -> 5 | G2: =+F2+1 -> 6 | H2: =+G2+1 -> 7 | I2: =+H2+1 -> 8 | J2: =+I2+1 -> 9 | ... AA2: =+Z2+1 -> 26 | AB2: 27 | AC2: =+AB2+1 -> 28 | AD2: 29 | AE2: 30 | AF2: 31 | AG2: TOTAL
A3: Total de Inscritos | B3: =SUM(B4:B27) -> 188 | C3: =SUM(C4:C27) -> 224 | D3: =SUM(D4:D27) -> 197 | E3: =SUM(E4:E27) -> 186 | F3: =SUM(F4:F27) -> 185 | G3: =SUM(G4:G27) -> 168 | H3: =SUM(H4:H27) -> 174 | I3: =SUM(I4:I27) -> 167 | ... AF3: =SUM(AF4:AF27) -> 237 | AG3: =SUM(B3:AF3) -> 6448
A4: 08:00 | C4: 8 | D4: 5 | J4: 5 | K4: 4 | R4: 4 | X4: 15 | Y4: 2 | AE4: 9 | AF4: 2 | AG4: =SUM(B4:AF4) -> 54
A5: 09:00 | C5: 6 | D5: 4 | J5: 7 | K5: 9 | Q5: 4 | R5: 12 | X5: 9 | Y5: 7 | AE5: 10 | AF5: 13 | AG5: =SUM(B5:AF5) -> 81
A6: 10:00 | C6: 11 | D6: 12 | E6: 1 | J6: 12 | K6: 6 | Q6: 6 | R6: 12 | X6: 8 | Y6: 12 | AE6: 11 | AF6: 17 | AG6: =SUM(B6:AF6) -> 108
A7: 11:00 | B7: 7 | C7: 21 | D7: 16 | E7: 9 | F7: 15 | G7: 8 | H7: 16 | I7: 3 | J7: 16 | K7: 17 | L7: 9 | M7: 16 | N7: 12 | O7: 8 | P7: 14 | Q7: 31 | R7: 28 | S7: 11 | T7: 11 | U7: 8 | V7: 9 | W7: 5 | X7: 18 | Y7: 28 | Z7: 14 | AA7: 13 | AB7: 7 | AC7: 12 | AD7: 9 | AE7: 14 | AF7: 13 | AG7: =SUM(B7:AF7) -> 418
A8: 12:00 | B8: 15 | C8: 9 | D8: 13 | E8: 7 | F8: 3 | G8: 2 | H8: 2 | I8: 3 | J8: 7 | K8: 17 | L8: 6 | M8: 7 | O8: 5 | P8: 4 | Q8: 10 | R8: 18 | S8: 9 | T8: 4 | U8: 10 | V8: 1 | W8: 8 | X8: 21 | Y8: 17 | Z8: 11 | AA8: 4 | AB8: 4 | AC8: 3 | AD8: 5 | AE8: 21 | AF8: 21 | AG8: =SUM(B8:AF8) -> 267
A9: 13:00 | B9: 4 | C9: 15 | D9: 9 | E9: 4 | F9: 1 | G9: 6 | H9: 2 | I9: 4 | J9: 12 | K9: 7 | L9: 3 | M9: 4 | N9: 4 | O9: 3 | P9: 4 | Q9: 5 | R9: 14 | S9: 3 | T9: 5 | U9: 4 | V9: 3 | W9: 3 | X9: 9 | Y9: 13 | Z9: 7 | AA9: 6 | AB9: 6 | AC9: 2 | AD9: 2 | AE9: 17 | AF9: 10 | AG9: =SUM(B9:AF9) -> 191
A10: 14:00 | B10: 3 | C10: 11 | D10: 9 | E10: 5 | F10: 6 | G10: 1 | H10: 5 | I10: 2 | J10: 11 | K10: 8 | L10: 3 | M10: 3 | N10: 6 | O10: 4 | Q10: 32 | R10: 13 | S10: 1 | T10: 4 | U10: 6 | V10: 4 | W10: 5 | X10: 15 | Y10: 19 | Z10: 7 | AA10: 6 | AB10: 4 | AC10: 5 | AD10: 5 | AE10: 11 | AF10: 19 | AG10: =SUM(B10:AF10) -> 233
A11: 15:00 | B11: 2 | C11: 14 | D11: 13 | E11: 3 | F11: 9 | G11: 8 | H11: 4 | I11: 2 | J11: 10 | K11: 12 | L11: 7 | M11: 6 | N11: 8 | O11: 3 | P11: 2 | Q11: 23 | R11: 10 | S11: 2 | T11: 7 | U11: 4 | V11: 2 | W11: 2 | X11: 18 | Y11: 16 | Z11: 4 | AA11: 4 | AB11: 5 | AC11: 4 | AD11: 6 | AE11: 19 | AF11: 19 | AG11: =SUM(B11:AF11) -> 248
A12: 16:00 | B12: 4 | C12: 14 | D12: 20 | E12: 2 | F12: 5 | G12: 4 | H12: 3 | I12: 3 | J12: 22 | K12: 15 | L12: 3 | M12: 2 | N12: 5 | O12: 1 | P12: 2 | Q12: 28 | R12: 20 | S12: 1 | T12: 4 | U12: 2 | V12: 7 | W12: 5 | X12: 23 | Y12: 24 | Z12: 5 | AA12: 5 | AC12: 1 | AD12: 3 | AE12: 12 | AF12: 16 | AG12: =SUM(B12:AF12) -> 261
A13: 17:00 | B13: 41 | C13: 13 | D13: 11 | E13: 43 | F13: 46 | G13: 45 | H13: 50 | I13: 36 | J13: 19 | K13: 13 | L13: 46 | M13: 52 | N13: 48 | O13: 52 | P13: 48 | Q13: 27 | R13: 14 | S13: 75 | T13: 68 | U13: 53 | V13: 53 | W13: 60 | X13: 22 | Y13: 15 | Z13: 74 | AA13: 63 | AB13: 58 | AC13: 40 | AD13: 50 | AE13: 20 | AF13: 24 | AG13: =SUM(B13:AF13) -> 1279
A14: 18:00 | B14: 13 | C14: 11 | D14: 11 | E14: 17 | F14: 24 | G14: 18 | H14: 25 | I14: 13 | J14: 21 | K14: 10 | L14: 17 | M14: 18 | N14: 19 | O14: 25 | P14: 17 | Q14: 12 | R14: 19 | S14: 32 | T14: 19 | U14: 22 | V14: 25 | W14: 26 | X14: 12 | Y14: 20 | Z14: 15 | AA14: 21 | AB14: 23 | AC14: 21 | AD14: 29 | AE14: 18 | AF14: 12 | AG14: =SUM(B14:AF14) -> 585
A15: 19:00 | B15: 21 | C15: 21 | D15: 10 | E15: 18 | F15: 16 | G15: 17 | H15: 20 | I15: 14 | J15: 20 | K15: 16 | L15: 23 | M15: 20 | N15: 21 | O15: 14 | P15: 21 | Q15: 21 | R15: 14 | S15: 25 | T15: 19 | U15: 22 | V15: 23 | W15: 14 | X15: 15 | Y15: 10 | Z15: 17 | AA15: 19 | AB15: 22 | AC15: 17 | AD15: 19 | AE15: 13 | AF15: 16 | AG15: =SUM(B15:AF15) -> 558
A16: 20:00 | B16: 13 | C16: 9 | D16: 18 | E16: 18 | F16: 14 | G16: 14 | H16: 10 | I16: 22 | J16: 16 | K16: 14 | L16: 22 | M16: 13 | N16: 16 | O16: 8 | P16: 15 | Q16: 17 | R16: 12 | S16: 20 | T16: 25 | U16: 17 | V16: 17 | W16: 24 | X16: 12 | Y16: 14 | Z16: 32 | AA16: 15 | AB16: 16 | AC16: 20 | AD16: 15 | AE16: 16 | AF16: 11 | AG16: =SUM(B16:AF16) -> 505
A17: 21:00 | B17: 16 | C17: 15 | D17: 15 | E17: 22 | F17: 17 | G17: 17 | H17: 13 | I17: 15 | J17: 11 | K17: 12 | L17: 16 | M17: 17 | N17: 22 | O17: 11 | P17: 19 | Q17: 13 | R17: 18 | S17: 16 | T17: 21 | U17: 14 | V17: 19 | W17: 12 | X17: 13 | Y17: 20 | Z17: 32 | AA17: 19 | AB17: 15 | AC17: 11 | AD17: 14 | AE17: 10 | AF17: 12 | AG17: =SUM(B17:AF17) -> 497
A18: 22:00 | B18: 12 | C18: 7 | D18: 7 | E18: 10 | F18: 11 | G18: 7 | H18: 9 | I18: 14 | J18: 12 | K18: 14 | L18: 17 | M18: 9 | N18: 14 | O18: 10 | P18: 12 | Q18: 10 | R18: 11 | S18: 13 | T18: 8 | U18: 19 | V18: 12 | W18: 16 | X18: 9 | Y18: 5 | Z18: 29 | AA18: 12 | AB18: 9 | AC18: 16 | AD18: 16 | AE18: 12 | AF18: 10 | AG18: =SUM(B18:AF18) -> 372
A19: 23:00 | B19: 11 | C19: 8 | D19: 12 | E19: 10 | F19: 5 | G19: 9 | H19: 8 | I19: 10 | J19: 6 | K19: 10 | L19: 7 | M19: 13 | N19: 6 | O19: 11 | P19: 7 | Q19: 9 | R19: 8 | S19: 8 | T19: 13 | U19: 6 | V19: 9 | W19: 7 | X19: 8 | Y19: 6 | Z19: 9 | AA19: 11 | AB19: 11 | AC19: 11 | AD19: 7 | AE19: 9 | AG19: =SUM(B19:AF19) -> 265
A20: 00:00 | B20: 7 | C20: 10 | D20: 5 | E20: 8 | F20: 7 | G20: 4 | I20: 6 | J20: 2 | K20: 6 | L20: 6 | M20: 1 | N20: 2 | O20: 3 | P20: 5 | Q20: 1 | R20: 4 | S20: 6 | T20: 5 | U20: 4 | V20: 4 | W20: 1 | X20: 5 | Y20: 5 | Z20: 6 | AA20: 3 | AB20: 2 | AC20: 4 | AD20: 7 | AE20: 12 | AF20: 5 | AG20: =SUM(B20:AF20) -> 146
A21: 01:00 | B21: 2 | C21: 4 | D21: 4 | E21: 5 | F21: 4 | G21: 4 | H21: 3 | I21: 2 | J21: 3 | K21: 3 | L21: 4 | M21: 3 | N21: 4 | O21: 2 | P21: 3 | Q21: 3 | R21: 5 | S21: 3 | T21: 2 | U21: 1 | V21: 3 | W21: 7 | X21: 5 | Y21: 6 | Z21: 5 | AA21: 1 | AB21: 2 | AC21: 3 | AD21: 9 | AE21: 4 | AF21: 10 | AG21: =SUM(B21:AF21) -> 119
A22: 02:00 | B22: 1 | C22: 4 | D22: 1 | H22: 1 | I22: 7 | K22: 2 | L22: 5 | M22: 2 | N22: 1 | O22: 1 | P22: 2 | Q22: 3 | R22: 3 | T22: 2 | U22: 5 | V22: 3 | W22: 3 | X22: 3 | Y22: 4 | Z22: 1 | AB22: 3 | AC22: 1 | AD22: 2 | AG22: =SUM(B22:AF22) -> 60
A23: 03:00 | B23: 6 | C23: 2 | D23: 1 | G23: 1 | H23: 1 | I23: 4 | J23: 1 | K23: 2 | L23: 1 | M23: 1 | N23: 2 | O23: 1 | Q23: 2 | R23: 3 | S23: 1 | T23: 1 | U23: 1 | V23: 2 | X23: 3 | Y23: 2 | Z23: 2 | AA23: 1 | AD23: 2 | AE23: 2 | AF23: 1 | AG23: =SUM(B23:AF23) -> 46
A24: 04:00 | B24: 3 | C24: 5 | E24: 1 | F24: 2 | H24: 1 | I24: 1 | J24: 1 | K24: 1 | L24: 1 | M24: 2 | N24: 1 | O24: 4 | P24: 1 | Q24: 2 | R24: 3 | T24: 3 | V24: 1 | W24: 1 | X24: 2 | Y24: 1 | Z24: 2 | AA24: 3 | AC24: 2 | AD24: 1 | AE24: 3 | AF24: 1 | AG24: =SUM(B24:AF24) -> 49
A25: 05:00 | B25: 3 | C25: 1 | E25: 3 | G25: 1 | I25: 1 | J25: 6 | M25: 1 | N25: 1 | P25: 2 | Q25: 3 | S25: 1 | U25: 2 | V25: 3 | W25: 2 | X25: 2 | Z25: 2 | AA25: 1 | AB25: 1 | AD25: 3 | AE25: 1 | AF25: 2 | AG25: =SUM(B25:AF25) -> 42
A26: 06:00 | B26: 2 | C26: 1 | D26: 1 | H26: 1 | J26: 1 | M26: 1 | P26: 2 | Q26: 1 | U26: 2 | W26: 3 | X26: 2 | AB26: 2 | AC26: 1 | AD26: 1 | AE26: 3 | AF26: 1 | AG26: =SUM(B26:AF26) -> 25
A27: 07:00 | B27: 2 | C27: 4 | G27: 2 | I27: 5 | J27: 3 | L27: 1 | P27: 2 | Q27: 6 | R27: 1 | W27: 4 | Y27: 1 | AC27: 2 | AD27: 3 | AE27: 1 | AF27: 2 | AG27: =SUM(B27:AF27) -> 39
A28: Total de atendidos | B28: =SUM(B29:B52) -> 172 | C28: =SUM(C29:C52) -> 219 | D28: =SUM(D29:D52) -> 194 | E28: =SUM(E29:E52) -> 170 | F28: =SUM(F29:F52) -> 174 | G28: =SUM(G29:G52) -> 154 | H28: =SUM(H29:H52) -> 158 | I28: =SUM(I29:I52) -> 157 | ... AF28: =SUM(AF29:AF52) -> 223 | AG28: =SUM(B28:AF28) -> 5734
A29: 08:00 | B29: 1 | C29: 2 | D29: 3 | I29: 4 | K29: 2 | Q29: 1 | R29: 1 | Y29: 1 | AD29: 2 | AE29: 3 | AG29: =SUM(B29:AF29) -> 20
A30: 09:00 | C30: 8 | D30: 4 | J30: 12 | K30: 6 | Q30: 1 | R30: 6 | X30: 6 | Y30: 6 | AE30: 6 | AF30: 7 | AG30: =SUM(B30:AF30) -> 62
A31: 10:00 | C31: 11 | D31: 9 | J31: 7 | K31: 10 | R31: 15 | X31: 9 | Y31: 7 | AE31: 12 | AF31: 13 | AG31: =SUM(B31:AF31) -> 93
A32: 11:00 | B32: 4 | C32: 15 | D32: 12 | E32: 3 | F32: 5 | G32: 5 | H32: 6 | I32: 2 | J32: 15 | K32: 9 | L32: 3 | M32: 1 | N32: 5 | O32: 3 | P32: 4 | Q32: 20 | R32: 16 | S32: 2 | T32: 4 | U32: 2 | V32: 7 | W32: 5 | X32: 8 | Y32: 7 | Z32: 2 | AA32: 4 | AB32: 5 | AC32: 4 | AD32: 3 | AE32: 12 | AF32: 18 | AG32: =SUM(B32:AF32) -> 211
A33: 12:00 | B33: 8 | C33: 10 | D33: 13 | E33: 9 | F33: 9 | G33: 4 | H33: 7 | I33: 3 | J33: 11 | K33: 15 | L33: 9 | M33: 4 | N33: 7 | O33: 5 | P33: 9 | Q33: 9 | R33: 11 | S33: 8 | T33: 9 | U33: 10 | V33: 2 | W33: 8 | X33: 9 | Y33: 10 | Z33: 9 | AA33: 10 | AB33: 4 | AC33: 8 | AD33: 7 | AE33: 15 | AF33: 14 | AG33: =SUM(B33:AF33) -> 266
A34: 13:00 | B34: 4 | C34: 11 | D34: 11 | E34: 6 | F34: 1 | G34: 2 | I34: 2 | J34: 8 | K34: 12 | L34: 1 | M34: 1 | N34: 2 | P34: 3 | Q34: 7 | R34: 7 | S34: 3 | T34: 2 | V34: 1 | W34: 3 | X34: 8 | Y34: 9 | Z34: 5 | AA34: 5 | AB34: 3 | AC34: 3 | AD34: 2 | AE34: 9 | AF34: 13 | AG34: =SUM(B34:AF34) -> 144
A35: 14:00 | B35: 4 | C35: 13 | D35: 8 | E35: 4 | F35: 6 | G35: 4 | H35: 6 | I35: 3 | J35: 12 | K35: 12 | L35: 6 | M35: 5 | N35: 3 | O35: 4 | P35: 4 | Q35: 17 | R35: 10 | S35: 4 | T35: 4 | U35: 6 | V35: 5 | W35: 5 | X35: 8 | Y35: 11 | Z35: 8 | AA35: 3 | AB35: 6 | AC35: 7 | AD35: 2 | AE35: 11 | AF35: 15 | AG35: =SUM(B35:AF35) -> 216
A36: 15:00 | B36: 9 | C36: 17 | D36: 13 | E36: 2 | F36: 9 | G36: 4 | H36: 8 | I36: 1 | J36: 10 | K36: 7 | L36: 7 | M36: 3 | N36: 7 | O36: 6 | P36: 3 | Q36: 26 | R36: 11 | S36: 8 | T36: 7 | U36: 9 | V36: 4 | W36: 2 | X36: 14 | Y36: 11 | Z36: 14 | AA36: 7 | AB36: 6 | AC36: 1 | AD36: 8 | AE36: 12 | AF36: 11 | AG36: =SUM(B36:AF36) -> 257
A37: 16:00 | B37: 4 | C37: 16 | D37: 15 | E37: 3 | F37: 5 | G37: 5 | H37: 4 | I37: 3 | J37: 10 | K37: 17 | L37: 1 | M37: 5 | N37: 3 | O37: 3 | Q37: 11 | R37: 19 | S37: 1 | T37: 3 | U37: 3 | V37: 4 | W37: 5 | X37: 16 | Y37: 9 | Z37: 8 | AA37: 2 | AB37: 1 | AC37: 4 | AD37: 3 | AE37: 14 | AF37: 14 | AG37: =SUM(B37:AF37) -> 211
A38: 17:00 | B38: 3 | C38: 13 | D38: 17 | E38: 5 | F38: 13 | G38: 16 | H38: 10 | I38: 7 | J38: 17 | K38: 10 | L38: 3 | M38: 12 | N38: 3 | O38: 6 | P38: 13 | Q38: 12 | R38: 18 | S38: 6 | T38: 9 | U38: 8 | V38: 9 | W38: 55 | X38: 14 | Y38: 21 | Z38: 8 | AA38: 3 | AB38: 10 | AC38: 6 | AD38: 10 | AE38: 17 | AF38: 20 | AG38: =SUM(B38:AF38) -> 374
A39: 18:00 | B39: 19 | C39: 9 | D39: 11 | E39: 14 | F39: 27 | G39: 20 | H39: 14 | I39: 21 | J39: 14 | K39: 14 | L39: 6 | M39: 18 | N39: 21 | O39: 16 | P39: 31 | Q39: 10 | R39: 21 | S39: 19 | T39: 29 | U39: 19 | V39: 20 | W39: 23 | X39: 15 | Y39: 14 | Z39: 18 | AA39: 22 | AB39: 22 | AC39: 15 | AD39: 28 | AE39: 15 | AF39: 11 | AG39: =SUM(B39:AF39) -> 556
A40: 19:00 | B40: 26 | C40: 16 | D40: 12 | E40: 22 | F40: 27 | G40: 19 | H40: 21 | I40: 23 | J40: 6 | K40: 12 | L40: 34 | M40: 17 | N40: 20 | O40: 22 | P40: 24 | Q40: 15 | R40: 10 | S40: 17 | T40: 25 | U40: 24 | V40: 22 | W40: 10 | X40: 9 | Y40: 13 | Z40: 22 | AA40: 27 | AB40: 23 | AC40: 22 | AD40: 22 | AE40: 15 | AF40: 15 | AG40: =SUM(B40:AF40) -> 592
A41: 20:00 | B41: 10 | C41: 14 | D41: 12 | E41: 27 | F41: 22 | G41: 15 | H41: 24 | I41: 13 | J41: 8 | K41: 10 | L41: 32 | M41: 17 | N41: 21 | O41: 22 | P41: 24 | Q41: 19 | R41: 15 | S41: 24 | T41: 26 | U41: 20 | V41: 21 | W41: 19 | X41: 18 | Y41: 14 | Z41: 32 | AA41: 23 | AB41: 22 | AC41: 21 | AD41: 11 | AE41: 10 | AF41: 15 | AG41: =SUM(B41:AF41) -> 581
...

Sheet ABRIL
A2: ABRIL | B2: 1 | C2: =+B2+1 -> 2 | D2: =+C2+1 -> 3 | E2: =+D2+1 -> 4 | F2: =+E2+1 -> 5 | G2: =+F2+1 -> 6 | H2: =+G2+1 -> 7 | I2: =+H2+1 -> 8 | J2: =+I2+1 -> 9 | ... AA2: =+Z2+1 -> 26 | AB2: 27 | AC2: =+AB2+1 -> 28 | AD2: 29 | AE2: 30 | AG2: TOTAL
A3: Total de Inscritos | B3: =SUM(B4:B27) -> 221 | C3: =SUM(C4:C27) -> 209 | D3: =SUM(D4:D27) -> 189 | E3: =SUM(E4:E27) -> 164 | F3: =SUM(F4:F27) -> 161 | G3: =SUM(G4:G27) -> 233 | H3: =SUM(H4:H27) -> 247 | I3: =SUM(I4:I27) -> 178 | ... AF3: =SUM(AF4:AF27) -> 0 | AG3: =SUM(B3:AF3) -> 5662
A4: 08:00 | G4: 8 | H4: 5 | N4: 4 | O4: 3 | T4: 7 | U4: 3 | V4: 6 | AB4: 12 | AC4: 2 | AG4: =SUM(B4:AF4) -> 50
A5: 09:00 | G5: 10 | H5: 10 | N5: 6 | O5: 9 | T5: 10 | U5: 5 | V5: 13 | AB5: 14 | AC5: 8 | AG5: =SUM(B5:AF5) -> 85
A6: 10:00 | G6: 20 | H6: 23 | N6: 22 | O6: 7 | T6: 9 | U6: 18 | V6: 11 | AB6: 20 | AC6: 18 | AG6: =SUM(B6:AF6) -> 148
A7: 11:00 | B7: 11 | C7: 15 | D7: 7 | E7: 1 | G7: 25 | H7: 26 | J7: 1 | K7: 4 | M7: 1 | N7: 22 | O7: 15 | P7: 4 | Q7: 3 | R7: 1 | T7: 11 | U7: 27 | V7: 14 | W7: 4 | AA7: 2 | AB7: 10 | AC7: 14 | AD7: 1 | AG7: =SUM(B7:AF7) -> 219
A8: 12:00 | B8: 2 | C8: 4 | D8: 6 | G8: 15 | H8: 15 | I8: 1 | L8: 1 | N8: 19 | O8: 18 | P8: 1 | R8: 1 | T8: 15 | U8: 18 | V8: 14 | AB8: 17 | AC8: 17 | AD8: 2 | AG8: =SUM(B8:AF8) -> 166
A9: 13:00 | B9: 4 | D9: 5 | G9: 13 | H9: 11 | K9: 4 | N9: 23 | O9: 23 | P9: 1 | T9: 14 | U9: 10 | V9: 10 | Y9: 1 | AB9: 23 | AC9: 17 | AG9: =SUM(B9:AF9) -> 159
A10: 14:00 | B10: 3 | C10: 6 | D10: 6 | F10: 1 | G10: 12 | H10: 7 | K10: 2 | N10: 7 | O10: 14 | P10: 3 | Q10: 2 | R10: 2 | S10: 1 | T10: 8 | U10: 12 | V10: 14 | W10: 1 | AA10: 2 | AB10: 19 | AC10: 10 | AD10: 2 | AE10: 3 | AG10: =SUM(B10:AF10) -> 137
A11: 15:00 | B11: 5 | C11: 7 | D11: 9 | G11: 9 | H11: 11 | J11: 1 | K11: 3 | M11: 3 | N11: 11 | O11: 24 | Q11: 1 | R11: 1 | S11: 2 | T11: 12 | U11: 23 | V11: 19 | W11: 1 | Z11: 1 | AA11: 1 | AB11: 23 | AC11: 21 | AE11: 2 | AG11: =SUM(B11:AF11) -> 190
A12: 16:00 | B12: 6 | C12: 8 | D12: 5 | E12: 1 | G12: 8 | H12: 22 | J12: 2 | K12: 3 | N12: 26 | O12: 19 | R12: 1 | T12: 14 | U12: 10 | V12: 17 | Y12: 1 | AB12: 19 | AC12: 17 | AG12: =SUM(B12:AF12) -> 179
A13: 17:00 | B13: 60 | C13: 55 | D13: 47 | E13: 53 | F13: 57 | G13: 15 | H13: 27 | J13: 63 | K13: 52 | L13: 64 | M13: 55 | N13: 23 | O13: 14 | P13: 60 | Q13: 67 | R13: 64 | S13: 56 | T13: 14 | U13: 13 | V13: 25 | W13: 67 | X13: 73 | Y13: 62 | Z13: 55 | AA13: 58 | AB13: 16 | AC13: 24 | AD13: 71 | AE13: 65 | AG13: =SUM(B13:AF13) -> 1375
A14: 18:00 | B14: 20 | C14: 25 | D14: 23 | E14: 11 | F14: 17 | G14: 24 | H14: 16 | I14: 67 | J14: 21 | K14: 28 | L14: 18 | M14: 12 | N14: 9 | O14: 5 | P14: 26 | Q14: 19 | R14: 14 | S14: 19 | T14: 17 | U14: 19 | V14: 33 | W14: 37 | X14: 16 | Y14: 19 | Z14: 28 | AA14: 21 | AB14: 19 | AC14: 12 | AD14: 27 | AE14: 18 | AG14: =SUM(B14:AF14) -> 640
A15: 19:00 | B15: 21 | C15: 18 | D15: 22 | E15: 24 | F15: 19 | G15: 16 | H15: 18 | I15: 22 | J15: 23 | K15: 17 | L15: 11 | M15: 11 | N15: 19 | O15: 14 | P15: 29 | Q15: 20 | R15: 22 | S15: 16 | T15: 19 | U15: 19 | V15: 9 | W15: 22 | X15: 15 | Y15: 20 | Z15: 20 | AA15: 17 | AB15: 6 | AC15: 13 | AD15: 20 | AE15: 11 | AG15: =SUM(B15:AF15) -> 533
A16: 20:00 | B16: 21 | C16: 18 | D16: 18 | E16: 13 | F16: 20 | G16: 16 | H16: 8 | I16: 21 | J16: 14 | K16: 15 | L16: 13 | M16: 19 | N16: 9 | O16: 14 | P16: 22 | Q16: 16 | R16: 11 | S16: 14 | T16: 6 | U16: 10 | V16: 12 | W16: 13 | X16: 16 | Y16: 15 | Z16: 11 | AA16: 12 | AB16: 6 | AC16: 16 | AD16: 15 | AE16: 14 | AG16: =SUM(B16:AF16) -> 428
A17: 21:00 | B17: 24 | C17: 18 | D17: 16 | E17: 22 | F17: 18 | G17: 9 | H17: 19 | I17: 23 | J17: 7 | K17: 15 | L17: 12 | M17: 14 | N17: 9 | O17: 8 | P17: 25 | Q17: 11 | R17: 19 | S17: 11 | T17: 10 | U17: 9 | V17: 11 | W17: 14 | X17: 14 | Y17: 15 | Z17: 7 | AA17: 26 | AB17: 12 | AC17: 11 | AD17: 12 | AE17: 12 | AG17: =SUM(B17:AF17) -> 433
A18: 22:00 | B18: 14 | C18: 19 | D18: 8 | E18: 19 | F18: 6 | G18: 11 | H18: 9 | I18: 15 | J18: 6 | K18: 6 | L18: 8 | M18: 8 | N18: 2 | O18: 10 | P18: 14 | Q18: 12 | R18: 14 | S18: 12 | T18: 11 | U18: 7 | V18: 12 | W18: 13 | X18: 11 | Y18: 9 | Z18: 3 | AA18: 10 | AB18: 5 | AC18: 18 | AD18: 12 | AE18: 9 | AG18: =SUM(B18:AF18) -> 313
A19: 23:00 | B19: 12 | C19: 5 | D19: 2 | E19: 5 | F19: 3 | G19: 7 | H19: 10 | I19: 16 | J19: 9 | K19: 14 | L19: 3 | M19: 5 | N19: 2 | O19: 4 | P19: 8 | Q19: 6 | R19: 4 | S19: 7 | T19: 5 | U19: 7 | V19: 6 | W19: 2 | X19: 8 | Y19: 8 | Z19: 9 | AA19: 9 | AB19: 9 | AC19: 4 | AD19: 10 | AE19: 3 | AG19: =SUM(B19:AF19) -> 202
A20: 00:00 | B20: 8 | C20: 5 | D20: 2 | E20: 2 | F20: 7 | G20: 7 | H20: 2 | I20: 7 | J20: 2 | K20: 1 | L20: 4 | M20: 4 | N20: 4 | O20: 7 | Q20: 2 | R20: 8 | S20: 6 | T20: 1 | U20: 6 | V20: 3 | W20: 1 | X20: 3 | Y20: 4 | Z20: 4 | AA20: 3 | AB20: 1 | AC20: 6 | AD20: 3 | AE20: 6 | AG20: =SUM(B20:AF20) -> 119
A21: 01:00 | B21: 2 | C21: 2 | D21: 5 | E21: 6 | F21: 2 | G21: 1 | H21: 3 | J21: 1 | L21: 5 | M21: 3 | N21: 3 | O21: 2 | Q21: 3 | R21: 3 | S21: 3 | T21: 1 | U21: 4 | V21: 4 | W21: 1 | X21: 1 | Y21: 5 | Z21: 5 | AA21: 6 | AB21: 1 | AC21: 1 | AE21: 4 | AG21: =SUM(B21:AF21) -> 77
A22: 02:00 | B22: 6 | D22: 2 | E22: 1 | F22: 3 | G22: 3 | H22: 1 | I22: 1 | J22: 1 | K22: 2 | M22: 4 | N22: 2 | O22: 2 | P22: 5 | R22: 4 | S22: 3 | T22: 3 | U22: 2 | V22: 2 | AB22: 2 | AC22: 1 | AD22: 1 | AE22: 8 | AG22: =SUM(B22:AF22) -> 59
A23: 03:00 | B23: 1 | C23: 1 | D23: 4 | E23: 2 | F23: 2 | H23: 1 | L23: 2 | M23: 2 | N23: 1 | O23: 2 | P23: 2 | Q23: 4 | R23: 1 | S23: 2 | T23: 2 | U23: 2 | V23: 2 | Y23: 1 | AA23: 1 | AE23: 2 | AG23: =SUM(B23:AF23) -> 37
A24: 04:00 | B24: 1 | C24: 1 | D24: 2 | E24: 1 | F24: 2 | I24: 5 | M24: 3 | N24: 1 | O24: 2 | P24: 2 | R24: 1 | S24: 4 | T24: 1 | V24: 1 | X24: 3 | Z24: 1 | AA24: 2 | AB24: 1 | AC24: 1 | AE24: 2 | AG24: =SUM(B24:AF24) -> 37
A25: 05:00 | C25: 1 | F25: 2 | J25: 1 | K25: 5 | L25: 1 | M25: 1 | N25: 2 | R25: 1 | S25: 1 | U25: 2 | V25: 1 | X25: 1 | AA25: 1 | AB25: 2 | AG25: =SUM(B25:AF25) -> 22
A26: 06:00 | C26: 1 | E26: 2 | F26: 1 | G26: 2 | H26: 2 | J26: 4 | L26: 1 | M26: 1 | Q26: 3 | R26: 2 | S26: 3 | T26: 3 | U26: 2 | Y26: 1 | AB26: 1 | AD26: 1 | AE26: 2 | AG26: =SUM(B26:AF26) -> 32
A27: 07:00 | E27: 1 | F27: 1 | G27: 2 | H27: 1 | J27: 2 | M27: 4 | N27: 2 | P27: 1 | T27: 1 | U27: 1 | V27: 1 | W27: 1 | AA27: 1 | AC27: 2 | AE27: 1 | AG27: =SUM(B27:AF27) -> 22
A28: Total de atendidos | B28: =SUM(B29:B52) -> 182 | C28: =SUM(C29:C52) -> 193 | D28: =SUM(D29:D52) -> 176 | E28: =SUM(E29:E52) -> 146 | F28: =SUM(F29:F52) -> 137 | G28: =SUM(G29:G52) -> 222 | H28: =SUM(H29:H52) -> 216 | I28: =SUM(I29:I52) -> 153 | ... AF28: =SUM(AF29:AF52) -> 0 | AG28: =SUM(B28:AF28) -> 5114
A29: 08:00 | G29: 3 | H29: 2 | J29: 1 | M29: 3 | N29: 4 | O29: 2 | T29: 9 | U29: 1 | V29: 4 | AA29: 1 | AB29: 5 | AC29: 2 | AG29: =SUM(B29:AF29) -> 37
