Workbook

Sheet detalle CIE10
A1: CIE_10 | B1: Descriptor
A2: J00-J06
A3: J00X | B3: RINOFARINGITIS AGUDA (RESFRIADO COMUN)
A4: J010 | B4: SINUSITIS MAXILAR AGUDA
A5: J011 | B5: SINUSITIS FRONTAL AGUDA
A6: J012 | B6: SINUSITIS ETMOIDAL AGUDA
A7: J013 | B7: SINUSITIS ESFENOIDAL AGUDA
A8: J014 | B8: PANSINUSITIS AGUDA
A9: J018 | B9: OTRAS SINUSITIS AGUDAS
A10: J019 | B10: SINUSITIS AGUDA, NO ESPECIFICADA
A11: J020 | B11: FARINGITIS ESTREPTOCOCICA
A12: J028 | B12: FARINGITIS AGUDA DEBIDA A OTROS MICROORGANISMOS ESPECIFICADOS
A13: J029 | B13: FARINGITIS AGUDA, NO ESPECIFICADA
A14: J030 | B14: AMIGDALITIS ESTREPTOCOCICA
... A24: J069 | B24: INFECCION AGUDA DE LAS VÍAS RESPIRATORIAS SUPERIORES, NO ESPECIFICADA
A26: J09-J11
A27: J09X | B27: INFLUENZA DEBIDA A CIERTOS VIRUS DE LA INFLUENZA IDENTIFICADOS
A28: J100 | B28: INFLUENZA CON NEUMONIA, DEBIDA A VIRUS DE LA INFLUENZA IDENTIFICADO
A29: J101 | B29: INFLUENZA CON OTRAS MANIFESTACIONES RESPIRATORIAS, DEBIDA A VIRUS DE LA INFLUENZA IDENTIFICADO
A30: J108 | B30: INFLUENZA, CON OTRAS MANIFESTACIONES, DEBIDA A VIRUS DE LA INFLUENZA IDENTIFICADO
A31: J110 | B31: INFLUENZA CON NEUMONIA, VIRUS NO IDENTIFICADO
A32: J111 | B32: INFLUENZA CON OTRAS MANIFESTACIONES RESPIRATORIAS, VIRUS NO IDENTIFICADO
A33: J118 | B33: INFLUENZA CON OTRAS MANIFESTACIONES, VIRUS NO IDENTIFICADO
A36: J12-J18
A37: J120 | B37: NEUMONIA DEBIDA A ADENOVIRUS
A38: J121 | B38: NEUMONIA DEBIDA A VIRUS SINCICIAL RESPIRATORIO
A39: J122 | B39: NEUMONIA DEBIDA A VIRUS PARAINFLUENZA
A40: J123 | B40: NEUMONÍA DEBIDA A METANEUMOVIRUS HUMANO
A41: J128 | B41: NEUMONIA DEBIDA A OTROS VIRUS
A42: J129 | B42: NEUMONIA VIRAL, NO ESPECIFICADA (VIRUS)
A43: J13X | B43: NEUMONIA DEBIDA A STREPTOCOCCUS PNEUMONIAE
A44: J14X | B44: NEUMONIA DEBIDA A HAEMOPHILUS INFLUENZAE
A45: J150 | B45: NEUMONIA DEBIDA A KLEBSIELLA PNEUMONIAE
A46: J151 | B46: NEUMONIA DEBIDA A PSEUDOMONAS
A47: J152 | B47: NEUMONIA DEBIDA A ESTAFILOCOCOS
A48: J153 | B48: NEUMONIA DEBIDA A ESTREPTOCOCOS DEL GRUPO B
... A61: J189 | B61: NEUMONIA, NO ESPECIFICADA
A64: J20-J21
A65: J200 | B65: BRONQUITIS AGUDA DEBIDA A MYCOPLASMA PNEUMONIAE
A66: J201 | B66: BRONQUITIS AGUDA DEBIDA A HAEMOPHILUS INFLUENZAE
...

Sheet FORMATO
A2: X X X X X | B2: 1 | C2: =+B2+1 -> 2 | D2: =+C2+1 -> 3 | E2: =+D2+1 -> 4 | F2: =+E2+1 -> 5 | G2: =+F2+1 -> 6 | H2: =+G2+1 -> 7 | I2: =+H2+1 -> 8 | J2: =+I2+1 -> 9 | ... AA2: =+Z2+1 -> 26 | AB2: 27 | AC2: =+AB2+1 -> 28 | AD2: 29 | AE2: 30 | AF2: 31 | AG2: TOTAL
A3: Total de Inscritos | B3: =SUM(B4:B27) -> 0 | C3: =SUM(C4:C27) -> 0 | D3: =SUM(D4:D27) -> 0 | E3: =SUM(E4:E27) -> 0 | F3: =SUM(F4:F27) -> 0 | G3: =SUM(G4:G27) -> 0 | H3: =SUM(H4:H27) -> 0 | I3: =SUM(I4:I27) -> 0 | ... AF3: =SUM(AF4:AF27) -> 0 | AG3: =SUM(B3:AF3) -> 0
A4: 08:00 | AG4: =SUM(B4:AF4) -> 0
A5: 09:00 | AG5: =SUM(B5:AF5) -> 0
A6: 10:00 | AG6: =SUM(B6:AF6) -> 0
A7: 11:00 | AG7: =SUM(B7:AF7) -> 0
A8: 12:00 | AG8: =SUM(B8:AF8) -> 0
A9: 13:00 | AG9: =SUM(B9:AF9) -> 0
A10: 14:00 | AG10: =SUM(B10:AF10) -> 0
A11: 15:00 | AG11: =SUM(B11:AF11) -> 0
A12: 16:00 | AG12: =SUM(B12:AF12) -> 0
A13: 17:00 | AG13: =SUM(B13:AF13) -> 0
A14: 18:00 | AG14: =SUM(B14:AF14) -> 0
A15: 19:00 | AG15: =SUM(B15:AF15) -> 0
... A27: 07:00 | AG27: =SUM(B27:AF27) -> 0
A28: Total de atendidos | B28: =SUM(B29:B52) -> 0 | C28: =SUM(C29:C52) -> 0 | D28: =SUM(D29:D52) -> 0 | E28: =SUM(E29:E52) -> 0 | F28: =SUM(F29:F52) -> 0 | G28: =SUM(G29:G52) -> 0 | H28: =SUM(H29:H52) -> 0 | I28: =SUM(I29:I52) -> 0 | ... AF28: =SUM(AF29:AF52) -> 0 | AG28: =SUM(B28:AF28) -> 0
A29: 08:00 | AG29: =SUM(B29:AF29) -> 0
A30: 09:00 | AG30: =SUM(B30:AF30) -> 0
A31: 10:00 | AG31: =SUM(B31:AF31) -> 0
A32: 11:00 | AG32: =SUM(B32:AF32) -> 0
A33: 12:00 | AG33: =SUM(B33:AF33) -> 0
A34: 13:00 | AG34: =SUM(B34:AF34) -> 0
A35: 14:00 | AG35: =SUM(B35:AF35) -> 0
A36: 15:00 | AG36: =SUM(B36:AF36) -> 0
A37: 16:00 | AG37: =SUM(B37:AF37) -> 0
A38: 17:00 | AG38: =SUM(B38:AF38) -> 0
A39: 18:00 | AG39: =SUM(B39:AF39) -> 0
A40: 19:00 | AG40: =SUM(B40:AF40) -> 0
... A52: 07:00 | AG52: =SUM(B52:AF52) -> 0
A53: Total de NSP | B53: =SUM(B54:B77) -> 0 | C53: =SUM(C54:C77) -> 0 | D53: =SUM(D54:D77) -> 0 | E53: =SUM(E54:E77) -> 0 | F53: =SUM(F54:F77) -> 0 | G53: =SUM(G54:G77) -> 0 | H53: =SUM(H54:H77) -> 0 | I53: =SUM(I54:I77) -> 0 | ... AF53: =SUM(AF54:AF77) -> 0 | AG53: =SUM(B53:AF53) -> 0
A54: 08:00 | AG54: =SUM(B54:AF54) -> 0
A55: 09:00 | AG55: =SUM(B55:AF55) -> 0
A56: 10:00 | AG56: =SUM(B56:AF56) -> 0
A57: 11:00 | AG57: =SUM(B57:AF57) -> 0
A58: 12:00 | AG58: =SUM(B58:AF58) -> 0
A59: 13:00 | AG59: =SUM(B59:AF59) -> 0
A60: 14:00 | AG60: =SUM(B60:AF60) -> 0
A61: 15:00 | AG61: =SUM(B61:AF61) -> 0
A62: 16:00 | AG62: =SUM(B62:AF62) -> 0
A63: 17:00 | AG63: =SUM(B63:AF63) -> 0
...

Sheet CONSOLIDADO
A2: ENERO - DICIEMBRE 2020 | B2: ENERO | C2: FEBRERO | D2: MARZO | E2: ABRIL | F2: MAYO | G2: JUNIO | H2: JULIO | I2: AGOSTO | J2: SEPTIEMBRE | K2: OCTUBRE | L2: NOVIEMBRE | M2: DICIEMBRE | N2: TOTAL
A3: Total de Inscritos | B3: =+ENERO!$AG3 -> 5388 | C3: =+FEBRERO!$AG3 -> 5213 | D3: =+MARZO!$AG3 -> 4021 | E3: =+ABRIL!$AG3 -> 1992 | F3: =+MAYO!$AG3 -> 2659 | G3: =+JUNIO!$AG3 -> 2845 | H3: =+JULIO!$AG3 -> 3279 | I3: =+AGOSTO!$AG3 -> 3351 | J3: =+SEPTIEMBRE!$AG3 -> 3235 | K3: =+OCTUBRE!$AG3 -> 3797 | L3: =+NOVIEMBRE!$AG3 -> 4118 | M3: =+DICIEMBRE!$AG3 -> 4099 | N3: =SUM(B3:M3) -> 43997
A4: 08:00 | B4: =+ENERO!$AG4 -> 55 | C4: =+FEBRERO!$AG4 -> 67 | D4: =+MARZO!$AG4 -> 46 | E4: =+ABRIL!$AG4 -> 77 | F4: =+MAYO!$AG4 -> 109 | G4: =+JUNIO!$AG4 -> 113 | H4: =+JULIO!$AG4 -> 165 | I4: =+AGOSTO!$AG4 -> 175 | J4: =+SEPTIEMBRE!$AG4 -> 129 | K4: =+OCTUBRE!$AG4 -> 141 | L4: =+NOVIEMBRE!$AG4 -> 67 | M4: =+DICIEMBRE!$AG4 -> 80 | N4: =SUM(B4:M4) -> 1224
A5: 09:00 | B5: =+ENERO!$AG5 -> 80 | C5: =+FEBRERO!$AG5 -> 111 | D5: =+MARZO!$AG5 -> 80 | E5: =+ABRIL!$AG5 -> 108 | F5: =+MAYO!$AG5 -> 141 | G5: =+JUNIO!$AG5 -> 154 | H5: =+JULIO!$AG5 -> 190 | I5: =+AGOSTO!$AG5 -> 199 | J5: =+SEPTIEMBRE!$AG5 -> 159 | K5: =+OCTUBRE!$AG5 -> 166 | L5: =+NOVIEMBRE!$AG5 -> 120 | M5: =+DICIEMBRE!$AG5 -> 110 | N5: =SUM(B5:M5) -> 1618
A6: 10:00 | B6: =+ENERO!$AG6 -> 113 | C6: =+FEBRERO!$AG6 -> 112 | D6: =+MARZO!$AG6 -> 91 | E6: =+ABRIL!$AG6 -> 110 | F6: =+MAYO!$AG6 -> 142 | G6: =+JUNIO!$AG6 -> 166 | H6: =+JULIO!$AG6 -> 214 | I6: =+AGOSTO!$AG6 -> 227 | J6: =+SEPTIEMBRE!$AG6 -> 175 | K6: =+OCTUBRE!$AG6 -> 199 | L6: =+NOVIEMBRE!$AG6 -> 137 | M6: =+DICIEMBRE!$AG6 -> 130 | N6: =SUM(B6:M6) -> 1816
A7: 11:00 | B7: =+ENERO!$AG7 -> 108 | C7: =+FEBRERO!$AG7 -> 128 | D7: =+MARZO!$AG7 -> 114 | E7: =+ABRIL!$AG7 -> 117 | F7: =+MAYO!$AG7 -> 176 | G7: =+JUNIO!$AG7 -> 230 | H7: =+JULIO!$AG7 -> 207 | I7: =+AGOSTO!$AG7 -> 246 | J7: =+SEPTIEMBRE!$AG7 -> 227 | K7: =+OCTUBRE!$AG7 -> 236 | L7: =+NOVIEMBRE!$AG7 -> 157 | M7: =+DICIEMBRE!$AG7 -> 159 | N7: =SUM(B7:M7) -> 2105
A8: 12:00 | B8: =+ENERO!$AG8 -> 108 | C8: =+FEBRERO!$AG8 -> 111 | D8: =+MARZO!$AG8 -> 121 | E8: =+ABRIL!$AG8 -> 137 | F8: =+MAYO!$AG8 -> 215 | G8: =+JUNIO!$AG8 -> 214 | H8: =+JULIO!$AG8 -> 216 | I8: =+AGOSTO!$AG8 -> 227 | J8: =+SEPTIEMBRE!$AG8 -> 259 | K8: =+OCTUBRE!$AG8 -> 243 | L8: =+NOVIEMBRE!$AG8 -> 162 | M8: =+DICIEMBRE!$AG8 -> 160 | N8: =SUM(B8:M8) -> 2173
A9: 13:00 | B9: =+ENERO!$AG9 -> 114 | C9: =+FEBRERO!$AG9 -> 90 | D9: =+MARZO!$AG9 -> 93 | E9: =+ABRIL!$AG9 -> 106 | F9: =+MAYO!$AG9 -> 124 | G9: =+JUNIO!$AG9 -> 167 | H9: =+JULIO!$AG9 -> 175 | I9: =+AGOSTO!$AG9 -> 187 | J9: =+SEPTIEMBRE!$AG9 -> 197 | K9: =+OCTUBRE!$AG9 -> 201 | L9: =+NOVIEMBRE!$AG9 -> 169 | M9: =+DICIEMBRE!$AG9 -> 136 | N9: =SUM(B9:M9) -> 1759
A10: 14:00 | B10: =+ENERO!$AG10 -> 96 | C10: =+FEBRERO!$AG10 -> 96 | D10: =+MARZO!$AG10 -> 82 | E10: =+ABRIL!$AG10 -> 124 | F10: =+MAYO!$AG10 -> 144 | G10: =+JUNIO!$AG10 -> 180 | H10: =+JULIO!$AG10 -> 235 | I10: =+AGOSTO!$AG10 -> 227 | J10: =+SEPTIEMBRE!$AG10 -> 215 | K10: =+OCTUBRE!$AG10 -> 225 | L10: =+NOVIEMBRE!$AG10 -> 368 | M10: =+DICIEMBRE!$AG10 -> 419 | N10: =SUM(B10:M10) -> 2411
A11: 15:00 | B11: =+ENERO!$AG11 -> 101 | C11: =+FEBRERO!$AG11 -> 111 | D11: =+MARZO!$AG11 -> 103 | E11: =+ABRIL!$AG11 -> 123 | F11: =+MAYO!$AG11 -> 191 | G11: =+JUNIO!$AG11 -> 214 | H11: =+JULIO!$AG11 -> 227 | I11: =+AGOSTO!$AG11 -> 258 | J11: =+SEPTIEMBRE!$AG11 -> 212 | K11: =+OCTUBRE!$AG11 -> 253 | L11: =+NOVIEMBRE!$AG11 -> 259 | M11: =+DICIEMBRE!$AG11 -> 287 | N11: =SUM(B11:M11) -> 2339
A12: 16:00 | B12: =+ENERO!$AG12 -> 123 | C12: =+FEBRERO!$AG12 -> 139 | D12: =+MARZO!$AG12 -> 87 | E12: =+ABRIL!$AG12 -> 145 | F12: =+MAYO!$AG12 -> 224 | G12: =+JUNIO!$AG12 -> 243 | H12: =+JULIO!$AG12 -> 300 | I12: =+AGOSTO!$AG12 -> 248 | J12: =+SEPTIEMBRE!$AG12 -> 253 | K12: =+OCTUBRE!$AG12 -> 298 | L12: =+NOVIEMBRE!$AG12 -> 362 | M12: =+DICIEMBRE!$AG12 -> 359 | N12: =SUM(B12:M12) -> 2781
A13: 17:00 | B13: =+ENERO!$AG13 -> 1360 | C13: =+FEBRERO!$AG13 -> 1170 | D13: =+MARZO!$AG13 -> 1013 | E13: =+ABRIL!$AG13 -> 187 | F13: =+MAYO!$AG13 -> 267 | G13: =+JUNIO!$AG13 -> 251 | H13: =+JULIO!$AG13 -> 353 | I13: =+AGOSTO!$AG13 -> 309 | J13: =+SEPTIEMBRE!$AG13 -> 240 | K13: =+OCTUBRE!$AG13 -> 372 | L13: =+NOVIEMBRE!$AG13 -> 454 | M13: =+DICIEMBRE!$AG13 -> 390 | N13: =SUM(B13:M13) -> 6366
A14: 18:00 | B14: =+ENERO!$AG14 -> 514 | C14: =+FEBRERO!$AG14 -> 501 | D14: =+MARZO!$AG14 -> 411 | E14: =+ABRIL!$AG14 -> 141 | F14: =+MAYO!$AG14 -> 192 | G14: =+JUNIO!$AG14 -> 195 | H14: =+JULIO!$AG14 -> 255 | I14: =+AGOSTO!$AG14 -> 231 | J14: =+SEPTIEMBRE!$AG14 -> 248 | K14: =+OCTUBRE!$AG14 -> 307 | L14: =+NOVIEMBRE!$AG14 -> 340 | M14: =+DICIEMBRE!$AG14 -> 326 | N14: =SUM(B14:M14) -> 3661
... A80: PAR | B80: =+ENERO!$AG80 -> 510 | C80: =+FEBRERO!$AG80 -> 3 | D80: =+MARZO!$AG80 -> 365 | E80: =+ABRIL!$AG80 -> 554 | F80: =+MAYO!$AG80 -> 775 | G80: =+JUNIO!$AG80 -> 755 | H80: =+JULIO!$AG80 -> 1059 | I80: =+AGOSTO!$AG80 -> 1145 | J80: =+SEPTIEMBRE!$AG80 -> 884 | K80: =+OCTUBRE!$AG80 -> 961 | L80: =+NOVIEMBRE!$AG80 -> 913 | M80: =+DICIEMBRE!$AG80 -> 952 | N80: =SUM(B80:M80) -> 8876
A81: TOTAL NSP | B81: =+ENERO!$AG81 -> 494 | C81: =+FEBRERO!$AG81 -> 454 | D81: =+MARZO!$AG81 -> 319 | E81: =+ABRIL!$AG81 -> 96 | F81: =+MAYO!$AG81 -> 123 | G81: =+JUNIO!$AG81 -> 147 | H81: =+JULIO!$AG81 -> 213 | I81: =+AGOSTO!$AG81 -> 194 | J81: =+SEPTIEMBRE!$AG81 -> 167 | K81: =+OCTUBRE!$AG81 -> 173 | L81: =+NOVIEMBRE!$AG81 -> 244 | M81: =+DICIEMBRE!$AG81 -> 218 | N81: =SUM(B81:M81) -> 2842 | O81: =IF(N81<>N53,"*","")
A82: PAR | B82: =+ENERO!$AG82 -> 20 | C82: =+FEBRERO!$AG82 -> 2 | D82: =+MARZO!$AG82 -> 4 | E82: =+ABRIL!$AG82 -> 51 | F82: =+MAYO!$AG82 -> 68 | G82: =+JUNIO!$AG82 -> 107 | H82: =+JULIO!$AG82 -> 146 | I82: =+AGOSTO!$AG82 -> 104 | J82: =+SEPTIEMBRE!$AG82 -> 78 | K82: =+OCTUBRE!$AG82 -> 57 | L82: =+NOVIEMBRE!$AG82 -> 63 | M82: =+DICIEMBRE!$AG82 -> 53 | N82: =SUM(B82:M82) -> 753
A83: SAR | B83: =+ENERO!$AG83 -> 474 | C83: =+FEBRERO!$AG83 -> 452 | D83: =+MARZO!$AG83 -> 315 | E83: =+ABRIL!$AG83 -> 45 | F83: =+MAYO!$AG83 -> 55 | G83: =+JUNIO!$AG83 -> 40 | H83: =+JULIO!$AG83 -> 67 | I83: =+AGOSTO!$AG83 -> 90 | J83: =+SEPTIEMBRE!$AG83 -> 89 | K83: =+OCTUBRE!$AG83 -> 116 | L83: =+NOVIEMBRE!$AG83 -> 181 | M83: =+DICIEMBRE!$AG83 -> 165 | N83: =SUM(B83:M83) -> 2089
A84: NSP PEDIATR. / ADULTOS | B84: =+ENERO!$AG84 -> 494 | C84: =+FEBRERO!$AG84 -> 454 | D84: =+MARZO!$AG84 -> 319 | E84: =+ABRIL!$AG84 -> 96 | F84: =+MAYO!$AG84 -> 123 | G84: =+JUNIO!$AG84 -> 147 | H84: =+JULIO!$AG84 -> 213 | I84: =+AGOSTO!$AG84 -> 194 | J84: =+SEPTIEMBRE!$AG84 -> 167 | K84: =+OCTUBRE!$AG84 -> 173 | L84: =+NOVIEMBRE!$AG84 -> 244 | M84: =+DICIEMBRE!$AG84 -> 218 | N84: =SUM(B84:M84) -> 2842 | O84: =IF(N84<>N82+N83,"*","") | P84: NSP
A85: NSP PEDIATRICOS (<15 AÑOS) | B85: =+ENERO!$AG85 -> 82 | C85: =+FEBRERO!$AG85 -> 73 | D85: =+MARZO!$AG85 -> 41 | E85: =+ABRIL!$AG85 -> 10 | F85: =+MAYO!$AG85 -> 11 | G85: =+JUNIO!$AG85 -> 13 | H85: =+JULIO!$AG85 -> 11 | I85: =+AGOSTO!$AG85 -> 16 | J85: =+SEPTIEMBRE!$AG85 -> 11 | K85: =+OCTUBRE!$AG85 -> 19 | L85: =+NOVIEMBRE!$AG85 -> 23 | M85: =+DICIEMBRE!$AG85 -> 31 | N85: =SUM(B85:M85) -> 341
A86: NSP ADULTOS | B86: =+ENERO!$AG86 -> 412 | C86: =+FEBRERO!$AG86 -> 381 | D86: =+MARZO!$AG86 -> 278 | E86: =+ABRIL!$AG86 -> 86 | F86: =+MAYO!$AG86 -> 112 | G86: =+JUNIO!$AG86 -> 134 | H86: =+JULIO!$AG86 -> 202 | I86: =+AGOSTO!$AG86 -> 178 | J86: =+SEPTIEMBRE!$AG86 -> 156 | K86: =+OCTUBRE!$AG86 -> 154 | L86: =+NOVIEMBRE!$AG86 -> 221 | M86: =+DICIEMBRE!$AG86 -> 187 | N86: =SUM(B86:M86) -> 2501
A87: NSP CATEGORIZACION | B87: =+ENERO!$AG87 -> 494 | C87: =+FEBRERO!$AG87 -> 454 | D87: =+MARZO!$AG87 -> 319 | E87: =+ABRIL!$AG87 -> 96 | F87: =+MAYO!$AG87 -> 123 | G87: =+JUNIO!$AG87 -> 147 | H87: =+JULIO!$AG87 -> 213 | I87: =+AGOSTO!$AG87 -> 194 | J87: =+SEPTIEMBRE!$AG87 -> 167 | K87: =+OCTUBRE!$AG87 -> 173 | L87: =+NOVIEMBRE!$AG87 -> 244 | M87: =+DICIEMBRE!$AG87 -> 218 | N87: =SUM(B87:M87) -> 2842 | O87: =IF(N87<>N84,"*","")
A88: SIN CATEGORIZACIÓN nsp | B88: =+ENERO!$AG88 -> 184 | C88: =+FEBRERO!$AG88 -> 137 | D88: =+MARZO!$AG88 -> 120 | E88: =+ABRIL!$AG88 -> 62 | F88: =+MAYO!$AG88 -> 83 | G88: =+JUNIO!$AG88 -> 102 | H88: =+JULIO!$AG88 -> 133 | I88: =+AGOSTO!$AG88 -> 105 | J88: =+SEPTIEMBRE!$AG88 -> 99 | K88: =+OCTUBRE!$AG88 -> 108 | L88: =+NOVIEMBRE!$AG88 -> 145 | M88: =+DICIEMBRE!$AG88 -> 117 | N88: =SUM(B88:M88) -> 1395
A89: C2 | B89: =+ENERO!$AG89 -> 0 | C89: =+FEBRERO!$AG89 -> 0 | D89: =+MARZO!$AG89 -> 0 | E89: =+ABRIL!$AG89 -> 0 | F89: =+MAYO!$AG89 -> 0 | G89: =+JUNIO!$AG89 -> 0 | H89: =+JULIO!$AG89 -> 0 | I89: =+AGOSTO!$AG89 -> 0 | J89: =+SEPTIEMBRE!$AG89 -> 0 | K89: =+OCTUBRE!$AG89 -> 0 | L89: =+NOVIEMBRE!$AG89 -> 0 | M89: =+DICIEMBRE!$AG89 -> 0 | N89: =SUM(B89:M89) -> 0
A90: C3 | B90: =+ENERO!$AG90 -> 5 | C90: =+FEBRERO!$AG90 -> 5 | D90: =+MARZO!$AG90 -> 3 | E90: =+ABRIL!$AG90 -> 1 | F90: =+MAYO!$AG90 -> 0 | G90: =+JUNIO!$AG90 -> 3 | H90: =+JULIO!$AG90 -> 3 | I90: =+AGOSTO!$AG90 -> 3 | J90: =+SEPTIEMBRE!$AG90 -> 3 | K90: =+OCTUBRE!$AG90 -> 2 | L90: =+NOVIEMBRE!$AG90 -> 5 | M90: =+DICIEMBRE!$AG90 -> 5 | N90: =SUM(B90:M90) -> 38
A91: C4 | B91: =+ENERO!$AG91 -> 155 | C91: =+FEBRERO!$AG91 -> 183 | D91: =+MARZO!$AG91 -> 88 | E91: =+ABRIL!$AG91 -> 17 | F91: =+MAYO!$AG91 -> 11 | G91: =+JUNIO!$AG91 -> 9 | H91: =+JULIO!$AG91 -> 12 | I91: =+AGOSTO!$AG91 -> 24 | J91: =+SEPTIEMBRE!$AG91 -> 18 | K91: =+OCTUBRE!$AG91 -> 17 | L91: =+NOVIEMBRE!$AG91 -> 36 | M91: =+DICIEMBRE!$AG91 -> 49 | N91: =SUM(B91:M91) -> 619
A92: C5 | B92: =+ENERO!$AG92 -> 150 | C92: =+FEBRERO!$AG92 -> 129 | D92: =+MARZO!$AG92 -> 108 | E92: =+ABRIL!$AG92 -> 16 | F92: =+MAYO!$AG92 -> 29 | G92: =+JUNIO!$AG92 -> 33 | H92: =+JULIO!$AG92 -> 65 | I92: =+AGOSTO!$AG92 -> 62 | J92: =+SEPTIEMBRE!$AG92 -> 47 | K92: =+OCTUBRE!$AG92 -> 46 | L92: =+NOVIEMBRE!$AG92 -> 58 | M92: =+DICIEMBRE!$AG92 -> 47 | N92: =SUM(B92:M92) -> 790
A93: TOTAL PACIENTES ATENDIDOS | B93: =+ENERO!$AG93 -> 4894 | C93: =+FEBRERO!$AG93 -> 4759 | D93: =+MARZO!$AG93 -> 3702 | E93: =+ABRIL!$AG93 -> 1895 | F93: =+MAYO!$AG93 -> 2536 | G93: =+JUNIO!$AG93 -> 2696 | H93: =+JULIO!$AG93 -> 3064 | I93: =+AGOSTO!$AG93 -> 3157 | J93: =+SEPTIEMBRE!$AG93 -> 3068 | K93: =+OCTUBRE!$AG93 -> 3624 | L93: =+NOVIEMBRE!$AG93 -> 3874 | M93: =+DICIEMBRE!$AG93 -> 3881 | N93: =SUM(B93:M93) -> 41150 | O93: =IF(N93<>N28,"*","")
A94: Menor 15 años | B94: =+ENERO!$AG94 -> 667 | C94: =+FEBRERO!$AG94 -> 579 | D94: =+MARZO!$AG94 -> 429 | E94: =+ABRIL!$AG94 -> 92 | F94: =+MAYO!$AG94 -> 165 | G94: =+JUNIO!$AG94 -> 160 | H94: =+JULIO!$AG94 -> 185 | I94: =+AGOSTO!$AG94 -> 212 | J94: =+SEPTIEMBRE!$AG94 -> 211 | K94: =+OCTUBRE!$AG94 -> 296 | L94: =+NOVIEMBRE!$AG94 -> 379 | M94: =+DICIEMBRE!$AG94 -> 316 | N94: =SUM(B94:M94) -> 3691
A95: Menor 1 Año | B95: =+ENERO!$AG95 -> 23 | C95: =+FEBRERO!$AG95 -> 34 | D95: =+MARZO!$AG95 -> 30 | E95: =+ABRIL!$AG95 -> 5 | F95: =+MAYO!$AG95 -> 13 | G95: =+JUNIO!$AG95 -> 9 | H95: =+JULIO!$AG95 -> 9 | I95: =+AGOSTO!$AG95 -> 10 | J95: =+SEPTIEMBRE!$AG95 -> 8 | K95: =+OCTUBRE!$AG95 -> 16 | L95: =+NOVIEMBRE!$AG95 -> 21 | M95: =+DICIEMBRE!$AG95 -> 14 | N95: =SUM(B95:M95) -> 192
A96: 1 Año | B96: =+ENERO!$AG96 -> 65 | C96: =+FEBRERO!$AG96 -> 47 | D96: =+MARZO!$AG96 -> 38 | E96: =+ABRIL!$AG96 -> 12 | F96: =+MAYO!$AG96 -> 5 | G96: =+JUNIO!$AG96 -> 15 | H96: =+JULIO!$AG96 -> 18 | I96: =+AGOSTO!$AG96 -> 16 | J96: =+SEPTIEMBRE!$AG96 -> 19 | K96: =+OCTUBRE!$AG96 -> 20 | L96: =+NOVIEMBRE!$AG96 -> 39 | M96: =+DICIEMBRE!$AG96 -> 31 | N96: =SUM(B96:M96) -> 325
A97: 2 - 4 | B97: =+ENERO!$AG97 -> 133 | C97: =+FEBRERO!$AG97 -> 109 | D97: =+MARZO!$AG97 -> 88 | E97: =+ABRIL!$AG97 -> 19 | F97: =+MAYO!$AG97 -> 32 | G97: =+JUNIO!$AG97 -> 23 | H97: =+JULIO!$AG97 -> 32 | I97: =+AGOSTO!$AG97 -> 29 | J97: =+SEPTIEMBRE!$AG97 -> 39 | K97: =+OCTUBRE!$AG97 -> 78 | L97: =+NOVIEMBRE!$AG97 -> 77 | M97: =+DICIEMBRE!$AG97 -> 73 | N97: =SUM(B97:M97) -> 732
A98: 5 - 9 | B98: =+ENERO!$AG98 -> 232 | C98: =+FEBRERO!$AG98 -> 175 | D98: =+MARZO!$AG98 -> 133 | E98: =+ABRIL!$AG98 -> 25 | F98: =+MAYO!$AG98 -> 56 | G98: =+JUNIO!$AG98 -> 43 | H98: =+JULIO!$AG98 -> 56 | I98: =+AGOSTO!$AG98 -> 84 | J98: =+SEPTIEMBRE!$AG98 -> 83 | K98: =+OCTUBRE!$AG98 -> 90 | L98: =+NOVIEMBRE!$AG98 -> 122 | M98: =+DICIEMBRE!$AG98 -> 96 | N98: =SUM(B98:M98) -> 1195
A99: 10 - 14 | B99: =+ENERO!$AG99 -> 214 | C99: =+FEBRERO!$AG99 -> 214 | D99: =+MARZO!$AG99 -> 140 | E99: =+ABRIL!$AG99 -> 31 | F99: =+MAYO!$AG99 -> 59 | G99: =+JUNIO!$AG99 -> 70 | H99: =+JULIO!$AG99 -> 70 | I99: =+AGOSTO!$AG99 -> 73 | J99: =+SEPTIEMBRE!$AG99 -> 62 | K99: =+OCTUBRE!$AG99 -> 92 | L99: =+NOVIEMBRE!$AG99 -> 120 | M99: =+DICIEMBRE!$AG99 -> 102 | N99: =SUM(B99:M99) -> 1247
A100: Mayor de 15 años | B100: =+ENERO!$AG100 -> 4227 | C100: =+FEBRERO!$AG100 -> 4180 | D100: =+MARZO!$AG100 -> 3273 | E100: =+ABRIL!$AG100 -> 1803 | F100: =+MAYO!$AG100 -> 2371 | G100: =+JUNIO!$AG100 -> 2536 | H100: =+JULIO!$AG100 -> 2879 | I100: =+AGOSTO!$AG100 -> 2945 | J100: =+SEPTIEMBRE!$AG100 -> 2857 | K100: =+OCTUBRE!$AG100 -> 3328 | L100: =+NOVIEMBRE!$AG100 -> 3495 | M100: =+DICIEMBRE!$AG100 -> 3565 | N100: =SUM(B100:M100) -> 37459
A101: 15 - 19 | B101: =+ENERO!$AG101 -> 319 | C101: =+FEBRERO!$AG101 -> 296 | D101: =+MARZO!$AG101 -> 290 | E101: =+ABRIL!$AG101 -> 83 | F101: =+MAYO!$AG101 -> 123 | G101: =+JUNIO!$AG101 -> 126 | H101: =+JULIO!$AG101 -> 174 | I101: =+AGOSTO!$AG101 -> 168 | J101: =+SEPTIEMBRE!$AG101 -> 168 | K101: =+OCTUBRE!$AG101 -> 240 | L101: =+NOVIEMBRE!$AG101 -> 257 | M101: =+DICIEMBRE!$AG101 -> 242 | N101: =SUM(B101:M101) -> 2486
A102: 20 - 24 | B102: =+ENERO!$AG102 -> 449 | C102: =+FEBRERO!$AG102 -> 470 | D102: =+MARZO!$AG102 -> 388 | E102: =+ABRIL!$AG102 -> 179 | F102: =+MAYO!$AG102 -> 216 | G102: =+JUNIO!$AG102 -> 252 | H102: =+JULIO!$AG102 -> 260 | I102: =+AGOSTO!$AG102 -> 241 | J102: =+SEPTIEMBRE!$AG102 -> 301 | K102: =+OCTUBRE!$AG102 -> 332 | L102: =+NOVIEMBRE!$AG102 -> 403 | M102: =+DICIEMBRE!$AG102 -> 433 | N102: =SUM(B102:M102) -> 3924
A103: 25 - 29 | B103: =+ENERO!$AG103 -> 409 | C103: =+FEBRERO!$AG103 -> 388 | D103: =+MARZO!$AG103 -> 323 | E103: =+ABRIL!$AG103 -> 176 | F103: =+MAYO!$AG103 -> 251 | G103: =+JUNIO!$AG103 -> 267 | H103: =+JULIO!$AG103 -> 263 | I103: =+AGOSTO!$AG103 -> 264 | J103: =+SEPTIEMBRE!$AG103 -> 284 | K103: =+OCTUBRE!$AG103 -> 343 | L103: =+NOVIEMBRE!$AG103 -> 385 | M103: =+DICIEMBRE!$AG103 -> 389 | N103: =SUM(B103:M103) -> 3742
A104: 30 - 34 | B104: =+ENERO!$AG104 -> 366 | C104: =+FEBRERO!$AG104 -> 314 | D104: =+MARZO!$AG104 -> 300 | E104: =+ABRIL!$AG104 -> 170 | F104: =+MAYO!$AG104 -> 196 | G104: =+JUNIO!$AG104 -> 249 | H104: =+JULIO!$AG104 -> 301 | I104: =+AGOSTO!$AG104 -> 227 | J104: =+SEPTIEMBRE!$AG104 -> 254 | K104: =+OCTUBRE!$AG104 -> 312 | L104: =+NOVIEMBRE!$AG104 -> 307 | M104: =+DICIEMBRE!$AG104 -> 328 | N104: =SUM(B104:M104) -> 3324
A105: 35 - 39 | B105: =+ENERO!$AG105 -> 315 | C105: =+FEBRERO!$AG105 -> 298 | D105: =+MARZO!$AG105 -> 245 | E105: =+ABRIL!$AG105 -> 196 | F105: =+MAYO!$AG105 -> 222 | G105: =+JUNIO!$AG105 -> 236 | H105: =+JULIO!$AG105 -> 215 | I105: =+AGOSTO!$AG105 -> 227 | J105: =+SEPTIEMBRE!$AG105 -> 203 | K105: =+OCTUBRE!$AG105 -> 273 | L105: =+NOVIEMBRE!$AG105 -> 260 | M105: =+DICIEMBRE!$AG105 -> 302 | N105: =SUM(B105:M105) -> 2992
... A114: 80 y mas | B114: =+ENERO!$AG114 -> 191 | C114: =+FEBRERO!$AG114 -> 212 | D114: =+MARZO!$AG114 -> 137 | E114: =+ABRIL!$AG114 -> 40 | F114: =+MAYO!$AG114 -> 86 | G114: =+JUNIO!$AG114 -> 62 | H114: =+JULIO!$AG114 -> 123 | I114: =+AGOSTO!$AG114 -> 156 | J114: =+SEPTIEMBRE!$AG114 -> 116 | K114: =+OCTUBRE!$AG114 -> 160 | L114: =+NOVIEMBRE!$AG114 -> 125 | M114: =+DICIEMBRE!$AG114 -> 131 | N114: =SUM(B114:M114) -> 1539
...

Sheet ENERO
A2: ENERO | B2: 1 | C2: =+B2+1 -> 2 | D2: =+C2+1 -> 3 | E2: =+D2+1 -> 4 | F2: =+E2+1 -> 5 | G2: =+F2+1 -> 6 | H2: =+G2+1 -> 7 | I2: =+H2+1 -> 8 | J2: =+I2+1 -> 9 | ... AA2: =+Z2+1 -> 26 | AB2: 27 | AC2: =+AB2+1 -> 28 | AD2: 29 | AE2: 30 | AF2: 31 | AG2: TOTAL
A3: Total de Inscritos | B3: =SUM(B4:B27) -> 163 | C3: =SUM(C4:C27) -> 169 | D3: =SUM(D4:D27) -> 175 | E3: =SUM(E4:E27) -> 225 | F3: =SUM(F4:F27) -> 228 | G3: =SUM(G4:G27) -> 188 | H3: =SUM(H4:H27) -> 165 | I3: =SUM(I4:I27) -> 155 | ... AF3: =SUM(AF4:AF27) -> 170 | AG3: =SUM(B3:AF3) -> 5388
A4: 08:00 | B4: 5 | E4: 11 | F4: 2 | L4: 3 | M4: 6 | S4: 3 | T4: 10 | Z4: 10 | AA4: 5 | AG4: =SUM(B4:AF4) -> 55
A5: 09:00 | B5: 9 | E5: 7 | F5: 7 | H5: 1 | L5: 5 | M5: 6 | S5: 11 | T5: 10 | Z5: 14 | AA5: 10 | AG5: =SUM(B5:AF5) -> 80
A6: 10:00 | B6: 9 | E6: 12 | F6: 15 | L6: 10 | M6: 11 | R6: 1 | S6: 10 | T6: 16 | Z6: 10 | AA6: 19 | AG6: =SUM(B6:AF6) -> 113
A7: 11:00 | B7: 10 | E7: 16 | F7: 12 | L7: 14 | M7: 16 | S7: 10 | T7: 13 | Y7: 1 | Z7: 8 | AA7: 8 | AG7: =SUM(B7:AF7) -> 108
A8: 12:00 | B8: 11 | E8: 13 | F8: 13 | L8: 8 | M8: 15 | S8: 12 | T8: 15 | Z8: 7 | AA8: 14 | AG8: =SUM(B8:AF8) -> 108
A9: 13:00 | B9: 15 | E9: 9 | F9: 16 | H9: 1 | L9: 14 | M9: 8 | S9: 7 | T9: 10 | Z9: 20 | AA9: 13 | AD9: 1 | AG9: =SUM(B9:AF9) -> 114
A10: 14:00 | B10: 9 | E10: 13 | F10: 14 | L10: 12 | M10: 10 | S10: 11 | T10: 3 | U10: 1 | Z10: 10 | AA10: 13 | AG10: =SUM(B10:AF10) -> 96
A11: 15:00 | B11: 8 | E11: 12 | F11: 9 | L11: 9 | M11: 7 | S11: 19 | T11: 12 | Z11: 9 | AA11: 16 | AG11: =SUM(B11:AF11) -> 101
A12: 16:00 | B12: 3 | E12: 18 | F12: 17 | L12: 16 | M12: 10 | N12: 2 | P12: 1 | Q12: 1 | S12: 8 | T12: 18 | V12: 1 | Z12: 16 | AA12: 12 | AG12: =SUM(B12:AF12) -> 123
A13: 17:00 | B13: 14 | C13: 67 | D13: 64 | E13: 14 | F13: 20 | G13: 67 | H13: 65 | I13: 48 | J13: 43 | K13: 55 | L13: 17 | M13: 16 | N13: 55 | O13: 54 | P13: 60 | Q13: 68 | R13: 48 | S13: 13 | T13: 22 | U13: 48 | V13: 48 | W13: 60 | X13: 55 | Y13: 49 | Z13: 13 | AA13: 17 | AB13: 50 | AC13: 56 | AD13: 63 | AE13: 39 | AF13: 52 | AG13: =SUM(B13:AF13) -> 1360
A14: 18:00 | B14: 9 | C14: 19 | D14: 20 | E14: 20 | F14: 11 | G14: 25 | H14: 15 | I14: 18 | J14: 20 | K14: 19 | L14: 16 | M14: 14 | N14: 17 | O14: 17 | P14: 13 | Q14: 10 | R14: 25 | S14: 17 | T14: 11 | U14: 27 | V14: 18 | W14: 10 | X14: 17 | Y14: 10 | Z14: 12 | AA14: 13 | AB14: 17 | AC14: 13 | AD14: 15 | AE14: 25 | AF14: 21 | AG14: =SUM(B14:AF14) -> 514
A15: 19:00 | B15: 7 | C15: 18 | D15: 12 | E15: 16 | F15: 8 | G15: 21 | H15: 18 | I15: 11 | J15: 21 | K15: 17 | L15: 10 | M15: 12 | N15: 20 | O15: 19 | P15: 12 | Q15: 15 | R15: 13 | S15: 16 | T15: 8 | U15: 15 | V15: 17 | W15: 15 | X15: 14 | Y15: 17 | Z15: 10 | AA15: 17 | AB15: 14 | AC15: 12 | AD15: 14 | AE15: 16 | AF15: 13 | AG15: =SUM(B15:AF15) -> 448
A16: 20:00 | B16: 15 | C16: 14 | D16: 19 | E16: 6 | F16: 18 | G16: 21 | H16: 22 | I16: 18 | J16: 11 | K16: 14 | L16: 21 | M16: 15 | N16: 18 | O16: 11 | P16: 15 | Q16: 21 | R16: 17 | S16: 8 | T16: 16 | U16: 22 | V16: 19 | W16: 15 | X16: 20 | Y16: 21 | Z16: 14 | AA16: 11 | AB16: 32 | AC16: 14 | AD16: 8 | AE16: 17 | AF16: 17 | AG16: =SUM(B16:AF16) -> 510
A17: 21:00 | B17: 9 | C17: 15 | D17: 23 | E17: 9 | F17: 16 | G17: 14 | H17: 15 | I17: 18 | J17: 10 | K17: 7 | L17: 9 | M17: 15 | N17: 16 | O17: 19 | P17: 13 | Q17: 15 | R17: 9 | S17: 16 | T17: 8 | U17: 8 | V17: 11 | W17: 15 | X17: 11 | Y17: 14 | Z17: 17 | AA17: 25 | AB17: 28 | AC17: 10 | AD17: 15 | AE17: 16 | AF17: 17 | AG17: =SUM(B17:AF17) -> 443
A18: 22:00 | B18: 10 | C18: 10 | D18: 9 | E18: 7 | F18: 19 | G18: 18 | H18: 10 | I18: 18 | J18: 16 | K18: 10 | L18: 9 | M18: 13 | N18: 23 | O18: 9 | P18: 9 | Q18: 9 | R18: 12 | S18: 10 | T18: 24 | U18: 12 | V18: 16 | W18: 19 | X18: 15 | Y18: 13 | Z18: 15 | AA18: 13 | AB18: 11 | AC18: 13 | AD18: 18 | AE18: 7 | AF18: 17 | AG18: =SUM(B18:AF18) -> 414
A19: 23:00 | B19: 4 | C19: 14 | D19: 13 | E19: 20 | F19: 14 | G19: 9 | H19: 4 | I19: 10 | J19: 9 | K19: 6 | L19: 11 | M19: 12 | N19: 7 | O19: 10 | P19: 12 | Q19: 7 | R19: 7 | S19: 9 | T19: 6 | U19: 13 | V19: 10 | W19: 8 | X19: 11 | Y19: 7 | Z19: 11 | AA19: 9 | AB19: 9 | AC19: 11 | AD19: 11 | AE19: 12 | AF19: 11 | AG19: =SUM(B19:AF19) -> 307
A20: 00:00 | B20: 4 | C20: 1 | D20: 4 | E20: 6 | F20: 5 | G20: 4 | H20: 6 | I20: 3 | J20: 4 | K20: 1 | L20: 9 | M20: 7 | N20: 5 | O20: 4 | P20: 5 | Q20: 4 | R20: 8 | S20: 4 | T20: 5 | U20: 6 | V20: 12 | W20: 6 | X20: 5 | Y20: 7 | Z20: 8 | AA20: 5 | AB20: 2 | AC20: 5 | AD20: 4 | AE20: 6 | AF20: 8 | AG20: =SUM(B20:AF20) -> 163
A21: 01:00 | B21: 5 | C21: 3 | D21: 2 | E21: 4 | F21: 6 | G21: 2 | H21: 1 | I21: 2 | J21: 1 | K21: 2 | L21: 5 | M21: 3 | N21: 1 | O21: 3 | P21: 2 | Q21: 3 | R21: 6 | S21: 4 | T21: 6 | U21: 2 | V21: 4 | W21: 1 | X21: 9 | Y21: 4 | Z21: 3 | AA21: 4 | AB21: 1 | AC21: 2 | AD21: 6 | AE21: 3 | AF21: 5 | AG21: =SUM(B21:AF21) -> 105
A22: 02:00 | B22: 4 | C22: 2 | D22: 3 | E22: 3 | F22: 3 | H22: 3 | I22: 6 | J22: 1 | K22: 1 | L22: 3 | M22: 3 | N22: 3 | O22: 2 | P22: 1 | Q22: 1 | R22: 4 | S22: 4 | T22: 4 | U22: 2 | V22: 4 | W22: 2 | X22: 3 | Y22: 3 | AA22: 4 | AB22: 1 | AC22: 2 | AD22: 2 | AE22: 1 | AF22: 3 | AG22: =SUM(B22:AF22) -> 78
A23: 03:00 | B23: 3 | C23: 1 | E23: 1 | H23: 1 | I23: 1 | J23: 2 | K23: 3 | L23: 1 | N23: 2 | O23: 1 | P23: 3 | R23: 3 | T23: 1 | U23: 1 | V23: 1 | W23: 3 | Y23: 1 | Z23: 3 | AA23: 1 | AB23: 1 | AD23: 1 | AG23: =SUM(B23:AF23) -> 35
A24: 04:00 | C24: 3 | D24: 3 | E24: 3 | F24: 1 | G24: 1 | J24: 2 | K24: 2 | L24: 2 | N24: 5 | O24: 1 | P24: 1 | R24: 1 | S24: 2 | T24: 1 | U24: 1 | V24: 2 | W24: 1 | X24: 1 | Y24: 1 | Z24: 3 | AA24: 1 | AB24: 1 | AE24: 1 | AF24: 1 | AG24: =SUM(B24:AF24) -> 41
A25: 05:00 | C25: 2 | E25: 2 | F25: 2 | G25: 4 | H25: 3 | I25: 1 | L25: 1 | N25: 1 | O25: 1 | P25: 1 | Q25: 2 | R25: 3 | T25: 4 | W25: 1 | Y25: 4 | Z25: 1 | AD25: 1 | AE25: 1 | AF25: 2 | AG25: =SUM(B25:AF25) -> 37
A26: 06:00 | D26: 2 | E26: 1 | G26: 2 | I26: 1 | K26: 2 | L26: 1 | P26: 1 | R26: 1 | T26: 1 | Z26: 4 | AA26: 1 | AC26: 4 | AE26: 3 | AF26: 2 | AG26: =SUM(B26:AF26) -> 26
A27: 07:00 | D27: 1 | E27: 2 | J27: 1 | K27: 1 | Q27: 1 | S27: 1 | Z27: 1 | AF27: 1 | AG27: =SUM(B27:AF27) -> 9
A28: Total de atendidos | B28: =SUM(B29:B52) -> 156 | C28: =SUM(C29:C52) -> 152 | D28: =SUM(D29:D52) -> 145 | E28: =SUM(E29:E52) -> 191 | F28: =SUM(F29:F52) -> 218 | G28: =SUM(G29:G52) -> 150 | H28: =SUM(H29:H52) -> 136 | I28: =SUM(I29:I52) -> 132 | ... AF28: =SUM(AF29:AF52) -> 147 | AG28: =SUM(B28:AF28) -> 4894
A29: 08:00 | B29: 5 | D29: 1 | E29: 5 | F29: 2 | K29: 1 | L29: 3 | M29: 3 | S29: 2 | T29: 3 | Z29: 3 | AA29: 3 | AG29: =SUM(B29:AF29) -> 31
A30: 09:00 | B30: 5 | E30: 6 | F30: 4 | L30: 2 | M30: 8 | S30: 7 | T30: 7 | Z30: 9 | AA30: 4 | AG30: =SUM(B30:AF30) -> 52
A31: 10:00 | B31: 9 | E31: 12 | F31: 9 | L31: 9 | M31: 8 | R31: 1 | S31: 12 | T31: 19 | Z31: 11 | AA31: 11 | AG31: =SUM(B31:AF31) -> 101
A32: 11:00 | B32: 5 | E32: 8 | F32: 12 | L32: 11 | M32: 14 | S32: 11 | T32: 10 | Z32: 10 | AA32: 15 | AG32: =SUM(B32:AF32) -> 96
A33: 12:00 | B33: 14 | E33: 10 | F33: 11 | L33: 6 | M33: 14 | S33: 10 | T33: 12 | Y33: 1 | Z33: 11 | AA33: 13 | AG33: =SUM(B33:AF33) -> 102
A34: 13:00 | B34: 11 | E34: 8 | F34: 10 | H34: 1 | L34: 9 | M34: 9 | S34: 8 | T34: 8 | Z34: 7 | AA34: 15 | AD34: 1 | AG34: =SUM(B34:AF34) -> 87
A35: 14:00 | B35: 12 | E35: 5 | F35: 11 | L35: 5 | M35: 10 | S35: 7 | T35: 9 | U35: 1 | Z35: 12 | AA35: 11 | AG35: =SUM(B35:AF35) -> 83
A36: 15:00 | B36: 8 | E36: 17 | F36: 14 | L36: 15 | M36: 9 | S36: 12 | T36: 14 | Z36: 13 | AA36: 16 | AG36: =SUM(B36:AF36) -> 118
A37: 16:00 | B37: 6 | E37: 7 | F37: 13 | L37: 12 | M37: 12 | S37: 13 | T37: 8 | Z37: 13 | AA37: 16 | AG37: =SUM(B37:AF37) -> 100
A38: 17:00 | B38: 7 | C38: 11 | D38: 3 | E38: 16 | F38: 13 | G38: 9 | H38: 2 | I38: 6 | J38: 7 | K38: 4 | L38: 16 | M38: 15 | N38: 11 | O38: 6 | P38: 8 | Q38: 7 | R38: 4 | S38: 16 | T38: 23 | U38: 9 | V38: 7 | W38: 9 | X38: 12 | Z38: 15 | AA38: 15 | AB38: 4 | AC38: 52 | AD38: 6 | AE38: 38 | AF38: 49 | AG38: =SUM(B38:AF38) -> 400
A39: 18:00 | B39: 12 | C39: 20 | D39: 18 | E39: 6 | F39: 15 | G39: 23 | H39: 14 | I39: 20 | J39: 11 | K39: 10 | L39: 14 | M39: 9 | N39: 19 | O39: 26 | P39: 22 | Q39: 20 | R39: 10 | S39: 13 | T39: 18 | U39: 26 | V39: 17 | W39: 20 | X39: 15 | Y39: 8 | Z39: 10 | AA39: 13 | AB39: 25 | AC39: 11 | AD39: 23 | AE39: 25 | AF39: 16 | AG39: =SUM(B39:AF39) -> 509
A40: 19:00 | B40: 8 | C40: 17 | D40: 16 | E40: 8 | F40: 14 | G40: 21 | H40: 16 | I40: 26 | J40: 21 | K40: 20 | L40: 12 | M40: 19 | N40: 20 | O40: 24 | P40: 25 | Q40: 17 | R40: 17 | S40: 13 | T40: 7 | U40: 34 | V40: 25 | W40: 18 | X40: 17 | Y40: 16 | Z40: 12 | AA40: 8 | AB40: 21 | AC40: 11 | AD40: 28 | AE40: 15 | AF40: 10 | AG40: =SUM(B40:AF40) -> 536
A41: 20:00 | B41: 12 | C41: 20 | D41: 23 | E41: 8 | F41: 20 | G41: 16 | H41: 21 | I41: 22 | J41: 22 | K41: 17 | L41: 10 | M41: 11 | N41: 23 | O41: 18 | P41: 21 | Q41: 23 | R41: 15 | S41: 13 | T41: 12 | U41: 25 | V41: 22 | W41: 24 | X41: 17 | Y41: 17 | Z41: 10 | AA41: 13 | AB41: 22 | AC41: 14 | AD41: 19 | AE41: 16 | AF41: 17 | AG41: =SUM(B41:AF41) -> 543
...

Sheet FEBRERO
A2: FEBRERO | B2: 1 | C2: =+B2+1 -> 2 | D2: =+C2+1 -> 3 | E2: =+D2+1 -> 4 | F2: =+E2+1 -> 5 | G2: =+F2+1 -> 6 | H2: =+G2+1 -> 7 | I2: =+H2+1 -> 8 | J2: =+I2+1 -> 9 | ... AA2: =+Z2+1 -> 26 | AB2: 27 | AC2: =+AB2+1 -> 28 | AD2: 29 | AE2: 30 | AF2: 31 | AG2: TOTAL
A3: Total de Inscritos | B3: =SUM(B4:B27) -> 227 | C3: =SUM(C4:C27) -> 199 | D3: =SUM(D4:D27) -> 175 | E3: =SUM(E4:E27) -> 145 | F3: =SUM(F4:F27) -> 149 | G3: =SUM(G4:G27) -> 142 | H3: =SUM(H4:H27) -> 177 | I3: =SUM(I4:I27) -> 197 | ... AF3: =SUM(AF4:AF27) -> 0 | AG3: =SUM(B3:AF3) -> 5213
A4: 08:00 | B4: 8 | C4: 14 | I4: 8 | J4: 6 | P4: 10 | Q4: 9 | W4: 5 | X4: 4 | AD4: 3 | AG4: =SUM(B4:AF4) -> 67
A5: 09:00 | B5: 18 | C5: 7 | I5: 6 | J5: 9 | P5: 18 | Q5: 11 | W5: 15 | X5: 9 | AD5: 18 | AG5: =SUM(B5:AF5) -> 111
A6: 10:00 | B6: 11 | C6: 12 | I6: 11 | J6: 16 | P6: 12 | Q6: 15 | W6: 10 | X6: 16 | AD6: 9 | AG6: =SUM(B6:AF6) -> 112
A7: 11:00 | B7: 21 | C7: 11 | I7: 15 | J7: 14 | P7: 13 | Q7: 17 | W7: 12 | X7: 14 | AD7: 11 | AG7: =SUM(B7:AF7) -> 128
A8: 12:00 | B8: 14 | C8: 10 | I8: 10 | J8: 13 | P8: 14 | Q8: 12 | W8: 6 | X8: 16 | AD8: 16 | AG8: =SUM(B8:AF8) -> 111
A9: 13:00 | B9: 13 | C9: 13 | I9: 9 | J9: 11 | P9: 7 | Q9: 9 | W9: 9 | X9: 9 | AD9: 10 | AG9: =SUM(B9:AF9) -> 90
A10: 14:00 | B10: 9 | C10: 6 | I10: 13 | J10: 14 | P10: 11 | Q10: 9 | W10: 9 | X10: 14 | AD10: 11 | AG10: =SUM(B10:AF10) -> 96
A11: 15:00 | B11: 10 | C11: 15 | I11: 6 | J11: 10 | P11: 14 | Q11: 11 | W11: 16 | X11: 16 | AD11: 13 | AG11: =SUM(B11:AF11) -> 111
A12: 16:00 | B12: 17 | C12: 7 | I12: 11 | J12: 7 | K12: 1 | P12: 16 | Q12: 17 | U12: 2 | W12: 19 | X12: 16 | Y12: 1 | AD12: 25 | AG12: =SUM(B12:AF12) -> 139
A13: 17:00 | B13: 14 | C13: 11 | D13: 56 | E13: 55 | F13: 45 | G13: 45 | H13: 57 | I13: 12 | J13: 15 | K13: 47 | L13: 52 | M13: 27 | N13: 47 | O13: 38 | P13: 13 | Q13: 14 | R13: 56 | S13: 51 | T13: 54 | U13: 60 | V13: 61 | W13: 15 | X13: 25 | Y13: 59 | Z13: 68 | AA13: 46 | AB13: 58 | AC13: 46 | AD13: 23 | AG13: =SUM(B13:AF13) -> 1170
A14: 18:00 | B14: 11 | C14: 15 | D14: 19 | E14: 20 | F14: 13 | G14: 20 | H14: 19 | I14: 16 | J14: 18 | K14: 21 | L14: 12 | M14: 22 | N14: 18 | O14: 17 | P14: 19 | Q14: 21 | R14: 19 | S14: 28 | T14: 20 | U14: 11 | V14: 14 | W14: 16 | X14: 12 | Y14: 22 | Z14: 15 | AA14: 22 | AB14: 17 | AC14: 11 | AD14: 13 | AG14: =SUM(B14:AF14) -> 501
A15: 19:00 | B15: 13 | C15: 10 | D15: 18 | E15: 17 | F15: 21 | G15: 21 | H15: 16 | I15: 14 | J15: 8 | K15: 16 | L15: 17 | M15: 24 | N15: 15 | O15: 12 | P15: 18 | Q15: 21 | R15: 23 | S15: 21 | T15: 19 | U15: 16 | V15: 18 | W15: 16 | X15: 11 | Y15: 12 | Z15: 15 | AA15: 13 | AB15: 25 | AC15: 14 | AD15: 15 | AG15: =SUM(B15:AF15) -> 479
A16: 20:00 | B16: 12 | C16: 9 | D16: 14 | E16: 11 | F16: 17 | G16: 17 | H16: 14 | I16: 9 | J16: 15 | K16: 19 | L16: 20 | M16: 13 | N16: 14 | O16: 13 | P16: 14 | Q16: 14 | R16: 26 | S16: 27 | T16: 21 | U16: 15 | V16: 16 | W16: 20 | X16: 16 | Y16: 20 | Z16: 9 | AA16: 15 | AB16: 17 | AC16: 21 | AD16: 13 | AG16: =SUM(B16:AF16) -> 461
A17: 21:00 | B17: 18 | C17: 10 | D17: 20 | E17: 10 | F17: 12 | G17: 16 | H17: 24 | I17: 18 | J17: 11 | K17: 23 | L17: 18 | M17: 17 | N17: 18 | O17: 18 | P17: 9 | Q17: 16 | R17: 18 | S17: 19 | T17: 23 | U17: 10 | V17: 12 | W17: 8 | X17: 9 | Y17: 16 | Z17: 16 | AA17: 25 | AB17: 20 | AC17: 13 | AD17: 17 | AG17: =SUM(B17:AF17) -> 464
A18: 22:00 | B18: 9 | C18: 21 | D18: 14 | E18: 12 | F18: 11 | G18: 10 | H18: 18 | I18: 9 | J18: 21 | K18: 19 | L18: 14 | M18: 15 | N18: 22 | O18: 13 | P18: 13 | Q18: 9 | R18: 23 | S18: 17 | T18: 18 | U18: 14 | V18: 11 | W18: 21 | X18: 10 | Y18: 9 | Z18: 12 | AA18: 11 | AB18: 13 | AC18: 8 | AD18: 15 | AG18: =SUM(B18:AF18) -> 412
A19: 23:00 | B19: 11 | C19: 11 | D19: 10 | E19: 9 | F19: 9 | G19: 5 | H19: 10 | I19: 13 | J19: 9 | K19: 19 | L19: 8 | M19: 14 | N19: 11 | O19: 4 | P19: 7 | Q19: 14 | R19: 6 | S19: 9 | T19: 10 | U19: 15 | V19: 11 | W19: 11 | X19: 11 | Y19: 13 | Z19: 10 | AA19: 15 | AB19: 13 | AC19: 9 | AD19: 10 | AG19: =SUM(B19:AF19) -> 307
A20: 00:00 | B20: 6 | C20: 7 | D20: 10 | E20: 4 | F20: 9 | G20: 1 | H20: 3 | I20: 4 | J20: 2 | K20: 5 | L20: 8 | M20: 1 | N20: 2 | O20: 4 | P20: 6 | Q20: 7 | R20: 1 | S20: 8 | T20: 7 | U20: 2 | V20: 9 | W20: 4 | X20: 2 | Y20: 2 | Z20: 3 | AA20: 6 | AB20: 8 | AC20: 5 | AD20: 3 | AG20: =SUM(B20:AF20) -> 139
A21: 01:00 | B21: 4 | C21: 4 | D21: 3 | E21: 5 | F21: 6 | G21: 1 | H21: 6 | I21: 5 | J21: 2 | K21: 4 | L21: 5 | M21: 4 | N21: 2 | O21: 3 | P21: 6 | Q21: 2 | R21: 2 | T21: 5 | U21: 9 | V21: 6 | W21: 4 | X21: 3 | Y21: 3 | Z21: 5 | AA21: 2 | AB21: 4 | AC21: 4 | AD21: 4 | AG21: =SUM(B21:AF21) -> 113
A22: 02:00 | B22: 6 | C22: 2 | D22: 4 | E22: 2 | F22: 1 | G22: 1 | H22: 2 | I22: 2 | J22: 3 | K22: 1 | L22: 2 | N22: 1 | O22: 1 | P22: 1 | Q22: 2 | T22: 3 | U22: 2 | V22: 1 | X22: 1 | Y22: 3 | AA22: 7 | AB22: 2 | AC22: 4 | AG22: =SUM(B22:AF22) -> 54
A23: 03:00 | B23: 1 | C23: 2 | D23: 2 | F23: 1 | H23: 1 | I23: 1 | J23: 1 | K23: 2 | L23: 2 | M23: 2 | O23: 1 | Q23: 4 | R23: 2 | S23: 1 | U23: 1 | V23: 2 | W23: 3 | X23: 1 | Y23: 2 | Z23: 2 | AA23: 1 | AB23: 2 | AC23: 1 | AD23: 3 | AG23: =SUM(B23:AF23) -> 41
A24: 04:00 | B24: 1 | C24: 1 | D24: 1 | F24: 1 | H24: 3 | I24: 1 | J24: 5 | K24: 1 | L24: 1 | M24: 1 | N24: 2 | O24: 2 | P24: 1 | Q24: 1 | R24: 1 | S24: 2 | U24: 2 | V24: 2 | W24: 2 | Y24: 2 | Z24: 1 | AB24: 1 | AC24: 1 | AG24: =SUM(B24:AF24) -> 36
A25: 05:00 | D25: 1 | F25: 1 | G25: 3 | H25: 3 | I25: 1 | L25: 1 | M25: 1 | O25: 1 | P25: 5 | Q25: 3 | R25: 4 | S25: 1 | U25: 1 | V25: 1 | Y25: 1 | Z25: 1 | AA25: 2 | AB25: 1 | AC25: 1 | AD25: 1 | AG25: =SUM(B25:AF25) -> 34
A26: 06:00 | C26: 1 | D26: 2 | F26: 2 | G26: 1 | H26: 1 | L26: 1 | N26: 2 | O26: 1 | P26: 2 | Q26: 1 | R26: 1 | S26: 1 | V26: 1 | W26: 1 | Z26: 2 | AA26: 1 | AB26: 2 | AD26: 2 | AG26: =SUM(B26:AF26) -> 25
A27: 07:00 | D27: 1 | G27: 1 | I27: 3 | P27: 2 | V27: 2 | W27: 2 | AD27: 1 | AG27: =SUM(B27:AF27) -> 12
A28: Total de atendidos | B28: =SUM(B29:B52) -> 215 | C28: =SUM(C29:C52) -> 199 | D28: =SUM(D29:D52) -> 169 | E28: =SUM(E29:E52) -> 136 | F28: =SUM(F29:F52) -> 143 | G28: =SUM(G29:G52) -> 116 | H28: =SUM(H29:H52) -> 157 | I28: =SUM(I29:I52) -> 172 | ... AF28: =SUM(AF29:AF52) -> 0 | AG28: =SUM(B28:AF28) -> 4759
A29: 08:00 | B29: 3 | C29: 6 | I29: 8 | J29: 4 | P29: 4 | Q29: 5 | V29: 2 | W29: 1 | X29: 3 | AD29: 3 | AG29: =SUM(B29:AF29) -> 39
A30: 09:00 | B30: 3 | C30: 12 | I30: 5 | J30: 5 | P30: 6 | Q30: 9 | V30: 2 | W30: 5 | X30: 7 | AD30: 7 | AG30: =SUM(B30:AF30) -> 61
A31: 10:00 | B31: 10 | C31: 8 | I31: 6 | J31: 8 | P31: 12 | Q31: 11 | W31: 15 | X31: 12 | AD31: 16 | AG31: =SUM(B31:AF31) -> 98
A32: 11:00 | B32: 14 | C32: 12 | I32: 14 | J32: 14 | P32: 12 | Q32: 15 | W32: 14 | X32: 16 | AD32: 11 | AG32: =SUM(B32:AF32) -> 122
A33: 12:00 | B33: 10 | C33: 10 | I33: 9 | J33: 11 | P33: 8 | Q33: 13 | W33: 9 | X33: 13 | AD33: 11 | AG33: =SUM(B33:AF33) -> 94
A34: 13:00 | B34: 10 | C34: 7 | I34: 5 | J34: 6 | P34: 10 | Q34: 14 | W34: 9 | X34: 13 | AD34: 13 | AG34: =SUM(B34:AF34) -> 87
A35: 14:00 | B35: 20 | C35: 16 | I35: 6 | J35: 11 | P35: 8 | Q35: 10 | W35: 10 | X35: 14 | AD35: 8 | AG35: =SUM(B35:AF35) -> 103
A36: 15:00 | B36: 16 | C36: 8 | I36: 9 | J36: 12 | P36: 10 | Q36: 12 | W36: 9 | X36: 8 | AD36: 11 | AG36: =SUM(B36:AF36) -> 95
A37: 16:00 | B37: 7 | C37: 12 | I37: 9 | J37: 18 | P37: 11 | Q37: 13 | W37: 17 | X37: 14 | AD37: 19 | AG37: =SUM(B37:AF37) -> 120
A38: 17:00 | B38: 14 | C38: 10 | D38: 6 | E38: 1 | F38: 3 | G38: 5 | H38: 9 | I38: 10 | J38: 15 | K38: 6 | L38: 4 | M38: 8 | N38: 5 | O38: 7 | P38: 15 | Q38: 19 | R38: 8 | S38: 12 | T38: 6 | U38: 6 | V38: 5 | W38: 19 | X38: 21 | Y38: 6 | Z38: 6 | AA38: 3 | AB38: 8 | AC38: 3 | AD38: 18 | AG38: =SUM(B38:AF38) -> 258
A39: 18:00 | B39: 11 | C39: 14 | D39: 19 | E39: 15 | F39: 19 | G39: 16 | H39: 18 | I39: 12 | J39: 13 | K39: 22 | L39: 10 | M39: 20 | N39: 19 | O39: 17 | P39: 6 | Q39: 10 | R39: 27 | S39: 23 | T39: 20 | U39: 19 | V39: 15 | W39: 11 | X39: 19 | Y39: 22 | Z39: 22 | AA39: 28 | AB39: 18 | AC39: 19 | AD39: 19 | AG39: =SUM(B39:AF39) -> 503
A40: 19:00 | B40: 14 | C40: 12 | D40: 24 | E40: 22 | F40: 21 | G40: 21 | H40: 20 | I40: 7 | J40: 14 | K40: 26 | L40: 22 | M40: 26 | N40: 25 | O40: 22 | P40: 10 | Q40: 20 | R40: 22 | S40: 22 | T40: 23 | U40: 19 | V40: 20 | W40: 15 | X40: 16 | Y40: 29 | Z40: 11 | AA40: 27 | AB40: 24 | AC40: 25 | AD40: 14 | AG40: =SUM(B40:AF40) -> 573
A41: 20:00 | B41: 19 | C41: 9 | D41: 29 | E41: 23 | F41: 16 | G41: 16 | H41: 19 | I41: 7 | J41: 15 | K41: 25 | L41: 23 | M41: 22 | N41: 16 | O41: 16 | P41: 11 | Q41: 19 | R41: 21 | S41: 20 | T41: 23 | U41: 19 | V41: 14 | W41: 14 | X41: 13 | Y41: 21 | Z41: 25 | AA41: 25 | AB41: 19 | AC41: 13 | AD41: 17 | AG41: =SUM(B41:AF41) -> 529
...

Sheet MARZO
A2: MARZO | B2: 1 | C2: =+B2+1 -> 2 | D2: =+C2+1 -> 3 | E2: =+D2+1 -> 4 | F2: =+E2+1 -> 5 | G2: =+F2+1 -> 6 | H2: =+G2+1 -> 7 | I2: =+H2+1 -> 8 | J2: =+I2+1 -> 9 | ... AA2: =+Z2+1 -> 26 | AB2: 27 | AC2: =+AB2+1 -> 28 | AD2: 29 | AE2: 30 | AF2: 31 | AG2: TOTAL
A3: Total de Inscritos | B3: =SUM(B4:B27) -> 188 | C3: =SUM(C4:C27) -> 165 | D3: =SUM(D4:D27) -> 193 | E3: =SUM(E4:E27) -> 156 | F3: =SUM(F4:F27) -> 165 | G3: =SUM(G4:G27) -> 144 | H3: =SUM(H4:H27) -> 216 | I3: =SUM(I4:I27) -> 206 | ... AF3: =SUM(AF4:AF27) -> 63 | AG3: =SUM(B3:AF3) -> 4021
A4: 08:00 | B4: 3 | H4: 9 | I4: 4 | O4: 5 | P4: 6 | Q4: 1 | R4: 1 | V4: 5 | W4: 3 | Y4: 2 | Z4: 1 | AD4: 1 | AF4: 5 | AG4: =SUM(B4:AF4) -> 46
A5: 09:00 | B5: 8 | D5: 2 | H5: 9 | I5: 8 | N5: 1 | O5: 19 | P5: 17 | V5: 5 | W5: 3 | AB5: 1 | AC5: 2 | AD5: 2 | AF5: 3 | AG5: =SUM(B5:AF5) -> 80
A6: 10:00 | B6: 14 | H6: 12 | I6: 13 | O6: 9 | P6: 17 | U6: 1 | V6: 3 | W6: 5 | Z6: 1 | AC6: 5 | AD6: 9 | AE6: 1 | AF6: 1 | AG6: =SUM(B6:AF6) -> 91
A7: 11:00 | B7: 22 | H7: 17 | I7: 15 | O7: 13 | P7: 19 | V7: 2 | W7: 7 | Y7: 1 | Z7: 1 | AA7: 1 | AC7: 4 | AD7: 8 | AE7: 1 | AF7: 3 | AG7: =SUM(B7:AF7) -> 114
A8: 12:00 | B8: 16 | H8: 19 | I8: 9 | O8: 14 | P8: 16 | Q8: 2 | V8: 9 | W8: 13 | X8: 1 | AA8: 1 | AC8: 7 | AD8: 11 | AF8: 3 | AG8: =SUM(B8:AF8) -> 121
A9: 13:00 | B9: 7 | H9: 13 | I9: 13 | O9: 16 | P9: 12 | V9: 6 | W9: 8 | Z9: 1 | AC9: 4 | AD9: 11 | AF9: 2 | AG9: =SUM(B9:AF9) -> 93
A10: 14:00 | B10: 7 | H10: 10 | I10: 9 | N10: 1 | O10: 18 | P10: 9 | V10: 3 | W10: 4 | AA10: 3 | AC10: 8 | AD10: 8 | AF10: 2 | AG10: =SUM(B10:AF10) -> 82
A11: 15:00 | B11: 9 | H11: 10 | I11: 6 | O11: 24 | P11: 12 | V11: 5 | W11: 11 | X11: 1 | Z11: 2 | AC11: 9 | AD11: 8 | AF11: 6 | AG11: =SUM(B11:AF11) -> 103
A12: 16:00 | B12: 9 | H12: 11 | I12: 18 | M12: 1 | O12: 11 | P12: 16 | V12: 3 | W12: 1 | X12: 1 | AC12: 3 | AD12: 8 | AE12: 1 | AF12: 4 | AG12: =SUM(B12:AF12) -> 87
A13: 17:00 | B13: 10 | C13: 66 | D13: 69 | E13: 58 | F13: 55 | G13: 58 | H13: 28 | I13: 14 | J13: 60 | K13: 68 | L13: 74 | M13: 55 | N13: 70 | O13: 19 | P13: 19 | Q13: 52 | R13: 36 | S13: 20 | T13: 21 | U13: 24 | V13: 7 | W13: 6 | X13: 11 | Y13: 16 | Z13: 14 | AA13: 17 | AB13: 29 | AC13: 10 | AD13: 6 | AE13: 16 | AF13: 5 | AG13: =SUM(B13:AF13) -> 1013
A14: 18:00 | B14: 15 | C14: 18 | D14: 20 | E14: 17 | F14: 19 | G14: 22 | H14: 20 | I14: 11 | J14: 25 | K14: 23 | L14: 15 | M14: 18 | N14: 20 | O14: 18 | P14: 15 | Q14: 21 | R14: 20 | S14: 10 | T14: 10 | U14: 8 | V14: 4 | W14: 4 | X14: 12 | Y14: 4 | Z14: 5 | AA14: 7 | AB14: 5 | AC14: 5 | AD14: 5 | AE14: 7 | AF14: 8 | AG14: =SUM(B14:AF14) -> 411
A15: 19:00 | B15: 9 | C15: 17 | D15: 21 | E15: 15 | F15: 16 | G15: 16 | H15: 11 | I15: 12 | J15: 23 | K15: 22 | L15: 17 | M15: 38 | N15: 17 | O15: 6 | P15: 21 | Q15: 14 | R15: 20 | S15: 14 | T15: 6 | U15: 7 | V15: 3 | W15: 7 | X15: 3 | Y15: 7 | Z15: 6 | AA15: 9 | AB15: 5 | AC15: 7 | AD15: 10 | AE15: 6 | AF15: 3 | AG15: =SUM(B15:AF15) -> 388
A16: 20:00 | B16: 13 | C16: 18 | D16: 16 | E16: 23 | F16: 20 | G16: 7 | H16: 12 | I16: 18 | J16: 22 | K16: 20 | L16: 23 | M16: 16 | N16: 14 | O16: 15 | P16: 17 | Q16: 17 | R16: 14 | S16: 5 | T16: 5 | U16: 6 | V16: 4 | W16: 3 | X16: 3 | Y16: 3 | Z16: 6 | AA16: 10 | AB16: 3 | AC16: 5 | AD16: 6 | AE16: 5 | AF16: 7 | AG16: =SUM(B16:AF16) -> 356
A17: 21:00 | B17: 11 | C17: 9 | D17: 23 | E17: 21 | F17: 15 | G17: 11 | H17: 6 | I17: 10 | J17: 15 | K17: 19 | L17: 26 | M17: 13 | N17: 10 | O17: 5 | P17: 16 | Q17: 17 | R17: 12 | S17: 3 | T17: 5 | U17: 9 | V17: 3 | W17: 1 | X17: 3 | Y17: 1 | Z17: 5 | AA17: 2 | AB17: 3 | AC17: 5 | AD17: 4 | AE17: 3 | AF17: 4 | AG17: =SUM(B17:AF17) -> 290
A18: 22:00 | B18: 12 | C18: 9 | D18: 15 | E18: 8 | F18: 15 | G18: 11 | H18: 10 | I18: 15 | J18: 10 | K18: 14 | L18: 13 | M18: 8 | N18: 10 | O18: 16 | P18: 10 | Q18: 11 | R18: 14 | S18: 3 | T18: 8 | U18: 3 | V18: 3 | W18: 3 | X18: 2 | Y18: 2 | Z18: 3 | AA18: 1 | AB18: 4 | AC18: 5 | AD18: 2 | AE18: 5 | AF18: 3 | AG18: =SUM(B18:AF18) -> 248
A19: 23:00 | B19: 10 | C19: 14 | D19: 8 | E19: 7 | F19: 7 | G19: 6 | H19: 4 | I19: 8 | J19: 13 | K19: 7 | L19: 8 | M19: 12 | N19: 7 | O19: 16 | P19: 6 | Q19: 3 | R19: 2 | S19: 4 | T19: 7 | U19: 5 | V19: 1 | Y19: 1 | Z19: 1 | AA19: 3 | AB19: 1 | AC19: 1 | AD19: 1 | AE19: 3 | AF19: 2 | AG19: =SUM(B19:AF19) -> 168
A20: 00:00 | B20: 3 | C20: 2 | D20: 6 | E20: 1 | F20: 7 | G20: 2 | H20: 3 | I20: 8 | J20: 5 | K20: 5 | L20: 2 | M20: 2 | N20: 3 | O20: 5 | P20: 6 | Q20: 4 | R20: 6 | T20: 1 | U20: 3 | V20: 5 | W20: 1 | X20: 1 | Z20: 1 | AA20: 2 | AB20: 2 | AC20: 2 | AE20: 4 | AG20: =SUM(B20:AF20) -> 92
A21: 01:00 | B21: 3 | C21: 4 | D21: 4 | E21: 2 | F21: 2 | G21: 6 | H21: 5 | I21: 6 | J21: 3 | K21: 1 | L21: 7 | M21: 4 | N21: 2 | P21: 3 | Q21: 2 | R21: 2 | U21: 4 | V21: 2 | Y21: 1 | Z21: 3 | AB21: 2 | AC21: 2 | AD21: 3 | AG21: =SUM(B21:AF21) -> 73
A22: 02:00 | B22: 6 | C22: 4 | D22: 5 | E22: 4 | F22: 3 | G22: 1 | H22: 1 | I22: 3 | K22: 2 | L22: 5 | M22: 1 | N22: 2 | O22: 3 | P22: 3 | Q22: 2 | R22: 3 | S22: 1 | T22: 2 | U22: 3 | V22: 1 | W22: 1 | X22: 1 | Z22: 1 | AA22: 2 | AB22: 1 | AC22: 1 | AD22: 1 | AE22: 2 | AG22: =SUM(B22:AF22) -> 65
A23: 03:00 | C23: 1 | D23: 1 | F23: 1 | G23: 1 | I23: 2 | J23: 2 | K23: 3 | L23: 4 | M23: 1 | N23: 2 | Q23: 1 | R23: 1 | S23: 1 | T23: 1 | AA23: 1 | AC23: 1 | AE23: 1 | AF23: 2 | AG23: =SUM(B23:AF23) -> 27
A24: 04:00 | B24: 1 | D24: 1 | F24: 2 | G24: 2 | H24: 1 | I24: 1 | K24: 1 | O24: 1 | AA24: 1 | AB24: 2 | AG24: =SUM(B24:AF24) -> 13
A25: 05:00 | C25: 1 | D25: 1 | F25: 2 | H25: 1 | J25: 1 | K25: 3 | M25: 1 | N25: 3 | P25: 1 | Q25: 4 | T25: 1 | V25: 1 | AG25: =SUM(B25:AF25) -> 20
A26: 06:00 | C26: 2 | D26: 1 | G26: 1 | H26: 2 | I26: 3 | J26: 1 | K26: 1 | M26: 1 | O26: 2 | Q26: 2 | R26: 3 | S26: 1 | T26: 1 | AA26: 1 | AG26: =SUM(B26:AF26) -> 22
A27: 07:00 | F27: 1 | H27: 2 | K27: 1 | N27: 2 | O27: 1 | Q27: 1 | R27: 1 | T27: 1 | U27: 1 | W27: 3 | X27: 2 | AA27: 1 | AC27: 1 | AG27: =SUM(B27:AF27) -> 18
A28: Total de atendidos | B28: =SUM(B29:B52) -> 188 | C28: =SUM(C29:C52) -> 152 | D28: =SUM(D29:D52) -> 172 | E28: =SUM(E29:E52) -> 147 | F28: =SUM(F29:F52) -> 143 | G28: =SUM(G29:G52) -> 129 | H28: =SUM(H29:H52) -> 202 | I28: =SUM(I29:I52) -> 200 | ... AF28: =SUM(AF29:AF52) -> 61 | AG28: =SUM(B28:AF28) -> 3702
A29: 08:00 | B29: 3 | H29: 6 | I29: 4 | O29: 3 | P29: 2 | R29: 1 | V29: 2 | W29: 3 | AD29: 1 | AG29: =SUM(B29:AF29) -> 25
A30: 09:00 | B30: 4 | H30: 7 | I30: 4 | N30: 1 | O30: 6 | P30: 8 | Q30: 1 | V30: 2 | W30: 2 | AB30: 1 | AC30: 2 | AD30: 2 | AF30: 3 | AG30: =SUM(B30:AF30) -> 43
A31: 10:00 | B31: 12 | H31: 11 | I31: 10 | O31: 15 | P31: 12 | V31: 4 | W31: 4 | Z31: 1 | AC31: 5 | AD31: 4 | AF31: 4 | AG31: =SUM(B31:AF31) -> 82
A32: 11:00 | B32: 10 | H32: 10 | I32: 14 | O32: 13 | P32: 16 | V32: 3 | W32: 5 | Y32: 1 | Z32: 1 | AC32: 2 | AD32: 9 | AF32: 3 | AG32: =SUM(B32:AF32) -> 87
A33: 12:00 | B33: 18 | H33: 10 | I33: 12 | O33: 11 | P33: 13 | Q33: 2 | V33: 3 | W33: 11 | X33: 1 | AA33: 1 | AC33: 5 | AD33: 6 | AE33: 1 | AF33: 3 | AG33: =SUM(B33:AF33) -> 97
A34: 13:00 | B34: 19 | H34: 11 | I34: 9 | O34: 13 | P34: 13 | V34: 8 | W34: 8 | Z34: 1 | AC34: 5 | AD34: 11 | AF34: 3 | AG34: =SUM(B34:AF34) -> 101
A35: 14:00 | B35: 10 | H35: 10 | I35: 13 | O35: 13 | P35: 16 | V35: 6 | W35: 5 | AC35: 5 | AD35: 9 | AG35: =SUM(B35:AF35) -> 87
A36: 15:00 | B36: 4 | H36: 9 | I36: 9 | N36: 1 | O36: 12 | P36: 9 | V36: 2 | W36: 5 | X36: 1 | Z36: 2 | AA36: 3 | AC36: 7 | AD36: 6 | AF36: 9 | AG36: =SUM(B36:AF36) -> 79
A37: 16:00 | B37: 12 | H37: 15 | I37: 15 | O37: 16 | P37: 15 | V37: 6 | W37: 9 | AC37: 5 | AD37: 6 | AE37: 1 | AF37: 1 | AG37: =SUM(B37:AF37) -> 101
A38: 17:00 | B38: 11 | C38: 2 | D38: 6 | E38: 5 | F38: 8 | G38: 5 | H38: 15 | I38: 15 | J38: 8 | K38: 7 | L38: 2 | M38: 5 | N38: 6 | O38: 21 | P38: 19 | Q38: 4 | T38: 7 | U38: 7 | V38: 5 | W38: 3 | X38: 3 | Y38: =5+1 -> 6 | Z38: =4+1 -> 5 | AA38: 4 | AB38: 7 | AC38: 7 | AD38: 5 | AE38: 6 | AF38: 5 | AG38: =SUM(B38:AF38) -> 209
A39: 18:00 | B39: 12 | C39: 23 | D39: 19 | E39: 20 | F39: 20 | G39: 24 | H39: 15 | I39: 9 | J39: 21 | K39: 23 | L39: 23 | M39: 22 | N39: 27 | O39: 17 | P39: 9 | Q39: 18 | R39: 11 | S39: 5 | T39: 14 | U39: 9 | V39: 6 | W39: 7 | X39: 10 | Y39: 12 | Z39: 10 | AA39: 8 | AB39: 11 | AC39: 6 | AD39: 11 | AE39: 13 | AF39: 6 | AG39: =SUM(B39:AF39) -> 441
A40: 19:00 | B40: 10 | C40: 26 | D40: 24 | E40: 37 | F40: 22 | G40: 27 | H40: 8 | I40: 8 | J40: 18 | K40: 26 | L40: 22 | M40: 17 | N40: 24 | O40: 14 | P40: 18 | Q40: 20 | R40: 18 | S40: 10 | T40: 15 | U40: 5 | V40: 4 | W40: 4 | X40: 8 | Y40: 5 | Z40: 7 | AA40: 10 | AB40: 9 | AC40: 8 | AD40: 7 | AE40: 7 | AF40: 5 | AG40: =SUM(B40:AF40) -> 443
A41: 20:00 | B41: 12 | C41: 21 | D41: 32 | E41: 22 | F41: 27 | G41: 13 | H41: 14 | I41: 14 | J41: 24 | K41: 21 | L41: 24 | M41: 31 | N41: 18 | O41: 16 | P41: 20 | Q41: 18 | R41: 16 | S41: 13 | T41: 5 | U41: 8 | V41: 3 | W41: 3 | X41: 9 | Y41: 6 | Z41: 6 | AA41: 7 | AB41: 8 | AC41: 5 | AD41: 8 | AE41: 6 | AF41: 7 | AG41: =SUM(B41:AF41) -> 437
...

Sheet ABRIL
A2: ABRIL | B2: 1 | C2: =+B2+1 -> 2 | D2: =+C2+1 -> 3 | E2: =+D2+1 -> 4 | F2: =+E2+1 -> 5 | G2: =+F2+1 -> 6 | H2: =+G2+1 -> 7 | I2: =+H2+1 -> 8 | J2: =+I2+1 -> 9 | ... AA2: =+Z2+1 -> 26 | AB2: 27 | AC2: =+AB2+1 -> 28 | AD2: 29 | AE2: 30 | AF2: 31 | AG2: TOTAL
A3: Total de Inscritos | B3: =SUM(B4:B27) -> 79 | C3: =SUM(C4:C27) -> 75 | D3: =SUM(D4:D27) -> 78 | E3: =SUM(E4:E27) -> 65 | F3: =SUM(F4:F27) -> 75 | G3: =SUM(G4:G27) -> 94 | H3: =SUM(H4:H27) -> 73 | I3: =SUM(I4:I27) -> 63 | ... AF3: =SUM(AF4:AF27) -> 0 | AG3: =SUM(B3:AF3) -> 1992
A4: 08:00 | B4: 4 | C4: 5 | D4: 2 | E4: 1 | F4: 4 | G4: 8 | H4: 7 | K4: 2 | L4: 2 | M4: 3 | N4: 3 | O4: 1 | P4: 3 | Q4: 4 | R4: 3 | S4: 2 | U4: 2 | V4: 3 | W4: 2 | X4: 2 | Y4: 3 | Z4: 2 | AA4: 3 | AB4: 5 | AE4: 1 | AG4: =SUM(B4:AF4) -> 77
A5: 09:00 | B5: 8 | C5: 2 | D5: 3 | E5: 2 | F5: 3 | G5: 5 | H5: 4 | I5: 5 | J5: 4 | K5: 1 | L5: 2 | M5: 4 | N5: 4 | O5: 3 | P5: 1 | Q5: 3 | R5: 4 | S5: 2 | T5: 3 | U5: 5 | V5: 4 | W5: 3 | X5: 5 | Y5: 6 | Z5: 2 | AA5: 6 | AB5: 12 | AE5: 2 | AG5: =SUM(B5:AF5) -> 108
A6: 10:00 | B6: 4 | C6: 6 | D6: 6 | E6: 3 | F6: 3 | G6: 7 | H6: 3 | I6: 4 | J6: 2 | K6: 3 | L6: 5 | M6: 3 | N6: 4 | O6: 6 | P6: 3 | Q6: 2 | R6: 5 | S6: 1 | T6: 2 | U6: 5 | V6: 2 | W6: 3 | X6: 2 | Y6: 2 | Z6: 6 | AA6: 6 | AB6: 3 | AE6: 9 | AG6: =SUM(B6:AF6) -> 110
A7: 11:00 | B7: 6 | C7: 7 | D7: 3 | E7: 4 | F7: 4 | G7: 8 | H7: 3 | I7: 4 | J7: 2 | K7: 6 | L7: 2 | M7: 1 | N7: 11 | O7: 4 | P7: 5 | Q7: 2 | R7: 1 | S7: 4 | T7: 6 | U7: 3 | V7: 3 | W7: 3 | X7: 7 | Y7: 2 | Z7: 2 | AA7: 6 | AB7: 4 | AE7: 4 | AG7: =SUM(B7:AF7) -> 117
A8: 12:00 | B8: 2 | C8: 6 | D8: 4 | E8: 7 | F8: 9 | G8: 5 | H8: 2 | I8: 5 | J8: 5 | K8: 3 | L8: 5 | M8: 2 | N8: 5 | O8: 5 | P8: 3 | Q8: 1 | R8: 4 | S8: 15 | T8: 8 | U8: 3 | V8: 3 | W8: 2 | X8: 6 | Y8: 5 | Z8: 5 | AA8: 7 | AB8: 8 | AE8: 2 | AG8: =SUM(B8:AF8) -> 137
A9: 13:00 | B9: 4 | C9: 4 | D9: 2 | E9: 4 | F9: 7 | G9: 4 | H9: 4 | I9: 5 | J9: 3 | K9: 4 | L9: 8 | M9: 3 | N9: 8 | O9: 3 | P9: 3 | Q9: 3 | R9: 4 | S9: 5 | T9: 1 | U9: 1 | V9: 3 | W9: 3 | X9: 3 | Y9: 1 | Z9: 2 | AA9: 8 | AB9: 1 | AE9: 5 | AG9: =SUM(B9:AF9) -> 106
A10: 14:00 | B10: 5 | C10: 3 | D10: 7 | E10: 5 | F10: 4 | G10: 10 | H10: 8 | I10: 3 | J10: 3 | K10: 4 | L10: 7 | M10: 5 | N10: 4 | O10: 2 | P10: 1 | R10: 4 | S10: 6 | T10: 2 | U10: 4 | V10: 3 | W10: 4 | X10: 2 | Y10: 3 | Z10: 3 | AA10: 4 | AB10: 7 | AD10: 5 | AE10: 6 | AG10: =SUM(B10:AF10) -> 124
A11: 15:00 | B11: 6 | C11: 4 | D11: 5 | E11: 7 | F11: 5 | G11: 11 | H11: 7 | J11: 1 | K11: 2 | L11: 4 | M11: 3 | O11: 3 | P11: 3 | Q11: 3 | R11: 6 | S11: 6 | T11: 6 | U11: 3 | V11: 2 | W11: 3 | X11: 4 | Y11: 3 | Z11: 7 | AA11: 5 | AB11: 3 | AD11: 5 | AE11: 6 | AG11: =SUM(B11:AF11) -> 123
A12: 16:00 | B12: 6 | C12: 11 | D12: 3 | E12: 5 | F12: 5 | G12: 4 | H12: 5 | I12: 1 | J12: 1 | K12: 3 | L12: 4 | M12: 3 | N12: 8 | O12: 4 | P12: 5 | Q12: 8 | R12: 6 | S12: 6 | T12: 4 | U12: 5 | V12: 4 | W12: 6 | X12: 6 | Y12: 4 | Z12: 2 | AA12: 5 | AB12: 4 | AD12: 9 | AE12: 8 | AG12: =SUM(B12:AF12) -> 145
A13: 17:00 | B13: 8 | C13: 7 | D13: 6 | E13: 4 | F13: 7 | G13: 5 | H13: 8 | I13: 10 | J13: 9 | K13: 2 | L13: 6 | M13: 5 | N13: 8 | O13: 5 | P13: 3 | Q13: 3 | R13: 7 | S13: 7 | T13: 5 | U13: 8 | V13: 6 | W13: 4 | X13: 8 | Y13: 12 | Z13: 8 | AA13: 6 | AD13: 8 | AE13: 12 | AG13: =SUM(B13:AF13) -> 187
A14: 18:00 | B14: 4 | C14: 4 | D14: 8 | E14: 8 | F14: 2 | G14: 6 | H14: 4 | I14: 4 | J14: 4 | K14: 2 | L14: 6 | M14: 3 | N14: 7 | O14: 5 | P14: 5 | Q14: 4 | R14: 3 | S14: 5 | T14: 5 | U14: 9 | V14: 4 | W14: 7 | X14: 8 | Y14: 3 | Z14: 5 | AA14: 7 | AD14: 3 | AE14: 6 | AG14: =SUM(B14:AF14) -> 141
A15: 19:00 | C15: 3 | D15: 2 | E15: 1 | G15: 4 | H15: 3 | I15: 6 | J15: 4 | K15: 1 | L15: 1 | M15: 3 | N15: 6 | O15: 2 | P15: 5 | Q15: 2 | R15: 2 | S15: 1 | T15: 3 | U15: 6 | V15: 6 | W15: 3 | X15: 5 | Y15: 4 | Z15: 7 | AA15: 4 | AD15: 3 | AE15: 7 | AG15: =SUM(B15:AF15) -> 94
A16: 20:00 | B16: 3 | C16: 5 | D16: 3 | E16: 1 | F16: 4 | G16: 8 | H16: 10 | I16: 2 | J16: 4 | K16: 2 | L16: 2 | M16: 3 | N16: 3 | O16: 4 | P16: 3 | Q16: 1 | R16: 6 | S16: 1 | T16: 6 | U16: 7 | V16: 4 | W16: 3 | X16: 6 | Y16: 3 | Z16: 1 | AA16: 2 | AD16: 4 | AE16: 3 | AG16: =SUM(B16:AF16) -> 104
A17: 21:00 | B17: 7 | C17: 2 | D17: 4 | E17: 3 | F17: 4 | G17: 3 | H17: 4 | I17: 4 | J17: 2 | K17: 4 | M17: 1 | N17: 5 | O17: 6 | P17: 1 | Q17: 8 | R17: 2 | S17: 5 | T17: 6 | U17: 2 | V17: 1 | W17: 5 | X17: 2 | Y17: 6 | Z17: 2 | AA17: 2 | AD17: 3 | AE17: 4 | AG17: =SUM(B17:AF17) -> 98
A18: 22:00 | C18: 2 | D18: 2 | E18: 3 | F18: 4 | G18: 2 | H18: 1 | I18: 3 | J18: 2 | K18: 1 | L18: 4 | M18: 1 | N18: 1 | O18: 2 | P18: 1 | Q18: 2 | R18: 1 | S18: 5 | T18: 6 | U18: 3 | V18: 2 | X18: 4 | Y18: 5 | Z18: 3 | AE18: 1 | AG18: =SUM(B18:AF18) -> 61
A19: 23:00 | C19: 1 | D19: 3 | E19: 1 | F19: 1 | G19: 1 | I19: 2 | J19: 1 | L19: 1 | M19: 1 | N19: 1 | O19: 1 | P19: 3 | Q19: 1 | R19: 3 | S19: 1 | T19: 7 | U19: 1 | V19: 3 | W19: 2 | X19: 3 | Y19: 1 | AA19: 2 | AE19: 3 | AG19: =SUM(B19:AF19) -> 44
A20: 00:00 | C20: 1 | D20: 5 | E20: 2 | F20: 3 | I20: 2 | J20: 3 | K20: 2 | L20: 1 | Q20: 2 | R20: 6 | S20: 1 | T20: 2 | U20: 2 | V20: 2 | W20: 2 | Y20: 2 | Z20: 4 | AD20: 1 | AE20: 1 | AG20: =SUM(B20:AF20) -> 44
A21: 01:00 | B21: 6 | C21: 1 | D21: 2 | E21: 2 | F21: 3 | K21: 1 | N21: 1 | O21: 1 | P21: 1 | Q21: 10 | R21: 1 | S21: 1 | T21: 4 | U21: 2 | W21: 1 | X21: 2 | Y21: 1 | Z21: 3 | AD21: 3 | AE21: 1 | AG21: =SUM(B21:AF21) -> 47
A22: 02:00 | B22: 2 | D22: 1 | F22: 1 | G22: 1 | I22: 2 | L22: 1 | N22: 1 | O22: 4 | P22: 3 | Q22: 1 | R22: 4 | S22: 2 | T22: 3 | V22: 4 | X22: 6 | Y22: 1 | Z22: 2 | AA22: 2 | AD22: 4 | AE22: 2 | AG22: =SUM(B22:AF22) -> 47
A23: 03:00 | B23: 2 | D23: 4 | J23: 2 | O23: 1 | P23: 2 | R23: 1 | V23: 2 | AD23: 3 | AG23: =SUM(B23:AF23) -> 17
A24: 04:00 | D24: 1 | E24: 1 | L24: 3 | N24: 1 | Q24: 2 | R24: 2 | U24: 3 | V24: 3 | W24: 2 | Y24: 1 | AA24: 1 | AD24: 1 | AE24: 1 | AG24: =SUM(B24:AF24) -> 22
A25: 05:00 | B25: 1 | E25: 1 | F25: 1 | G25: 1 | K25: 1 | L25: 1 | M25: 1 | N25: 1 | R25: 1 | S25: 1 | V25: 1 | Z25: 1 | AD25: 2 | AE25: 2 | AG25: =SUM(B25:AF25) -> 16
A26: 06:00 | C26: 1 | D26: 1 | F26: 1 | G26: 1 | N26: 2 | P26: 1 | R26: 3 | Z26: 1 | AG26: =SUM(B26:AF26) -> 11
A27: 07:00 | B27: 1 | D27: 1 | I27: 1 | S27: 1 | T27: 1 | V27: 1 | W27: 1 | X27: 1 | Z27: 1 | AA27: 3 | AG27: =SUM(B27:AF27) -> 12
A28: Total de atendidos | B28: =SUM(B29:B52) -> 75 | C28: =SUM(C29:C52) -> 73 | D28: =SUM(D29:D52) -> 75 | E28: =SUM(E29:E52) -> 65 | F28: =SUM(F29:F52) -> 74 | G28: =SUM(G29:G52) -> 83 | H28: =SUM(H29:H52) -> 63 | I28: =SUM(I29:I52) -> 58 | ... AF28: =SUM(AF29:AF52) -> 0 | AG28: =SUM(B28:AF28) -> 1895
A29: 08:00 | B29: 2 | E29: 1 | F29: 1 | G29: 3 | H29: 2 | K29: 2 | L29: 1 | N29: 1 | O29: 1 | S29: 3 | W29: 1 | X29: 2 | Y29: 1 | Z29: 2 | AA29: 2 | AG29: =SUM(B29:AF29) -> 25
A30: 09:00 | B30: 4 | C30: 7 | D30: 4 | E30: 2 | F30: 5 | G30: 2 | H30: 8 | I30: 3 | J30: 4 | K30: 1 | L30: 2 | M30: 6 | N30: 5 | O30: 2 | P30: 3 | Q30: 5 | R30: 4 | S30: 2 | T30: 2 | U30: 2 | V30: 4 | W30: 2 | X30: 1 | Y30: 6 | Z30: 2 | AA30: 5 | AB30: 7 | AE30: 2 | AG30: =SUM(B30:AF30) -> 102
A31: 10:00 | B31: 5 | C31: 2 | D31: 2 | E31: 2 | F31: 3 | G31: 7 | H31: 2 | I31: 3 | J31: 2 | K31: 1 | L31: 4 | M31: 3 | N31: 2 | O31: 3 | P31: 2 | Q31: 3 | R31: 6 | S31: 1 | T31: 3 | U31: 8 | V31: 2 | W31: 4 | X31: 5 | Y31: 2 | Z31: 4 | AA31: 4 | AB31: 6 | AE31: 6 | AG31: =SUM(B31:AF31) -> 97
A32: 11:00 | B32: 2 | C32: 7 | D32: 6 | E32: 4 | F32: 4 | G32: 5 | H32: 4 | I32: 3 | K32: 6 | L32: 3 | M32: 2 | N32: 9 | O32: 5 | P32: 5 | Q32: 1 | R32: 3 | S32: 2 | T32: 4 | U32: 3 | V32: 1 | W32: 1 | X32: 6 | Y32: 2 | Z32: 5 | AA32: 5 | AB32: 6 | AE32: 6 | AG32: =SUM(B32:AF32) -> 110
A33: 12:00 | B33: 6 | C33: 7 | D33: 5 | E33: 7 | F33: 7 | G33: 8 | H33: 2 | I33: 5 | J33: 5 | K33: 5 | L33: 4 | M33: 2 | N33: 7 | O33: 4 | P33: 2 | Q33: 2 | R33: 3 | S33: 7 | T33: 4 | U33: 1 | V33: 2 | W33: 2 | X33: 6 | Y33: 4 | Z33: 3 | AA33: 8 | AB33: 5 | AE33: 2 | AG33: =SUM(B33:AF33) -> 125
A34: 13:00 | B34: 3 | C34: 5 | D34: 1 | E34: 3 | F34: 6 | G34: 4 | H34: 3 | I34: 4 | J34: 5 | L34: 4 | M34: 3 | N34: 4 | O34: 4 | P34: 2 | Q34: 2 | R34: 5 | S34: 8 | T34: 6 | U34: 2 | V34: 1 | W34: 3 | X34: 4 | Y34: 2 | Z34: 3 | AA34: 8 | AB34: 4 | AE34: 2 | AG34: =SUM(B34:AF34) -> 101
A35: 14:00 | B35: 4 | C35: 3 | D35: 4 | E35: 5 | F35: 7 | G35: 5 | H35: 3 | I35: 4 | J35: 2 | K35: 7 | L35: 5 | M35: 2 | N35: 5 | O35: 3 | P35: 1 | R35: 3 | S35: 8 | T35: 1 | U35: 4 | V35: 4 | W35: 2 | Y35: 2 | Z35: 2 | AA35: 5 | AB35: 3 | AD35: 4 | AE35: 8 | AG35: =SUM(B35:AF35) -> 106
A36: 15:00 | B36: 6 | C36: 2 | D36: 5 | E36: 5 | F36: 4 | G36: 7 | H36: 4 | I36: 1 | J36: 1 | K36: 1 | L36: 7 | M36: 4 | N36: 4 | O36: 4 | P36: 4 | Q36: 2 | R36: 4 | S36: 6 | T36: 4 | U36: 4 | V36: 3 | W36: 7 | X36: 4 | Y36: 2 | Z36: 5 | AA36: 3 | AB36: 4 | AD36: 6 | AE36: 5 | AG36: =SUM(B36:AF36) -> 118
A37: 16:00 | B37: 7 | C37: 7 | D37: 2 | E37: 4 | F37: 5 | G37: 9 | H37: 7 | J37: 1 | K37: 3 | L37: 4 | N37: 7 | O37: 3 | P37: 1 | Q37: 6 | R37: 4 | S37: 7 | T37: 5 | U37: 5 | V37: 4 | W37: 3 | X37: 8 | Y37: 5 | Z37: 5 | AA37: 2 | AB37: 6 | AD37: 7 | AE37: 8 | AG37: =SUM(B37:AF37) -> 135
A38: 17:00 | B38: 4 | C38: 4 | D38: 3 | E38: 6 | F38: 6 | G38: 2 | H38: 6 | I38: 4 | J38: 5 | K38: 3 | L38: 4 | M38: 8 | N38: 3 | O38: 5 | P38: 2 | Q38: 4 | R38: 7 | S38: 7 | T38: 6 | U38: 5 | V38: 3 | W38: 4 | X38: 3 | Y38: 6 | Z38: 3 | AA38: 5 | AD38: 5 | AE38: 9 | AG38: =SUM(B38:AF38) -> 132
A39: 18:00 | B39: 7 | C39: 11 | D39: 7 | E39: 6 | F39: 4 | G39: 6 | H39: 6 | I39: 5 | J39: 8 | K39: 2 | L39: 6 | M39: 3 | N39: 8 | O39: 4 | P39: 6 | Q39: 4 | R39: 6 | S39: 6 | T39: 4 | U39: 9 | V39: 6 | W39: 3 | X39: 9 | Y39: 9 | Z39: 4 | AA39: 6 | AD39: 6 | AE39: 6 | AG39: =SUM(B39:AF39) -> 167
A40: 19:00 | B40: 3 | C40: 3 | D40: 5 | E40: 5 | F40: 1 | G40: 6 | H40: 2 | I40: 6 | J40: 3 | K40: 1 | L40: 2 | M40: 5 | N40: 6 | O40: 3 | P40: 7 | Q40: 3 | R40: 3 | S40: 4 | T40: 2 | U40: 7 | V40: 5 | W40: 7 | X40: 7 | Y40: 3 | Z40: 5 | AA40: 6 | AD40: 4 | AE40: 7 | AG40: =SUM(B40:AF40) -> 121
A41: 20:00 | B41: 3 | C41: 5 | D41: 6 | E41: 1 | F41: 2 | G41: 5 | H41: 7 | I41: 5 | J41: 3 | K41: 1 | L41: 4 | M41: 1 | N41: 2 | O41: 4 | P41: 5 | Q41: 2 | R41: 4 | S41: 1 | T41: 5 | U41: 4 | V41: 6 | W41: 4 | X41: 5 | Y41: 4 | Z41: 6 | AA41: 1 | AE41: 4 | AG41: =SUM(B41:AF41) -> 100
...

Sheet MAYO
A2: MAYO | B2: 1 | C2: =+B2+1 -> 2 | D2: =+C2+1 -> 3 | E2: =+D2+1 -> 4 | F2: =+E2+1 -> 5 | G2: =+F2+1 -> 6 | H2: =+G2+1 -> 7 | I2: =+H2+1 -> 8 | J2: =+I2+1 -> 9 | ... AA2: =+Z2+1 -> 26 | AB2: 27 | AC2: =+AB2+1 -> 28 | AD2: 29 | AE2: 30 | AF2: 31 | AG2: TOTAL
A3: Total de Inscritos | B3: =SUM(B4:B27) -> 73 | C3: =SUM(C4:C27) -> 79 | D3: =SUM(D4:D27) -> 70 | E3: =SUM(E4:E27) -> 94 | F3: =SUM(F4:F27) -> 68 | G3: =SUM(G4:G27) -> 61 | H3: =SUM(H4:H27) -> 73 | I3: =SUM(I4:I27) -> 91 | ... AF3: =SUM(AF4:AF27) -> 73 | AG3: =SUM(B3:AF3) -> 2659
A4: 08:00 | B4: 2 | D4: 2 | E4: 8 | F4: 4 | G4: 2 | H4: 1 | I4: 6 | J4: 1 | L4: 8 | M4: 4 | N4: 8 | O4: 3 | P4: 2 | Q4: 4 | R4: 1 | S4: 2 | T4: 2 | U4: 6 | V4: 2 | W4: 4 | X4: 2 | Y4: 1 | Z4: 12 | AA4: 5 | AB4: 3 | AC4: 5 | AD4: 4 | AE4: 2 | AF4: 3 | AG4: =SUM(B4:AF4) -> 109
A5: 09:00 | B5: 5 | C5: 2 | D5: 1 | E5: 9 | F5: 3 | G5: 2 | H5: 2 | I5: 2 | J5: 2 | K5: 3 | L5: 3 | M5: 6 | N5: 7 | O5: 6 | P5: 7 | Q5: 7 | R5: 5 | S5: 4 | T5: 4 | U5: 4 | V5: 4 | W5: 2 | X5: 3 | Y5: 7 | Z5: 6 | AA5: 6 | AB5: 8 | AC5: 6 | AD5: 10 | AE5: 2 | AF5: 3 | AG5: =SUM(B5:AF5) -> 141
A6: 10:00 | B6: 5 | C6: 5 | D6: 1 | E6: 5 | F6: 3 | G6: 2 | H6: 2 | I6: 2 | J6: 4 | K6: 3 | L6: 10 | M6: 3 | N6: 4 | O6: 10 | P6: 8 | Q6: 6 | S6: 3 | T6: 1 | U6: 7 | V6: 3 | W6: 9 | X6: 5 | Y6: 3 | Z6: 5 | AA6: 6 | AB6: 6 | AC6: 5 | AD6: 5 | AE6: 4 | AF6: 7 | AG6: =SUM(B6:AF6) -> 142
A7: 11:00 | B7: 8 | C7: 7 | D7: 5 | E7: 8 | F7: 4 | G7: 4 | H7: 5 | I7: 3 | J7: 3 | K7: 3 | L7: 10 | M7: 9 | N7: 3 | O7: 12 | P7: 6 | Q7: 1 | R7: 5 | S7: 3 | T7: 6 | U7: 4 | V7: 1 | W7: 5 | X7: 7 | Y7: 6 | Z7: 14 | AA7: 8 | AB7: 5 | AC7: 6 | AD7: 7 | AE7: 7 | AF7: 1 | AG7: =SUM(B7:AF7) -> 176
A8: 12:00 | B8: 4 | C8: 7 | D8: 3 | E8: 7 | F8: 6 | G8: 5 | H8: 6 | I8: 5 | J8: 3 | K8: 6 | L8: 8 | M8: 3 | N8: 12 | O8: 18 | P8: 6 | Q8: 5 | R8: 4 | S8: 8 | T8: 4 | U8: 9 | V8: 6 | W8: 11 | X8: 5 | Y8: 8 | Z8: 6 | AA8: 7 | AB8: 12 | AC8: 6 | AD8: 10 | AE8: 8 | AF8: 7 | AG8: =SUM(B8:AF8) -> 215
A9: 13:00 | B9: 1 | C9: 5 | D9: 6 | E9: 3 | F9: 3 | G9: 2 | H9: 1 | I9: 1 | J9: 2 | K9: 4 | L9: 4 | M9: 5 | N9: 4 | O9: 7 | P9: 5 | Q9: 4 | R9: 5 | S9: 2 | T9: 2 | U9: 7 | V9: 9 | W9: 6 | X9: 3 | Y9: 3 | Z9: 9 | AA9: 6 | AB9: 5 | AC9: 2 | AD9: 1 | AE9: 1 | AF9: 6 | AG9: =SUM(B9:AF9) -> 124
