Workbook

Sheet FORMATO 2021
A2: X X X X X | B2: 1 | C2: =+B2+1 -> 2 | D2: =+C2+1 -> 3 | E2: =+D2+1 -> 4 | F2: =+E2+1 -> 5 | G2: =+F2+1 -> 6 | H2: =+G2+1 -> 7 | I2: =+H2+1 -> 8 | J2: =+I2+1 -> 9 | ... AA2: =+Z2+1 -> 26 | AB2: 27 | AC2: =+AB2+1 -> 28 | AD2: 29 | AE2: 30 | AF2: 31 | AG2: TOTAL
A3: Total de Inscritos | B3: =SUM(B4:B27) -> 0 | C3: =SUM(C4:C27) -> 0 | D3: =SUM(D4:D27) -> 0 | E3: =SUM(E4:E27) -> 0 | F3: =SUM(F4:F27) -> 0 | G3: =SUM(G4:G27) -> 0 | H3: =SUM(H4:H27) -> 0 | I3: =SUM(I4:I27) -> 0 | ... AF3: =SUM(AF4:AF27) -> 0 | AG3: =SUM(B3:AF3) -> 0
A4: 08:00 | AG4: =SUM(B4:AF4) -> 0
A5: 09:00 | AG5: =SUM(B5:AF5) -> 0
A6: 10:00 | AG6: =SUM(B6:AF6) -> 0
A7: 11:00 | AG7: =SUM(B7:AF7) -> 0
A8: 12:00 | AG8: =SUM(B8:AF8) -> 0
A9: 13:00 | AG9: =SUM(B9:AF9) -> 0
A10: 14:00 | AG10: =SUM(B10:AF10) -> 0
A11: 15:00 | AG11: =SUM(B11:AF11) -> 0
A12: 16:00 | AG12: =SUM(B12:AF12) -> 0
A13: 17:00 | AG13: =SUM(B13:AF13) -> 0
A14: 18:00 | AG14: =SUM(B14:AF14) -> 0
A15: 19:00 | AG15: =SUM(B15:AF15) -> 0
... A27: 07:00 | AG27: =SUM(B27:AF27) -> 0
A28: Total de atendidos | B28: =SUM(B29:B52) -> 0 | C28: =SUM(C29:C52) -> 0 | D28: =SUM(D29:D52) -> 0 | E28: =SUM(E29:E52) -> 0 | F28: =SUM(F29:F52) -> 0 | G28: =SUM(G29:G52) -> 0 | H28: =SUM(H29:H52) -> 0 | I28: =SUM(I29:I52) -> 0 | ... AF28: =SUM(AF29:AF52) -> 0 | AG28: =SUM(B28:AF28) -> 0
A29: 08:00 | AG29: =SUM(B29:AF29) -> 0
A30: 09:00 | AG30: =SUM(B30:AF30) -> 0
A31: 10:00 | AG31: =SUM(B31:AF31) -> 0
A32: 11:00 | AG32: =SUM(B32:AF32) -> 0
A33: 12:00 | AG33: =SUM(B33:AF33) -> 0
A34: 13:00 | AG34: =SUM(B34:AF34) -> 0
A35: 14:00 | AG35: =SUM(B35:AF35) -> 0
A36: 15:00 | AG36: =SUM(B36:AF36) -> 0
A37: 16:00 | AG37: =SUM(B37:AF37) -> 0
A38: 17:00 | AG38: =SUM(B38:AF38) -> 0
A39: 18:00 | AG39: =SUM(B39:AF39) -> 0
A40: 19:00 | AG40: =SUM(B40:AF40) -> 0
... A52: 07:00 | AG52: =SUM(B52:AF52) -> 0
A53: Total de NSP | B53: =SUM(B54:B77) -> 0 | C53: =SUM(C54:C77) -> 0 | D53: =SUM(D54:D77) -> 0 | E53: =SUM(E54:E77) -> 0 | F53: =SUM(F54:F77) -> 0 | G53: =SUM(G54:G77) -> 0 | H53: =SUM(H54:H77) -> 0 | I53: =SUM(I54:I77) -> 0 | ... AF53: =SUM(AF54:AF77) -> 0 | AG53: =SUM(B53:AF53) -> 0
A54: 08:00 | AG54: =SUM(B54:AF54) -> 0
A55: 09:00 | AG55: =SUM(B55:AF55) -> 0
A56: 10:00 | AG56: =SUM(B56:AF56) -> 0
A57: 11:00 | AG57: =SUM(B57:AF57) -> 0
A58: 12:00 | AG58: =SUM(B58:AF58) -> 0
A59: 13:00 | AG59: =SUM(B59:AF59) -> 0
A60: 14:00 | AG60: =SUM(B60:AF60) -> 0
A61: 15:00 | AG61: =SUM(B61:AF61) -> 0
A62: 16:00 | AG62: =SUM(B62:AF62) -> 0
A63: 17:00 | AG63: =SUM(B63:AF63) -> 0
...

Sheet CONSOLIDADO
A2: 2021 | B2: ENERO | C2: FEBRERO | D2: MARZO | E2: ABRIL | F2: MAYO | G2: JUNIO | H2: JULIO | I2: AGOSTO | J2: SEPTIEMBRE | K2: OCTUBRE | L2: NOVIEMBRE | M2: DICIEMBRE | N2: TOTAL
A3: Total de Inscritos | B3: =+ENERO!$AG3 -> 4381 | C3: =+FEBRERO!$AG3 -> 4349 | D3: =+MARZO!$AG3 -> 4712 | E3: =+ABRIL!$AG3 -> 4111 | F3: =+MAYO!$AG3 -> 4600 | G3: =+JUNIO!$AG3 -> 4530 | H3: =+JULIO!$AG3 -> 4477 | I3: =+AGOSTO!$AG3 -> 4539 | J3: =+SEPTIEMBRE!$AG3 -> 4026 | K3: =+OCTUBRE!$AG3 -> 4760 | L3: =+NOVIEMBRE!$AG3 -> 5101 | M3: =+DICIEMBRE!$AG3 -> 1329 | N3: =SUM(B3:M3) -> 50915
A4: 08:00 | B4: =+ENERO!$AG4 -> 117 | C4: =+FEBRERO!$AG4 -> 129 | D4: =+MARZO!$AG4 -> 77 | E4: =+ABRIL!$AG4 -> 102 | F4: =+MAYO!$AG4 -> 140 | G4: =+JUNIO!$AG4 -> 138 | H4: =+JULIO!$AG4 -> 100 | I4: =+AGOSTO!$AG4 -> 104 | J4: =+SEPTIEMBRE!$AG4 -> 78 | K4: =+OCTUBRE!$AG4 -> 80 | L4: =+NOVIEMBRE!$AG4 -> 106 | M4: =+DICIEMBRE!$AG4 -> 27 | N4: =SUM(B4:M4) -> 1198
A5: 09:00 | B5: =+ENERO!$AG5 -> 129 | C5: =+FEBRERO!$AG5 -> 181 | D5: =+MARZO!$AG5 -> 137 | E5: =+ABRIL!$AG5 -> 144 | F5: =+MAYO!$AG5 -> 170 | G5: =+JUNIO!$AG5 -> 184 | H5: =+JULIO!$AG5 -> 138 | I5: =+AGOSTO!$AG5 -> 155 | J5: =+SEPTIEMBRE!$AG5 -> 116 | K5: =+OCTUBRE!$AG5 -> 163 | L5: =+NOVIEMBRE!$AG5 -> 139 | M5: =+DICIEMBRE!$AG5 -> 44 | N5: =SUM(B5:M5) -> 1700
A6: 10:00 | B6: =+ENERO!$AG6 -> 186 | C6: =+FEBRERO!$AG6 -> 196 | D6: =+MARZO!$AG6 -> 189 | E6: =+ABRIL!$AG6 -> 169 | F6: =+MAYO!$AG6 -> 173 | G6: =+JUNIO!$AG6 -> 202 | H6: =+JULIO!$AG6 -> 168 | I6: =+AGOSTO!$AG6 -> 166 | J6: =+SEPTIEMBRE!$AG6 -> 134 | K6: =+OCTUBRE!$AG6 -> 142 | L6: =+NOVIEMBRE!$AG6 -> 151 | M6: =+DICIEMBRE!$AG6 -> 43 | N6: =SUM(B6:M6) -> 1919
A7: 11:00 | B7: =+ENERO!$AG7 -> 192 | C7: =+FEBRERO!$AG7 -> 226 | D7: =+MARZO!$AG7 -> 204 | E7: =+ABRIL!$AG7 -> 212 | F7: =+MAYO!$AG7 -> 249 | G7: =+JUNIO!$AG7 -> 226 | H7: =+JULIO!$AG7 -> 199 | I7: =+AGOSTO!$AG7 -> 179 | J7: =+SEPTIEMBRE!$AG7 -> 139 | K7: =+OCTUBRE!$AG7 -> 140 | L7: =+NOVIEMBRE!$AG7 -> 173 | M7: =+DICIEMBRE!$AG7 -> 61 | N7: =SUM(B7:M7) -> 2200
A8: 12:00 | B8: =+ENERO!$AG8 -> 230 | C8: =+FEBRERO!$AG8 -> 240 | D8: =+MARZO!$AG8 -> 213 | E8: =+ABRIL!$AG8 -> 208 | F8: =+MAYO!$AG8 -> 249 | G8: =+JUNIO!$AG8 -> 249 | H8: =+JULIO!$AG8 -> 247 | I8: =+AGOSTO!$AG8 -> 174 | J8: =+SEPTIEMBRE!$AG8 -> 143 | K8: =+OCTUBRE!$AG8 -> 179 | L8: =+NOVIEMBRE!$AG8 -> 187 | M8: =+DICIEMBRE!$AG8 -> 40 | N8: =SUM(B8:M8) -> 2359
A9: 13:00 | B9: =+ENERO!$AG9 -> 197 | C9: =+FEBRERO!$AG9 -> 178 | D9: =+MARZO!$AG9 -> 173 | E9: =+ABRIL!$AG9 -> 196 | F9: =+MAYO!$AG9 -> 233 | G9: =+JUNIO!$AG9 -> 186 | H9: =+JULIO!$AG9 -> 168 | I9: =+AGOSTO!$AG9 -> 162 | J9: =+SEPTIEMBRE!$AG9 -> 132 | K9: =+OCTUBRE!$AG9 -> 151 | L9: =+NOVIEMBRE!$AG9 -> 150 | M9: =+DICIEMBRE!$AG9 -> 42 | N9: =SUM(B9:M9) -> 1968
A10: 14:00 | B10: =+ENERO!$AG10 -> 170 | C10: =+FEBRERO!$AG10 -> 212 | D10: =+MARZO!$AG10 -> 148 | E10: =+ABRIL!$AG10 -> 187 | F10: =+MAYO!$AG10 -> 197 | G10: =+JUNIO!$AG10 -> 184 | H10: =+JULIO!$AG10 -> 155 | I10: =+AGOSTO!$AG10 -> 170 | J10: =+SEPTIEMBRE!$AG10 -> 104 | K10: =+OCTUBRE!$AG10 -> 155 | L10: =+NOVIEMBRE!$AG10 -> 154 | M10: =+DICIEMBRE!$AG10 -> 37 | N10: =SUM(B10:M10) -> 1873
A11: 15:00 | B11: =+ENERO!$AG11 -> 195 | C11: =+FEBRERO!$AG11 -> 218 | D11: =+MARZO!$AG11 -> 191 | E11: =+ABRIL!$AG11 -> 197 | F11: =+MAYO!$AG11 -> 247 | G11: =+JUNIO!$AG11 -> 256 | H11: =+JULIO!$AG11 -> 189 | I11: =+AGOSTO!$AG11 -> 184 | J11: =+SEPTIEMBRE!$AG11 -> 161 | K11: =+OCTUBRE!$AG11 -> 164 | L11: =+NOVIEMBRE!$AG11 -> 211 | M11: =+DICIEMBRE!$AG11 -> 55 | N11: =SUM(B11:M11) -> 2268
A12: 16:00 | B12: =+ENERO!$AG12 -> 271 | C12: =+FEBRERO!$AG12 -> 342 | D12: =+MARZO!$AG12 -> 246 | E12: =+ABRIL!$AG12 -> 232 | F12: =+MAYO!$AG12 -> 298 | G12: =+JUNIO!$AG12 -> 263 | H12: =+JULIO!$AG12 -> 221 | I12: =+AGOSTO!$AG12 -> 237 | J12: =+SEPTIEMBRE!$AG12 -> 176 | K12: =+OCTUBRE!$AG12 -> 226 | L12: =+NOVIEMBRE!$AG12 -> 245 | M12: =+DICIEMBRE!$AG12 -> 63 | N12: =SUM(B12:M12) -> 2820
A13: 17:00 | B13: =+ENERO!$AG13 -> 709 | C13: =+FEBRERO!$AG13 -> 511 | D13: =+MARZO!$AG13 -> 970 | E13: =+ABRIL!$AG13 -> 784 | F13: =+MAYO!$AG13 -> 829 | G13: =+JUNIO!$AG13 -> 890 | H13: =+JULIO!$AG13 -> 890 | I13: =+AGOSTO!$AG13 -> 972 | J13: =+SEPTIEMBRE!$AG13 -> 917 | K13: =+OCTUBRE!$AG13 -> 984 | L13: =+NOVIEMBRE!$AG13 -> 975 | M13: =+DICIEMBRE!$AG13 -> 247 | N13: =SUM(B13:M13) -> 9678
A14: 18:00 | B14: =+ENERO!$AG14 -> 382 | C14: =+FEBRERO!$AG14 -> 358 | D14: =+MARZO!$AG14 -> 399 | E14: =+ABRIL!$AG14 -> 394 | F14: =+MAYO!$AG14 -> 408 | G14: =+JUNIO!$AG14 -> 388 | H14: =+JULIO!$AG14 -> 424 | I14: =+AGOSTO!$AG14 -> 445 | J14: =+SEPTIEMBRE!$AG14 -> 379 | K14: =+OCTUBRE!$AG14 -> 465 | L14: =+NOVIEMBRE!$AG14 -> 520 | M14: =+DICIEMBRE!$AG14 -> 114 | N14: =SUM(B14:M14) -> 4676
... A80: PAR | B80: =+ENERO!$AG80 -> 812 | C80: =+FEBRERO!$AG80 -> 986 | D80: =+MARZO!$AG80 -> 931 | E80: =+ABRIL!$AG80 -> 794 | F80: =+MAYO!$AG80 -> 887 | G80: =+JUNIO!$AG80 -> 1095 | H80: =+JULIO!$AG80 -> 814 | I80: =+AGOSTO!$AG80 -> 738 | J80: =+SEPTIEMBRE!$AG80 -> 664 | K80: =+OCTUBRE!$AG80 -> 602 | L80: =+NOVIEMBRE!$AG80 -> 903 | M80: =+DICIEMBRE!$AG80 -> 127 | N80: =SUM(B80:M80) -> 9353
A81: TOTAL NSP | B81: =+ENERO!$AG81 -> 279 | C81: =+FEBRERO!$AG81 -> 190 | D81: =+MARZO!$AG81 -> 263 | E81: =+ABRIL!$AG81 -> 235 | F81: =+MAYO!$AG81 -> 240 | G81: =+JUNIO!$AG81 -> 182 | H81: =+JULIO!$AG81 -> 159 | I81: =+AGOSTO!$AG81 -> 203 | J81: =+SEPTIEMBRE!$AG81 -> 181 | K81: =+OCTUBRE!$AG81 -> 210 | L81: =+NOVIEMBRE!$AG81 -> 334 | M81: =+DICIEMBRE!$AG81 -> 33 | N81: =SUM(B81:M81) -> 2509 | O81: =IF(N81<>N53,"*","")
A82: PAR | B82: =+ENERO!$AG82 -> 36 | C82: =+FEBRERO!$AG82 -> 92 | D82: =+MARZO!$AG82 -> 21 | E82: =+ABRIL!$AG82 -> 42 | F82: =+MAYO!$AG82 -> 35 | G82: =+JUNIO!$AG82 -> 42 | H82: =+JULIO!$AG82 -> 13 | I82: =+AGOSTO!$AG82 -> 20 | J82: =+SEPTIEMBRE!$AG82 -> 16 | K82: =+OCTUBRE!$AG82 -> 7 | L82: =+NOVIEMBRE!$AG82 -> 16 | M82: =+DICIEMBRE!$AG82 -> 4 | N82: =SUM(B82:M82) -> 344
A83: SAR | B83: =+ENERO!$AG83 -> 243 | C83: =+FEBRERO!$AG83 -> 98 | D83: =+MARZO!$AG83 -> 242 | E83: =+ABRIL!$AG83 -> 193 | F83: =+MAYO!$AG83 -> 205 | G83: =+JUNIO!$AG83 -> 140 | H83: =+JULIO!$AG83 -> 146 | I83: =+AGOSTO!$AG83 -> 183 | J83: =+SEPTIEMBRE!$AG83 -> 165 | K83: =+OCTUBRE!$AG83 -> 203 | L83: =+NOVIEMBRE!$AG83 -> 318 | M83: =+DICIEMBRE!$AG83 -> 29 | N83: =SUM(B83:M83) -> 2165
A84: NSP PEDIATR. / ADULTOS | B84: =+ENERO!$AG84 -> 279 | C84: =+FEBRERO!$AG84 -> 190 | D84: =+MARZO!$AG84 -> 263 | E84: =+ABRIL!$AG84 -> 235 | F84: =+MAYO!$AG84 -> 240 | G84: =+JUNIO!$AG84 -> 182 | H84: =+JULIO!$AG84 -> 159 | I84: =+AGOSTO!$AG84 -> 203 | J84: =+SEPTIEMBRE!$AG84 -> 181 | K84: =+OCTUBRE!$AG84 -> 210 | L84: =+NOVIEMBRE!$AG84 -> 339 | M84: =+DICIEMBRE!$AG84 -> 33 | N84: =SUM(B84:M84) -> 2514 | O84: =IF(N84<>N82+N83,"*","") -> * | P84: NSP
A85: NSP PEDIATRICOS (<15 AÑOS) | B85: =+ENERO!$AG85 -> 31 | C85: =+FEBRERO!$AG85 -> 18 | D85: =+MARZO!$AG85 -> 20 | E85: =+ABRIL!$AG85 -> 27 | F85: =+MAYO!$AG85 -> 19 | G85: =+JUNIO!$AG85 -> 15 | H85: =+JULIO!$AG85 -> 15 | I85: =+AGOSTO!$AG85 -> 26 | J85: =+SEPTIEMBRE!$AG85 -> 24 | K85: =+OCTUBRE!$AG85 -> 28 | L85: =+NOVIEMBRE!$AG85 -> 63 | M85: =+DICIEMBRE!$AG85 -> 2 | N85: =SUM(B85:M85) -> 288
A86: NSP ADULTOS | B86: =+ENERO!$AG86 -> 248 | C86: =+FEBRERO!$AG86 -> 172 | D86: =+MARZO!$AG86 -> 243 | E86: =+ABRIL!$AG86 -> 208 | F86: =+MAYO!$AG86 -> 221 | G86: =+JUNIO!$AG86 -> 167 | H86: =+JULIO!$AG86 -> 144 | I86: =+AGOSTO!$AG86 -> 177 | J86: =+SEPTIEMBRE!$AG86 -> 157 | K86: =+OCTUBRE!$AG86 -> 182 | L86: =+NOVIEMBRE!$AG86 -> 276 | M86: =+DICIEMBRE!$AG86 -> 31 | N86: =SUM(B86:M86) -> 2226
A87: NSP CATEGORIZACION | B87: =+ENERO!$AG87 -> 279 | C87: =+FEBRERO!$AG87 -> 190 | D87: =+MARZO!$AG87 -> 263 | E87: =+ABRIL!$AG87 -> 235 | F87: =+MAYO!$AG87 -> 240 | G87: =+JUNIO!$AG87 -> 182 | H87: =+JULIO!$AG87 -> 159 | I87: =+AGOSTO!$AG87 -> 203 | J87: =+SEPTIEMBRE!$AG87 -> 181 | K87: =+OCTUBRE!$AG87 -> 210 | L87: =+NOVIEMBRE!$AG87 -> 339 | M87: =+DICIEMBRE!$AG87 -> 33 | N87: =SUM(B87:M87) -> 2514 | O87: =IF(N87<>N84,"*","")
A88: SIN CATEGORIZACIÓN nsp | B88: =+ENERO!$AG88 -> 124 | C88: =+FEBRERO!$AG88 -> 111 | D88: =+MARZO!$AG88 -> 126 | E88: =+ABRIL!$AG88 -> 129 | F88: =+MAYO!$AG88 -> 127 | G88: =+JUNIO!$AG88 -> 80 | H88: =+JULIO!$AG88 -> 62 | I88: =+AGOSTO!$AG88 -> 83 | J88: =+SEPTIEMBRE!$AG88 -> 63 | K88: =+OCTUBRE!$AG88 -> 71 | L88: =+NOVIEMBRE!$AG88 -> 121 | M88: =+DICIEMBRE!$AG88 -> 13 | N88: =SUM(B88:M88) -> 1110
A89: C2 | B89: =+ENERO!$AG89 -> 0 | C89: =+FEBRERO!$AG89 -> 0 | D89: =+MARZO!$AG89 -> 0 | E89: =+ABRIL!$AG89 -> 0 | F89: =+MAYO!$AG89 -> 0 | G89: =+JUNIO!$AG89 -> 0 | H89: =+JULIO!$AG89 -> 0 | I89: =+AGOSTO!$AG89 -> 0 | J89: =+SEPTIEMBRE!$AG89 -> 0 | K89: =+OCTUBRE!$AG89 -> 0 | L89: =+NOVIEMBRE!$AG89 -> 0 | M89: =+DICIEMBRE!$AG89 -> 0 | N89: =SUM(B89:M89) -> 0
A90: C3 | B90: =+ENERO!$AG90 -> 2 | C90: =+FEBRERO!$AG90 -> 2 | D90: =+MARZO!$AG90 -> 4 | E90: =+ABRIL!$AG90 -> 8 | F90: =+MAYO!$AG90 -> 6 | G90: =+JUNIO!$AG90 -> 1 | H90: =+JULIO!$AG90 -> 1 | I90: =+AGOSTO!$AG90 -> 2 | J90: =+SEPTIEMBRE!$AG90 -> 6 | K90: =+OCTUBRE!$AG90 -> 1 | L90: =+NOVIEMBRE!$AG90 -> 2 | M90: =+DICIEMBRE!$AG90 -> 0 | N90: =SUM(B90:M90) -> 35
A91: C4 | B91: =+ENERO!$AG91 -> 80 | C91: =+FEBRERO!$AG91 -> 50 | D91: =+MARZO!$AG91 -> 77 | E91: =+ABRIL!$AG91 -> 58 | F91: =+MAYO!$AG91 -> 67 | G91: =+JUNIO!$AG91 -> 69 | H91: =+JULIO!$AG91 -> 46 | I91: =+AGOSTO!$AG91 -> 60 | J91: =+SEPTIEMBRE!$AG91 -> 58 | K91: =+OCTUBRE!$AG91 -> 80 | L91: =+NOVIEMBRE!$AG91 -> 145 | M91: =+DICIEMBRE!$AG91 -> 12 | N91: =SUM(B91:M91) -> 802
A92: C5 | B92: =+ENERO!$AG92 -> 73 | C92: =+FEBRERO!$AG92 -> 27 | D92: =+MARZO!$AG92 -> 56 | E92: =+ABRIL!$AG92 -> 40 | F92: =+MAYO!$AG92 -> 40 | G92: =+JUNIO!$AG92 -> 32 | H92: =+JULIO!$AG92 -> 50 | I92: =+AGOSTO!$AG92 -> 58 | J92: =+SEPTIEMBRE!$AG92 -> 54 | K92: =+OCTUBRE!$AG92 -> 58 | L92: =+NOVIEMBRE!$AG92 -> 71 | M92: =+DICIEMBRE!$AG92 -> 8 | N92: =SUM(B92:M92) -> 567
A93: TOTAL PACIENTES ATENDIDOS | B93: =+ENERO!$AG93 -> 4102 | C93: =+FEBRERO!$AG93 -> 4159 | D93: =+MARZO!$AG93 -> 4448 | E93: =+ABRIL!$AG93 -> 3879 | F93: =+MAYO!$AG93 -> 4360 | G93: =+JUNIO!$AG93 -> 4348 | H93: =+JULIO!$AG93 -> 4318 | I93: =+AGOSTO!$AG93 -> 4336 | J93: =+SEPTIEMBRE!$AG93 -> 3845 | K93: =+OCTUBRE!$AG93 -> 4549 | L93: =+NOVIEMBRE!$AG93 -> 4918 | M93: =+DICIEMBRE!$AG93 -> 1296 | N93: =SUM(B93:M93) -> 48558 | O93: =IF(N93<>N28,"*","") -> *
A94: Menor 15 años | B94: =+ENERO!$AG94 -> 287 | C94: =+FEBRERO!$AG94 -> 272 | D94: =+MARZO!$AG94 -> 351 | E94: =+ABRIL!$AG94 -> 286 | F94: =+MAYO!$AG94 -> 261 | G94: =+JUNIO!$AG94 -> 312 | H94: =+JULIO!$AG94 -> 349 | I94: =+AGOSTO!$AG94 -> 395 | J94: =+SEPTIEMBRE!$AG94 -> 409 | K94: =+OCTUBRE!$AG94 -> 617 | L94: =+NOVIEMBRE!$AG94 -> 652 | M94: =+DICIEMBRE!$AG94 -> 164 | N94: =SUM(B94:M94) -> 4355
A95: Menor 1 Año | B95: =+ENERO!$AG95 -> 11 | C95: =+FEBRERO!$AG95 -> 10 | D95: =+MARZO!$AG95 -> 10 | E95: =+ABRIL!$AG95 -> 12 | F95: =+MAYO!$AG95 -> 6 | G95: =+JUNIO!$AG95 -> 11 | H95: =+JULIO!$AG95 -> 5 | I95: =+AGOSTO!$AG95 -> 16 | J95: =+SEPTIEMBRE!$AG95 -> 13 | K95: =+OCTUBRE!$AG95 -> 24 | L95: =+NOVIEMBRE!$AG95 -> 10 | M95: =+DICIEMBRE!$AG95 -> 12 | N95: =SUM(B95:M95) -> 140
A96: 1 Año | B96: =+ENERO!$AG96 -> 14 | C96: =+FEBRERO!$AG96 -> 16 | D96: =+MARZO!$AG96 -> 23 | E96: =+ABRIL!$AG96 -> 22 | F96: =+MAYO!$AG96 -> 13 | G96: =+JUNIO!$AG96 -> 29 | H96: =+JULIO!$AG96 -> 24 | I96: =+AGOSTO!$AG96 -> 22 | J96: =+SEPTIEMBRE!$AG96 -> 33 | K96: =+OCTUBRE!$AG96 -> 76 | L96: =+NOVIEMBRE!$AG96 -> 59 | M96: =+DICIEMBRE!$AG96 -> 13 | N96: =SUM(B96:M96) -> 344
A97: 2 - 4 | B97: =+ENERO!$AG97 -> 57 | C97: =+FEBRERO!$AG97 -> 52 | D97: =+MARZO!$AG97 -> 67 | E97: =+ABRIL!$AG97 -> 36 | F97: =+MAYO!$AG97 -> 36 | G97: =+JUNIO!$AG97 -> 55 | H97: =+JULIO!$AG97 -> 53 | I97: =+AGOSTO!$AG97 -> 64 | J97: =+SEPTIEMBRE!$AG97 -> 104 | K97: =+OCTUBRE!$AG97 -> 175 | L97: =+NOVIEMBRE!$AG97 -> 198 | M97: =+DICIEMBRE!$AG97 -> 54 | N97: =SUM(B97:M97) -> 951
A98: 5 - 9 | B98: =+ENERO!$AG98 -> 91 | C98: =+FEBRERO!$AG98 -> 94 | D98: =+MARZO!$AG98 -> 114 | E98: =+ABRIL!$AG98 -> 110 | F98: =+MAYO!$AG98 -> 79 | G98: =+JUNIO!$AG98 -> 95 | H98: =+JULIO!$AG98 -> 118 | I98: =+AGOSTO!$AG98 -> 131 | J98: =+SEPTIEMBRE!$AG98 -> 130 | K98: =+OCTUBRE!$AG98 -> 186 | L98: =+NOVIEMBRE!$AG98 -> 222 | M98: =+DICIEMBRE!$AG98 -> 37 | N98: =SUM(B98:M98) -> 1407
A99: 10 - 14 | B99: =+ENERO!$AG99 -> 114 | C99: =+FEBRERO!$AG99 -> 100 | D99: =+MARZO!$AG99 -> 137 | E99: =+ABRIL!$AG99 -> 106 | F99: =+MAYO!$AG99 -> 127 | G99: =+JUNIO!$AG99 -> 122 | H99: =+JULIO!$AG99 -> 149 | I99: =+AGOSTO!$AG99 -> 162 | J99: =+SEPTIEMBRE!$AG99 -> 129 | K99: =+OCTUBRE!$AG99 -> 156 | L99: =+NOVIEMBRE!$AG99 -> 163 | M99: =+DICIEMBRE!$AG99 -> 48 | N99: =SUM(B99:M99) -> 1513
A100: Mayor de 15 años | B100: =+ENERO!$AG100 -> 3815 | C100: =+FEBRERO!$AG100 -> 3887 | D100: =+MARZO!$AG100 -> 4097 | E100: =+ABRIL!$AG100 -> 3593 | F100: =+MAYO!$AG100 -> 4099 | G100: =+JUNIO!$AG100 -> 4036 | H100: =+JULIO!$AG100 -> 3969 | I100: =+AGOSTO!$AG100 -> 3941 | J100: =+SEPTIEMBRE!$AG100 -> 3436 | K100: =+OCTUBRE!$AG100 -> 3932 | L100: =+NOVIEMBRE!$AG100 -> 4266 | M100: =+DICIEMBRE!$AG100 -> 1132 | N100: =SUM(B100:M100) -> 44203
A101: 15 - 19 | B101: =+ENERO!$AG101 -> 221 | C101: =+FEBRERO!$AG101 -> 254 | D101: =+MARZO!$AG101 -> 286 | E101: =+ABRIL!$AG101 -> 246 | F101: =+MAYO!$AG101 -> 257 | G101: =+JUNIO!$AG101 -> 256 | H101: =+JULIO!$AG101 -> 261 | I101: =+AGOSTO!$AG101 -> 272 | J101: =+SEPTIEMBRE!$AG101 -> 196 | K101: =+OCTUBRE!$AG101 -> 218 | L101: =+NOVIEMBRE!$AG101 -> 264 | M101: =+DICIEMBRE!$AG101 -> 90 | N101: =SUM(B101:M101) -> 2821
A102: 20 - 24 | B102: =+ENERO!$AG102 -> 479 | C102: =+FEBRERO!$AG102 -> 422 | D102: =+MARZO!$AG102 -> 478 | E102: =+ABRIL!$AG102 -> 451 | F102: =+MAYO!$AG102 -> 495 | G102: =+JUNIO!$AG102 -> 527 | H102: =+JULIO!$AG102 -> 487 | I102: =+AGOSTO!$AG102 -> 447 | J102: =+SEPTIEMBRE!$AG102 -> 378 | K102: =+OCTUBRE!$AG102 -> 470 | L102: =+NOVIEMBRE!$AG102 -> 503 | M102: =+DICIEMBRE!$AG102 -> 120 | N102: =SUM(B102:M102) -> 5257
A103: 25 - 29 | B103: =+ENERO!$AG103 -> 434 | C103: =+FEBRERO!$AG103 -> 450 | D103: =+MARZO!$AG103 -> 483 | E103: =+ABRIL!$AG103 -> 472 | F103: =+MAYO!$AG103 -> 494 | G103: =+JUNIO!$AG103 -> 516 | H103: =+JULIO!$AG103 -> 472 | I103: =+AGOSTO!$AG103 -> 415 | J103: =+SEPTIEMBRE!$AG103 -> 388 | K103: =+OCTUBRE!$AG103 -> 370 | L103: =+NOVIEMBRE!$AG103 -> 506 | M103: =+DICIEMBRE!$AG103 -> 119 | N103: =SUM(B103:M103) -> 5119
A104: 30 - 34 | B104: =+ENERO!$AG104 -> 413 | C104: =+FEBRERO!$AG104 -> 378 | D104: =+MARZO!$AG104 -> 417 | E104: =+ABRIL!$AG104 -> 370 | F104: =+MAYO!$AG104 -> 455 | G104: =+JUNIO!$AG104 -> 462 | H104: =+JULIO!$AG104 -> 480 | I104: =+AGOSTO!$AG104 -> 351 | J104: =+SEPTIEMBRE!$AG104 -> 285 | K104: =+OCTUBRE!$AG104 -> 348 | L104: =+NOVIEMBRE!$AG104 -> 397 | M104: =+DICIEMBRE!$AG104 -> 111 | N104: =SUM(B104:M104) -> 4467
A105: 35 - 39 | B105: =+ENERO!$AG105 -> 306 | C105: =+FEBRERO!$AG105 -> 311 | D105: =+MARZO!$AG105 -> 384 | E105: =+ABRIL!$AG105 -> 339 | F105: =+MAYO!$AG105 -> 370 | G105: =+JUNIO!$AG105 -> 343 | H105: =+JULIO!$AG105 -> 332 | I105: =+AGOSTO!$AG105 -> 337 | J105: =+SEPTIEMBRE!$AG105 -> 260 | K105: =+OCTUBRE!$AG105 -> 311 | L105: =+NOVIEMBRE!$AG105 -> 363 | M105: =+DICIEMBRE!$AG105 -> 85 | N105: =SUM(B105:M105) -> 3741
... A114: 80 y mas | B114: =+ENERO!$AG114 -> 126 | C114: =+FEBRERO!$AG114 -> 158 | D114: =+MARZO!$AG114 -> 137 | E114: =+ABRIL!$AG114 -> 122 | F114: =+MAYO!$AG114 -> 135 | G114: =+JUNIO!$AG114 -> 137 | H114: =+JULIO!$AG114 -> 133 | I114: =+AGOSTO!$AG114 -> 143 | J114: =+SEPTIEMBRE!$AG114 -> 177 | K114: =+OCTUBRE!$AG114 -> 237 | L114: =+NOVIEMBRE!$AG114 -> 188 | M114: =+DICIEMBRE!$AG114 -> 53 | N114: =SUM(B114:M114) -> 1746
...

Sheet ENERO
A2: ENERO | B2: 1 | C2: =+B2+1 -> 2 | D2: =+C2+1 -> 3 | E2: =+D2+1 -> 4 | F2: =+E2+1 -> 5 | G2: =+F2+1 -> 6 | H2: =+G2+1 -> 7 | I2: =+H2+1 -> 8 | J2: =+I2+1 -> 9 | ... AA2: =+Z2+1 -> 26 | AB2: 27 | AC2: =+AB2+1 -> 28 | AD2: 29 | AE2: 30 | AF2: 31 | AG2: TOTAL
A3: Total de Inscritos | B3: =SUM(B4:B27) -> 123 | C3: =SUM(C4:C27) -> 143 | D3: =SUM(D4:D27) -> 148 | E3: =SUM(E4:E27) -> 140 | F3: =SUM(F4:F27) -> 133 | G3: =SUM(G4:G27) -> 119 | H3: =SUM(H4:H27) -> 139 | I3: =SUM(I4:I27) -> 122 | ... AF3: =SUM(AF4:AF27) -> 137 | AG3: =SUM(B3:AF3) -> 4381
A4: 08:00 | B4: 2 | C4: 5 | D4: 6 | E4: 6 | F4: 2 | G4: 1 | H4: 1 | I4: 3 | J4: 1 | K4: 2 | L4: 3 | M4: 2 | N4: 4 | O4: 5 | P4: 2 | Q4: 2 | R4: 4 | S4: 2 | T4: 7 | V4: 2 | W4: 4 | X4: 4 | Y4: 7 | Z4: 6 | AA4: 12 | AB4: 4 | AC4: 6 | AD4: 3 | AE4: 5 | AF4: 4 | AG4: =SUM(B4:AF4) -> 117
A5: 09:00 | B5: 2 | C5: 11 | D5: 3 | E5: 6 | F5: 2 | G5: 2 | H5: 1 | I5: 1 | J5: 4 | K5: 5 | L5: 5 | M5: 1 | N5: 3 | O5: 4 | Q5: 4 | R5: 5 | S5: 5 | T5: 6 | U5: 6 | V5: 5 | W5: 3 | X5: 6 | Y5: 3 | Z5: 2 | AA5: 8 | AB5: 7 | AC5: 5 | AD5: 3 | AE5: 6 | AF5: 5 | AG5: =SUM(B5:AF5) -> 129
A6: 10:00 | B6: 5 | C6: 12 | D6: 7 | E6: 2 | F6: 1 | G6: 3 | H6: 6 | I6: 4 | J6: 14 | K6: 8 | L6: 5 | M6: 2 | N6: 4 | O6: 2 | P6: 1 | Q6: 2 | R6: 6 | S6: 3 | T6: 5 | U6: 5 | V6: 2 | W6: 1 | X6: 8 | Y6: 5 | Z6: 11 | AA6: 13 | AB6: 11 | AC6: 8 | AD6: 5 | AE6: 14 | AF6: 11 | AG6: =SUM(B6:AF6) -> 186
A7: 11:00 | B7: 7 | C7: 4 | D7: 5 | E7: 4 | F7: 1 | G7: 2 | H7: 1 | I7: 5 | J7: 9 | K7: 8 | M7: 4 | N7: 5 | O7: 3 | P7: 4 | Q7: 10 | R7: 9 | S7: 4 | T7: 9 | U7: 9 | V7: 6 | W7: 3 | X7: 16 | Y7: 5 | Z7: 8 | AA7: 12 | AB7: 4 | AC7: 5 | AD7: 8 | AE7: 13 | AF7: 9 | AG7: =SUM(B7:AF7) -> 192
A8: 12:00 | B8: 9 | C8: 9 | D8: 13 | E8: 1 | F8: 4 | G8: 5 | H8: 8 | I8: 3 | J8: 7 | K8: 10 | L8: 8 | M8: 4 | N8: 3 | O8: 1 | P8: 2 | Q8: 13 | R8: 16 | S8: 5 | T8: 8 | U8: 7 | V8: 1 | W8: 5 | X8: 17 | Y8: 10 | Z8: 8 | AA8: 8 | AB8: 12 | AC8: 6 | AD8: 9 | AE8: 14 | AF8: 4 | AG8: =SUM(B8:AF8) -> 230
A9: 13:00 | B9: 13 | C9: 11 | D9: 13 | E9: 5 | F9: 2 | G9: 1 | H9: 5 | I9: 1 | J9: 7 | K9: 8 | L9: 3 | M9: 2 | N9: 8 | O9: 2 | P9: 5 | Q9: 7 | R9: 7 | S9: 13 | T9: 7 | U9: 4 | V9: 3 | W9: 3 | X9: 5 | Y9: 6 | Z9: 10 | AA9: 8 | AB9: 5 | AC9: 6 | AD9: 10 | AE9: 9 | AF9: 8 | AG9: =SUM(B9:AF9) -> 197
A10: 14:00 | B10: 7 | C10: 5 | D10: 4 | E10: 7 | F10: 4 | G10: 4 | H10: 1 | I10: 6 | J10: 6 | K10: 3 | L10: 2 | M10: 2 | N10: 6 | O10: 1 | P10: 4 | Q10: 6 | R10: 7 | S10: 6 | T10: 3 | V10: 9 | W10: 4 | X10: 5 | Y10: 7 | Z10: 13 | AA10: 17 | AB10: 2 | AC10: 11 | AD10: 4 | AE10: 7 | AF10: 7 | AG10: =SUM(B10:AF10) -> 170
A11: 15:00 | B11: 6 | C11: 11 | D11: 13 | F11: 4 | G11: 4 | H11: 7 | J11: 13 | K11: 7 | L11: 5 | M11: 3 | N11: 3 | O11: 4 | P11: 3 | Q11: 8 | R11: 18 | S11: 2 | T11: 5 | U11: 3 | V11: 3 | X11: 5 | Y11: 13 | Z11: 8 | AA11: 13 | AB11: 5 | AC11: 3 | AD11: 5 | AE11: 13 | AF11: 8 | AG11: =SUM(B11:AF11) -> 195
A12: 16:00 | B12: 7 | C12: 14 | D12: 14 | E12: 1 | F12: 2 | H12: 1 | I12: 5 | J12: 12 | K12: 16 | L12: 1 | M12: 6 | N12: 3 | O12: 2 | P12: 4 | Q12: 13 | R12: 23 | S12: 11 | T12: 12 | U12: 6 | V12: 7 | W12: 7 | X12: 6 | Y12: 10 | Z12: 16 | AA12: 9 | AB12: 13 | AC12: 11 | AD12: 14 | AE12: 9 | AF12: 16 | AG12: =SUM(B12:AF12) -> 271
A13: 17:00 | B13: 2 | C13: 9 | D13: 11 | E13: 39 | F13: 35 | G13: 34 | H13: 31 | I13: 33 | J13: 7 | K13: 16 | L13: 42 | M13: 24 | N13: 37 | O13: 38 | P13: 32 | Q13: 5 | R13: 10 | S13: 35 | T13: 25 | U13: 18 | V13: 32 | W13: 37 | X13: 15 | Y13: 6 | Z13: 11 | AA13: 21 | AB13: 34 | AC13: 31 | AD13: 14 | AE13: 8 | AF13: 17 | AG13: =SUM(B13:AF13) -> 709
A14: 18:00 | B14: 8 | C14: 12 | D14: 9 | E14: 7 | F14: 16 | G14: 10 | H14: 8 | I14: 14 | J14: 7 | K14: 12 | L14: 18 | M14: 15 | N14: 11 | O14: 10 | P14: 8 | Q14: 14 | R14: 6 | S14: 21 | T14: 15 | U14: 9 | V14: 7 | W14: 10 | X14: 7 | Y14: 9 | Z14: 19 | AA14: 19 | AB14: 18 | AC14: 27 | AD14: 11 | AE14: 14 | AF14: 11 | AG14: =SUM(B14:AF14) -> 382
A15: 19:00 | B15: 10 | C15: 13 | D15: 5 | E15: 15 | F15: 16 | G15: 12 | H15: 20 | I15: 12 | J15: 5 | K15: 9 | L15: 13 | M15: 10 | N15: 17 | O15: 17 | P15: 3 | Q15: 13 | R15: 12 | S15: 17 | T15: 12 | U15: 14 | V15: 8 | W15: 9 | X15: 5 | Y15: 9 | Z15: 18 | AA15: 14 | AB15: 9 | AC15: 11 | AD15: 9 | AE15: 5 | AF15: 6 | AG15: =SUM(B15:AF15) -> 348
A16: 20:00 | B16: 6 | C16: 2 | D16: 5 | E16: 7 | F16: 5 | G16: 5 | H16: 12 | I16: 9 | J16: 8 | K16: 7 | L16: 10 | M16: 10 | N16: 11 | O16: 6 | P16: 15 | Q16: 3 | R16: 6 | S16: 16 | T16: 7 | U16: 12 | V16: 6 | W16: 11 | X16: 5 | Y16: 10 | Z16: 11 | AA16: 9 | AB16: 10 | AC16: 3 | AD16: 9 | AE16: 13 | AF16: 11 | AG16: =SUM(B16:AF16) -> 260
A17: 21:00 | B17: 8 | C17: 6 | D17: 13 | E17: 14 | F17: 9 | G17: 7 | H17: 14 | I17: 7 | J17: 5 | K17: 13 | L17: 6 | M17: 10 | N17: 9 | O17: 7 | P17: 7 | Q17: 8 | R17: 8 | S17: 8 | T17: 9 | U17: 12 | V17: 14 | W17: 12 | X17: 7 | Y17: 13 | Z17: 14 | AA17: 8 | AB17: 6 | AC17: 12 | AD17: 8 | AE17: 9 | AF17: 4 | AG17: =SUM(B17:AF17) -> 287
A18: 22:00 | B18: 6 | C18: 5 | D18: 12 | E18: 11 | F18: 12 | G18: 12 | H18: 4 | I18: 5 | J18: 10 | K18: 5 | L18: 11 | M18: 10 | N18: 6 | O18: 2 | P18: 8 | Q18: 6 | R18: 4 | S18: 5 | T18: 5 | U18: 9 | V18: 12 | W18: 13 | X18: 6 | Y18: 4 | Z18: 7 | AA18: 7 | AB18: 12 | AC18: 3 | AD18: 2 | AE18: 6 | AF18: 3 | AG18: =SUM(B18:AF18) -> 223
A19: 23:00 | B19: 5 | D19: 5 | E19: 6 | F19: 5 | G19: 5 | H19: 1 | I19: 6 | J19: 3 | K19: 9 | L19: 4 | M19: 2 | N19: 6 | O19: 2 | P19: 1 | Q19: 4 | R19: 8 | S19: 6 | T19: 11 | U19: 8 | V19: 10 | W19: 10 | X19: 5 | Y19: 1 | Z19: 2 | AA19: 7 | AB19: 4 | AC19: 4 | AD19: 6 | AE19: 3 | AF19: 5 | AG19: =SUM(B19:AF19) -> 154
A20: 00:00 | B20: 8 | C20: 3 | D20: 3 | E20: 4 | F20: 6 | G20: 2 | H20: 8 | I20: 3 | J20: 1 | K20: 4 | L20: 2 | M20: 2 | N20: 4 | O20: 3 | P20: 2 | Q20: 5 | R20: 3 | S20: 4 | T20: 3 | U20: 5 | V20: 5 | W20: 3 | X20: 3 | Y20: 5 | Z20: 7 | AA20: 5 | AB20: 2 | AC20: 2 | AD20: 1 | AE20: 1 | AF20: 1 | AG20: =SUM(B20:AF20) -> 110
A21: 01:00 | B21: 6 | C21: 4 | D21: 1 | E21: 2 | G21: 5 | H21: 1 | I21: 1 | J21: 2 | K21: 2 | L21: 5 | M21: 1 | N21: 3 | P21: 3 | Q21: 4 | R21: 2 | S21: 2 | T21: 1 | U21: 2 | V21: 1 | W21: 1 | X21: 3 | Y21: 2 | Z21: 1 | AA21: 1 | AD21: 6 | AF21: 3 | AG21: =SUM(B21:AF21) -> 65
A22: 02:00 | B22: 3 | C22: 2 | E22: 1 | G22: 1 | H22: 2 | K22: 2 | O22: 1 | P22: 5 | R22: 1 | S22: 1 | U22: 2 | V22: 1 | W22: 4 | Y22: 2 | AE22: 3 | AF22: 1 | AG22: =SUM(B22:AF22) -> 32
A23: 03:00 | B23: 1 | D23: 1 | F23: 2 | I23: 1 | J23: 2 | K23: 1 | N23: 2 | S23: 1 | T23: 1 | V23: 2 | W23: 2 | X23: 1 | Y23: 1 | AB23: 3 | AD23: 2 | AE23: 2 | AF23: 1 | AG23: =SUM(B23:AF23) -> 26
A24: 04:00 | C24: 1 | F24: 1 | G24: 2 | H24: 1 | I24: 2 | J24: 1 | K24: 1 | L24: 1 | M24: 1 | N24: 2 | O24: 2 | P24: 1 | S24: 1 | U24: 1 | V24: 1 | Z24: 1 | AB24: 1 | AD24: 1 | AE24: 1 | AF24: 1 | AG24: =SUM(B24:AF24) -> 24
A25: 05:00 | C25: 2 | D25: 4 | F25: 3 | I25: 1 | L25: 1 | R25: 1 | T25: 1 | AE25: 3 | AG25: =SUM(B25:AF25) -> 16
A26: 06:00 | B26: 1 | C26: 1 | D26: 1 | F26: 1 | G26: 2 | H26: 5 | J26: 1 | K26: 1 | N26: 1 | O26: 2 | Q26: 1 | R26: 1 | U26: 2 | W26: 1 | X26: 3 | Y26: 1 | AA26: 2 | AB26: 2 | AD26: 1 | AE26: 4 | AF26: 1 | AG26: =SUM(B26:AF26) -> 35
A27: 07:00 | B27: 1 | C27: 1 | E27: 2 | H27: 1 | P27: 1 | R27: 2 | S27: 2 | T27: 1 | U27: 1 | W27: 2 | X27: 1 | Y27: 2 | AA27: 3 | AD27: 1 | AE27: 2 | AG27: =SUM(B27:AF27) -> 23
A28: Total de atendidos | B28: =SUM(B29:B52) -> 116 | C28: =SUM(C29:C52) -> 137 | D28: =SUM(D29:D52) -> 142 | E28: =SUM(E29:E52) -> 122 | F28: =SUM(F29:F52) -> 122 | G28: =SUM(G29:G52) -> 106 | H28: =SUM(H29:H52) -> 129 | I28: =SUM(I29:I52) -> 109 | ... AF28: =SUM(AF29:AF52) -> 131 | AG28: =SUM(B28:AF28) -> 4102
A29: 08:00 | B29: 2 | C29: 5 | D29: 3 | E29: 3 | F29: 2 | G29: 1 | H29: 1 | I29: 2 | K29: 1 | N29: 2 | O29: 3 | P29: 2 | Q29: 1 | R29: 3 | S29: 2 | T29: 1 | V29: 2 | W29: 1 | X29: 1 | Y29: 2 | AA29: 9 | AB29: 1 | AC29: 1 | AD29: 2 | AF29: 2 | AG29: =SUM(B29:AF29) -> 55
A30: 09:00 | B30: 1 | C30: 7 | D30: 5 | E30: 5 | F30: 2 | G30: 1 | H30: 1 | I30: 1 | J30: 4 | K30: 5 | L30: 4 | M30: 3 | N30: 2 | O30: 5 | Q30: 1 | R30: 1 | S30: 3 | T30: 8 | U30: 3 | V30: 1 | W30: 2 | X30: 4 | Y30: 5 | Z30: 4 | AA30: 10 | AB30: 6 | AC30: 5 | AD30: 2 | AE30: 6 | AF30: 4 | AG30: =SUM(B30:AF30) -> 111
A31: 10:00 | B31: 6 | C31: 9 | D31: 5 | E31: 4 | F31: 1 | G31: 2 | H31: 4 | I31: 2 | J31: 6 | K31: 9 | L31: 5 | N31: 3 | O31: 3 | Q31: 5 | R31: 9 | S31: 3 | T31: 4 | U31: 5 | V31: 4 | W31: 2 | X31: 8 | Y31: 4 | Z31: 4 | AA31: 6 | AB31: 7 | AC31: 6 | AD31: 5 | AE31: 8 | AF31: 10 | AG31: =SUM(B31:AF31) -> 149
A32: 11:00 | B32: 3 | C32: 7 | D32: 7 | E32: 3 | F32: 1 | G32: 4 | H32: 4 | I32: 3 | J32: 12 | K32: 2 | L32: 4 | M32: 3 | N32: 5 | O32: 2 | P32: 4 | Q32: 4 | R32: 5 | S32: 3 | T32: 8 | U32: 5 | V32: 4 | W32: 3 | X32: 9 | Y32: 6 | Z32: 6 | AA32: 10 | AB32: 10 | AC32: 6 | AD32: 6 | AE32: 14 | AF32: 10 | AG32: =SUM(B32:AF32) -> 173
A33: 12:00 | B33: 9 | C33: 9 | D33: 8 | E33: 5 | G33: 2 | H33: 4 | I33: 4 | J33: 7 | K33: 10 | L33: 1 | M33: 5 | N33: 2 | O33: 2 | P33: 2 | Q33: 10 | R33: 6 | S33: 6 | T33: 3 | U33: 10 | V33: 5 | W33: 4 | X33: 14 | Y33: 8 | Z33: 9 | AA33: 11 | AB33: 5 | AC33: 9 | AD33: 6 | AE33: 9 | AF33: 4 | AG33: =SUM(B33:AF33) -> 189
A34: 13:00 | B34: 7 | C34: 2 | D34: 12 | E34: 2 | F34: 3 | G34: 3 | H34: 7 | I34: 4 | J34: 5 | K34: 6 | L34: 4 | M34: 3 | N34: 3 | O34: 1 | P34: 3 | Q34: 12 | R34: 13 | S34: 4 | T34: 9 | U34: 4 | W34: 2 | X34: 10 | Y34: 2 | Z34: 6 | AA34: 8 | AB34: 5 | AC34: 1 | AD34: 7 | AE34: 8 | AF34: 3 | AG34: =SUM(B34:AF34) -> 159
A35: 14:00 | B35: 12 | C35: 11 | D35: 9 | E35: 3 | F35: 3 | G35: 3 | H35: 2 | I35: 2 | J35: 6 | K35: 7 | L35: 4 | M35: 2 | N35: 4 | O35: 2 | P35: 2 | Q35: 8 | R35: 9 | S35: 6 | T35: 8 | U35: 3 | V35: 4 | W35: 3 | X35: 8 | Y35: 6 | Z35: 7 | AA35: 13 | AB35: 9 | AC35: 6 | AD35: 9 | AE35: 12 | AF35: 8 | AG35: =SUM(B35:AF35) -> 191
A36: 15:00 | B36: 6 | C36: 8 | D36: 7 | E36: 6 | F36: 6 | G36: 3 | H36: 2 | I36: 3 | J36: 8 | K36: 4 | L36: 3 | M36: 3 | N36: 4 | O36: 3 | P36: 2 | Q36: 4 | R36: 12 | S36: 6 | T36: 3 | U36: 1 | V36: 5 | W36: 5 | X36: 6 | Y36: 11 | Z36: 7 | AA36: 13 | AB36: 5 | AC36: 9 | AD36: 5 | AE36: 9 | AF36: 12 | AG36: =SUM(B36:AF36) -> 181
A37: 16:00 | B37: 8 | C37: 9 | D37: 10 | E37: 3 | F37: 3 | G37: 3 | H37: 7 | I37: 2 | J37: 6 | K37: 14 | L37: 5 | M37: 3 | N37: 3 | O37: 8 | P37: 2 | Q37: 10 | R37: 15 | S37: 8 | T37: 5 | U37: 5 | V37: 3 | W37: 5 | X37: 8 | Y37: 15 | Z37: 11 | AA37: 11 | AB37: 9 | AC37: 7 | AD37: 6 | AE37: 12 | AF37: 11 | AG37: =SUM(B37:AF37) -> 227
A38: 17:00 | B38: 5 | C38: 4 | D38: 13 | E38: 7 | F38: 8 | G38: 6 | H38: 4 | I38: 9 | J38: 15 | K38: 16 | L38: 6 | M38: 6 | N38: 10 | O38: 17 | P38: 10 | Q38: 9 | R38: 19 | S38: 5 | T38: 12 | U38: 7 | V38: 8 | W38: 5 | X38: 10 | Y38: 9 | Z38: 9 | AA38: 10 | AB38: 8 | AC38: 12 | AD38: 9 | AE38: 12 | AF38: 15 | AG38: =SUM(B38:AF38) -> 295
A39: 18:00 | B39: 7 | C39: 13 | D39: 8 | E39: 8 | F39: 15 | G39: 11 | H39: 13 | I39: 9 | J39: 7 | K39: 13 | L39: 15 | M39: 13 | N39: 12 | O39: 17 | P39: 10 | Q39: 11 | R39: 3 | S39: 10 | T39: 17 | U39: 9 | V39: 17 | W39: 13 | X39: 9 | Y39: 3 | Z39: 16 | AA39: 17 | AB39: 20 | AC39: 16 | AD39: 11 | AE39: 13 | AF39: 12 | AG39: =SUM(B39:AF39) -> 368
A40: 19:00 | B40: 5 | C40: 10 | D40: 8 | E40: 10 | F40: 12 | G40: 8 | H40: 21 | I40: 13 | J40: 7 | K40: 9 | L40: 12 | M40: 17 | N40: 16 | O40: 15 | P40: 13 | Q40: 12 | R40: 12 | S40: 15 | T40: 20 | U40: 14 | V40: 20 | W40: 14 | X40: 8 | Y40: 13 | Z40: 17 | AA40: 17 | AB40: 24 | AC40: 25 | AD40: 17 | AE40: 9 | AF40: 9 | AG40: =SUM(B40:AF40) -> 422
A41: 20:00 | B41: 9 | C41: 15 | D41: 8 | E41: 8 | F41: 15 | G41: 9 | H41: 12 | I41: 15 | J41: 8 | K41: 11 | L41: 19 | M41: 13 | N41: 13 | O41: 15 | P41: 17 | Q41: 9 | R41: 9 | S41: 13 | T41: 14 | U41: 15 | V41: 6 | W41: 16 | X41: 5 | Y41: 9 | Z41: 25 | AA41: 17 | AB41: 14 | AC41: 19 | AD41: 10 | AE41: 7 | AF41: 7 | AG41: =SUM(B41:AF41) -> 382
...

Sheet FEBRERO
A2: FEBRERO | B2: 1 | C2: =+B2+1 -> 2 | D2: =+C2+1 -> 3 | E2: =+D2+1 -> 4 | F2: =+E2+1 -> 5 | G2: =+F2+1 -> 6 | H2: =+G2+1 -> 7 | I2: =+H2+1 -> 8 | J2: =+I2+1 -> 9 | ... AA2: =+Z2+1 -> 26 | AB2: 27 | AC2: =+AB2+1 -> 28 | AD2: 29 | AE2: 30 | AF2: 31 | AG2: TOTAL
A3: Total de Inscritos | B3: =SUM(B4:B27) -> 191 | C3: =SUM(C4:C27) -> 173 | D3: =SUM(D4:D27) -> 152 | E3: =SUM(E4:E27) -> 142 | F3: =SUM(F4:F27) -> 143 | G3: =SUM(G4:G27) -> 148 | H3: =SUM(H4:H27) -> 161 | I3: =SUM(I4:I27) -> 215 | ... AF3: =SUM(AF4:AF27) -> 0 | AG3: =SUM(B3:AF3) -> 4349
A4: 08:00 | B4: 7 | C4: 8 | D4: 8 | E4: 8 | F4: 5 | G4: 3 | H4: 2 | I4: 6 | J4: 5 | K4: 6 | L4: 6 | M4: 8 | N4: 5 | O4: 3 | P4: 3 | Q4: 4 | R4: 9 | S4: 1 | T4: 5 | U4: 2 | V4: 6 | W4: 5 | X4: 2 | Y4: 5 | Z4: 3 | AA4: 2 | AB4: 2 | AG4: =SUM(B4:AF4) -> 129
A5: 09:00 | B5: 12 | C5: 9 | D5: 2 | E5: 12 | F5: 9 | G5: 4 | H5: 4 | I5: 18 | J5: 11 | K5: 3 | L5: 8 | M5: 5 | N5: 6 | O5: 3 | P5: 5 | Q5: 7 | R5: 6 | S5: 7 | T5: 2 | U5: 9 | V5: 3 | W5: 5 | X5: 3 | Y5: 5 | Z5: 8 | AA5: 8 | AB5: 3 | AC5: 4 | AG5: =SUM(B5:AF5) -> 181
A6: 10:00 | B6: 10 | C6: 11 | D6: 8 | E6: 6 | F6: 5 | G6: 13 | H6: 9 | I6: 12 | J6: 6 | K6: 8 | L6: 8 | M6: 10 | N6: 10 | O6: 4 | P6: 4 | Q6: 9 | R6: 8 | S6: 10 | T6: 4 | U6: 7 | V6: 3 | W6: 5 | X6: 2 | Y6: 2 | Z6: 4 | AA6: 5 | AB6: 6 | AC6: 7 | AG6: =SUM(B6:AF6) -> 196
A7: 11:00 | B7: 8 | C7: 1 | D7: 5 | E7: 7 | F7: 4 | G7: 9 | H7: 10 | I7: 12 | J7: 8 | K7: 12 | L7: 6 | M7: 19 | N7: 8 | O7: 7 | P7: 11 | Q7: 6 | R7: 8 | S7: 11 | T7: 6 | U7: 11 | V7: 15 | W7: 9 | X7: 10 | Y7: 4 | Z7: 4 | AA7: 2 | AB7: 8 | AC7: 5 | AG7: =SUM(B7:AF7) -> 226
A8: 12:00 | B8: 10 | C8: 15 | D8: 7 | E8: 10 | F8: 7 | G8: 6 | H8: 11 | I8: 16 | J8: 9 | K8: 11 | L8: 2 | M8: 8 | N8: 10 | O8: 5 | P8: 12 | Q8: 8 | R8: 8 | S8: 8 | T8: 4 | U8: 9 | V8: 7 | W8: 6 | X8: 4 | Y8: 9 | Z8: 4 | AA8: 8 | AB8: 11 | AC8: 15 | AG8: =SUM(B8:AF8) -> 240
A9: 13:00 | B9: 2 | C9: 3 | D9: 8 | E9: 6 | F9: 2 | G9: 11 | H9: 10 | I9: 9 | J9: 3 | K9: 6 | L9: 9 | M9: 5 | N9: 11 | O9: 9 | P9: 9 | Q9: 8 | R9: 1 | S9: 4 | T9: 2 | U9: 9 | V9: 16 | W9: 3 | X9: 4 | Y9: 3 | Z9: 5 | AA9: 4 | AB9: 7 | AC9: 9 | AG9: =SUM(B9:AF9) -> 178
A10: 14:00 | B10: 4 | C10: 9 | D10: 10 | E10: 8 | F10: 6 | G10: 9 | H10: 8 | I10: 7 | J10: 8 | K10: 8 | L10: 7 | M10: 5 | N10: 12 | O10: 14 | P10: 7 | Q10: 8 | R10: 4 | S10: 14 | T10: 7 | U10: 14 | V10: 7 | W10: 2 | X10: 6 | Y10: 10 | Z10: 2 | AA10: 5 | AB10: 4 | AC10: 7 | AG10: =SUM(B10:AF10) -> 212
A11: 15:00 | B11: 8 | C11: 6 | D11: 10 | E11: 4 | F11: 6 | G11: 12 | H11: 10 | I11: 12 | J11: 7 | K11: 7 | L11: 16 | M11: 9 | N11: 11 | O11: 8 | P11: 10 | Q11: 5 | R11: 3 | S11: 10 | T11: 8 | U11: 8 | V11: 1 | W11: 3 | X11: 11 | Y11: 3 | Z11: 12 | AA11: 2 | AB11: 9 | AC11: 7 | AG11: =SUM(B11:AF11) -> 218
A12: 16:00 | B12: 25 | C12: 14 | D12: 10 | E12: 8 | F12: 11 | G12: 16 | H12: 13 | I12: 22 | J12: 12 | K12: 12 | L12: 13 | M12: 17 | N12: 7 | O12: 11 | P12: 18 | Q12: 10 | R12: 23 | S12: 19 | T12: 1 | U12: 6 | V12: 6 | W12: 12 | X12: 16 | Y12: 6 | Z12: 12 | AA12: 6 | AB12: 9 | AC12: 7 | AG12: =SUM(B12:AF12) -> 342
A13: 17:00 | B13: 20 | C13: 27 | D13: 22 | E13: 13 | F13: 21 | G13: 6 | H13: 12 | I13: 23 | J13: 18 | K13: 23 | L13: 25 | M13: 29 | N13: 12 | O13: 8 | P13: 25 | Q13: 26 | R13: 21 | S13: 23 | T13: 35 | U13: 9 | V13: 7 | W13: 23 | X13: 13 | Y13: 20 | Z13: 15 | AA13: 17 | AB13: 9 | AC13: 9 | AG13: =SUM(B13:AF13) -> 511
A14: 18:00 | B14: 20 | C14: 20 | D14: 8 | E14: 13 | F14: 17 | G14: 7 | H14: 14 | I14: 12 | J14: 15 | K14: 17 | L14: 20 | M14: 20 | N14: 8 | O14: 8 | P14: 14 | Q14: 16 | R14: 7 | S14: 11 | T14: 18 | U14: 12 | V14: 5 | W14: 14 | X14: 15 | Y14: 10 | Z14: 8 | AA14: 12 | AB14: 13 | AC14: 4 | AG14: =SUM(B14:AF14) -> 358
A15: 19:00 | B15: 9 | C15: 9 | D15: 6 | E15: 16 | F15: 11 | G15: 9 | H15: 4 | I15: 13 | J15: 14 | K15: 21 | L15: 11 | M15: 11 | N15: 8 | O15: 10 | P15: 13 | Q15: 10 | R15: 10 | S15: 14 | T15: 4 | U15: 7 | V15: 15 | W15: 13 | X15: 17 | Y15: 8 | Z15: 10 | AA15: 15 | AB15: 11 | AC15: 9 | AG15: =SUM(B15:AF15) -> 308
A16: 20:00 | B16: 12 | C16: 8 | D16: 4 | E16: 7 | F16: 8 | G16: 4 | H16: 6 | I16: 11 | J16: 15 | K16: 15 | L16: 8 | M16: 7 | N16: 12 | O16: 8 | P16: 9 | Q16: 16 | R16: 10 | S16: 7 | T16: 12 | U16: 7 | V16: 12 | W16: 14 | X16: 4 | Y16: 9 | Z16: 10 | AA16: 11 | AB16: 8 | AC16: 5 | AG16: =SUM(B16:AF16) -> 259
... A18: 22:00 | B18: 9 | C18: 6 | D18: 14 | E18: 10 | F18: 7 | G18: 6 | H18: 13 | I18: 8 | J18: 11 | K18: 7 | L18: 3 | M18: 7 | N18: 8 | O18: 7 | P18: 11 | Q18: 9 | R18: 10 | S18: 9 | T18: 5 | U18: 5 | V18: 7 | W18: 7 | X18: 5 | Y18: 12 | Z18: 12 | AA18: 7 | AB18: 12 | AC18: 14 | AG18: =SUM(B18:AF18) -> 241
A19: 23:00 | B19: 8 | C19: 6 | D19: 5 | E19: 6 | F19: 5 | G19: 4 | H19: 10 | I19: 6 | J19: 8 | K19: 6 | L19: 3 | N19: 5 | O19: 6 | P19: 5 | Q19: 9 | R19: 1 | S19: 6 | T19: 4 | U19: 5 | V19: 3 | W19: 4 | X19: 7 | Y19: 4 | Z19: 4 | AA19: 6 | AB19: 5 | AC19: 5 | AG19: =SUM(B19:AF19) -> 146
A20: 00:00 | C20: 1 | D20: 7 | F20: 1 | G20: 2 | H20: 4 | I20: 5 | J20: 3 | K20: 4 | L20: 5 | M20: 2 | O20: 4 | P20: 4 | Q20: 1 | R20: 5 | S20: 6 | T20: 2 | U20: 4 | V20: 2 | W20: 4 | X20: 5 | Y20: 4 | Z20: 3 | AA20: 4 | AB20: 7 | AC20: 3 | AG20: =SUM(B20:AF20) -> 92
A21: 01:00 | B21: 5 | C21: 0 | D21: 2 | F21: 3 | G21: 2 | H21: 3 | I21: 1 | J21: 2 | K21: 1 | N21: 3 | O21: 5 | P21: 2 | R21: 2 | S21: 1 | U21: 3 | W21: 1 | X21: 1 | Y21: 1 | Z21: 2 | AA21: 3 | AB21: 6 | AG21: =SUM(B21:AF21) -> 49
A22: 02:00 | B22: 3 | C22: 2 | F22: 3 | G22: 1 | H22: 2 | I22: 6 | J22: 1 | L22: 2 | N22: 1 | O22: 3 | P22: 1 | Q22: 2 | R22: 2 | T22: 1 | U22: 1 | W22: 1 | X22: 2 | Y22: 5 | Z22: 1 | AC22: 4 | AG22: =SUM(B22:AF22) -> 44
A23: 03:00 | B23: 2 | C23: 0 | D23: 1 | F23: 1 | G23: 1 | H23: 1 | J23: 1 | L23: 2 | M23: 1 | N23: 2 | O23: 2 | P23: 1 | Q23: 1 | R23: 2 | T23: 1 | U23: 1 | V23: 1 | W23: 1 | X23: 4 | AA23: 1 | AB23: 3 | AC23: 1 | AG23: =SUM(B23:AF23) -> 31
A24: 04:00 | B24: 1 | C24: 1 | G24: 2 | I24: 1 | J24: 1 | L24: 1 | M24: 1 | N24: 1 | O24: 2 | Q24: 1 | S24: 3 | T24: 5 | U24: 2 | V24: 2 | AB24: 2 | AC24: 2 | AG24: =SUM(B24:AF24) -> 28
A25: 05:00 | C25: 0 | D25: 1 | F25: 1 | H25: 2 | L25: 2 | M25: 1 | O25: 1 | Q25: 1 | V25: 1 | Z25: 2 | AA25: 3 | AG25: =SUM(B25:AF25) -> 15
A26: 06:00 | B26: 1 | C26: 2 | D26: 4 | F26: 3 | G26: 1 | H26: 1 | I26: 1 | J26: 2 | M26: 1 | N26: 1 | Q26: 4 | S26: 2 | T26: 1 | U26: 1 | W26: 2 | Y26: 2 | Z26: 1 | AG26: =SUM(B26:AF26) -> 30
A27: 07:00 | C27: 1 | D27: 1 | I27: 2 | J27: 1 | K27: 1 | L27: 2 | M27: 1 | N27: 1 | Q27: 2 | T27: 1 | W27: 1 | X27: 1 | AA27: 1 | AB27: 1 | AC27: 1 | AG27: =SUM(B27:AF27) -> 18
A28: Total de atendidos | B28: =SUM(B29:B52) -> 179 | C28: =SUM(C29:C52) -> 162 | D28: =SUM(D29:D52) -> 147 | E28: =SUM(E29:E52) -> 135 | F28: =SUM(F29:F52) -> 139 | G28: =SUM(G29:G52) -> 144 | H28: =SUM(H29:H52) -> 148 | I28: =SUM(I29:I52) -> 204 | ... AF28: =SUM(AF29:AF52) -> 0 | AG28: =SUM(B28:AF28) -> 4159
A29: 08:00 | B29: 3 | C29: 3 | D29: 8 | E29: 3 | F29: 5 | G29: 1 | H29: 1 | I29: 5 | J29: 1 | K29: 3 | L29: 4 | M29: 4 | O29: 2 | P29: 1 | Q29: 3 | R29: 4 | S29: 1 | T29: 1 | U29: 1 | V29: 2 | W29: 2 | X29: 1 | Y29: 5 | AA29: 1 | AB29: 1 | AG29: =SUM(B29:AF29) -> 66
A30: 09:00 | B30: 7 | C30: 7 | D30: 3 | E30: 8 | F30: 9 | G30: 2 | H30: 2 | I30: 9 | J30: 8 | K30: 3 | L30: 9 | M30: 7 | N30: 5 | O30: 2 | P30: 5 | Q30: 7 | R30: 7 | S30: 2 | T30: 5 | U30: 2 | V30: 4 | W30: 5 | X30: 5 | Y30: 4 | Z30: 6 | AA30: 3 | AB30: 2 | AC30: 4 | AG30: =SUM(B30:AF30) -> 142
A31: 10:00 | B31: 8 | C31: 5 | D31: 2 | E31: 9 | F31: 5 | G31: 10 | H31: 4 | I31: 9 | J31: 9 | K31: 9 | L31: 8 | M31: 8 | N31: 9 | O31: 5 | P31: 3 | Q31: 8 | R31: 7 | S31: 10 | T31: 4 | U31: 11 | V31: 5 | W31: 6 | Y31: 3 | Z31: 3 | AA31: 9 | AB31: 5 | AC31: 5 | AG31: =SUM(B31:AF31) -> 179
A32: 11:00 | B32: 6 | C32: 7 | D32: 7 | E32: 5 | F32: 3 | G32: 6 | H32: 8 | I32: 18 | J32: 6 | K32: 9 | L32: 5 | M32: 12 | N32: 10 | O32: 4 | P32: 9 | Q32: 6 | R32: 10 | S32: 5 | T32: 4 | U32: 8 | V32: 4 | W32: 7 | X32: 4 | Y32: 2 | Z32: 5 | AA32: 3 | AB32: 4 | AC32: 5 | AG32: =SUM(B32:AF32) -> 182
A33: 12:00 | B33: 8 | C33: 5 | D33: 6 | E33: 11 | F33: 6 | G33: 8 | H33: 8 | I33: 14 | J33: 10 | K33: 11 | L33: 4 | M33: 13 | N33: 7 | O33: 7 | P33: 10 | Q33: 9 | R33: 6 | S33: 14 | T33: 6 | U33: 6 | V33: 9 | W33: 5 | X33: 8 | Y33: 10 | Z33: 3 | AA33: 5 | AB33: 7 | AC33: 5 | AG33: =SUM(B33:AF33) -> 221
A34: 13:00 | B34: 3 | C34: 5 | D34: 10 | E34: 7 | F34: 1 | G34: 11 | H34: 9 | I34: 12 | J34: 4 | K34: 7 | L34: 7 | M34: 5 | N34: 8 | O34: 6 | P34: 8 | Q34: 7 | R34: 2 | S34: 7 | T34: 1 | U34: 6 | V34: 13 | W34: 8 | X34: 4 | Y34: 4 | Z34: 5 | AA34: 5 | AB34: 8 | AC34: 8 | AG34: =SUM(B34:AF34) -> 181
A35: 14:00 | B35: 7 | C35: 8 | D35: 3 | E35: 4 | F35: 6 | G35: 9 | H35: 9 | I35: 4 | J35: 5 | K35: 3 | L35: 5 | M35: 6 | N35: 10 | O35: 12 | P35: 12 | Q35: 3 | R35: 2 | S35: 8 | T35: 4 | U35: 10 | V35: 8 | W35: 1 | X35: 7 | Y35: 7 | Z35: 3 | AA35: 2 | AB35: 9 | AC35: 12 | AG35: =SUM(B35:AF35) -> 179
A36: 15:00 | B36: 7 | C36: 10 | D36: 14 | E36: 7 | F36: 6 | G36: 8 | H36: 7 | I36: 9 | J36: 8 | K36: 10 | L36: 12 | M36: 11 | N36: 13 | O36: 7 | P36: 7 | Q36: 9 | R36: 5 | S36: 9 | T36: 6 | U36: 11 | V36: 9 | W36: 3 | X36: 4 | Y36: 4 | Z36: 8 | AA36: 6 | AB36: 6 | AC36: 11 | AG36: =SUM(B36:AF36) -> 227
A37: 16:00 | B37: 10 | C37: 8 | D37: 8 | E37: 8 | F37: 11 | G37: 16 | H37: 4 | I37: 15 | J37: 7 | K37: 8 | L37: 10 | M37: 10 | N37: 12 | O37: 11 | P37: 13 | Q37: 6 | R37: 14 | S37: 6 | T37: 6 | U37: 10 | V37: 6 | W37: 6 | X37: 12 | Y37: 6 | Z37: 7 | AA37: 3 | AB37: 10 | AC37: 11 | AG37: =SUM(B37:AF37) -> 254
A38: 17:00 | B38: 10 | C38: 10 | D38: 8 | E38: 5 | F38: 21 | G38: 13 | H38: 13 | I38: 5 | J38: 7 | K38: 7 | L38: 11 | M38: 12 | N38: 11 | O38: 13 | P38: 4 | Q38: 9 | R38: 8 | S38: 6 | T38: 7 | U38: 12 | V38: 5 | W38: 7 | X38: 7 | Y38: 5 | Z38: 8 | AA38: 5 | AB38: 8 | AC38: 1 | AG38: =SUM(B38:AF38) -> 238
A39: 18:00 | B39: 17 | C39: 17 | D39: 16 | E39: 11 | F39: 17 | G39: 6 | H39: 7 | I39: 16 | J39: 13 | K39: 14 | L39: 17 | M39: 16 | N39: 8 | O39: 8 | P39: 11 | Q39: 21 | R39: 10 | S39: 18 | T39: 18 | U39: 13 | V39: 8 | W39: 16 | X39: 13 | Y39: 12 | Z39: 8 | AA39: 15 | AB39: 12 | AC39: 9 | AG39: =SUM(B39:AF39) -> 367
A40: 19:00 | B40: 26 | C40: 20 | D40: 10 | E40: 13 | F40: 11 | G40: 6 | H40: 14 | I40: 21 | J40: 17 | K40: 13 | L40: 14 | M40: 19 | N40: 9 | O40: 7 | P40: 13 | Q40: 15 | R40: 20 | S40: 20 | T40: 21 | U40: 9 | V40: 13 | W40: 17 | X40: 15 | Y40: 15 | Z40: 20 | AA40: 16 | AB40: 10 | AC40: 10 | AG40: =SUM(B40:AF40) -> 414
A41: 20:00 | B41: 17 | C41: 19 | D41: 8 | E41: 17 | F41: 7 | G41: 8 | H41: 12 | I41: 20 | J41: 23 | K41: 9 | L41: 13 | M41: 20 | N41: 7 | O41: 10 | P41: 19 | Q41: 20 | R41: 7 | S41: 25 | T41: 15 | U41: 8 | V41: 10 | W41: 12 | X41: 11 | Y41: 7 | Z41: 11 | AA41: 13 | AB41: 9 | AC41: 4 | AG41: =SUM(B41:AF41) -> 361
A42: 21:00 | B42: 10 | C42: 17 | D42: 7 | E42: 6 | F42: 7 | G42: 16 | H42: 10 | I42: 17 | J42: 11 | K42: 12 | L42: 14 | M42: 13 | N42: 13 | O42: 7 | P42: 19 | Q42: 14 | R42: 12 | S42: 4 | T42: 10 | U42: 10 | V42: 14 | W42: 12 | X42: 14 | Y42: 12 | Z42: 9 | AA42: 10 | AB42: 10 | AC42: 11 | AG42: =SUM(B42:AF42) -> 321
...

Sheet MARZO
A2: MARZO | B2: 1 | C2: =+B2+1 -> 2 | D2: =+C2+1 -> 3 | E2: =+D2+1 -> 4 | F2: =+E2+1 -> 5 | G2: =+F2+1 -> 6 | H2: =+G2+1 -> 7 | I2: =+H2+1 -> 8 | J2: =+I2+1 -> 9 | ... AA2: =+Z2+1 -> 26 | AB2: 27 | AC2: =+AB2+1 -> 28 | AD2: 29 | AE2: 30 | AF2: 31 | AG2: TOTAL
A3: Total de Inscritos | B3: =SUM(B4:B27) -> 177 | C3: =SUM(C4:C27) -> 126 | D3: =SUM(D4:D27) -> 157 | E3: =SUM(E4:E27) -> 142 | F3: =SUM(F4:F27) -> 126 | G3: =SUM(G4:G27) -> 156 | H3: =SUM(H4:H27) -> 165 | I3: =SUM(I4:I27) -> 155 | ... AF3: =SUM(AF4:AF27) -> 125 | AG3: =SUM(B3:AF3) -> 4712
A4: 08:00 | B4: 3 | C4: 2 | D4: 4 | E4: 1 | F4: 1 | G4: 4 | H4: 3 | I4: 4 | K4: 2 | L4: 1 | M4: 1 | N4: 4 | O4: 1 | P4: 4 | Q4: 2 | R4: 2 | S4: 6 | T4: 2 | U4: 4 | V4: 1 | W4: 5 | X4: 1 | Y4: 1 | Z4: 1 | AA4: 5 | AC4: 3 | AD4: 6 | AE4: 2 | AF4: 1 | AG4: =SUM(B4:AF4) -> 77
A5: 09:00 | B5: 6 | C5: 1 | D5: 3 | E5: 7 | F5: 3 | G5: 2 | H5: 4 | I5: 6 | J5: 6 | K5: 2 | L5: 3 | M5: 3 | N5: 4 | O5: 2 | P5: 6 | Q5: 7 | R5: 4 | S5: 4 | T5: 4 | U5: 10 | V5: 1 | W5: 7 | X5: 4 | Y5: 4 | Z5: 9 | AA5: 4 | AB5: 6 | AC5: 5 | AD5: 3 | AE5: 6 | AF5: 1 | AG5: =SUM(B5:AF5) -> 137
A6: 10:00 | B6: 6 | C6: 2 | D6: 2 | E6: 3 | F6: 3 | G6: 12 | H6: 16 | I6: 9 | J6: 4 | K6: 4 | L6: 5 | M6: 5 | N6: 5 | O6: 11 | P6: 5 | Q6: 5 | R6: 1 | S6: 9 | T6: 3 | U6: 10 | V6: 5 | W6: 10 | X6: 3 | Y6: 4 | Z6: 7 | AA6: 8 | AB6: 6 | AC6: 7 | AD6: 10 | AE6: 4 | AF6: 5 | AG6: =SUM(B6:AF6) -> 189
A7: 11:00 | B7: 5 | C7: 4 | D7: 2 | E7: 6 | F7: 2 | G7: 15 | H7: 11 | I7: 7 | J7: 6 | K7: 2 | L7: 1 | M7: 1 | N7: 10 | O7: 8 | P7: 3 | Q7: 6 | R7: 1 | S7: 2 | T7: 7 | U7: 14 | V7: 5 | W7: 9 | X7: 10 | Y7: 9 | Z7: 10 | AA7: 10 | AB7: 4 | AC7: 7 | AD7: 16 | AE7: 5 | AF7: 6 | AG7: =SUM(B7:AF7) -> 204
A8: 12:00 | B8: 7 | C8: 2 | D8: 7 | E8: 3 | F8: 2 | G8: 8 | H8: 14 | I8: 2 | J8: 3 | K8: 1 | L8: 10 | M8: 3 | N8: 13 | O8: 12 | P8: 5 | Q8: 9 | R8: 6 | S8: 9 | T8: 3 | U8: 12 | V8: 14 | W8: 9 | X8: 9 | Y8: 5 | Z8: 8 | AA8: 8 | AB8: 9 | AC8: 7 | AD8: 4 | AE8: 7 | AF8: 2 | AG8: =SUM(B8:AF8) -> 213
A9: 13:00 | B9: 2 | C9: 1 | D9: 2 | E9: 3 | F9: 3 | G9: 15 | H9: 4 | I9: 1 | J9: 3 | K9: 4 | L9: 1 | N9: 18 | O9: 15 | Q9: 4 | R9: 1 | T9: 1 | U9: 14 | V9: 10 | W9: 12 | X9: 3 | Z9: 8 | AA9: 7 | AB9: 11 | AC9: 11 | AD9: 3 | AE9: 12 | AF9: 4 | AG9: =SUM(B9:AF9) -> 173
A10: 14:00 | B10: 3 | C10: 2 | D10: 6 | E10: 3 | F10: 3 | G10: 6 | H10: 5 | I10: 7 | J10: 1 | L10: 6 | M10: 1 | N10: 5 | O10: 12 | P10: 4 | Q10: 6 | R10: 1 | S10: 6 | T10: 5 | U10: 15 | V10: 5 | W10: 2 | X10: 6 | Y10: 3 | AA10: 4 | AB10: 7 | AC10: 13 | AD10: 7 | AE10: 1 | AF10: 3 | AG10: =SUM(B10:AF10) -> 148
A11: 15:00 | B11: 3 | C11: 5 | D11: 8 | E11: 1 | G11: 12 | H11: 5 | I11: 5 | J11: 3 | K11: 5 | L11: 4 | M11: 3 | N11: 9 | O11: 15 | P11: 4 | Q11: 7 | R11: 4 | S11: 6 | T11: 5 | U11: 5 | V11: 16 | W11: 7 | X11: 6 | Y11: 4 | Z11: 4 | AA11: 4 | AB11: 4 | AC11: 18 | AD11: 10 | AE11: 7 | AF11: 2 | AG11: =SUM(B11:AF11) -> 191
A12: 16:00 | B12: 5 | C12: 3 | D12: 2 | E12: 4 | F12: 12 | G12: 8 | H12: 11 | I12: 4 | J12: 5 | K12: 8 | L12: 4 | M12: 3 | N12: 17 | O12: 12 | P12: 8 | Q12: 1 | R12: 6 | S12: 1 | T12: 6 | U12: 16 | V12: 15 | W12: 9 | X12: 10 | Y12: 8 | Z12: 10 | AA12: 9 | AB12: 10 | AC12: 19 | AD12: 4 | AE12: 7 | AF12: 9 | AG12: =SUM(B12:AF12) -> 246
A13: 17:00 | B13: 36 | C13: 30 | D13: 38 | E13: 32 | F13: 33 | G13: 18 | H13: 13 | I13: 36 | J13: 43 | K13: 43 | L13: 44 | M13: 41 | N13: 11 | O13: 17 | P13: 38 | Q13: 34 | R13: 49 | S13: 37 | T13: 29 | U13: 18 | V13: 13 | W13: 47 | X13: 34 | Y13: 33 | Z13: 45 | AA13: 44 | AB13: 10 | AC13: 11 | AD13: 32 | AE13: 32 | AF13: 29 | AG13: =SUM(B13:AF13) -> 970
A14: 18:00 | B14: 14 | C14: 14 | D14: 12 | E14: 14 | F14: 6 | G14: 4 | H14: 12 | I14: 13 | J14: 12 | K14: 18 | L14: 16 | M14: 25 | N14: 13 | O14: 7 | P14: 12 | Q14: 19 | R14: 10 | S14: 9 | T14: 13 | U14: 11 | V14: 9 | W14: 17 | X14: 18 | Y14: 17 | Z14: 12 | AA14: 20 | AB14: 9 | AC14: 6 | AD14: 19 | AE14: 4 | AF14: 14 | AG14: =SUM(B14:AF14) -> 399
A15: 19:00 | B15: 20 | C15: 17 | D15: 18 | E15: 11 | F15: 12 | G15: 6 | H15: 13 | I15: 13 | J15: 15 | K15: 13 | L15: 8 | M15: 12 | N15: 14 | O15: 10 | P15: 7 | Q15: 13 | R15: 14 | S15: 12 | T15: 5 | U15: 11 | V15: 5 | W15: 9 | X15: 13 | Y15: 11 | Z15: 10 | AA15: 7 | AB15: 6 | AC15: 15 | AD15: 16 | AE15: 6 | AF15: 14 | AG15: =SUM(B15:AF15) -> 356
A16: 20:00 | B16: 25 | C16: 18 | D16: 7 | E16: 13 | F16: 5 | G16: 10 | H16: 11 | I16: 13 | J16: 11 | K16: 12 | L16: 13 | M16: 10 | N16: 9 | O16: 13 | P16: 16 | Q16: 11 | R16: 10 | S16: 17 | T16: 8 | U16: 10 | V16: 8 | W16: 13 | X16: 9 | Y16: 8 | Z16: 10 | AA16: 13 | AB16: 5 | AC16: 10 | AD16: 8 | AE16: 7 | AF16: 10 | AG16: =SUM(B16:AF16) -> 343
A17: 21:00 | B17: 11 | C17: 6 | D17: 7 | E17: 12 | F17: 10 | G17: 6 | H17: 12 | I17: 10 | J17: 14 | K17: 13 | L17: 9 | M17: 16 | N17: 9 | O17: 14 | P17: 10 | Q17: 11 | R17: 13 | S17: 4 | T17: 8 | U17: 5 | V17: 12 | W17: 13 | X17: 8 | Y17: 19 | Z17: 5 | AA17: 5 | AB17: 4 | AC17: 8 | AD17: 14 | AE17: 9 | AF17: 9 | AG17: =SUM(B17:AF17) -> 306
A18: 22:00 | B18: 10 | C18: 8 | D18: 13 | E18: 14 | F18: 11 | G18: 11 | H18: 8 | I18: 13 | J18: 8 | K18: 2 | L18: 12 | M18: 6 | N18: 13 | O18: 5 | P18: 6 | Q18: 7 | R18: 6 | S18: 4 | T18: 6 | U18: 4 | V18: 13 | W18: 10 | X18: 12 | Y18: 7 | Z18: 6 | AA18: 7 | AB18: 7 | AC18: 5 | AD18: 6 | AE18: 2 | AF18: 4 | AG18: =SUM(B18:AF18) -> 246
A19: 23:00 | B19: 10 | C19: 2 | D19: 10 | E19: 3 | F19: 2 | G19: 7 | H19: 7 | I19: 3 | J19: 5 | K19: 12 | L19: 2 | M19: 8 | N19: 4 | O19: 2 | P19: 2 | Q19: 7 | R19: 11 | T19: 3 | U19: 2 | V19: 2 | W19: 5 | X19: 4 | Y19: 2 | Z19: 3 | AA19: 2 | AB19: 2 | AC19: 4 | AD19: 5 | AE19: 8 | AF19: 5 | AG19: =SUM(B19:AF19) -> 144
A20: 00:00 | B20: 5 | C20: 3 | D20: 3 | E20: 2 | F20: 1 | G20: 2 | H20: 3 | I20: 5 | J20: 3 | K20: 5 | L20: 11 | M20: 3 | N20: 4 | O20: 1 | P20: 5 | Q20: 3 | R20: 2 | T20: 6 | U20: 5 | V20: 2 | W20: 5 | X20: 6 | Y20: 3 | Z20: 8 | AA20: 5 | AB20: 5 | AC20: 3 | AD20: 2 | AE20: 1 | AF20: 1 | AG20: =SUM(B20:AF20) -> 113
A21: 01:00 | B21: 1 | C21: 2 | D21: 5 | E21: 4 | F21: 6 | G21: 4 | H21: 5 | I21: 1 | J21: 4 | K21: 1 | L21: 1 | M21: 1 | N21: 4 | O21: 1 | P21: 4 | Q21: 5 | R21: 4 | S21: 1 | T21: 3 | U21: 1 | V21: 7 | W21: 1 | X21: 3 | Y21: 1 | AC21: 5 | AD21: 4 | AF21: 2 | AG21: =SUM(B21:AF21) -> 81
A22: 02:00 | B22: 1 | C22: 1 | D22: 1 | E22: 4 | F22: 5 | G22: 3 | H22: 3 | J22: 2 | K22: 1 | L22: 2 | M22: 1 | N22: 2 | R22: 1 | T22: 3 | U22: 2 | V22: 1 | W22: 2 | Y22: 2 | AA22: 2 | AB22: 3 | AC22: 2 | AD22: 1 | AE22: 1 | AF22: 2 | AG22: =SUM(B22:AF22) -> 48
A23: 03:00 | B23: 1 | C23: 1 | D23: 3 | F23: 4 | G23: 1 | H23: 1 | J23: 2 | K23: 2 | M23: 1 | O23: 1 | P23: 4 | Q23: 1 | R23: 1 | T23: 1 | U23: 3 | V23: 3 | W23: 4 | Y23: 1 | AA23: 2 | AB23: 2 | AG23: =SUM(B23:AF23) -> 39
A24: 04:00 | D24: 3 | E24: 1 | I24: 1 | J24: 2 | M24: 2 | O24: 1 | P24: 2 | T24: 2 | X24: 1 | Y24: 1 | AB24: 1 | AG24: =SUM(B24:AF24) -> 17
A25: 05:00 | B25: 2 | E25: 1 | H25: 1 | I25: 2 | J25: 2 | L25: 1 | M25: 2 | N25: 4 | O25: 1 | R25: 1 | S25: 1 | T25: 1 | X25: 1 | AA25: 1 | AB25: 1 | AC25: 3 | AF25: 2 | AG25: =SUM(B25:AF25) -> 27
A26: 06:00 | B26: 1 | C26: 1 | D26: 1 | F26: 1 | H26: 3 | K26: 4 | O26: 2 | P26: 1 | Q26: 1 | U26: 1 | W26: 1 | X26: 1 | Z26: 1 | AC26: 2 | AG26: =SUM(B26:AF26) -> 21
A27: 07:00 | C27: 1 | F27: 1 | G27: 2 | K27: 1 | L27: 2 | M27: 1 | P27: 2 | W27: 2 | Z27: 3 | AA27: 3 | AB27: 3 | AC27: 1 | AD27: 1 | AE27: 1 | AG27: =SUM(B27:AF27) -> 24
A28: Total de atendidos | B28: =SUM(B29:B52) -> 160 | C28: =SUM(C29:C52) -> 118 | D28: =SUM(D29:D52) -> 151 | E28: =SUM(E29:E52) -> 130 | F28: =SUM(F29:F52) -> 124 | G28: =SUM(G29:G52) -> 149 | H28: =SUM(H29:H52) -> 158 | I28: =SUM(I29:I52) -> 150 | ... AF28: =SUM(AF29:AF52) -> 119 | AG28: =SUM(B28:AF28) -> 4448
A29: 08:00 | C29: 1 | D29: 3 | E29: 1 | I29: 2 | K29: 1 | L29: 2 | M29: 1 | N29: 1 | P29: 1 | R29: 1 | S29: 3 | T29: 2 | U29: 1 | V29: 1 | W29: 2 | X29: 1 | AA29: 2 | AB29: 1 | AC29: 1 | AD29: 4 | AE29: 1 | AF29: 1 | AG29: =SUM(B29:AF29) -> 34
A30: 09:00 | B30: 5 | C30: 1 | D30: 3 | E30: 2 | F30: 4 | G30: 5 | H30: 6 | I30: 6 | J30: 3 | K30: 3 | L30: 3 | M30: 4 | N30: 4 | O30: 2 | P30: 5 | Q30: 8 | R30: 3 | S30: 5 | T30: 3 | U30: 7 | V30: 1 | W30: 7 | X30: 2 | Y30: 4 | Z30: 8 | AA30: 5 | AB30: 1 | AC30: 5 | AD30: 4 | AE30: 6 | AG30: =SUM(B30:AF30) -> 125
A31: 10:00 | B31: 8 | C31: 3 | D31: 1 | E31: 7 | F31: 2 | H31: 9 | I31: 3 | J31: 3 | K31: 2 | L31: 5 | M31: 4 | N31: 5 | O31: 6 | P31: 5 | Q31: 3 | R31: 2 | S31: 7 | T31: 4 | U31: 7 | V31: 1 | W31: 4 | X31: 6 | Y31: 4 | Z31: 5 | AA31: 3 | AB31: 6 | AC31: 5 | AD31: 7 | AE31: 4 | AF31: 4 | AG31: =SUM(B31:AF31) -> 135
A32: 11:00 | B32: 4 | C32: 1 | D32: 2 | E32: 4 | F32: 3 | G32: 7 | H32: 10 | I32: 8 | J32: 5 | K32: 3 | L32: 2 | M32: 2 | N32: 6 | O32: 10 | P32: 6 | Q32: 6 | R32: 1 | S32: 6 | T32: 2 | U32: 12 | V32: 5 | W32: 7 | X32: 3 | Y32: 3 | Z32: 7 | AA32: 6 | AB32: 8 | AC32: 7 | AD32: 8 | AE32: 4 | AF32: 6 | AG32: =SUM(B32:AF32) -> 164
A33: 12:00 | B33: 5 | C33: 3 | D33: 3 | E33: 6 | G33: 11 | H33: 11 | I33: 7 | J33: 6 | K33: 2 | L33: 6 | M33: 3 | N33: 12 | O33: 8 | P33: 4 | Q33: 6 | R33: 3 | S33: 4 | T33: 7 | U33: 10 | V33: 8 | W33: 7 | X33: 7 | Y33: 6 | Z33: 9 | AA33: 5 | AB33: 5 | AC33: 9 | AD33: 8 | AE33: 6 | AF33: 3 | AG33: =SUM(B33:AF33) -> 190
A34: 13:00 | B34: 4 | C34: 2 | D34: 6 | E34: 2 | F34: 4 | G34: 10 | H34: 9 | I34: 1 | J34: 1 | K34: 2 | L34: 5 | N34: 12 | O34: 14 | P34: 2 | Q34: 5 | R34: 5 | S34: 5 | T34: 1 | U34: 12 | V34: 10 | W34: 5 | X34: 7 | Y34: 3 | Z34: 7 | AA34: 2 | AB34: 13 | AC34: 2 | AD34: 5 | AE34: 5 | AF34: 2 | AG34: =SUM(B34:AF34) -> 163
A35: 14:00 | B35: 3 | C35: 3 | D35: 4 | E35: 2 | F35: 4 | G35: 12 | H35: 8 | I35: 5 | J35: 3 | K35: 2 | L35: 3 | M35: 1 | N35: 12 | O35: 12 | P35: 2 | Q35: 3 | S35: 1 | T35: 4 | U35: 9 | V35: 6 | W35: 3 | X35: 6 | Y35: 4 | Z35: 5 | AA35: 7 | AB35: 5 | AC35: 9 | AD35: 7 | AE35: 5 | AF35: 5 | AG35: =SUM(B35:AF35) -> 155
A36: 15:00 | B36: 6 | C36: 2 | D36: 8 | E36: 2 | G36: 8 | H36: 4 | I36: 5 | J36: 4 | K36: 3 | L36: 4 | M36: 1 | N36: 10 | O36: 14 | P36: 6 | Q36: 7 | R36: 4 | S36: 8 | T36: 5 | U36: 13 | V36: 13 | W36: 6 | X36: 7 | Y36: 4 | Z36: 2 | AA36: 7 | AB36: 8 | AC36: 12 | AD36: 7 | AE36: 7 | AF36: 2 | AG36: =SUM(B36:AF36) -> 189
A37: 16:00 | B37: 2 | C37: 5 | D37: 5 | E37: 2 | F37: 5 | G37: 14 | H37: 8 | I37: 6 | J37: 1 | K37: 6 | L37: 6 | M37: 4 | N37: 12 | O37: 12 | P37: 4 | Q37: 5 | R37: 5 | S37: 4 | T37: 2 | U37: 13 | V37: 14 | W37: 9 | X37: 5 | Y37: 3 | Z37: 9 | AA37: 9 | AB37: 7 | AC37: 13 | AD37: 7 | AE37: 9 | AF37: 6 | AG37: =SUM(B37:AF37) -> 212
A38: 17:00 | B38: 6 | C38: 5 | D38: 8 | E38: 4 | F38: 4 | G38: 11 | H38: 13 | I38: 4 | J38: 8 | K38: 6 | L38: 5 | M38: 9 | N38: 15 | O38: 14 | P38: 8 | Q38: 7 | R38: 6 | S38: 8 | T38: 8 | U38: 18 | V38: 15 | W38: 8 | X38: 7 | Y38: 8 | Z38: 13 | AA38: 9 | AB38: 7 | AC38: 14 | AD38: 9 | AE38: 10 | AF38: 7 | AG38: =SUM(B38:AF38) -> 274
A39: 18:00 | B39: 11 | C39: 13 | D39: 19 | E39: 13 | F39: 14 | G39: 14 | H39: 10 | I39: 13 | J39: 14 | K39: 20 | L39: 10 | M39: 14 | N39: 13 | O39: 14 | P39: 14 | Q39: 22 | R39: 14 | S39: 10 | T39: 17 | U39: 16 | V39: 13 | W39: 16 | X39: 16 | Y39: 12 | Z39: 14 | AA39: 17 | AB39: 12 | AC39: 16 | AD39: 18 | AE39: 14 | AF39: 13 | AG39: =SUM(B39:AF39) -> 446
A40: 19:00 | B40: 18 | C40: 19 | D40: 16 | E40: 16 | F40: 12 | G40: 9 | H40: 12 | I40: 18 | J40: 21 | K40: 20 | L40: 22 | M40: 17 | N40: 10 | O40: 8 | P40: 17 | Q40: 20 | R40: 18 | S40: 18 | T40: 20 | U40: 9 | V40: 8 | W40: 23 | X40: 20 | Y40: 21 | Z40: 23 | AA40: 17 | AB40: 7 | AC40: 15 | AD40: 23 | AE40: 16 | AF40: 19 | AG40: =SUM(B40:AF40) -> 512
A41: 20:00 | B41: 21 | C41: 18 | D41: 17 | E41: 18 | F41: 18 | G41: 8 | H41: 9 | I41: 20 | J41: 12 | K41: 20 | L41: 23 | M41: 23 | N41: 10 | O41: 12 | P41: 12 | Q41: 19 | R41: 23 | S41: 19 | T41: 8 | U41: 12 | V41: 8 | W41: 17 | X41: 11 | Y41: 14 | Z41: 19 | AA41: 21 | AB41: 7 | AC41: 15 | AD41: 10 | AE41: 7 | AF41: 17 | AG41: =SUM(B41:AF41) -> 468
...

Sheet ABRIL
A2: ABRIL | B2: 1 | C2: =+B2+1 -> 2 | D2: =+C2+1 -> 3 | E2: =+D2+1 -> 4 | F2: =+E2+1 -> 5 | G2: =+F2+1 -> 6 | H2: =+G2+1 -> 7 | I2: =+H2+1 -> 8 | J2: =+I2+1 -> 9 | ... AA2: =+Z2+1 -> 26 | AB2: 27 | AC2: =+AB2+1 -> 28 | AD2: 29 | AE2: 30 | AF2: 31 | AG2: TOTAL
A3: Total de Inscritos | B3: =SUM(B4:B27) -> 126 | C3: =SUM(C4:C27) -> 159 | D3: =SUM(D4:D27) -> 137 | E3: =SUM(E4:E27) -> 132 | F3: =SUM(F4:F27) -> 156 | G3: =SUM(G4:G27) -> 131 | H3: =SUM(H4:H27) -> 137 | I3: =SUM(I4:I27) -> 126 | ... AF3: =SUM(AF4:AF27) -> 0 | AG3: =SUM(B3:AF3) -> 4111
A4: 08:00 | B4: 1 | C4: 2 | E4: 8 | F4: 4 | G4: 3 | H4: 5 | I4: 3 | K4: 5 | L4: 5 | M4: 8 | N4: 5 | O4: 3 | P4: 2 | Q4: 5 | R4: 4 | S4: 3 | T4: 6 | U4: 4 | V4: 1 | W4: 4 | X4: 1 | Y4: 4 | Z4: 2 | AA4: 2 | AB4: 3 | AC4: 7 | AD4: 1 | AE4: 1 | AG4: =SUM(B4:AF4) -> 102
A5: 09:00 | C5: 5 | D5: 3 | E5: 13 | F5: 4 | G5: 2 | H5: 5 | I5: 4 | J5: 7 | K5: 9 | L5: 8 | M5: 4 | N5: 3 | O5: 3 | P5: 2 | Q5: 5 | R5: 12 | S5: 7 | T5: 6 | U5: 3 | V5: 4 | W5: 1 | X5: 4 | Y5: 5 | Z5: 10 | AA5: 4 | AB5: 1 | AC5: 5 | AD5: 4 | AE5: 1 | AG5: =SUM(B5:AF5) -> 144
A6: 10:00 | B6: 4 | C6: 7 | D6: 13 | E6: 7 | F6: 7 | G6: 2 | H6: 6 | I6: 6 | J6: 2 | K6: 6 | L6: 6 | M6: 8 | N6: 1 | O6: 3 | P6: 7 | Q6: 4 | R6: 7 | S6: 7 | T6: 11 | U6: 7 | V6: 6 | W6: 5 | X6: 3 | Y6: 5 | Z6: 7 | AA6: 5 | AB6: 3 | AC6: 4 | AD6: 9 | AE6: 1 | AG6: =SUM(B6:AF6) -> 169
A7: 11:00 | B7: 9 | C7: 8 | D7: 11 | E7: 8 | F7: 4 | G7: 6 | H7: 8 | I7: 7 | J7: 4 | K7: 8 | L7: 13 | M7: 11 | N7: 7 | O7: 3 | P7: 7 | Q7: 8 | R7: 13 | S7: 8 | T7: 10 | U7: 6 | V7: 3 | W7: 2 | X7: 6 | Y7: 8 | Z7: 9 | AA7: 7 | AB7: 6 | AC7: 3 | AD7: 7 | AE7: 2 | AG7: =SUM(B7:AF7) -> 212
A8: 12:00 | B8: 5 | C8: 9 | D8: 7 | E8: 6 | F8: 6 | G8: 4 | H8: 4 | I8: 4 | J8: 1 | K8: 10 | L8: 15 | M8: 11 | N8: 10 | O8: 4 | P8: 10 | Q8: 3 | R8: 13 | S8: 9 | T8: 8 | U8: 4 | V8: 3 | W8: 5 | X8: 4 | Y8: 13 | Z8: 15 | AA8: 6 | AB8: 7 | AC8: 6 | AD8: 3 | AE8: 3 | AG8: =SUM(B8:AF8) -> 208
A9: 13:00 | B9: 8 | C9: 12 | D9: 17 | E9: 16 | F9: 10 | G9: 7 | H9: 6 | I9: 6 | J9: 5 | K9: 9 | L9: 6 | M9: 4 | N9: 5 | O9: 7 | P9: 3 | Q9: 3 | R9: 9 | S9: 12 | T9: 5 | U9: 5 | V9: 4 | W9: 3 | X9: 12 | Y9: 2 | Z9: 8 | AA9: 2 | AB9: 1 | AD9: 5 | AE9: 4 | AG9: =SUM(B9:AF9) -> 196
A10: 14:00 | C10: 10 | D10: 8 | E10: 11 | F10: 5 | H10: 5 | I10: 3 | J10: 8 | K10: 18 | L10: 5 | M10: 5 | N10: 10 | O10: 6 | P10: 1 | Q10: 5 | R10: 9 | S10: 4 | T10: 2 | U10: 8 | V10: 8 | W10: 5 | X10: 9 | Y10: 10 | Z10: 11 | AA10: 8 | AB10: 1 | AC10: 2 | AD10: 4 | AE10: 6 | AG10: =SUM(B10:AF10) -> 187
A11: 15:00 | B11: 2 | C11: 12 | D11: 6 | E11: 15 | F11: 3 | G11: 8 | H11: 6 | I11: 3 | J11: 4 | K11: 7 | L11: 11 | M11: 5 | N11: 6 | O11: 7 | P11: 9 | Q11: 3 | R11: 7 | S11: 18 | T11: 7 | U11: 5 | V11: 3 | W11: 3 | X11: 2 | Y11: 7 | Z11: 9 | AA11: 5 | AB11: 7 | AC11: 8 | AD11: 4 | AE11: 5 | AG11: =SUM(B11:AF11) -> 197
A12: 16:00 | B12: 2 | C12: 15 | D12: 8 | E12: 7 | F12: 5 | G12: 7 | H12: 4 | I12: 12 | J12: 9 | K12: 12 | L12: 11 | M12: 8 | N12: 14 | O12: 10 | P12: 5 | Q12: 6 | R12: 9 | S12: 9 | T12: 11 | U12: 7 | V12: 3 | W12: 3 | X12: 11 | Y12: 8 | Z12: 6 | AA12: 2 | AB12: 8 | AC12: 2 | AD12: 8 | AE12: 10 | AG12: =SUM(B12:AF12) -> 232
A13: 17:00 | B13: 31 | C13: 11 | D13: 4 | E13: 9 | F13: 45 | G13: 38 | H13: 30 | I13: 33 | J13: 36 | K13: 16 | L13: 5 | M13: 28 | N13: 38 | O13: 34 | P13: 36 | Q13: 40 | R13: 10 | S13: 9 | T13: 35 | U13: 24 | V13: 28 | W13: 34 | X13: 27 | Y13: 12 | Z13: 9 | AA13: 41 | AB13: 35 | AC13: 33 | AD13: 40 | AE13: 13 | AG13: =SUM(B13:AF13) -> 784
A14: 18:00 | B14: 13 | C14: 18 | D14: 10 | E14: 5 | F14: 13 | G14: 14 | H14: 18 | I14: 6 | J14: 9 | K14: 11 | L14: 12 | M14: 14 | N14: 15 | O14: 24 | P14: 4 | Q14: 14 | R14: 11 | S14: 10 | T14: 20 | U14: 12 | V14: 12 | W14: 19 | X14: 17 | Y14: 15 | Z14: 11 | AA14: 20 | AB14: 13 | AC14: 12 | AD14: 13 | AE14: 9 | AG14: =SUM(B14:AF14) -> 394
A15: 19:00 | B15: 8 | C15: 10 | D15: 11 | E15: 5 | F15: 11 | G15: 12 | H15: 16 | I15: 9 | J15: 9 | K15: 7 | L15: 10 | M15: 15 | N15: 17 | O15: 13 | P15: 9 | Q15: 5 | R15: 9 | S15: 9 | T15: 17 | U15: 9 | V15: 6 | W15: 3 | X15: 7 | Y15: 12 | Z15: 9 | AA15: 9 | AB15: 10 | AC15: 16 | AD15: 8 | AE15: 10 | AG15: =SUM(B15:AF15) -> 301
A16: 20:00 | B16: 13 | C16: 5 | D16: 13 | E16: 3 | F16: 13 | G16: 7 | H16: 3 | I16: 9 | J16: 10 | K16: 9 | L16: 6 | M16: 9 | N16: 11 | O16: 8 | P16: 8 | Q16: 15 | R16: 3 | S16: 12 | T16: 8 | U16: 8 | V16: 7 | W16: 10 | X16: 4 | Y16: 8 | Z16: 5 | AA16: 7 | AB16: 5 | AC16: 15 | AD16: 8 | AE16: 9 | AG16: =SUM(B16:AF16) -> 251
A17: 21:00 | B17: 5 | C17: 5 | D17: 8 | E17: 3 | F17: 9 | G17: 2 | H17: 9 | I17: 6 | J17: 11 | K17: 10 | L17: 12 | M17: 5 | N17: 5 | O17: 7 | P17: 12 | Q17: 8 | R17: 3 | S17: 7 | T17: 10 | U17: 3 | V17: 5 | W17: 5 | X17: 10 | Y17: 3 | Z17: 4 | AA17: 10 | AB17: 2 | AC17: 11 | AD17: 7 | AE17: 4 | AG17: =SUM(B17:AF17) -> 201
A18: 22:00 | B18: 5 | C18: 7 | D18: 9 | E18: 4 | F18: 5 | G18: 3 | H18: 3 | I18: 3 | J18: 5 | K18: 3 | L18: 5 | M18: 4 | N18: 4 | O18: 6 | P18: 9 | Q18: 6 | R18: 3 | S18: 2 | T18: 5 | U18: 6 | V18: 2 | W18: 3 | X18: 3 | Y18: 2 | Z18: 4 | AA18: 8 | AB18: 4 | AC18: 3 | AD18: 3 | AG18: =SUM(B18:AF18) -> 129
A19: 23:00 | B19: 6 | C19: 3 | D19: 4 | E19: 4 | F19: 3 | G19: 3 | H19: 4 | I19: 4 | J19: 5 | K19: 2 | L19: 3 | M19: 3 | N19: 5 | O19: 5 | P19: 8 | Q19: 10 | R19: 2 | S19: 2 | T19: 3 | U19: 5 | V19: 1 | W19: 5 | X19: 2 | Z19: 8 | AA19: 4 | AB19: 1 | AC19: 2 | AD19: 3 | AE19: 2 | AG19: =SUM(B19:AF19) -> 112
A20: 00:00 | B20: 4 | C20: 5 | E20: 1 | F20: 3 | G20: 2 | H20: 1 | I20: 2 | J20: 2 | K20: 1 | L20: 3 | M20: 4 | N20: 5 | O20: 4 | P20: 3 | Q20: 3 | R20: 1 | S20: 2 | T20: 1 | U20: 8 | V20: 1 | W20: 1 | X20: 2 | Y20: 5 | Z20: 10 | AA20: 1 | AB20: 2 | AC20: 1 | AD20: 2 | AE20: 2 | AG20: =SUM(B20:AF20) -> 82
A21: 01:00 | B21: 2 | C21: 4 | E21: 2 | G21: 2 | H21: 1 | I21: 2 | K21: 4 | L21: 2 | M21: 3 | N21: 1 | O21: 3 | P21: 3 | Q21: 3 | R21: 1 | T21: 2 | U21: 2 | X21: 4 | Z21: 1 | AA21: 4 | AC21: 2 | AD21: 1 | AE21: 3 | AG21: =SUM(B21:AF21) -> 52
A22: 02:00 | B22: 2 | C22: 3 | D22: 2 | F22: 2 | G22: 2 | I22: 1 | J22: 1 | K22: 3 | L22: 1 | M22: 2 | N22: 2 | P22: 3 | Q22: 2 | U22: 2 | Y22: 1 | Z22: 2 | AA22: 2 | AD22: 1 | AG22: =SUM(B22:AF22) -> 34
A23: 03:00 | B23: 2 | C23: 1 | G23: 2 | I23: 1 | J23: 5 | K23: 1 | N23: 2 | O23: 1 | R23: 2 | S23: 1 | U23: 1 | V23: 1 | W23: 1 | X23: 1 | Z23: 2 | AB23: 2 | AC23: 1 | AD23: 3 | AE23: 1 | AG23: =SUM(B23:AF23) -> 31
A24: 04:00 | C24: 2 | E24: 1 | G24: 3 | K24: 1 | O24: 1 | P24: 1 | Q24: 4 | V24: 1 | AA24: 1 | AE24: 1 | AG24: =SUM(B24:AF24) -> 16
