Workbook

Sheet CONSOLIDADO
A2: MES | B2: ENERO | C2: FEBRERO | D2: MARZO | E2: ABRIL | F2: MAYO | G2: JUNIO | H2: JULIO | I2: AGOSTO | J2: SEPTIEMBRE | K2: OCTUBRE | L2: NOVIEMBRE | M2: DICIEMBRE | N2: TOTAL
A3: Total de Inscritos | B3: =+ENERO!$AG3 -> 6791 | C3: =+FEBRERO!$AG3 -> 5643 | D3: =+MARZO!$AG3 -> 8086 | E3: =+ABRIL!$AG3 -> 7514 | F3: =+MAYO!$AG3 -> 8107 | G3: =+JUNIO!$AG3 -> 5854 | H3: =+Julio!$AG3 -> 5599 | I3: =+agosto!$AG3 -> 6783 | J3: =+septiembre!$AG3 -> 7200 | K3: =+OCTUBRE!$AG3 -> 8467 | L3: =+NOVIEMBRE!$AG3 -> 7348 | M3: =+DICIEMBRE!$AG3 -> 6844 | N3: =SUM(B3:M3) -> 84236
A4: 08:00 | B4: =+ENERO!$AG4 -> 272 | C4: =+FEBRERO!$AG4 -> 234 | D4: =+MARZO!$AG4 -> 420 | E4: =+ABRIL!$AG4 -> 411 | F4: =+MAYO!$AG4 -> 431 | G4: =+JUNIO!$AG4 -> 278 | H4: =+Julio!$AG4 -> 249 | I4: =+agosto!$AG4 -> 322 | J4: =+septiembre!$AG4 -> 328 | K4: =+OCTUBRE!$AG4 -> 507 | L4: =+NOVIEMBRE!$AG4 -> 406 | M4: =+DICIEMBRE!$AG4 -> 341 | N4: =SUM(B4:M4) -> 4199
A5: 09:00 | B5: =+ENERO!$AG5 -> 357 | C5: =+FEBRERO!$AG5 -> 310 | D5: =+MARZO!$AG5 -> 534 | E5: =+ABRIL!$AG5 -> 444 | F5: =+MAYO!$AG5 -> 509 | G5: =+JUNIO!$AG5 -> 355 | H5: =+Julio!$AG5 -> 319 | I5: =+agosto!$AG5 -> 404 | J5: =+septiembre!$AG5 -> 418 | K5: =+OCTUBRE!$AG5 -> 546 | L5: =+NOVIEMBRE!$AG5 -> 443 | M5: =+DICIEMBRE!$AG5 -> 372 | N5: =SUM(B5:M5) -> 5011
A6: 10:00 | B6: =+ENERO!$AG6 -> 406 | C6: =+FEBRERO!$AG6 -> 335 | D6: =+MARZO!$AG6 -> 538 | E6: =+ABRIL!$AG6 -> 549 | F6: =+MAYO!$AG6 -> 552 | G6: =+JUNIO!$AG6 -> 417 | H6: =+Julio!$AG6 -> 376 | I6: =+agosto!$AG6 -> 451 | J6: =+septiembre!$AG6 -> 491 | K6: =+OCTUBRE!$AG6 -> 589 | L6: =+NOVIEMBRE!$AG6 -> 507 | M6: =+DICIEMBRE!$AG6 -> 463 | N6: =SUM(B6:M6) -> 5674
A7: 11:00 | B7: =+ENERO!$AG7 -> 448 | C7: =+FEBRERO!$AG7 -> 311 | D7: =+MARZO!$AG7 -> 535 | E7: =+ABRIL!$AG7 -> 569 | F7: =+MAYO!$AG7 -> 611 | G7: =+JUNIO!$AG7 -> 436 | H7: =+Julio!$AG7 -> 373 | I7: =+agosto!$AG7 -> 475 | J7: =+septiembre!$AG7 -> 488 | K7: =+OCTUBRE!$AG7 -> 603 | L7: =+NOVIEMBRE!$AG7 -> 507 | M7: =+DICIEMBRE!$AG7 -> 428 | N7: =SUM(B7:M7) -> 5784
A8: 12:00 | B8: =+ENERO!$AG8 -> 430 | C8: =+FEBRERO!$AG8 -> 347 | D8: =+MARZO!$AG8 -> 502 | E8: =+ABRIL!$AG8 -> 515 | F8: =+MAYO!$AG8 -> 543 | G8: =+JUNIO!$AG8 -> 381 | H8: =+Julio!$AG8 -> 365 | I8: =+agosto!$AG8 -> 418 | J8: =+septiembre!$AG8 -> 466 | K8: =+OCTUBRE!$AG8 -> 544 | L8: =+NOVIEMBRE!$AG8 -> 509 | M8: =+DICIEMBRE!$AG8 -> 444 | N8: =SUM(B8:M8) -> 5464
A9: 13:00 | B9: =+ENERO!$AG9 -> 303 | C9: =+FEBRERO!$AG9 -> 283 | D9: =+MARZO!$AG9 -> 417 | E9: =+ABRIL!$AG9 -> 382 | F9: =+MAYO!$AG9 -> 454 | G9: =+JUNIO!$AG9 -> 329 | H9: =+Julio!$AG9 -> 334 | I9: =+agosto!$AG9 -> 410 | J9: =+septiembre!$AG9 -> 423 | K9: =+OCTUBRE!$AG9 -> 468 | L9: =+NOVIEMBRE!$AG9 -> 365 | M9: =+DICIEMBRE!$AG9 -> 345 | N9: =SUM(B9:M9) -> 4513
A10: 14:00 | B10: =+ENERO!$AG10 -> 322 | C10: =+FEBRERO!$AG10 -> 293 | D10: =+MARZO!$AG10 -> 429 | E10: =+ABRIL!$AG10 -> 419 | F10: =+MAYO!$AG10 -> 531 | G10: =+JUNIO!$AG10 -> 358 | H10: =+Julio!$AG10 -> 333 | I10: =+agosto!$AG10 -> 435 | J10: =+septiembre!$AG10 -> 425 | K10: =+OCTUBRE!$AG10 -> 474 | L10: =+NOVIEMBRE!$AG10 -> 415 | M10: =+DICIEMBRE!$AG10 -> 375 | N10: =SUM(B10:M10) -> 4809
A11: 15:00 | B11: =+ENERO!$AG11 -> 412 | C11: =+FEBRERO!$AG11 -> 329 | D11: =+MARZO!$AG11 -> 461 | E11: =+ABRIL!$AG11 -> 465 | F11: =+MAYO!$AG11 -> 525 | G11: =+JUNIO!$AG11 -> 447 | H11: =+Julio!$AG11 -> 426 | I11: =+agosto!$AG11 -> 518 | J11: =+septiembre!$AG11 -> 497 | K11: =+OCTUBRE!$AG11 -> 543 | L11: =+NOVIEMBRE!$AG11 -> 423 | M11: =+DICIEMBRE!$AG11 -> 380 | N11: =SUM(B11:M11) -> 5426
A12: 16:00 | B12: =+ENERO!$AG12 -> 518 | C12: =+FEBRERO!$AG12 -> 422 | D12: =+MARZO!$AG12 -> 632 | E12: =+ABRIL!$AG12 -> 593 | F12: =+MAYO!$AG12 -> 617 | G12: =+JUNIO!$AG12 -> 412 | H12: =+Julio!$AG12 -> 459 | I12: =+agosto!$AG12 -> 527 | J12: =+septiembre!$AG12 -> 556 | K12: =+OCTUBRE!$AG12 -> 555 | L12: =+NOVIEMBRE!$AG12 -> 529 | M12: =+DICIEMBRE!$AG12 -> 442 | N12: =SUM(B12:M12) -> 6262
A13: 17:00 | B13: =+ENERO!$AG13 -> 523 | C13: =+FEBRERO!$AG13 -> 434 | D13: =+MARZO!$AG13 -> 567 | E13: =+ABRIL!$AG13 -> 616 | F13: =+MAYO!$AG13 -> 647 | G13: =+JUNIO!$AG13 -> 445 | H13: =+Julio!$AG13 -> 427 | I13: =+agosto!$AG13 -> 495 | J13: =+septiembre!$AG13 -> 502 | K13: =+OCTUBRE!$AG13 -> 613 | L13: =+NOVIEMBRE!$AG13 -> 548 | M13: =+DICIEMBRE!$AG13 -> 533 | N13: =SUM(B13:M13) -> 6350
A14: 18:00 | B14: =+ENERO!$AG14 -> 399 | C14: =+FEBRERO!$AG14 -> 366 | D14: =+MARZO!$AG14 -> 533 | E14: =+ABRIL!$AG14 -> 523 | F14: =+MAYO!$AG14 -> 505 | G14: =+JUNIO!$AG14 -> 350 | H14: =+Julio!$AG14 -> 346 | I14: =+agosto!$AG14 -> 445 | J14: =+septiembre!$AG14 -> 440 | K14: =+OCTUBRE!$AG14 -> 481 | L14: =+NOVIEMBRE!$AG14 -> 408 | M14: =+DICIEMBRE!$AG14 -> 392 | N14: =SUM(B14:M14) -> 5188
... A80: PAR | B80: =+ENERO!$AG80 -> 1866 | C80: =+FEBRERO!$AG80 -> 1526 | D80: =+MARZO!$AG80 -> 2438 | E80: =+ABRIL!$AG80 -> 2200 | F80: =+MAYO!$AG80 -> 2204 | G80: =+JUNIO!$AG80 -> 1803 | H80: =+Julio!$AG80 -> 1751 | I80: =+agosto!$AG80 -> 2003 | J80: =+septiembre!$AG80 -> 2096 | K80: =+OCTUBRE!$AG80 -> 2472 | L80: =+NOVIEMBRE!$AG80 -> 0 | M80: =+DICIEMBRE!$AG80 -> 0 | N80: =SUM(B80:M80) -> 20359
A81: TOTAL NSP | B81: =+ENERO!$AG81 -> 576 | C81: =+FEBRERO!$AG81 -> 396 | D81: =+MARZO!$AG81 -> 996 | E81: =+ABRIL!$AG81 -> 910 | F81: =+MAYO!$AG81 -> 1341 | G81: =+JUNIO!$AG81 -> 544 | H81: =+Julio!$AG81 -> 461 | I81: =+agosto!$AG81 -> 703 | J81: =+septiembre!$AG81 -> 766 | K81: =+OCTUBRE!$AG81 -> 1486 | L81: =+NOVIEMBRE!$AG81 -> 1170 | M81: =+DICIEMBRE!$AG81 -> 590 | N81: =SUM(B81:M81) -> 9939 | O81: =IF(N81<>N53,"*","") -> *
A82: PAR | B82: =+ENERO!$AG82 -> 196 | C82: =+FEBRERO!$AG82 -> 152 | D82: =+MARZO!$AG82 -> 402 | E82: =+ABRIL!$AG82 -> 373 | F82: =+MAYO!$AG82 -> 483 | G82: =+JUNIO!$AG82 -> 198 | H82: =+Julio!$AG82 -> 161 | I82: =+agosto!$AG82 -> 285 | J82: =+septiembre!$AG82 -> 303 | K82: =+OCTUBRE!$AG82 -> 384 | L82: =+NOVIEMBRE!$AG82 -> 259 | M82: =+DICIEMBRE!$AG82 -> 200 | N82: =SUM(B82:M82) -> 3396
A83: SAR | B83: =+ENERO!$AG83 -> 380 | C83: =+FEBRERO!$AG83 -> 244 | D83: =+MARZO!$AG83 -> 594 | E83: =+ABRIL!$AG83 -> 537 | F83: =+MAYO!$AG83 -> 858 | G83: =+JUNIO!$AG83 -> 346 | H83: =+Julio!$AG83 -> 300 | I83: =+agosto!$AG83 -> 418 | J83: =+septiembre!$AG83 -> 463 | K83: =+OCTUBRE!$AG83 -> 1112 | L83: =+NOVIEMBRE!$AG83 -> 911 | M83: =+DICIEMBRE!$AG83 -> 390 | N83: =SUM(B83:M83) -> 6553
A84: NSP PEDIATR. / ADULTOS | B84: =+ENERO!$AG84 -> 576 | C84: =+FEBRERO!$AG84 -> 396 | D84: =+MARZO!$AG84 -> 996 | E84: =+ABRIL!$AG84 -> 910 | F84: =+MAYO!$AG84 -> 1341 | G84: =+JUNIO!$AG84 -> 544 | H84: =+Julio!$AG84 -> 461 | I84: =+agosto!$AG84 -> 703 | J84: =+septiembre!$AG84 -> 766 | K84: =+OCTUBRE!$AG84 -> 1496 | L84: =+NOVIEMBRE!$AG84 -> 1170 | M84: =+DICIEMBRE!$AG84 -> 590 | N84: =SUM(B84:M84) -> 9949 | O84: =IF(N84<>N82+N83,"*","") | P84: NSP
A85: NSP PEDIATRICOS (<15 AÑOS) | B85: =+ENERO!$AG85 -> 102 | C85: =+FEBRERO!$AG85 -> 68 | D85: =+MARZO!$AG85 -> 231 | E85: =+ABRIL!$AG85 -> 242 | F85: =+MAYO!$AG85 -> 400 | G85: =+JUNIO!$AG85 -> 94 | H85: =+Julio!$AG85 -> 64 | I85: =+agosto!$AG85 -> 136 | J85: =+septiembre!$AG85 -> 160 | K85: =+OCTUBRE!$AG85 -> 355 | L85: =+NOVIEMBRE!$AG85 -> 285 | M85: =+DICIEMBRE!$AG85 -> 116 | N85: =SUM(B85:M85) -> 2253
A86: NSP ADULTOS | B86: =+ENERO!$AG86 -> 474 | C86: =+FEBRERO!$AG86 -> 328 | D86: =+MARZO!$AG86 -> 765 | E86: =+ABRIL!$AG86 -> 668 | F86: =+MAYO!$AG86 -> 941 | G86: =+JUNIO!$AG86 -> 450 | H86: =+Julio!$AG86 -> 397 | I86: =+agosto!$AG86 -> 567 | J86: =+septiembre!$AG86 -> 606 | K86: =+OCTUBRE!$AG86 -> 1141 | L86: =+NOVIEMBRE!$AG86 -> 885 | M86: =+DICIEMBRE!$AG86 -> 474 | N86: =SUM(B86:M86) -> 7696
A87: NSP CATEGORIZACION | B87: =+ENERO!$AG87 -> 576 | C87: =+FEBRERO!$AG87 -> 396 | D87: =+MARZO!$AG87 -> 996 | E87: =+ABRIL!$AG87 -> 910 | F87: =+MAYO!$AG87 -> 1341 | G87: =+JUNIO!$AG87 -> 544 | H87: =+Julio!$AG87 -> 461 | I87: =+agosto!$AG87 -> 703 | J87: =+septiembre!$AG87 -> 766 | K87: =+OCTUBRE!$AG87 -> 1496 | L87: =+NOVIEMBRE!$AG87 -> 1170 | M87: =+DICIEMBRE!$AG87 -> 590 | N87: =SUM(B87:M87) -> 9949 | O87: =IF(N87<>N84,"*","")
A88: SIN CATEGORIZACIÓN nsp | B88: =+ENERO!$AG88 -> 164 | C88: =+FEBRERO!$AG88 -> 111 | D88: =+MARZO!$AG88 -> 239 | E88: =+ABRIL!$AG88 -> 234 | F88: =+MAYO!$AG88 -> 337 | G88: =+JUNIO!$AG88 -> 115 | H88: =+Julio!$AG88 -> 102 | I88: =+agosto!$AG88 -> 174 | J88: =+septiembre!$AG88 -> 141 | K88: =+OCTUBRE!$AG88 -> 238 | L88: =+NOVIEMBRE!$AG88 -> 180 | M88: =+DICIEMBRE!$AG88 -> 179 | N88: =SUM(B88:M88) -> 2214
A89: C2 | B89: =+ENERO!$AG89 -> 1 | C89: =+FEBRERO!$AG89 -> 0 | D89: =+MARZO!$AG89 -> 0 | E89: =+ABRIL!$AG89 -> 1 | F89: =+MAYO!$AG89 -> 0 | G89: =+JUNIO!$AG89 -> 0 | H89: =+Julio!$AG89 -> 0 | I89: =+agosto!$AG89 -> 0 | J89: =+septiembre!$AG89 -> 1 | K89: =+OCTUBRE!$AG89 -> 0 | L89: =+NOVIEMBRE!$AG89 -> 0 | M89: =+DICIEMBRE!$AG89 -> 0 | N89: =SUM(B89:M89) -> 3
A90: C3 | B90: =+ENERO!$AG90 -> 5 | C90: =+FEBRERO!$AG90 -> 3 | D90: =+MARZO!$AG90 -> 7 | E90: =+ABRIL!$AG90 -> 12 | F90: =+MAYO!$AG90 -> 18 | G90: =+JUNIO!$AG90 -> 9 | H90: =+Julio!$AG90 -> 12 | I90: =+agosto!$AG90 -> 13 | J90: =+septiembre!$AG90 -> 16 | K90: =+OCTUBRE!$AG90 -> 27 | L90: =+NOVIEMBRE!$AG90 -> 17 | M90: =+DICIEMBRE!$AG90 -> 7 | N90: =SUM(B90:M90) -> 146
A91: C4 | B91: =+ENERO!$AG91 -> 202 | C91: =+FEBRERO!$AG91 -> 129 | D91: =+MARZO!$AG91 -> 507 | E91: =+ABRIL!$AG91 -> 432 | F91: =+MAYO!$AG91 -> 698 | G91: =+JUNIO!$AG91 -> 280 | H91: =+Julio!$AG91 -> 215 | I91: =+agosto!$AG91 -> 349 | J91: =+septiembre!$AG91 -> 348 | K91: =+OCTUBRE!$AG91 -> 753 | L91: =+NOVIEMBRE!$AG91 -> 593 | M91: =+DICIEMBRE!$AG91 -> 241 | N91: =SUM(B91:M91) -> 4747
A92: C5 | B92: =+ENERO!$AG92 -> 204 | C92: =+FEBRERO!$AG92 -> 153 | D92: =+MARZO!$AG92 -> 243 | E92: =+ABRIL!$AG92 -> 231 | F92: =+MAYO!$AG92 -> 288 | G92: =+JUNIO!$AG92 -> 140 | H92: =+Julio!$AG92 -> 132 | I92: =+agosto!$AG92 -> 167 | J92: =+septiembre!$AG92 -> 260 | K92: =+OCTUBRE!$AG92 -> 478 | L92: =+NOVIEMBRE!$AG92 -> 380 | M92: =+DICIEMBRE!$AG92 -> 163 | N92: =SUM(B92:M92) -> 2839
A93: TOTAL PACIENTES ATENDIDOS | B93: =+ENERO!$AG93 -> 6511 | C93: =+FEBRERO!$AG93 -> 5247 | D93: =+MARZO!$AG93 -> 7090 | E93: =+ABRIL!$AG93 -> 6604 | F93: =+MAYO!$AG93 -> 6766 | G93: =+JUNIO!$AG93 -> 5310 | H93: =+Julio!$AG93 -> 5138 | I93: =+agosto!$AG93 -> 6080 | J93: =+septiembre!$AG93 -> 6434 | K93: =+OCTUBRE!$AG93 -> 6981 | L93: =+NOVIEMBRE!$AG93 -> 6178 | M93: =+DICIEMBRE!$AG93 -> 6254 | N93: =SUM(B93:M93) -> 74593 | O93: =IF(N93<>N28,"*","") -> *
A94: Menor 15 años | B94: =+ENERO!$AG94 -> 867 | C94: =+FEBRERO!$AG94 -> 595 | D94: =+MARZO!$AG94 -> 1405 | E94: =+ABRIL!$AG94 -> 1537 | F94: =+MAYO!$AG94 -> 1942 | G94: =+JUNIO!$AG94 -> 983 | H94: =+Julio!$AG94 -> 586 | I94: =+agosto!$AG94 -> 1134 | J94: =+septiembre!$AG94 -> 1196 | K94: =+OCTUBRE!$AG94 -> 1370 | L94: =+NOVIEMBRE!$AG94 -> 1319 | M94: =+DICIEMBRE!$AG94 -> 1063 | N94: =SUM(B94:M94) -> 13997
A95: Menor 1 Año | B95: =+ENERO!$AG95 -> 38 | C95: =+FEBRERO!$AG95 -> 16 | D95: =+MARZO!$AG95 -> 23 | E95: =+ABRIL!$AG95 -> 21 | F95: =+MAYO!$AG95 -> 34 | G95: =+JUNIO!$AG95 -> 35 | H95: =+Julio!$AG95 -> 16 | I95: =+agosto!$AG95 -> 28 | J95: =+septiembre!$AG95 -> 24 | K95: =+OCTUBRE!$AG95 -> 30 | L95: =+NOVIEMBRE!$AG95 -> 24 | M95: =+DICIEMBRE!$AG95 -> 31 | N95: =SUM(B95:M95) -> 320
A96: 1 Año | B96: =+ENERO!$AG96 -> 59 | C96: =+FEBRERO!$AG96 -> 44 | D96: =+MARZO!$AG96 -> 60 | E96: =+ABRIL!$AG96 -> 62 | F96: =+MAYO!$AG96 -> 74 | G96: =+JUNIO!$AG96 -> 52 | H96: =+Julio!$AG96 -> 34 | I96: =+agosto!$AG96 -> 52 | J96: =+septiembre!$AG96 -> 54 | K96: =+OCTUBRE!$AG96 -> 68 | L96: =+NOVIEMBRE!$AG96 -> 51 | M96: =+DICIEMBRE!$AG96 -> 67 | N96: =SUM(B96:M96) -> 677
A97: 2 - 4 | B97: =+ENERO!$AG97 -> 233 | C97: =+FEBRERO!$AG97 -> 138 | D97: =+MARZO!$AG97 -> 275 | E97: =+ABRIL!$AG97 -> 366 | F97: =+MAYO!$AG97 -> 483 | G97: =+JUNIO!$AG97 -> 204 | H97: =+Julio!$AG97 -> 97 | I97: =+agosto!$AG97 -> 215 | J97: =+septiembre!$AG97 -> 215 | K97: =+OCTUBRE!$AG97 -> 247 | L97: =+NOVIEMBRE!$AG97 -> 227 | M97: =+DICIEMBRE!$AG97 -> 279 | N97: =SUM(B97:M97) -> 2979
A98: 5 - 9 | B98: =+ENERO!$AG98 -> 313 | C98: =+FEBRERO!$AG98 -> 208 | D98: =+MARZO!$AG98 -> 527 | E98: =+ABRIL!$AG98 -> 649 | F98: =+MAYO!$AG98 -> 796 | G98: =+JUNIO!$AG98 -> 397 | H98: =+Julio!$AG98 -> 220 | I98: =+agosto!$AG98 -> 430 | J98: =+septiembre!$AG98 -> 492 | K98: =+OCTUBRE!$AG98 -> 576 | L98: =+NOVIEMBRE!$AG98 -> 543 | M98: =+DICIEMBRE!$AG98 -> 399 | N98: =SUM(B98:M98) -> 5550
A99: 10 - 14 | B99: =+ENERO!$AG99 -> 224 | C99: =+FEBRERO!$AG99 -> 189 | D99: =+MARZO!$AG99 -> 520 | E99: =+ABRIL!$AG99 -> 439 | F99: =+MAYO!$AG99 -> 555 | G99: =+JUNIO!$AG99 -> 295 | H99: =+Julio!$AG99 -> 219 | I99: =+agosto!$AG99 -> 409 | J99: =+septiembre!$AG99 -> 411 | K99: =+OCTUBRE!$AG99 -> 449 | L99: =+NOVIEMBRE!$AG99 -> 474 | M99: =+DICIEMBRE!$AG99 -> 287 | N99: =SUM(B99:M99) -> 4471
A100: Mayor de 15 años | B100: =+ENERO!$AG100 -> 5644 | C100: =+FEBRERO!$AG100 -> 4652 | D100: =+MARZO!$AG100 -> 5685 | E100: =+ABRIL!$AG100 -> 5067 | F100: =+MAYO!$AG100 -> 4824 | G100: =+JUNIO!$AG100 -> 4327 | H100: =+Julio!$AG100 -> 4552 | I100: =+agosto!$AG100 -> 4946 | J100: =+septiembre!$AG100 -> 5238 | K100: =+OCTUBRE!$AG100 -> 5611 | L100: =+NOVIEMBRE!$AG100 -> 4859 | M100: =+DICIEMBRE!$AG100 -> 5191 | N100: =SUM(B100:M100) -> 60596
A101: 15 - 19 | B101: =+ENERO!$AG101 -> 364 | C101: =+FEBRERO!$AG101 -> 298 | D101: =+MARZO!$AG101 -> 513 | E101: =+ABRIL!$AG101 -> 509 | F101: =+MAYO!$AG101 -> 447 | G101: =+JUNIO!$AG101 -> 370 | H101: =+Julio!$AG101 -> 297 | I101: =+agosto!$AG101 -> 445 | J101: =+septiembre!$AG101 -> 421 | K101: =+OCTUBRE!$AG101 -> 468 | L101: =+NOVIEMBRE!$AG101 -> 378 | M101: =+DICIEMBRE!$AG101 -> 341 | N101: =SUM(B101:M101) -> 4851
A102: 20 - 24 | B102: =+ENERO!$AG102 -> 506 | C102: =+FEBRERO!$AG102 -> 438 | D102: =+MARZO!$AG102 -> 488 | E102: =+ABRIL!$AG102 -> 530 | F102: =+MAYO!$AG102 -> 487 | G102: =+JUNIO!$AG102 -> 397 | H102: =+Julio!$AG102 -> 364 | I102: =+agosto!$AG102 -> 451 | J102: =+septiembre!$AG102 -> 493 | K102: =+OCTUBRE!$AG102 -> 508 | L102: =+NOVIEMBRE!$AG102 -> 418 | M102: =+DICIEMBRE!$AG102 -> 440 | N102: =SUM(B102:M102) -> 5520
A103: 25 - 29 | B103: =+ENERO!$AG103 -> 527 | C103: =+FEBRERO!$AG103 -> 384 | D103: =+MARZO!$AG103 -> 489 | E103: =+ABRIL!$AG103 -> 448 | F103: =+MAYO!$AG103 -> 433 | G103: =+JUNIO!$AG103 -> 401 | H103: =+Julio!$AG103 -> 412 | I103: =+agosto!$AG103 -> 472 | J103: =+septiembre!$AG103 -> 460 | K103: =+OCTUBRE!$AG103 -> 449 | L103: =+NOVIEMBRE!$AG103 -> 444 | M103: =+DICIEMBRE!$AG103 -> 492 | N103: =SUM(B103:M103) -> 5411
A104: 30 - 34 | B104: =+ENERO!$AG104 -> 500 | C104: =+FEBRERO!$AG104 -> 394 | D104: =+MARZO!$AG104 -> 530 | E104: =+ABRIL!$AG104 -> 388 | F104: =+MAYO!$AG104 -> 401 | G104: =+JUNIO!$AG104 -> 380 | H104: =+Julio!$AG104 -> 358 | I104: =+agosto!$AG104 -> 389 | J104: =+septiembre!$AG104 -> 424 | K104: =+OCTUBRE!$AG104 -> 468 | L104: =+NOVIEMBRE!$AG104 -> 395 | M104: =+DICIEMBRE!$AG104 -> 432 | N104: =SUM(B104:M104) -> 5059
A105: 35 - 39 | B105: =+ENERO!$AG105 -> 374 | C105: =+FEBRERO!$AG105 -> 345 | D105: =+MARZO!$AG105 -> 421 | E105: =+ABRIL!$AG105 -> 362 | F105: =+MAYO!$AG105 -> 369 | G105: =+JUNIO!$AG105 -> 343 | H105: =+Julio!$AG105 -> 353 | I105: =+agosto!$AG105 -> 365 | J105: =+septiembre!$AG105 -> 383 | K105: =+OCTUBRE!$AG105 -> 430 | L105: =+NOVIEMBRE!$AG105 -> 392 | M105: =+DICIEMBRE!$AG105 -> 392 | N105: =SUM(B105:M105) -> 4529
... A114: 80 y mas | B114: =+ENERO!$AG114 -> 296 | C114: =+FEBRERO!$AG114 -> 279 | D114: =+MARZO!$AG114 -> 298 | E114: =+ABRIL!$AG114 -> 251 | F114: =+MAYO!$AG114 -> 207 | G114: =+JUNIO!$AG114 -> 207 | H114: =+Julio!$AG114 -> 255 | I114: =+agosto!$AG114 -> 265 | J114: =+septiembre!$AG114 -> 286 | K114: =+OCTUBRE!$AG114 -> 328 | L114: =+NOVIEMBRE!$AG114 -> 261 | M114: =+DICIEMBRE!$AG114 -> 337 | N114: =SUM(B114:M114) -> 3270
...

Sheet FORMATO
A2: MES | B2: 1 | C2: =+B2+1 -> 2 | D2: =+C2+1 -> 3 | E2: =+D2+1 -> 4 | F2: =+E2+1 -> 5 | G2: =+F2+1 -> 6 | H2: =+G2+1 -> 7 | I2: =+H2+1 -> 8 | J2: =+I2+1 -> 9 | ... AF2: =+AE2+1 -> 31 | AG2: TOTAL
A3: Total de Inscritos | B3: =SUM(B4:B27) -> 0 | C3: =SUM(C4:C27) -> 0 | D3: =SUM(D4:D27) -> 0 | E3: =SUM(E4:E27) -> 0 | F3: =SUM(F4:F27) -> 0 | G3: =SUM(G4:G27) -> 0 | H3: =SUM(H4:H27) -> 0 | I3: =SUM(I4:I27) -> 0 | ... AF3: =SUM(AF4:AF27) -> 0 | AG3: =SUM(B3:AF3) -> 0
A4: 08:00 | AG4: =SUM(B4:AF4) -> 0
A5: 09:00 | AG5: =SUM(B5:AF5) -> 0
A6: 10:00 | AG6: =SUM(B6:AF6) -> 0
A7: 11:00 | AG7: =SUM(B7:AF7) -> 0
A8: 12:00 | AG8: =SUM(B8:AF8) -> 0
A9: 13:00 | AG9: =SUM(B9:AF9) -> 0
A10: 14:00 | AG10: =SUM(B10:AF10) -> 0
A11: 15:00 | AG11: =SUM(B11:AF11) -> 0
A12: 16:00 | AG12: =SUM(B12:AF12) -> 0
A13: 17:00 | AG13: =SUM(B13:AF13) -> 0
A14: 18:00 | AG14: =SUM(B14:AF14) -> 0
A15: 19:00 | AG15: =SUM(B15:AF15) -> 0
... A27: 07:00 | AG27: =SUM(B27:AF27) -> 0
A28: Total de atendidos | B28: =SUM(B29:B52) -> 0 | C28: =SUM(C29:C52) -> 0 | D28: =SUM(D29:D52) -> 0 | E28: =SUM(E29:E52) -> 0 | F28: =SUM(F29:F52) -> 0 | G28: =SUM(G29:G52) -> 0 | H28: =SUM(H29:H52) -> 0 | I28: =SUM(I29:I52) -> 0 | ... AF28: =SUM(AF29:AF52) -> 0 | AG28: =SUM(B28:AF28) -> 0
A29: 08:00 | AG29: =SUM(B29:AF29) -> 0
A30: 09:00 | AG30: =SUM(B30:AF30) -> 0
A31: 10:00 | AG31: =SUM(B31:AF31) -> 0
A32: 11:00 | AG32: =SUM(B32:AF32) -> 0
A33: 12:00 | AG33: =SUM(B33:AF33) -> 0
A34: 13:00 | AG34: =SUM(B34:AF34) -> 0
A35: 14:00 | AG35: =SUM(B35:AF35) -> 0
A36: 15:00 | AG36: =SUM(B36:AF36) -> 0
A37: 16:00 | AG37: =SUM(B37:AF37) -> 0
A38: 17:00 | AG38: =SUM(B38:AF38) -> 0
A39: 18:00 | AG39: =SUM(B39:AF39) -> 0
A40: 19:00 | AG40: =SUM(B40:AF40) -> 0
... A52: 07:00 | AG52: =SUM(B52:AF52) -> 0
A53: Total de NSP | B53: =SUM(B54:B77) -> 0 | C53: =SUM(C54:C77) -> 0 | D53: =SUM(D54:D77) -> 0 | E53: =SUM(E54:E77) -> 0 | F53: =SUM(F54:F77) -> 0 | G53: =SUM(G54:G77) -> 0 | H53: =SUM(H54:H77) -> 0 | I53: =SUM(I54:I77) -> 0 | ... AF53: =SUM(AF54:AF77) -> 0 | AG53: =SUM(B53:AF53) -> 0
A54: 08:00 | AG54: =SUM(B54:AF54) -> 0
A55: 09:00 | AG55: =SUM(B55:AF55) -> 0
A56: 10:00 | AG56: =SUM(B56:AF56) -> 0
A57: 11:00 | AG57: =SUM(B57:AF57) -> 0
A58: 12:00 | AG58: =SUM(B58:AF58) -> 0
A59: 13:00 | AG59: =SUM(B59:AF59) -> 0
A60: 14:00 | AG60: =SUM(B60:AF60) -> 0
A61: 15:00 | AG61: =SUM(B61:AF61) -> 0
A62: 16:00 | AG62: =SUM(B62:AF62) -> 0
A63: 17:00 | AG63: =SUM(B63:AF63) -> 0
...

Sheet ENERO
A2: ENERO | B2: 1 | C2: =+B2+1 -> 2 | D2: =+C2+1 -> 3 | E2: =+D2+1 -> 4 | F2: =+E2+1 -> 5 | G2: =+F2+1 -> 6 | H2: =+G2+1 -> 7 | I2: =+H2+1 -> 8 | J2: =+I2+1 -> 9 | ... AA2: =+Z2+1 -> 26 | AB2: 27 | AC2: =+AB2+1 -> 28 | AD2: 29 | AE2: 30 | AF2: 31 | AG2: TOTAL
A3: Total de Inscritos | B3: =SUM(B4:B27) -> 210 | C3: =SUM(C4:C27) -> 253 | D3: =SUM(D4:D27) -> 303 | E3: =SUM(E4:E27) -> 249 | F3: =SUM(F4:F27) -> 263 | G3: =SUM(G4:G27) -> 246 | H3: =SUM(H4:H27) -> 250 | I3: =SUM(I4:I27) -> 207 | ... AF3: =SUM(AF4:AF27) -> 224 | AG3: =SUM(B3:AF3) -> 6791
A4: 08:00 | B4: 5 | C4: 13 | D4: 9 | E4: 12 | F4: 14 | G4: 6 | H4: 11 | I4: 4 | J4: 11 | K4: 11 | L4: 15 | M4: 12 | N4: 5 | O4: 13 | P4: 6 | Q4: 8 | R4: 8 | S4: 9 | T4: 11 | U4: 12 | V4: 8 | W4: 5 | X4: 8 | Y4: 7 | Z4: 11 | AA4: 16 | AB4: 11 | AF4: 11 | AG4: =SUM(B4:AF4) -> 272
A5: 09:00 | B5: 10 | C5: 10 | D5: 15 | E5: 17 | F5: 12 | G5: 10 | H5: 14 | I5: 4 | J5: 15 | K5: 11 | L5: 17 | M5: 11 | N5: 15 | O5: 12 | P5: 6 | Q5: 22 | R5: 13 | S5: 18 | T5: 18 | U5: 8 | V5: 15 | W5: 8 | X5: 14 | Y5: 8 | Z5: 12 | AA5: 8 | AB5: 8 | AE5: 12 | AF5: 14 | AG5: =SUM(B5:AF5) -> 357
A6: 10:00 | B6: 9 | C6: 15 | D6: 17 | E6: 14 | F6: 14 | G6: 19 | H6: 22 | I6: 12 | J6: 13 | K6: 15 | L6: 13 | M6: 14 | N6: 10 | O6: 17 | P6: 12 | Q6: 24 | R6: 13 | S6: 11 | T6: 11 | U6: 14 | V6: 10 | W6: 16 | X6: 18 | Y6: 7 | Z6: 10 | AA6: 13 | AB6: 13 | AE6: 16 | AF6: 14 | AG6: =SUM(B6:AF6) -> 406
A7: 11:00 | B7: 18 | C7: 19 | D7: 16 | E7: 19 | F7: 14 | G7: 21 | H7: 23 | I7: 16 | J7: 18 | K7: 16 | L7: 12 | M7: 10 | N7: 14 | O7: 14 | P7: 9 | Q7: 19 | R7: 18 | S7: 19 | T7: 13 | U7: 21 | V7: 13 | W7: 17 | X7: 17 | Y7: 8 | Z7: 15 | AA7: 6 | AB7: 8 | AE7: 18 | AF7: 17 | AG7: =SUM(B7:AF7) -> 448
A8: 12:00 | B8: 19 | C8: 21 | D8: 16 | E8: 21 | F8: 14 | G8: 11 | H8: 10 | I8: 19 | J8: 14 | K8: 18 | L8: 10 | M8: 12 | N8: 14 | O8: 14 | P8: 18 | Q8: 18 | R8: 23 | S8: 15 | T8: 10 | U8: 9 | V8: 13 | W8: 16 | X8: 12 | Y8: 19 | Z8: 10 | AA8: 17 | AB8: 12 | AE8: 14 | AF8: 11 | AG8: =SUM(B8:AF8) -> 430
A9: 13:00 | B9: 5 | C9: 17 | D9: 16 | E9: 8 | F9: 13 | G9: 15 | H9: 18 | I9: 6 | J9: 9 | K9: 8 | L9: 16 | M9: 9 | N9: 10 | O9: 14 | P9: 12 | Q9: 19 | R9: 7 | S9: 10 | T9: 7 | U9: 7 | V9: 8 | W9: 7 | X9: 11 | Y9: 11 | Z9: 7 | AA9: 6 | AB9: 12 | AE9: 7 | AF9: 8 | AG9: =SUM(B9:AF9) -> 303
A10: 14:00 | B10: 10 | C10: 19 | D10: 14 | E10: 8 | F10: 14 | G10: 15 | H10: 17 | I10: 11 | J10: 11 | K10: 12 | L10: 13 | M10: 5 | N10: 10 | O10: 13 | P10: 6 | Q10: 9 | R10: 8 | S10: 6 | T10: 11 | U10: 14 | V10: 14 | W10: 7 | X10: 14 | Y10: 11 | Z10: 12 | AA10: 9 | AB10: 15 | AE10: 8 | AF10: 6 | AG10: =SUM(B10:AF10) -> 322
A11: 15:00 | B11: 15 | C11: 14 | D11: 19 | E11: 17 | F11: 15 | G11: 10 | H11: 22 | I11: 15 | J11: 17 | K11: 20 | L11: 13 | M11: 18 | N11: 14 | O11: 10 | P11: 13 | Q11: 19 | R11: 9 | S11: 13 | T11: 7 | U11: 18 | V11: 13 | W11: 16 | X11: 11 | Y11: 12 | Z11: 7 | AA11: 12 | AB11: 16 | AE11: 16 | AF11: 11 | AG11: =SUM(B11:AF11) -> 412
A12: 16:00 | B12: 12 | C12: 20 | D12: 32 | E12: 20 | F12: 23 | G12: 18 | H12: 12 | I12: 14 | J12: 19 | K12: 13 | L12: 18 | M12: 13 | N12: 25 | O12: 18 | P12: 13 | Q12: 18 | R12: 24 | S12: 23 | T12: 25 | U12: 11 | V12: 15 | W12: 16 | X12: 10 | Y12: 18 | Z12: 26 | AA12: 13 | AB12: 9 | AE12: 26 | AF12: 14 | AG12: =SUM(B12:AF12) -> 518
A13: 17:00 | B13: 6 | C13: 8 | D13: 27 | E13: 24 | F13: 17 | G13: 23 | H13: 21 | I13: 6 | J13: 28 | K13: 17 | L13: 18 | M13: 20 | N13: 21 | O13: 12 | P13: 11 | Q13: 23 | R13: 15 | S13: 20 | T13: 24 | U13: 14 | V13: 9 | W13: 15 | X13: 19 | Y13: 19 | Z13: 28 | AA13: 18 | AB13: 15 | AE13: 25 | AF13: 20 | AG13: =SUM(B13:AF13) -> 523
A14: 18:00 | B14: 13 | C14: 14 | D14: 26 | E14: 9 | F14: 23 | G14: 19 | H14: 10 | I14: 16 | J14: 8 | K14: 19 | L14: 15 | M14: 21 | N14: 15 | O14: 10 | P14: 3 | Q14: 17 | R14: 9 | S14: 12 | T14: 16 | U14: 15 | V14: 8 | W14: 12 | X14: 8 | Y14: 17 | Z14: 12 | AA14: 12 | AB14: 16 | AE14: 18 | AF14: 6 | AG14: =SUM(B14:AF14) -> 399
A15: 19:00 | B15: 8 | C15: 12 | D15: 18 | E15: 19 | F15: 21 | G15: 14 | H15: 9 | I15: 9 | J15: 13 | K15: 16 | L15: 11 | M15: 8 | N15: 7 | O15: 13 | P15: 12 | Q15: 19 | R15: 24 | S15: 9 | T15: 17 | U15: 13 | V15: 13 | W15: 14 | X15: 24 | Y15: 12 | Z15: 9 | AA15: 11 | AB15: 10 | AE15: 8 | AF15: 15 | AG15: =SUM(B15:AF15) -> 388
A16: 20:00 | B16: 18 | C16: 14 | D16: 18 | E16: 19 | F16: 9 | G16: 20 | H16: 10 | I16: 11 | J16: 15 | K16: 15 | L16: 17 | M16: 16 | N16: 9 | O16: 15 | P16: 13 | Q16: 16 | R16: 14 | S16: 15 | T16: 17 | U16: 12 | V16: 7 | W16: 12 | X16: 16 | Y16: 14 | Z16: 15 | AA16: 17 | AB16: 13 | AE16: 16 | AF16: 14 | AG16: =SUM(B16:AF16) -> 417
... A22: 02:00 | B22: 0 | C22: 2 | D22: 3 | E22: 1 | F22: 5 | G22: 3 | H22: 8 | I22: 2 | J22: 4 | K22: 1 | L22: 3 | M22: 4 | N22: 4 | O22: 3 | P22: 0 | Q22: 4 | R22: 1 | S22: 3 | T22: 4 | U22: 1 | V22: 3 | W22: 3 | X22: 1 | Y22: 3 | Z22: 2 | AA22: 4 | AB22: 1 | AE22: 4 | AF22: 2 | AG22: =SUM(B22:AF22) -> 79
A23: 03:00 | B23: 1 | C23: 1 | D23: 0 | E23: 0 | F23: 4 | G23: 3 | H23: 1 | I23: 2 | J23: 0 | K23: 3 | L23: 1 | M23: 4 | N23: 7 | O23: 1 | P23: 0 | Q23: 3 | R23: 1 | S23: 4 | T23: 2 | X23: 1 | Y23: 2 | Z23: 1 | AA23: 1 | AE23: 2 | AF23: 5 | AG23: =SUM(B23:AF23) -> 50
A24: 04:00 | B24: 2 | C24: 0 | D24: 2 | E24: 0 | F24: 0 | G24: 0 | H24: 0 | I24: 1 | J24: 0 | K24: 1 | L24: 2 | M24: 1 | N24: 1 | O24: 2 | P24: 0 | Q24: 0 | R24: 0 | S24: 0 | T24: 1 | V24: 2 | Y24: 1 | AA24: 1 | AE24: 2 | AF24: 1 | AG24: =SUM(B24:AF24) -> 20
A25: 05:00 | B25: 2 | C25: 0 | D25: 2 | E25: 0 | F25: 2 | G25: 1 | H25: 3 | I25: 2 | J25: 0 | K25: 1 | L25: 2 | M25: 0 | N25: 0 | O25: 2 | P25: 5 | Q25: 0 | R25: 0 | S25: 0 | T25: 2 | U25: 1 | V25: 1 | W25: 1 | Z25: 2 | AF25: 4 | AG25: =SUM(B25:AF25) -> 33
A26: 06:00 | B26: 2 | C26: 0 | D26: 1 | E26: 0 | F26: 2 | G26: 3 | H26: 0 | I26: 3 | J26: 1 | K26: 2 | L26: 1 | M26: 0 | N26: 0 | O26: 1 | P26: 0 | Q26: 1 | R26: 1 | S26: 4 | T26: 0 | U26: 3 | W26: 3 | X26: 2 | Y26: 1 | Z26: 1 | AE26: 1 | AF26: 1 | AG26: =SUM(B26:AF26) -> 34
A27: 07:00 | B27: 2 | C27: 4 | D27: 3 | E27: 1 | F27: 10 | G27: 4 | H27: 2 | I27: 3 | J27: 2 | K27: 1 | L27: 7 | M27: 2 | N27: 0 | O27: 2 | P27: 7 | Q27: 5 | R27: 9 | S27: 5 | T27: 6 | U27: 2 | X27: 4 | Y27: 5 | Z27: 6 | AA27: 8 | AE27: 5 | AF27: 1 | AG27: =SUM(B27:AF27) -> 106
A28: Total de atendidos | B28: =SUM(B29:B52) -> 202 | C28: =SUM(C29:C52) -> 237 | D28: =SUM(D29:D52) -> 254 | E28: =SUM(E29:E52) -> 215 | F28: =SUM(F29:F52) -> 224 | G28: =SUM(G29:G52) -> 210 | H28: =SUM(H29:H52) -> 238 | I28: =SUM(I29:I52) -> 202 | ... AF28: =SUM(AF29:AF52) -> 195 | AG28: =SUM(B28:AF28) -> 6218
A29: 08:00 | B29: 2 | C29: 8 | D29: 7 | E29: 5 | F29: 8 | G29: 3 | H29: 3 | I29: 5 | J29: 4 | K29: 4 | L29: 12 | M29: 6 | N29: 3 | O29: 12 | P29: 3 | Q29: 7 | R29: 6 | S29: 8 | T29: 5 | U29: 5 | V29: 4 | W29: 2 | X29: 4 | Y29: 4 | Z29: 5 | AA29: 10 | AB29: 2 | AE29: 4 | AF29: 4 | AG29: =SUM(B29:AF29) -> 155
A30: 09:00 | B30: 6 | C30: 10 | D30: 8 | E30: 8 | F30: 12 | G30: 7 | H30: 14 | I30: 3 | J30: 10 | K30: 5 | L30: 13 | M30: 13 | N30: 6 | O30: 5 | P30: 10 | Q30: 8 | R30: 11 | S30: 10 | T30: 6 | U30: 10 | V30: 7 | W30: 7 | X30: 10 | Y30: 7 | Z30: 9 | AA30: 5 | AB30: 6 | AE30: 1 | AF30: 10 | AG30: =SUM(B30:AF30) -> 237
A31: 10:00 | B31: 10 | C31: 11 | D31: 15 | E31: 10 | F31: 8 | G31: 10 | H31: 14 | I31: 7 | J31: 11 | K31: 11 | L31: 9 | M31: 13 | N31: 11 | O31: 12 | P31: 10 | Q31: 13 | R31: 12 | S31: 11 | T31: 11 | U31: 6 | V31: 16 | W31: 9 | X31: 9 | Y31: 5 | Z31: 11 | AA31: 13 | AB31: 13 | AE31: 3 | AF31: 10 | AG31: =SUM(B31:AF31) -> 304
A32: 11:00 | B32: 9 | C32: 15 | D32: 13 | E32: 12 | F32: 10 | G32: 14 | H32: 18 | I32: 16 | J32: 10 | K32: 6 | L32: 9 | M32: 9 | N32: 16 | O32: 11 | P32: 10 | Q32: 11 | R32: 10 | S32: 6 | T32: 8 | U32: 11 | V32: 8 | W32: 8 | X32: 11 | Y32: 5 | Z32: 6 | AA32: 10 | AB32: 9 | AE32: 13 | AF32: 8 | AG32: =SUM(B32:AF32) -> 302
A33: 12:00 | B33: 14 | C33: 12 | D33: 15 | E33: 10 | F33: 10 | G33: 11 | H33: 14 | I33: 15 | J33: 12 | K33: 9 | L33: 13 | M33: 8 | N33: 1 | O33: 14 | P33: 11 | Q33: 19 | R33: 13 | S33: 13 | T33: 8 | U33: 10 | V33: 14 | W33: 10 | X33: 9 | Y33: 11 | Z33: 8 | AA33: 12 | AB33: 10 | AE33: 10 | AF33: 13 | AG33: =SUM(B33:AF33) -> 329
A34: 13:00 | B34: 12 | C34: 17 | D34: 5 | E34: 14 | F34: 7 | G34: 9 | H34: 15 | I34: 10 | J34: 6 | K34: 12 | L34: 7 | M34: 7 | N34: 6 | O34: 13 | P34: 13 | Q34: 7 | R34: 14 | S34: 9 | T34: 3 | U34: 7 | V34: 13 | W34: 11 | X34: 7 | Y34: 5 | Z34: 9 | AA34: 5 | AB34: 6 | AE34: 4 | AF34: 7 | AG34: =SUM(B34:AF34) -> 260
A35: 14:00 | B35: 7 | C35: 8 | D35: 14 | E35: 12 | F35: 11 | G35: 6 | H35: 11 | I35: 6 | J35: 12 | K35: 12 | L35: 4 | M35: 7 | N35: 8 | O35: 13 | P35: 9 | Q35: 19 | R35: 6 | S35: 3 | T35: 9 | U35: 10 | V35: 9 | W35: 9 | X35: 16 | Y35: 1 | Z35: 6 | AA35: 8 | AB35: 10 | AE35: 14 | AF35: 7 | AG35: =SUM(B35:AF35) -> 267
A36: 15:00 | B36: 11 | C36: 12 | D36: 17 | E36: 12 | F36: 11 | G36: 14 | H36: 16 | I36: 12 | J36: 13 | K36: 10 | L36: 9 | M36: 12 | N36: 11 | O36: 10 | P36: 8 | Q36: 14 | R36: 13 | S36: 14 | T36: 11 | U36: 12 | V36: 10 | W36: 11 | X36: 15 | Y36: 3 | Z36: 17 | AA36: 9 | AB36: 5 | AE36: 18 | AF36: 7 | AG36: =SUM(B36:AF36) -> 337
A37: 16:00 | B37: 7 | C37: 17 | D37: 15 | E37: 13 | F37: 6 | G37: 11 | H37: 16 | I37: 14 | J37: 12 | K37: 17 | L37: 7 | M37: 12 | N37: 10 | O37: 11 | P37: 10 | Q37: 15 | R37: 12 | S37: 13 | T37: 8 | U37: 8 | V37: 14 | W37: 17 | X37: 12 | Y37: 18 | Z37: 15 | AA37: 8 | AB37: 9 | AE37: 15 | AF37: 8 | AG37: =SUM(B37:AF37) -> 350
A38: 17:00 | B38: 16 | C38: 14 | D38: 7 | E38: 10 | F38: 13 | G38: 5 | H38: 15 | I38: 12 | J38: 5 | K38: 15 | L38: 14 | M38: 5 | N38: 10 | O38: 21 | P38: 11 | Q38: 10 | R38: 11 | S38: 9 | T38: 12 | U38: 9 | V38: 9 | W38: 13 | X38: 2 | Y38: 12 | Z38: 7 | AA38: 9 | AB38: 8 | AE38: 11 | AF38: 5 | AG38: =SUM(B38:AF38) -> 300
A39: 18:00 | B39: 10 | C39: 13 | D39: 10 | E39: 12 | F39: 20 | G39: 13 | H39: 16 | I39: 13 | J39: 14 | K39: 15 | L39: 15 | M39: 22 | N39: 10 | O39: 15 | P39: 14 | Q39: 12 | R39: 16 | S39: 9 | T39: 16 | U39: 19 | V39: 10 | W39: 14 | X39: 19 | Y39: 13 | Z39: 14 | AA39: 18 | AB39: 14 | AE39: 12 | AF39: 7 | AG39: =SUM(B39:AF39) -> 405
A40: 19:00 | B40: 9 | C40: 18 | D40: 28 | E40: 13 | F40: 17 | G40: 19 | H40: 12 | I40: 11 | J40: 20 | K40: 16 | L40: 22 | M40: 20 | N40: 16 | O40: 12 | P40: 9 | Q40: 16 | R40: 14 | S40: 24 | T40: 17 | U40: 17 | V40: 16 | W40: 13 | X40: 22 | Y40: 23 | Z40: 26 | AA40: 17 | AB40: 12 | AE40: 14 | AF40: 11 | AG40: =SUM(B40:AF40) -> 484
... A47: 02:00 | B47: 3 | C47: 0 | D47: 10 | E47: 1 | F47: 2 | G47: 3 | H47: 6 | I47: 2 | J47: 2 | K47: 5 | L47: 5 | M47: 3 | N47: 4 | O47: 1 | P47: 3 | Q47: 10 | R47: 10 | S47: 3 | T47: 3 | U47: 1 | V47: 4 | W47: 8 | X47: 1 | Y47: 1 | Z47: 7 | AA47: 3 | AB47: 3 | AE47: 3 | AF47: 4 | AG47: =SUM(B47:AF47) -> 111
A48: 03:00 | B48: 1 | C48: 1 | D48: 1 | E48: 0 | F48: 4 | G48: 6 | H48: 2 | I48: 1 | J48: 2 | K48: 0 | L48: 2 | M48: 4 | N48: 7 | O48: 2 | P48: 0 | Q48: 2 | R48: 0 | S48: 4 | T48: 1 | V48: 1 | W48: 5 | X48: 2 | Y48: 5 | Z48: 1 | AA48: 2 | AE48: 2 | AF48: 11 | AG48: =SUM(B48:AF48) -> 69
A49: 04:00 | B49: 2 | C49: 0 | D49: 0 | E49: 0 | F49: 2 | G49: 0 | H49: 1 | I49: 2 | J49: 0 | K49: 0 | L49: 2 | M49: 1 | N49: 1 | O49: 3 | P49: 0 | Q49: 1 | R49: 0 | S49: 0 | T49: 3 | V49: 2 | W49: 1 | AA49: 2 | AE49: 2 | AG49: =SUM(B49:AF49) -> 25
A50: 05:00 | B50: 1 | C50: 0 | D50: 2 | E50: 0 | F50: 4 | G50: 0 | H50: 1 | I50: 2 | J50: 0 | K50: 2 | L50: 2 | M50: 0 | N50: 0 | O50: 0 | P50: 3 | Q50: 0 | R50: 0 | S50: 0 | T50: 1 | V50: 1 | X50: 1 | Y50: 1 | Z50: 1 | AG50: =SUM(B50:AF50) -> 22
A51: 06:00 | B51: 1 | C51: 0 | D51: 3 | E51: 0 | F51: 0 | G51: 0 | H51: 2 | I51: 1 | J51: 0 | K51: 0 | L51: 0 | M51: 0 | N51: 0 | O51: 3 | P51: 2 | Q51: 1 | R51: 0 | S51: 0 | T51: 1 | U51: 3 | W51: 3 | Z51: 1 | AG51: =SUM(B51:AF51) -> 21
A52: 07:00 | B52: 4 | C52: 0 | D52: 2 | E52: 0 | F52: 0 | G52: 6 | H52: 0 | I52: 3 | J52: 1 | K52: 3 | L52: 2 | M52: 0 | N52: 0 | O52: 0 | P52: 2 | Q52: 1 | R52: 0 | S52: 3 | T52: 3 | U52: 3 | W52: 2 | X52: 3 | Y52: 4 | Z52: 2 | AA52: 3 | AE52: 2 | AG52: =SUM(B52:AF52) -> 49
...

Sheet FEBRERO
A2: FEBRERO | B2: 1 | C2: =+B2+1 -> 2 | D2: =+C2+1 -> 3 | E2: =+D2+1 -> 4 | F2: =+E2+1 -> 5 | G2: =+F2+1 -> 6 | H2: =+G2+1 -> 7 | I2: =+H2+1 -> 8 | J2: =+I2+1 -> 9 | ... AA2: =+Z2+1 -> 26 | AB2: 27 | AC2: =+AB2+1 -> 28 | AD2: 29 | AE2: 30 | AF2: 31 | AG2: TOTAL
A3: Total de Inscritos | B3: =SUM(B4:B27) -> 228 | C3: =SUM(C4:C27) -> 181 | D3: =SUM(D4:D27) -> 174 | E3: =SUM(E4:E27) -> 166 | F3: =SUM(F4:F27) -> 194 | G3: =SUM(G4:G27) -> 243 | H3: =SUM(H4:H27) -> 82 | I3: =SUM(I4:I27) -> 227 | ... AF3: =SUM(AF4:AF27) -> 0 | AG3: =SUM(B3:AF3) -> 5643 | AH3: =135+AG3 -> 5778
A4: 08:00 | B4: 14 | C4: 3 | D4: 9 | E4: 8 | F4: 6 | G4: 13 | I4: 10 | J4: 5 | K4: 13 | L4: 6 | M4: 5 | N4: 11 | O4: 13 | P4: 13 | Q4: 1 | R4: 5 | S4: 7 | T4: 2 | U4: 14 | V4: 7 | W4: 11 | X4: 9 | Y4: 5 | Z4: 10 | AA4: 2 | AB4: 15 | AC4: 17 | AG4: =SUM(B4:AF4) -> 234
A5: 09:00 | B5: 15 | C5: 13 | D5: 13 | E5: 17 | F5: 6 | G5: 15 | I5: 12 | J5: 6 | K5: 10 | L5: 13 | M5: 12 | N5: 11 | O5: 13 | P5: 16 | Q5: 11 | R5: 8 | S5: 10 | T5: 6 | U5: 11 | V5: 11 | W5: 12 | X5: 13 | Y5: 11 | Z5: 13 | AA5: 9 | AB5: 13 | AC5: 10 | AG5: =SUM(B5:AF5) -> 310
A6: 10:00 | B6: 12 | C6: 12 | D6: 12 | E6: 9 | F6: 16 | G6: 13 | I6: 12 | J6: 12 | K6: 11 | L6: 7 | M6: 10 | N6: 16 | O6: 15 | P6: 7 | Q6: 8 | R6: 11 | S6: 14 | T6: 12 | U6: 17 | V6: 12 | W6: 12 | X6: 13 | Y6: 11 | Z6: 15 | AA6: 9 | AB6: 15 | AC6: 22 | AG6: =SUM(B6:AF6) -> 335
A7: 11:00 | B7: 12 | C7: 9 | D7: 13 | E7: 10 | F7: 12 | G7: 14 | I7: 17 | J7: 10 | K7: 9 | L7: 12 | M7: 11 | N7: 19 | O7: 8 | P7: 10 | Q7: 11 | R7: 10 | S7: 8 | T7: 13 | U7: 15 | V7: 14 | W7: 15 | X7: 11 | Y7: 12 | Z7: 11 | AA7: 7 | AB7: 7 | AC7: 11 | AG7: =SUM(B7:AF7) -> 311
A8: 12:00 | B8: 16 | C8: 9 | D8: 19 | E8: 13 | F8: 19 | G8: 13 | I8: 15 | J8: 14 | K8: 15 | L8: 11 | M8: 15 | N8: 13 | O8: 12 | P8: 10 | Q8: 12 | R8: 9 | S8: 15 | T8: 9 | U8: 10 | V8: 9 | W8: 11 | X8: 9 | Y8: 10 | Z8: 13 | AA8: 18 | AB8: 12 | AC8: 16 | AG8: =SUM(B8:AF8) -> 347
A9: 13:00 | B9: 10 | C9: 16 | D9: 5 | E9: 5 | F9: 13 | G9: 7 | I9: 12 | J9: 13 | K9: 12 | L9: 16 | M9: 16 | N9: 7 | O9: 3 | P9: 6 | Q9: 13 | R9: 7 | S9: 13 | T9: 9 | U9: 14 | V9: 8 | W9: 9 | X9: 6 | Y9: 15 | Z9: 9 | AA9: 15 | AB9: 12 | AC9: 12 | AG9: =SUM(B9:AF9) -> 283
A10: 14:00 | B10: 9 | C10: 6 | D10: 13 | E10: 5 | F10: 19 | G10: 8 | I10: 11 | J10: 5 | K10: 13 | L10: 10 | M10: 11 | N10: 11 | O10: 7 | P10: 9 | Q10: 11 | R10: 7 | S10: 14 | T10: 9 | U10: 15 | V10: 15 | W10: 14 | X10: 14 | Y10: 11 | Z10: 9 | AA10: 8 | AB10: 16 | AC10: 13 | AG10: =SUM(B10:AF10) -> 293
A11: 15:00 | B11: 6 | C11: 12 | D11: 1 | E11: 16 | F11: 7 | G11: 11 | I11: 11 | J11: 15 | K11: 17 | L11: 11 | M11: 19 | N11: 12 | O11: 6 | P11: 16 | Q11: 9 | R11: 13 | S11: 9 | T11: 17 | U11: 15 | V11: 19 | W11: 8 | X11: 13 | Y11: 13 | Z11: 13 | AA11: 12 | AB11: 12 | AC11: 16 | AG11: =SUM(B11:AF11) -> 329
A12: 16:00 | B12: 14 | C12: 14 | D12: 14 | E12: 14 | F12: 10 | G12: 31 | I12: 17 | J12: 17 | K12: 17 | L12: 14 | M12: 17 | N12: 23 | O12: 9 | P12: 19 | Q12: 15 | R12: 10 | S12: 6 | T12: 14 | U12: 20 | V12: 20 | W12: 11 | X12: 20 | Y12: 15 | Z12: 8 | AA12: 12 | AB12: 17 | AC12: 24 | AG12: =SUM(B12:AF12) -> 422
A13: 17:00 | B13: 15 | C13: 20 | D13: 10 | E13: 11 | F13: 12 | G13: 21 | I13: 22 | J13: 23 | K13: 13 | L13: 14 | M13: 6 | N13: 15 | O13: 15 | P13: 23 | Q13: 12 | R13: 15 | S13: 12 | T13: 15 | U13: 27 | V13: 16 | W13: 16 | X13: 12 | Y13: 18 | Z13: 19 | AA13: 13 | AB13: 22 | AC13: 17 | AG13: =SUM(B13:AF13) -> 434
A14: 18:00 | B14: 20 | C14: 9 | D14: 10 | E14: 9 | F14: 10 | G14: 22 | I14: 16 | J14: 11 | K14: 7 | L14: 11 | M14: 8 | N14: 16 | O14: 10 | P14: 24 | Q14: 13 | R14: 8 | S14: 9 | T14: 16 | U14: 23 | V14: 22 | W14: 2 | X14: 10 | Y14: 13 | Z14: 18 | AA14: 16 | AB14: 13 | AC14: 20 | AG14: =SUM(B14:AF14) -> 366
A15: 19:00 | B15: 15 | C15: 9 | D15: 11 | E15: 11 | F15: 9 | G15: 18 | H15: 8 | I15: 9 | J15: 10 | K15: 7 | L15: 10 | M15: 10 | N15: 17 | O15: 9 | P15: 15 | Q15: 14 | R15: 12 | S15: 8 | T15: 12 | U15: 16 | V15: 12 | W15: 21 | X15: 18 | Y15: 10 | Z15: 8 | AA15: 13 | AB15: 18 | AC15: 16 | AG15: =SUM(B15:AF15) -> 346
A16: 20:00 | B16: 19 | C16: 8 | D16: 3 | E16: 6 | F16: 8 | G16: 12 | H16: 12 | I16: 10 | J16: 12 | K16: 8 | L16: 12 | M16: 20 | N16: 15 | O16: 11 | P16: 12 | Q16: 11 | R16: 16 | S16: 7 | T16: 6 | U16: 12 | V16: 12 | W16: 14 | X16: 6 | Y16: 14 | Z16: 8 | AA16: 7 | AB16: 17 | AC16: 10 | AG16: =SUM(B16:AF16) -> 308
A17: 21:00 | B17: 13 | C17: 11 | D17: 11 | E17: 7 | F17: 11 | G17: 11 | H17: 19 | I17: 16 | J17: 16 | K17: 14 | L17: 12 | M17: 9 | N17: 12 | O17: 14 | P17: 10 | Q17: 15 | R17: 9 | S17: 8 | T17: 14 | U17: 17 | V17: 11 | W17: 10 | X17: 7 | Y17: 8 | Z17: 14 | AA17: 9 | AB17: 6 | AC17: 13 | AG17: =SUM(B17:AF17) -> 327
A18: 22:00 | B18: 11 | C18: 4 | D18: 6 | E18: 8 | F18: 13 | G18: 10 | H18: 14 | I18: 10 | J18: 10 | K18: 13 | L18: 5 | M18: 9 | N18: 9 | O18: 6 | P18: 9 | Q18: 12 | R18: 5 | S18: 7 | T18: 11 | U18: 12 | V18: 8 | W18: 12 | X18: 5 | Y18: 9 | Z18: 6 | AA18: 5 | AB18: 16 | AC18: 16 | AG18: =SUM(B18:AF18) -> 261
A19: 23:00 | B19: 3 | C19: 7 | D19: 7 | E19: 3 | F19: 12 | G19: 10 | H19: 5 | I19: 7 | J19: 3 | K19: 4 | L19: 1 | M19: 6 | N19: 6 | O19: 8 | P19: 3 | Q19: 5 | R19: 4 | S19: 7 | T19: 9 | U19: 5 | V19: 11 | W19: 16 | X19: 7 | Y19: 6 | Z19: 10 | AA19: 4 | AB19: 4 | AC19: 7 | AG19: =SUM(B19:AF19) -> 180
A20: 00:00 | B20: 7 | C20: 6 | D20: 4 | E20: 6 | F20: 4 | G20: 6 | H20: 5 | I20: 5 | J20: 5 | K20: 9 | L20: 6 | M20: 7 | N20: 2 | O20: 1 | P20: 2 | Q20: 9 | R20: 6 | S20: 6 | T20: 4 | U20: 3 | V20: 7 | W20: 7 | X20: 2 | Y20: 4 | Z20: 5 | AA20: 8 | AB20: 7 | AC20: 3 | AG20: =SUM(B20:AF20) -> 146
A21: 01:00 | B21: 5 | C21: 3 | D21: 7 | E21: 2 | F21: 1 | G21: 5 | H21: 3 | I21: 3 | J21: 6 | K21: 0 | L21: 5 | M21: 4 | N21: 6 | O21: 4 | P21: 3 | Q21: 2 | R21: 3 | S21: 3 | T21: 6 | U21: 5 | V21: 0 | W21: 2 | X21: 1 | Y21: 1 | Z21: 1 | AA21: 8 | AB21: 3 | AC21: 1 | AG21: =SUM(B21:AF21) -> 93
A22: 02:00 | B22: 3 | C22: 5 | D22: 3 | E22: 3 | F22: 1 | G22: 3 | H22: 1 | I22: 1 | J22: 1 | K22: 1 | L22: 1 | M22: 1 | N22: 0 | O22: 2 | P22: 0 | Q22: 1 | R22: 1 | S22: 3 | T22: 1 | U22: 4 | V22: 1 | W22: 6 | X22: 4 | Y22: 2 | AA22: 5 | AB22: 3 | AC22: 1 | AG22: =SUM(B22:AF22) -> 58
A23: 03:00 | B23: 2 | C23: 0 | D23: 1 | E23: 0 | F23: 0 | G23: 0 | H23: 5 | I23: 1 | J23: 1 | K23: 2 | L23: 2 | M23: 2 | N23: 1 | O23: 2 | P23: 3 | Q23: 1 | R23: 3 | S23: 0 | T23: 1 | U23: 0 | V23: 1 | Y23: 0 | Z23: 1 | AA23: 2 | AB23: 1 | AC23: 1 | AG23: =SUM(B23:AF23) -> 33
A24: 04:00 | B24: 0 | C24: 1 | D24: 0 | E24: 1 | F24: 0 | G24: 0 | H24: 1 | I24: 1 | J24: 1 | K24: 0 | L24: 0 | M24: 1 | N24: 1 | O24: 3 | P24: 1 | Q24: 2 | R24: 1 | S24: 5 | T24: 1 | U24: 1 | V24: 4 | W24: 1 | X24: 6 | Y24: 1 | Z24: 2 | AA24: 4 | AB24: 2 | AC24: 5 | AG24: =SUM(B24:AF24) -> 46
A25: 05:00 | B25: 4 | C25: 0 | D25: 0 | E25: 1 | F25: 0 | G25: 0 | H25: 1 | I25: 1 | J25: 1 | K25: 2 | L25: 1 | M25: 0 | N25: 5 | O25: 1 | P25: 1 | Q25: 1 | R25: 1 | S25: 0 | T25: 0 | U25: 2 | V25: 0 | Y25: 0 | AA25: 1 | AB25: 4 | AC25: 3 | AG25: =SUM(B25:AF25) -> 30
A26: 06:00 | B26: 0 | C26: 1 | D26: 1 | E26: 0 | F26: 2 | G26: 0 | H26: 2 | I26: 0 | J26: 2 | K26: 0 | L26: 3 | M26: 0 | N26: 2 | O26: 0 | P26: 2 | Q26: 0 | R26: 1 | S26: 0 | T26: 1 | U26: 1 | V26: 2 | W26: 1 | X26: 3 | Y26: 4 | Z26: 2 | AA26: 3 | AB26: 1 | AC26: 1 | AG26: =SUM(B26:AF26) -> 35
A27: 07:00 | B27: 3 | C27: 3 | D27: 1 | E27: 1 | F27: 3 | G27: 0 | H27: 6 | I27: 8 | J27: 5 | K27: 4 | L27: 3 | M27: 13 | N27: 8 | O27: 2 | P27: 4 | Q27: 7 | R27: 2 | S27: 1 | T27: 5 | U27: 7 | V27: 2 | W27: 3 | X27: 6 | Y27: 4 | Z27: 2 | AA27: 5 | AB27: 3 | AC27: 5 | AG27: =SUM(B27:AF27) -> 116
A28: Total de atendidos | B28: =SUM(B29:B52) -> 190 | C28: =SUM(C29:C52) -> 162 | D28: =SUM(D29:D52) -> 159 | E28: =SUM(E29:E52) -> 164 | F28: =SUM(F29:F52) -> 193 | G28: =SUM(G29:G52) -> 208 | H28: =SUM(H29:H52) -> 78 | I28: =SUM(I29:I52) -> 197 | ... AF28: =SUM(AF29:AF52) -> 0 | AG28: =SUM(B28:AF28) -> 5247 | AH28: =135+AG28 -> 5382
A29: 08:00 | B29: 5 | C29: 3 | D29: 4 | E29: 4 | F29: 5 | G29: 3 | H29: 3 | I29: 11 | J29: 5 | K29: 8 | L29: 1 | M29: 8 | N29: 1 | O29: 4 | P29: 4 | Q29: 6 | R29: 3 | S29: 6 | T29: 5 | U29: 7 | V29: 3 | W29: 3 | X29: 8 | Y29: 4 | Z29: 3 | AA29: 6 | AB29: 6 | AC29: 5 | AG29: =SUM(B29:AF29) -> 134
A30: 09:00 | B30: 12 | C30: 7 | D30: 10 | E30: 13 | F30: 7 | G30: 9 | H30: 1 | I30: 6 | J30: 6 | K30: 11 | L30: 10 | M30: 12 | N30: 9 | O30: 17 | P30: 17 | Q30: 10 | R30: 8 | S30: 4 | T30: 4 | U30: 12 | V30: 9 | W30: 11 | X30: 14 | Y30: 8 | Z30: 5 | AA30: 5 | AB30: 13 | AC30: 11 | AG30: =SUM(B30:AF30) -> 261
A31: 10:00 | B31: 10 | C31: 5 | D31: 9 | E31: 10 | F31: 7 | G31: 10 | I31: 8 | J31: 8 | K31: 9 | L31: 10 | M31: 11 | N31: 15 | O31: 12 | P31: 11 | Q31: 5 | R31: 11 | S31: 16 | T31: 6 | U31: 14 | V31: 7 | W31: 9 | X31: 9 | Y31: 9 | Z31: 14 | AA31: 7 | AB31: 12 | AC31: 10 | AG31: =SUM(B31:AF31) -> 264
A32: 11:00 | B32: 6 | C32: 9 | D32: 1 | E32: 8 | F32: 12 | G32: 13 | I32: 8 | J32: 10 | K32: 11 | L32: 12 | M32: 10 | N32: 10 | O32: 11 | P32: 6 | Q32: 9 | R32: 9 | S32: 10 | T32: 17 | U32: 9 | V32: 7 | W32: 7 | X32: 12 | Y32: 10 | Z32: 16 | AA32: 11 | AB32: 13 | AC32: 11 | AG32: =SUM(B32:AF32) -> 268
A33: 12:00 | B33: 5 | C33: 10 | D33: 11 | E33: 7 | F33: 8 | G33: 9 | I33: 9 | J33: 6 | K33: 8 | L33: 11 | M33: 14 | N33: 11 | O33: 10 | P33: 8 | Q33: 10 | R33: 7 | S33: 17 | T33: 9 | U33: 5 | V33: 8 | W33: 14 | X33: 8 | Y33: 11 | Z33: 9 | AA33: 14 | AB33: 7 | AC33: 7 | AG33: =SUM(B33:AF33) -> 253
A34: 13:00 | B34: 7 | C34: 5 | D34: 5 | E34: 10 | F34: 9 | G34: 3 | I34: 4 | J34: 5 | K34: 9 | L34: 7 | M34: 15 | N34: 7 | O34: 7 | P34: 5 | Q34: 8 | R34: 6 | S34: 10 | T34: 10 | U34: 12 | V34: 7 | W34: 5 | X34: 4 | Y34: 4 | Z34: 9 | AA34: 12 | AB34: 4 | AC34: 5 | AG34: =SUM(B34:AF34) -> 194
A35: 14:00 | B35: 11 | C35: 10 | D35: 12 | E35: 7 | F35: 15 | G35: 10 | I35: 10 | J35: 9 | K35: 4 | L35: 7 | M35: 9 | N35: 12 | O35: 5 | P35: 9 | Q35: 6 | R35: 8 | S35: 9 | T35: 3 | U35: 4 | V35: 3 | W35: 6 | X35: 7 | Y35: 7 | Z35: 9 | AA35: 10 | AB35: 9 | AC35: 7 | AG35: =SUM(B35:AF35) -> 218
A36: 15:00 | B36: 9 | C36: 11 | D36: 13 | E36: 14 | F36: 18 | G36: 16 | I36: 14 | J36: 8 | K36: 11 | L36: 12 | M36: 10 | N36: 10 | O36: 8 | P36: 12 | Q36: 12 | R36: 8 | S36: 13 | T36: 14 | U36: 3 | W36: 7 | X36: 9 | Y36: 8 | Z36: 11 | AA36: 12 | AB36: 13 | AC36: 13 | AG36: =SUM(B36:AF36) -> 289
A37: 16:00 | B37: 10 | C37: 13 | D37: 9 | E37: 13 | F37: 10 | G37: 12 | I37: 9 | J37: 12 | K37: 11 | L37: 13 | M37: 11 | N37: 17 | O37: 5 | P37: 12 | Q37: 10 | R37: 9 | S37: 9 | T37: 18 | U37: 10 | V37: 8 | W37: 5 | X37: 10 | Y37: 6 | Z37: 6 | AA37: 10 | AB37: 12 | AC37: 14 | AG37: =SUM(B37:AF37) -> 284
A38: 17:00 | B38: 14 | C38: 8 | D38: 9 | E38: 7 | F38: 8 | G38: 6 | I38: 5 | J38: 9 | K38: 6 | L38: 17 | M38: 15 | N38: 8 | O38: 7 | P38: 13 | Q38: 10 | R38: 6 | S38: 8 | T38: 10 | U38: 14 | V38: 22 | W38: 9 | X38: 9 | Y38: 9 | Z38: 9 | AA38: 17 | AB38: 12 | AC38: 14 | AG38: =SUM(B38:AF38) -> 281
A39: 18:00 | B39: 11 | C39: 15 | D39: 6 | E39: 14 | F39: 22 | G39: 13 | I39: 14 | J39: 18 | K39: 14 | L39: 10 | M39: 12 | N39: 18 | O39: 18 | P39: 16 | Q39: 16 | R39: 12 | S39: 9 | T39: 15 | U39: 16 | V39: 20 | W39: 1 | X39: 21 | Y39: 15 | Z39: 19 | AA39: 12 | AB39: 16 | AC39: 17 | AG39: =SUM(B39:AF39) -> 390
A40: 19:00 | B40: 22 | C40: 16 | D40: 14 | E40: 14 | F40: 12 | G40: 15 | I40: 18 | J40: 19 | K40: 18 | L40: 13 | M40: 13 | N40: 18 | O40: 10 | P40: 19 | Q40: 20 | R40: 8 | S40: 11 | T40: 17 | U40: 20 | V40: 17 | W40: 15 | X40: 17 | Y40: 18 | Z40: 17 | AA40: 17 | AB40: 15 | AC40: 19 | AG40: =SUM(B40:AF40) -> 432
A41: 20:00 | B41: 15 | C41: 11 | D41: 13 | E41: 8 | F41: 12 | G41: 17 | H41: 6 | I41: 23 | J41: 16 | K41: 12 | L41: 12 | M41: 13 | N41: 18 | O41: 14 | P41: 25 | Q41: 16 | R41: 17 | S41: 11 | T41: 12 | U41: 18 | V41: 17 | W41: 14 | X41: 17 | Y41: 17 | Z41: 13 | AA41: 9 | AB41: 21 | AC41: 23 | AG41: =SUM(B41:AF41) -> 420
...

Sheet MARZO
A2: MARZO | B2: 1 | C2: =+B2+1 -> 2 | D2: =+C2+1 -> 3 | E2: =+D2+1 -> 4 | F2: =+E2+1 -> 5 | G2: =+F2+1 -> 6 | H2: =+G2+1 -> 7 | I2: =+H2+1 -> 8 | J2: =+I2+1 -> 9 | ... AA2: =+Z2+1 -> 26 | AB2: 27 | AC2: =+AB2+1 -> 28 | AD2: 29 | AE2: 30 | AF2: 31 | AG2: TOTAL
A3: Total de Inscritos | B3: =SUM(B4:B27) -> 203 | C3: =SUM(C4:C27) -> 191 | D3: =SUM(D4:D27) -> 226 | E3: =SUM(E4:E27) -> 220 | F3: =SUM(F4:F27) -> 204 | G3: =SUM(G4:G27) -> 245 | H3: =SUM(H4:H27) -> 233 | I3: =SUM(I4:I27) -> 225 | ... AF3: =SUM(AF4:AF27) -> 245 | AG3: =SUM(B3:AF3) -> 8086
A4: 08:00 | B4: 10 | C4: 11 | D4: 6 | E4: 10 | F4: 1 | G4: 18 | H4: 13 | I4: 16 | J4: 19 | K4: 11 | L4: 5 | M4: 4 | N4: 20 | O4: 19 | P4: 25 | Q4: 18 | R4: 17 | S4: 7 | T4: 6 | U4: 27 | V4: 21 | W4: 22 | X4: 17 | Y4: 20 | Z4: 9 | AA4: 13 | AB4: 6 | AC4: 16 | AD4: 8 | AE4: 14 | AF4: 11 | AG4: =SUM(B4:AF4) -> 420
A5: 09:00 | B5: 12 | C5: 11 | D5: 9 | E5: 13 | F5: 7 | G5: 18 | H5: 16 | I5: 10 | J5: 17 | K5: 16 | L5: 12 | M5: 15 | N5: 26 | O5: 20 | P5: 23 | Q5: 18 | R5: 22 | S5: 11 | T5: 13 | U5: 28 | V5: 29 | W5: 20 | X5: 17 | Y5: 16 | Z5: 29 | AA5: 9 | AB5: 26 | AC5: 22 | AD5: 12 | AE5: 19 | AF5: 18 | AG5: =SUM(B5:AF5) -> 534
A6: 10:00 | B6: 10 | C6: 14 | D6: 11 | E6: 15 | F6: 17 | G6: 21 | H6: 17 | I6: 15 | J6: 14 | K6: 5 | L6: 13 | M6: 11 | N6: 20 | O6: 21 | P6: 25 | Q6: 21 | R6: 19 | S6: 13 | T6: 17 | U6: 36 | V6: 32 | W6: 14 | X6: 15 | Y6: 21 | Z6: 17 | AA6: 14 | AB6: 20 | AC6: 20 | AD6: 16 | AE6: 17 | AF6: 17 | AG6: =SUM(B6:AF6) -> 538
A7: 11:00 | B7: 6 | C7: 10 | D7: 10 | E7: 22 | F7: 18 | G7: 10 | H7: 22 | I7: 9 | J7: 12 | K7: 12 | L7: 12 | M7: 16 | N7: 21 | O7: 14 | P7: 21 | Q7: 25 | R7: 19 | S7: 16 | T7: 24 | U7: 21 | V7: 13 | W7: 24 | X7: 26 | Y7: 25 | Z7: 16 | AA7: 19 | AB7: 24 | AC7: 18 | AD7: 23 | AE7: 16 | AF7: 11 | AG7: =SUM(B7:AF7) -> 535
A8: 12:00 | B8: 8 | C8: 5 | D8: 17 | E8: 15 | F8: 13 | G8: 12 | H8: 11 | I8: 12 | J8: 15 | K8: 19 | L8: 17 | M8: 25 | N8: 17 | O8: 19 | P8: 16 | Q8: 23 | R8: 16 | S8: 12 | T8: 19 | U8: 17 | V8: 15 | W8: 15 | X8: 19 | Y8: 9 | Z8: 25 | AA8: 27 | AB8: 17 | AC8: 17 | AD8: 16 | AE8: 13 | AF8: 21 | AG8: =SUM(B8:AF8) -> 502
A9: 13:00 | B9: 5 | C9: 3 | D9: 13 | E9: 9 | F9: 10 | G9: 11 | H9: 11 | I9: 4 | J9: 12 | K9: 8 | L9: 19 | M9: 37 | N9: 16 | O9: 14 | P9: 26 | Q9: 24 | R9: 9 | S9: 17 | T9: 21 | U9: 15 | V9: 9 | W9: 12 | X9: 12 | Y9: 6 | Z9: 13 | AA9: 10 | AB9: 17 | AC9: 17 | AD9: 15 | AE9: 12 | AF9: 10 | AG9: =SUM(B9:AF9) -> 417
A10: 14:00 | B10: 15 | C10: 18 | D10: 12 | E10: 9 | F10: 11 | G10: 12 | H10: 5 | I10: 9 | J10: 10 | K10: 13 | L10: 12 | M10: 16 | N10: 23 | O10: 18 | P10: 20 | Q10: 18 | R10: 23 | S10: 13 | T10: 9 | U10: 15 | V10: 17 | W10: 17 | X10: 12 | Y10: 10 | Z10: 13 | AA10: 15 | AB10: 11 | AC10: 20 | AD10: 7 | AE10: 11 | AF10: 15 | AG10: =SUM(B10:AF10) -> 429
A11: 15:00 | B11: 2 | C11: 9 | D11: 10 | E11: 12 | F11: 17 | G11: 18 | H11: 11 | I11: 12 | J11: 12 | K11: 22 | L11: 11 | M11: 16 | N11: 10 | O11: 18 | P11: 22 | Q11: 13 | R11: 12 | S11: 23 | T11: 15 | U11: 19 | V11: 16 | W11: 21 | X11: 12 | Y11: 14 | Z11: 15 | AA11: 18 | AB11: 16 | AC11: 22 | AD11: 14 | AE11: 14 | AF11: 15 | AG11: =SUM(B11:AF11) -> 461
A12: 16:00 | B12: 16 | C12: 18 | D12: 20 | E12: 16 | F12: 22 | G12: 19 | H12: 14 | I12: 21 | J12: 22 | K12: 10 | L12: 17 | M12: 19 | N12: 24 | O12: 31 | P12: 31 | Q12: 21 | R12: 23 | S12: 13 | T12: 23 | U12: 29 | V12: 26 | W12: 28 | X12: 20 | Y12: 14 | Z12: 20 | AA12: 17 | AB12: 25 | AC12: 12 | AD12: 29 | AE12: 17 | AF12: 15 | AG12: =SUM(B12:AF12) -> 632
A13: 17:00 | B13: 15 | C13: 13 | D13: 14 | E13: 18 | F13: 10 | G13: 14 | H13: 21 | I13: 25 | J13: 16 | K13: 17 | L13: 17 | M13: 20 | N13: 29 | O13: 17 | P13: 18 | Q13: 25 | R13: 8 | S13: 12 | T13: 14 | U13: 25 | V13: 28 | W13: 18 | X13: 19 | Y13: 14 | Z13: 13 | AA13: 27 | AB13: 25 | AC13: 21 | AD13: 18 | AE13: 22 | AF13: 14 | AG13: =SUM(B13:AF13) -> 567
A14: 18:00 | B14: 15 | C14: 11 | D14: 14 | E14: 12 | F14: 13 | G14: 17 | H14: 21 | I14: 15 | J14: 18 | K14: 13 | L14: 17 | M14: 18 | N14: 32 | O14: 20 | P14: 21 | Q14: 23 | R14: 8 | S14: 18 | T14: 9 | U14: 26 | V14: 33 | W14: 9 | X14: 16 | Y14: 13 | Z14: 13 | AA14: 9 | AB14: 25 | AC14: 20 | AD14: 19 | AE14: 16 | AF14: 19 | AG14: =SUM(B14:AF14) -> 533
A15: 19:00 | B15: 18 | C15: 10 | D15: 17 | E15: 11 | F15: 7 | G15: 18 | H15: 15 | I15: 17 | J15: 14 | K15: 12 | L15: 6 | M15: 11 | N15: 28 | O15: 19 | P15: 18 | Q15: 15 | R15: 13 | S15: 14 | T15: 5 | U15: 18 | V15: 21 | W15: 17 | X15: 21 | Y15: 21 | Z15: 21 | AA15: 18 | AB15: 20 | AC15: 8 | AD15: 12 | AE15: 18 | AF15: 15 | AG15: =SUM(B15:AF15) -> 478
... A27: 07:00 | B27: 9 | C27: 4 | D27: 3 | E27: 2 | F27: 1 | G27: 3 | H27: 4 | I27: 4 | J27: 7 | K27: 4 | L27: 2 | M27: 7 | N27: 8 | O27: 6 | P27: 9 | Q27: 11 | R27: 2 | S27: 4 | T27: 6 | U27: 5 | V27: 7 | W27: 7 | X27: 4 | Y27: 4 | Z27: 1 | AA27: 2 | AB27: 3 | AC27: 8 | AD27: 3 | AE27: 2 | AF27: 3 | AG27: =SUM(B27:AF27) -> 145
A28: Total de atendidos | B28: =SUM(B29:B52) -> 195 | C28: =SUM(C29:C52) -> 178 | D28: =SUM(D29:D52) -> 203 | E28: =SUM(E29:E52) -> 214 | F28: =SUM(F29:F52) -> 197 | G28: =SUM(G29:G52) -> 208 | H28: =SUM(H29:H52) -> 202 | I28: =SUM(I29:I52) -> 215 | ... AF28: =SUM(AF29:AF52) -> 225 | AG28: =SUM(B28:AF28) -> 7090
A29: 08:00 | B29: 7 | C29: 3 | D29: 5 | E29: 7 | G29: 7 | H29: 9 | I29: 9 | J29: 8 | K29: 2 | L29: 3 | M29: 6 | N29: 7 | O29: 5 | P29: 17 | Q29: 8 | S29: 3 | T29: 6 | U29: 9 | V29: 8 | W29: 5 | X29: 8 | Y29: 6 | Z29: 5 | AA29: 5 | AB29: 4 | AC29: 15 | AD29: 3 | AE29: 3 | AF29: 5 | AG29: =SUM(B29:AF29) -> 188
A30: 09:00 | B30: 13 | C30: 5 | D30: 6 | E30: 10 | F30: 4 | G30: 12 | H30: 6 | I30: 11 | J30: 10 | K30: 13 | L30: 8 | M30: 9 | N30: 14 | O30: 13 | P30: 19 | Q30: 12 | R30: 13 | S30: 5 | T30: 8 | U30: 15 | V30: 13 | W30: 14 | X30: 10 | Y30: 14 | Z30: 12 | AA30: 13 | AB30: 11 | AC30: 14 | AD30: 10 | AE30: 9 | AF30: 13 | AG30: =SUM(B30:AF30) -> 339
A31: 10:00 | B31: 6 | C31: 12 | D31: 7 | E31: 14 | F31: 12 | G31: 11 | H31: 8 | I31: 11 | J31: 5 | K31: 10 | L31: 12 | M31: 16 | N31: 15 | O31: 8 | P31: 9 | Q31: 13 | R31: 14 | S31: 14 | T31: 18 | U31: 11 | V31: 15 | W31: 11 | X31: 10 | Y31: 12 | Z31: 18 | AA31: 9 | AB31: 10 | AC31: 3 | AD31: 7 | AE31: 6 | AF31: 13 | AG31: =SUM(B31:AF31) -> 340
A32: 11:00 | B32: 9 | C32: 15 | D32: 11 | E32: 12 | F32: 15 | G32: 9 | H32: 12 | I32: 11 | J32: 13 | K32: 13 | L32: 18 | M32: 11 | N32: 13 | O32: 10 | P32: 13 | Q32: 10 | R32: 14 | S32: 14 | T32: 14 | U32: 17 | V32: 11 | W32: 12 | X32: 12 | Y32: 7 | Z32: 17 | AA32: 17 | AB32: 7 | AC32: 13 | AD32: 8 | AE32: 11 | AF32: 12 | AG32: =SUM(B32:AF32) -> 381
A33: 12:00 | B33: 9 | C33: 9 | D33: 9 | E33: 9 | F33: 19 | G33: 12 | H33: 5 | I33: 12 | J33: 14 | K33: 6 | L33: 14 | M33: 14 | N33: 3 | O33: 10 | P33: 14 | Q33: 11 | R33: 13 | S33: 14 | T33: 16 | U33: 15 | V33: 11 | W33: 9 | X33: 11 | Y33: 12 | Z33: 23 | AA33: 20 | AB33: 6 | AC33: 12 | AD33: 10 | AE33: 13 | AF33: 15 | AG33: =SUM(B33:AF33) -> 370
A34: 13:00 | B34: 6 | C34: 2 | D34: 6 | E34: 16 | F34: 8 | G34: 4 | H34: 8 | I34: 6 | J34: 5 | K34: 10 | L34: 9 | M34: 21 | N34: 4 | O34: 8 | P34: 8 | Q34: 9 | R34: 9 | S34: 9 | T34: 14 | U34: 6 | V34: 6 | W34: 11 | X34: 11 | Y34: 6 | Z34: 16 | AA34: 17 | AB34: 9 | AC34: 11 | AD34: 6 | AE34: 7 | AF34: 7 | AG34: =SUM(B34:AF34) -> 275
A35: 14:00 | B35: 5 | C35: 9 | D35: 4 | E35: 5 | F35: 4 | G35: 10 | H35: 10 | I35: 6 | J35: 8 | K35: 6 | L35: 18 | M35: 19 | N35: 12 | O35: 12 | P35: 10 | Q35: 13 | R35: 4 | S35: 8 | T35: 7 | U35: 12 | V35: 12 | W35: 15 | X35: 11 | Y35: 5 | Z35: 11 | AA35: 10 | AB35: 19 | AC35: 13 | AD35: 15 | AE35: 6 | AF35: 12 | AG35: =SUM(B35:AF35) -> 311
A36: 15:00 | B36: 6 | C36: 11 | D36: 7 | E36: 14 | F36: 16 | G36: 5 | H36: 11 | I36: 12 | J36: 9 | K36: 10 | L36: 13 | M36: 13 | N36: 8 | O36: 12 | P36: 19 | Q36: 21 | R36: 9 | S36: 14 | T36: 16 | U36: 16 | V36: 12 | W36: 15 | X36: 16 | Y36: 13 | Z36: 17 | AA36: 18 | AB36: 18 | AC36: 13 | AD36: 22 | AE36: 7 | AF36: 13 | AG36: =SUM(B36:AF36) -> 406
A37: 16:00 | B37: 8 | C37: 10 | D37: 21 | E37: 14 | F37: 12 | G37: 12 | H37: 9 | I37: 11 | J37: 12 | K37: 12 | L37: 11 | M37: 12 | N37: 13 | O37: 12 | P37: 17 | Q37: 9 | R37: 11 | S37: 20 | T37: 21 | U37: 17 | V37: 14 | W37: 14 | X37: 10 | Y37: 9 | Z37: 18 | AA37: 13 | AB37: 9 | AC37: 17 | AD37: 9 | AE37: 16 | AF37: 12 | AG37: =SUM(B37:AF37) -> 405
A38: 17:00 | B38: 8 | C38: 6 | D38: 4 | E38: 12 | F38: 17 | G38: 7 | H38: 8 | I38: 14 | J38: 4 | K38: 14 | L38: 18 | M38: 14 | N38: 15 | O38: 9 | P38: 18 | Q38: 13 | R38: 8 | S38: 16 | T38: 17 | U38: 14 | V38: 11 | W38: 9 | X38: 12 | Y38: 7 | Z38: 16 | AA38: 14 | AB38: 11 | AC38: 17 | AD38: 9 | AE38: 8 | AF38: 10 | AG38: =SUM(B38:AF38) -> 360
A39: 18:00 | B39: 17 | C39: 17 | D39: 15 | E39: 12 | F39: 14 | G39: 17 | H39: 17 | I39: 15 | J39: 13 | K39: 11 | L39: 19 | M39: 15 | N39: 20 | O39: 14 | P39: 18 | Q39: 22 | R39: 18 | S39: 21 | T39: 22 | U39: 18 | V39: 17 | W39: 15 | X39: 22 | Y39: 11 | Z39: 21 | AA39: 22 | AB39: 11 | AC39: 9 | AD39: 16 | AE39: 22 | AF39: 16 | AG39: =SUM(B39:AF39) -> 517
A40: 19:00 | B40: 16 | C40: 18 | D40: 12 | E40: 12 | F40: 8 | G40: 16 | H40: 21 | I40: 20 | J40: 21 | K40: 13 | L40: 14 | M40: 14 | N40: 22 | O40: 20 | P40: 22 | Q40: 25 | R40: 21 | S40: 13 | T40: 12 | U40: 14 | V40: 21 | W40: 19 | X40: 24 | Y40: 17 | Z40: 16 | AA40: 19 | AB40: 16 | AC40: 17 | AD40: 22 | AE40: 18 | AF40: 15 | AG40: =SUM(B40:AF40) -> 538
A41: 20:00 | B41: 18 | C41: 10 | D41: 15 | E41: 10 | F41: 21 | G41: 20 | H41: 19 | I41: 20 | J41: 21 | K41: 16 | L41: 7 | M41: 23 | N41: 17 | O41: 23 | P41: 20 | Q41: 22 | R41: 21 | S41: 18 | T41: 12 | U41: 13 | V41: 22 | W41: 19 | X41: 20 | Y41: 11 | Z41: 15 | AA41: 22 | AB41: 14 | AC41: 20 | AD41: 16 | AE41: 18 | AF41: 18 | AG41: =SUM(B41:AF41) -> 541
... A44: 23:00 | B44: 8 | C44: 5 | D44: 16 | E44: 11 | F44: 5 | G44: 15 | H44: 10 | I44: 16 | J44: 15 | K44: 14 | L44: 11 | M44: 19 | N44: 18 | O44: 16 | P44: 14 | Q44: 12 | R44: 7 | S44: 7 | T44: 11 | U44: 14 | V44: 13 | W44: 10 | X44: 10 | Y44: 6 | Z44: 12 | AA44: 17 | AB44: 13 | AC44: 11 | AD44: 5 | AE44: 8 | AF44: 13 | AG44: =SUM(B44:AF44) -> 362
A45: 00:00 | B45: 7 | C45: 11 | D45: 7 | E45: 7 | F45: 7 | G45: 17 | H45: 7 | I45: 5 | J45: 6 | K45: 4 | M45: 10 | N45: 4 | O45: 9 | P45: 8 | Q45: 10 | R45: 4 | S45: 7 | T45: 8 | U45: 9 | W45: 3 | X45: 8 | Y45: 8 | Z45: 8 | AA45: 6 | AB45: 9 | AC45: 15 | AD45: 12 | AE45: 9 | AF45: 7 | AG45: =SUM(B45:AF45) -> 232
A46: 01:00 | B46: 7 | C46: 12 | D46: 8 | E46: 13 | F46: 0 | H46: 4 | I46: 3 | J46: 1 | K46: 2 | L46: 2 | M46: 5 | N46: 10 | O46: 10 | P46: 14 | Q46: 10 | R46: 5 | S46: 5 | T46: 2 | U46: 9 | W46: 5 | X46: 4 | Y46: 7 | Z46: 7 | AA46: 4 | AB46: 11 | AC46: 4 | AD46: 4 | AE46: 0 | AF46: 7 | AG46: =SUM(B46:AF46) -> 175
A47: 02:00 | B47: 5 | C47: 2 | D47: 11 | E47: 1 | F47: 1 | I47: 0 | J47: 4 | K47: 17 | L47: 9 | M47: 3 | N47: 12 | O47: 3 | P47: 4 | Q47: 5 | R47: 9 | S47: 2 | T47: 0 | U47: 14 | W47: 3 | X47: 12 | Y47: 9 | Z47: 4 | AA47: 0 | AB47: 10 | AC47: 5 | AD47: 3 | AE47: 0 | AF47: 1 | AG47: =SUM(B47:AF47) -> 149
A48: 03:00 | B48: 2 | C48: 1 | D48: 10 | E48: 1 | F48: 0 | H48: 3 | I48: 5 | J48: 0 | K48: 0 | M48: 0 | N48: 0 | O48: 11 | P48: 1 | Q48: 1 | R48: 4 | S48: 2 | T48: 3 | U48: 7 | W48: 0 | Y48: 1 | Z48: 5 | AA48: 3 | AB48: 0 | AC48: 1 | AD48: 0 | AE48: 0 | AF48: 2 | AG48: =SUM(B48:AF48) -> 63
A49: 04:00 | B49: 3 | C49: 0 | D49: 2 | E49: 2 | F49: 6 | H49: 1 | I49: 0 | J49: 3 | K49: 0 | M49: 3 | N49: 3 | O49: 0 | P49: 1 | Q49: 1 | R49: 2 | S49: 4 | T49: 1 | U49: 1 | W49: 5 | Y49: 1 | Z49: 5 | AA49: 1 | AB49: 2 | AC49: 1 | AD49: 0 | AE49: 2 | AF49: 4 | AG49: =SUM(B49:AF49) -> 54
A50: 05:00 | B50: 0 | C50: 0 | D50: 3 | E50: 1 | F50: 4 | H50: 1 | I50: 0 | J50: 0 | K50: 0 | M50: 0 | N50: 3 | O50: 0 | P50: 0 | Q50: 5 | R50: 3 | S50: 2 | T50: 0 | U50: 0 | W50: 2 | Y50: 1 | Z50: 2 | AA50: 1 | AB50: 0 | AC50: 0 | AD50: 0 | AE50: 7 | AF50: 1 | AG50: =SUM(B50:AF50) -> 36
A51: 06:00 | B51: 3 | C51: 0 | D51: 0 | E51: 1 | F51: 0 | H51: 1 | I51: 0 | J51: 0 | K51: 0 | M51: 0 | N51: 0 | O51: 0 | P51: 1 | Q51: 2 | R51: 2 | S51: 1 | T51: 0 | U51: 0 | W51: 1 | Y51: 2 | Z51: 1 | AA51: 7 | AB51: 1 | AC51: 3 | AD51: 3 | AE51: 0 | AF51: 2 | AG51: =SUM(B51:AF51) -> 31
A52: 07:00 | B52: 3 | C52: 1 | D52: 0 | E52: 6 | F52: 1 | H52: 1 | I52: 0 | J52: 2 | K52: 0 | M52: 2 | N52: 3 | O52: 2 | P52: 1 | Q52: 3 | R52: 1 | S52: 3 | T52: 6 | U52: 3 | W52: 3 | Y52: 3 | Z52: 0 | AA52: 1 | AB52: 2 | AC52: 4 | AD52: 0 | AE52: 0 | AF52: 0 | AG52: =SUM(B52:AF52) -> 51
A53: Total de NSP | B53: =SUM(B54:B77) -> 8 | C53: =SUM(C54:C77) -> 13 | D53: =SUM(D54:D77) -> 23 | E53: =SUM(E54:E77) -> 6 | F53: =SUM(F54:F77) -> 7 | G53: =SUM(G54:G77) -> 37 | H53: =SUM(H54:H77) -> 31 | I53: =SUM(I54:I77) -> 10 | ... AF53: =SUM(AF54:AF77) -> 20 | AG53: =SUM(B53:AF53) -> 996
A54: 08:00 | J54: 1 | P54: 2 | Y54: 1 | AC54: 1 | AG54: =SUM(B54:AF54) -> 5
...

Sheet ABRIL
A2: ABRIL | B2: 1 | C2: =+B2+1 -> 2 | D2: =+C2+1 -> 3 | E2: =+D2+1 -> 4 | F2: =+E2+1 -> 5 | G2: =+F2+1 -> 6 | H2: =+G2+1 -> 7 | I2: =+H2+1 -> 8 | J2: =+I2+1 -> 9 | ... AA2: =+Z2+1 -> 26 | AB2: 27 | AC2: =+AB2+1 -> 28 | AD2: 29 | AE2: 30 | AF2: 31 | AG2: TOTAL
A3: Total de Inscritos | B3: =SUM(B4:B27) -> 244 | C3: =SUM(C4:C27) -> 221 | D3: =SUM(D4:D27) -> 278 | E3: =SUM(E4:E27) -> 238 | F3: =SUM(F4:F27) -> 264 | G3: =SUM(G4:G27) -> 225 | H3: =SUM(H4:H27) -> 200 | I3: =SUM(I4:I27) -> 227 | ... AF3: =SUM(AF4:AF27) -> 0 | AG3: =SUM(B3:AF3) -> 7514
A4: 08:00 | B4: 8 | C4: 6 | D4: 18 | E4: 19 | F4: 15 | G4: 11 | H4: 14 | I4: 15 | J4: 8 | K4: 21 | L4: 22 | M4: 19 | N4: 18 | O4: 13 | P4: 14 | Q4: 8 | R4: 7 | S4: 16 | T4: 9 | U4: 9 | V4: 14 | W4: 10 | X4: 4 | Y4: 24 | Z4: 13 | AA4: 20 | AB4: 14 | AC4: 15 | AD4: 17 | AE4: 10 | AG4: =SUM(B4:AF4) -> 411
A5: 09:00 | B5: 19 | C5: 13 | D5: 14 | E5: 14 | F5: 15 | G5: 14 | H5: 12 | I5: 7 | J5: 8 | K5: 16 | L5: 24 | M5: 16 | N5: 13 | O5: 14 | P5: 17 | Q5: 6 | R5: 16 | S5: 18 | T5: 15 | U5: 19 | V5: 9 | W5: 18 | X5: 7 | Y5: 21 | Z5: 21 | AA5: 13 | AB5: 12 | AC5: 20 | AD5: 14 | AE5: 19 | AG5: =SUM(B5:AF5) -> 444
A6: 10:00 | B6: 9 | C6: 21 | D6: 17 | E6: 17 | F6: 24 | G6: 11 | H6: 15 | I6: 22 | J6: 21 | K6: 22 | L6: 18 | M6: 29 | N6: 18 | O6: 16 | P6: 17 | Q6: 19 | R6: 15 | S6: 12 | T6: 13 | U6: 20 | V6: 19 | W6: 22 | X6: 20 | Y6: 22 | Z6: 19 | AA6: 11 | AB6: 23 | AC6: 13 | AD6: 28 | AE6: 16 | AG6: =SUM(B6:AF6) -> 549
A7: 11:00 | B7: 25 | C7: 14 | D7: 24 | E7: 14 | F7: 18 | G7: 17 | H7: 18 | I7: 13 | J7: 19 | K7: 27 | L7: 19 | M7: 24 | N7: 18 | O7: 12 | P7: 20 | Q7: 16 | R7: 21 | S7: 18 | T7: 18 | U7: 16 | V7: 14 | W7: 15 | X7: 23 | Y7: 19 | Z7: 28 | AA7: 15 | AB7: 20 | AC7: 20 | AD7: 20 | AE7: 24 | AG7: =SUM(B7:AF7) -> 569
A8: 12:00 | B8: 25 | C8: 15 | D8: 22 | E8: 9 | F8: 16 | G8: 16 | H8: 15 | I8: 13 | J8: 18 | K8: 21 | L8: 22 | M8: 26 | N8: 15 | O8: 11 | P8: 19 | Q8: 18 | R8: 15 | S8: 12 | T8: 13 | U8: 15 | V8: 22 | W8: 9 | X8: 15 | Y8: 32 | Z8: 23 | AA8: 15 | AB8: 17 | AC8: 9 | AD8: 17 | AE8: 20 | AG8: =SUM(B8:AF8) -> 515
A9: 13:00 | B9: 12 | C9: 10 | D9: 11 | E9: 13 | F9: 10 | G9: 13 | H9: 14 | I9: 18 | J9: 11 | K9: 11 | L9: 13 | M9: 10 | N9: 13 | O9: 10 | P9: 11 | Q9: 9 | R9: 8 | S9: 12 | T9: 12 | U9: 10 | V9: 12 | W9: 12 | X9: 22 | Y9: 22 | Z9: 14 | AA9: 18 | AB9: 9 | AC9: 7 | AD9: 15 | AE9: 20 | AG9: =SUM(B9:AF9) -> 382
A10: 14:00 | B10: 9 | C10: 15 | D10: 13 | E10: 7 | F10: 18 | G10: 8 | H10: 10 | I10: 14 | J10: 16 | K10: 18 | L10: 20 | M10: 10 | N10: 11 | O10: 10 | P10: 12 | Q10: 15 | R10: 24 | S10: 14 | T10: 20 | U10: 18 | V10: 11 | W10: 10 | X10: 11 | Y10: 19 | Z10: 22 | AA10: 21 | AB10: 14 | AC10: 5 | AD10: 7 | AE10: 17 | AG10: =SUM(B10:AF10) -> 419
A11: 15:00 | B11: 17 | C11: 17 | D11: 17 | E11: 21 | F11: 15 | G11: 11 | H11: 14 | I11: 15 | J11: 11 | K11: 17 | L11: 18 | M11: 18 | N11: 7 | O11: 18 | P11: 10 | Q11: 15 | R11: 20 | S11: 11 | T11: 12 | U11: 22 | V11: 11 | W11: 15 | X11: 14 | Y11: 20 | Z11: 20 | AA11: 15 | AB11: 20 | AC11: 18 | AD11: 17 | AE11: 9 | AG11: =SUM(B11:AF11) -> 465
A12: 16:00 | B12: 15 | C12: 20 | D12: 26 | E12: 24 | F12: 24 | G12: 16 | H12: 16 | I12: 22 | J12: 10 | K12: 26 | L12: 11 | M12: 21 | N12: 21 | O12: 23 | P12: 8 | Q12: 8 | R12: 29 | S12: 40 | T12: 24 | U12: 26 | V12: 20 | W12: 3 | X12: 10 | Y12: 26 | Z12: 25 | AA12: 24 | AB12: 29 | AC12: 13 | AD12: 18 | AE12: 15 | AG12: =SUM(B12:AF12) -> 593
A13: 17:00 | B13: 18 | C13: 13 | D13: 17 | E13: 21 | F13: 18 | G13: 26 | H13: 15 | I13: 12 | J13: 16 | K13: 28 | L13: 24 | M13: 15 | N13: 21 | O13: 16 | P13: 19 | Q13: 17 | R13: 23 | S13: 24 | T13: 31 | U13: 17 | V13: 19 | W13: 2 | X13: 33 | Y13: 22 | Z13: 21 | AA13: 37 | AB13: 32 | AC13: 23 | AD13: 18 | AE13: 18 | AG13: =SUM(B13:AF13) -> 616
A14: 18:00 | B14: 10 | C14: 17 | D14: 24 | E14: 19 | F14: 21 | G14: 14 | H14: 8 | I14: 14 | J14: 20 | K14: 24 | L14: 21 | M14: 22 | N14: 21 | O14: 17 | P14: 10 | Q14: 15 | R14: 27 | S14: 20 | T14: 19 | U14: 19 | V14: 12 | W14: 9 | X14: 20 | Y14: 25 | Z14: 19 | AA14: 16 | AB14: 19 | AC14: 22 | AD14: 4 | AE14: 15 | AG14: =SUM(B14:AF14) -> 523
A15: 19:00 | B15: 11 | C15: 9 | D15: 14 | E15: 11 | F15: 18 | G15: 13 | H15: 5 | I15: 7 | J15: 9 | K15: 24 | L15: 18 | M15: 13 | N15: 18 | O15: 12 | P15: 5 | Q15: 11 | R15: 17 | S15: 13 | T15: 25 | U15: 21 | V15: 19 | W15: 15 | X15: 9 | Y15: 21 | Z15: 13 | AA15: 15 | AB15: 9 | AC15: 6 | AD15: 9 | AE15: 12 | AG15: =SUM(B15:AF15) -> 402
... A18: 22:00 | B18: 13 | C18: 11 | D18: 7 | E18: 9 | F18: 16 | G18: 10 | H18: 12 | I18: 6 | J18: 7 | K18: 12 | L18: 8 | M18: 7 | N18: 7 | O18: 8 | P18: 6 | Q18: 8 | R18: 6 | S18: 12 | T18: 6 | U18: 12 | V18: 5 | W18: 9 | X18: 12 | Y18: 6 | Z18: 13 | AA18: 10 | AB18: 10 | AC18: 8 | AD18: 6 | AE18: 6 | AG18: =SUM(B18:AF18) -> 268
